Workbook

Sheet Cover
B2: PROJECT ZENITH — SDLC WORKSTREAM | INITIATIVE MODELS & WAVE TEMPLATES
B4: Workstream | C4: SDLC — Raise engineering throughput and reimagine PDLC through agentic loop engineering. ELT sponsor: Srini | WSL: Pooja | IOs: Pooja, Aruna.
B5: Purpose | C5: One file per workstream: each initiative has a Model sheet (all logic and inputs) formula-linked into its own copy of the standard WAVE business-case template. S2 gate: Sep 3/4; S3: Sep 18.
B6: Version / status | C6: v1 — structure complete; SDLC baselines pending data requests (models compute $0 until baseline inputs are populated; impact-driver rates are seeded from the Aug 13 / Board decks).
B7: Prepared | C7: Prepared by AAO model build, 31 Aug 2026. Sources: Project Zenith workplan vS_1; Zenith Business Case Template by Lever (WAVE); Aug 13 deck pp. 9, 19–21; Board deck pp. 12, 22.
B8: Sources | C8: Workplan SDLC tab (initiatives, data POV); SDLC Data Requests tab (12 requests, 4 shared by Pooja); WAVE standard template (reference copy at the end of this file).
B10: HOW THIS FILE IS ORGANIZED
B12: Cover | C12: This sheet — orientation, legend, deviations, open items.
B13: Instructions | C13: The WAVE template's own instruction sheet (as uploaded; dead broken-reference drop-down cells cleared).
B14: Rate Card | C14: Shared people-cost engine: rate basis (yearly/monthly/hourly), role table + blended rate, contingency reference, capitalization policy.
B15: Summary | C15: Portfolio roll-up of both initiatives (links to WAVE sheets).
B16: SDLC-1 Model / SDLC-1 WAVE | C16: Agentic loop engineering — model + linked WAVE template.
B17: SDLC-2 Model / SDLC-2 WAVE | C17: PDLC re-imagination — model + linked WAVE template.
B18: Standard Template | C18: Reference copy of the standard WAVE template (only error-guard fixes applied — see deviations).
B20: COLOR LEGEND
B22: Input — change freely
B23: Formula — do not overwrite
B24: Link to another sheet
B25: Section band
B27: MODEL -> WAVE LINKING
B29: • Each initiative has a '<code> Model' sheet (all logic and inputs) and a '<code> WAVE' sheet (the standard template). The WAVE sheet contains NO hardcoded numbers for this initiative — its benefit/cost rows link (green) to the Model sheet's feed rows in $M.
B30: • Model sheets use the same time grid as WAVE: columns L:P = FY2026–2030 annual, columns T:CA = Jan-2026..Dec-2030 monthly. Annual cells are SUMIFS of the monthly grid, so the WAVE monthly-vs-annual checks (CI1:CM1) pass by construction.
B31: • The 'Ann. Run Rate' (K) on feed rows is defined as the 2030 value, matching the WAVE rule 'Annualized Run Rate (K) = 2030 Value (P)'. Keep ramps reaching 100% before 2030.
B32: • Benefits ramp linearly from the go-live date over 'months to full run rate' — same convention as the Servicing S2 model. One-time costs spread evenly over each milestone's billing months.
B33: • People costs: milestone labor = Team size x Billing months x blended monthly rate (Rate Card) x (1 + contingency). Capitalization: each milestone carries a Cap % (default from Rate Card policy) that splits labor into WAVE CapEx vs OTC rows. Same for non-labor one-time items.
B35: DEVIATIONS FROM THE STANDARD WAVE TEMPLATE (documented fixes)
... B51: • Capitalization %s (Build/Test 80% default) need Finance sign-off (ASC 350-40).

Sheet Instructions
L1: 1 | M1: 2 | N1: 3 | O1: 4 | P1: 5 | R1: =COUNTIFS($R$78:$R$128, "Error") -> 0 | T1: 2026 | U1: 2026 | V1: 2026 | W1: 2026 | X1: 2026 | Y1: 2026 | Z1: 2026 | AA1: 2026 | AB1: 2026 | AC1: 2026 | AD1: 2026 | AE1: 2026 | AF1: 2027 | AG1: 2027 | AH1: 2027 | AI1: 2027 | AJ1: 2027 | AK1: 2027 | AL1: 2027 | AM1: 2027 | AN1: 2027 | AO1: 2027 | AP1: 2027 | AQ1: 2027 | AR1: 2028 | AS1: 2028 | AT1: 2028 | AU1: 2028 | AV1: 2028 | AW1: 2028 | AX1: 2028 | AY1: 2028 | AZ1: 2028 | BA1: 2028 | BB1: 2028 | BC1: 2028 | BD1: 2029 | BE1: 2029 | BF1: 2029 | BG1: 2029 | BH1: 2029 | BI1: 2029 | BJ1: 2029 | BK1: 2029 | BL1: 2029 | BM1: 2029 | BN1: 2029 | BO1: 2029 | BP1: 2030 | BQ1: 2030 | BR1: 2030 | BS1: 2030 | BT1: 2030 | BU1: 2030 | BV1: 2030 | BW1: 2030 | BX1: 2030 | BY1: 2030 | BZ1: 2030 | CA1: 2030 | CI1: =COUNTIFS(CI$78:CI$159, "FALSE") -> 0 | CJ1: =COUNTIFS(CJ$78:CJ$159, "FALSE") -> 4 | CK1: =COUNTIFS(CK$78:CK$159, "FALSE") -> 4 | CL1: =COUNTIFS(CL$78:CL$159, "FALSE") -> 0 | CM1: =COUNTIFS(CM$78:CM$159, "FALSE") -> 0
C9: ="#"&$F$13&" Initiative Business Case" -> #123456 Initiative Business Case
C11: INPUTS & ASSUMPTIONS
D13: Initiative # | F13: 123456
D14: Initiative Owner | F14: John Smith
D15: Initiative Name | F15: Leverage agentic AI for customer service and care centers, reducing number of calls handled by live customer care agents and increasing productivity | I15: Names - 5-7 words
I16: Descriptions - 10-20 words
D18: Estimated L4 date | F18: 46736
D19: Net Recurring Benefit ($M) | F19: =$K$128 -> 7.2
C21: SECTION I - PRIMARY VALUE DRIVER (ILLUSTRATIVE) | L21: CHECKS
D23: Illustrative example of value driver explanation - please edit fields to reflect value drivers for your Initiative | L23: Criteria (Column Reference) | P23: Check | Q23: Troubleshoot:
D24: Baseline | H24: Period | I24: KPI | J24: Inputs | L24: (A) Annualized Run Rate (K) = 2030 Value (P) | P24: =IF($R$1=0, "PASS", "ERROR") -> PASS | Q24: =IF(P24="Error", "Check column R for errors", "")
E25: # of calls handled by live agents | G25: [A] | H25: FY2025 | I25: # of calls | J25: 6000 | L25: (B) 2026 Value (L) = Sum of Monthly 2026 Values (CC) | P25: =IF($CI$1=0, "PASS", "ERROR") -> PASS | Q25: =IF(P25="Error", "Check column CI for errors", "")
E26: AHT | G26: [B] | H26: FY 2026 | I26: Seconds | J26: 150 | L26: (C) 2027 Value (M) = Sum of Monthly 2027 Values (CD) | P26: =IF($CJ$1=0, "PASS", "ERROR") -> ERROR | Q26: =IF(P26="Error", "Check column CJ for errors", "") -> Check column CJ for errors
E27: # of live agents handling calls | G27: [C] | H27: FY 2025 | I27: # of live agents | J27: 500 | L27: (D) 2028 Value (N) = Sum of Monthly 2028 Values (CE) | P27: =IF($CK$1=0, "PASS", "ERROR") -> ERROR | Q27: =IF(P27="Error", "Check column CK for errors", "") -> Check column CK for errors
E28: Average cost per agent | H28: FY 2026 | I28: $ / agent | J28: 50000 | L28: (E) 2029 Value (O) = Sum of Monthly 2029 Values (CF) | P28: =IF($CL$1=0, "PASS", "ERROR") -> PASS | Q28: =IF(P28="Error", "Check column CL for errors", "")
E29: Total spend on contact center for queue X | G29: [D] | H29: FY2025 | I29: $USD M | J29: =(J27*J28)/1000000 -> 25 | L29: (F) 2030 Value (P) = Sum of Monthly 2030 Values (CG) | P29: =IF($CM$1=0, "PASS", "ERROR") -> PASS | Q29: =IF(P29="Error", "Check column CM for errors", "")
D31: Goal | Y31: D
E32: # of calls handled by live agents | G32: [E] | I32: # of calls | J32: 4000
E33: AHT | G33: [F] | I33: Seconds | J33: 120
E34: # of live agents handling calls | G34: [G] | I34: # of live agents | J34: 260
E35: Average cost per agent | I35: $ / agent | J35: =J28 -> 50000
E36: Total spend on contact center for queue X | G36: [H] | H36: FY2026 | I36: $USD M | J36: =(J34*J35)/1000000 -> 13
D38: Incremental Improvement
E39: # of calls handled by live agents | G39: [A]-[E] | I39: # of calls | J39: =J25-J32 -> 2000
E40: AHT | G40: [B]-[F] | I40: Seconds | J40: =J26-J33 -> 30
E41: # of live agents handling calls | G41: [C]-[G] | I41: # of live agents | J41: =J27-J34 -> 240
E42: Total spend on contact center queue X | G42: [D]-[H] | I42: USD M | J42: =J29-J36 -> 12
D43: Baseline | H43: Period | I43: $USD M | J43: Inputs
E44: # xxxx | H44: FY2025 | I44: # xxxx | J44: 12000000
E45: xxxx unit cost | G45: [A] | H45: FY2025 | I45: $ xxxx | J45: 0.14
E46: xxxx total spend | G46: [B] | H46: FY2025 | I46: $USD K | J46: =(J44*J45)/1000 -> 1680
D48: Goal
E49: # xxxx | H49: FY2025 | I49: # xxxx | J49: =$J$25 -> 6000
E50: xxxx unit cost | G50: [C] | H50: FY2026 | I50: $ xxxx | J50: 0.1
E51: xxxx total spend | G51: [D] | H51: FY2026 | I51: $USD K | J51: =(J49*J50)/1000 -> 0.6
D53: Incremental Improvement
E54: =E50 -> xxxx unit cost | G54: [A]-[C] | I54: $ / xxxx | J54: =J45-J50 -> 0.04
E55: =E51 -> xxxx total spend | G55: [B]-[D] | I55: $USD K | J55: =J46-J51 -> 1679.4
D58: Baseline | H58: Period | I58: KPI | J58: Inputs
...

Sheet Rate Card
B2: RATE CARD — people-cost engine (shared by all initiative models)
B4: Blue cells with yellow fill = inputs you can change. Black = formulas. All initiative models pull the blended rate and policy tables from this sheet.
B6: 1. RATE BASIS
B8: Rate basis for people costs | D8: Yearly | F8: Choose how role rates are quoted, then TYPE YOUR RATES in the matching column of the role table below (Yearly->col D, Monthly->col E, Hourly->col F). The other columns show derived equivalents until you overwrite them. Hourly => monthly = $/hr x hours/day x days/month.
B10: Working hours per day | D10: 8 | F10: Used only when rate basis = Hourly.
B11: Billable days per month | D11: 21
B12: Months per year (for yearly basis) | D12: 12
B14: 2. STANDARD TEAM COMPOSITION & BLENDED RATE
B16: Role | C16: # in std team | D16: Yearly rate ($/yr) | E16: Monthly rate ($/mo) | F16: Hourly rate ($/hr) | G16: Monthly used ($/mo) | H16: Team cost ($/mo) | I16: Source / notes
B17: Engineer | C17: 3 | D17: 180000 | E17: =IF(D17="",0,D17/$D$12) -> 15000 | F17: =IF(D17="",0,E17/($D$10*$D$11)) -> 89.285714 | G17: =IF($D$8="Hourly",F17*$D$10*$D$11,IF($D$8="Monthly",E17,IF(D17="",0,D17/$D$12))) -> 15000 | H17: =IF(C17="",0,C17*G17) -> 45000
B18: QA Engineer | C18: 2 | D18: 140000 | E18: =IF(D18="",0,D18/$D$12) -> 11666.667 | F18: =IF(D18="",0,E18/($D$10*$D$11)) -> 69.444444 | G18: =IF($D$8="Hourly",F18*$D$10*$D$11,IF($D$8="Monthly",E18,IF(D18="",0,D18/$D$12))) -> 11666.667 | H18: =IF(C18="",0,C18*G18) -> 23333.333
B19: Solution Architect | C19: 1 | D19: 220000 | E19: =IF(D19="",0,D19/$D$12) -> 18333.333 | F19: =IF(D19="",0,E19/($D$10*$D$11)) -> 109.12698 | G19: =IF($D$8="Hourly",F19*$D$10*$D$11,IF($D$8="Monthly",E19,IF(D19="",0,D19/$D$12))) -> 18333.333 | H19: =IF(C19="",0,C19*G19) -> 18333.333
B20: Product Manager | C20: 1 | D20: 190000 | E20: =IF(D20="",0,D20/$D$12) -> 15833.333 | F20: =IF(D20="",0,E20/($D$10*$D$11)) -> 94.246032 | G20: =IF($D$8="Hourly",F20*$D$10*$D$11,IF($D$8="Monthly",E20,IF(D20="",0,D20/$D$12))) -> 15833.333 | H20: =IF(C20="",0,C20*G20) -> 15833.333
B21: Data Engineer | C21: 1 | D21: 185000 | E21: =IF(D21="",0,D21/$D$12) -> 15416.667 | F21: =IF(D21="",0,E21/($D$10*$D$11)) -> 91.765873 | G21: =IF($D$8="Hourly",F21*$D$10*$D$11,IF($D$8="Monthly",E21,IF(D21="",0,D21/$D$12))) -> 15416.667 | H21: =IF(C21="",0,C21*G21) -> 15416.667
B22: ML Engineer | C22: 1 | D22: 210000 | E22: =IF(D22="",0,D22/$D$12) -> 17500 | F22: =IF(D22="",0,E22/($D$10*$D$11)) -> 104.16667 | G22: =IF($D$8="Hourly",F22*$D$10*$D$11,IF($D$8="Monthly",E22,IF(D22="",0,D22/$D$12))) -> 17500 | H22: =IF(C22="",0,C22*G22) -> 17500
B23: Program Manager | C23: 1 | D23: 170000 | E23: =IF(D23="",0,D23/$D$12) -> 14166.667 | F23: =IF(D23="",0,E23/($D$10*$D$11)) -> 84.325397 | G23: =IF($D$8="Hourly",F23*$D$10*$D$11,IF($D$8="Monthly",E23,IF(D23="",0,D23/$D$12))) -> 14166.667 | H23: =IF(C23="",0,C23*G23) -> 14166.667
E24: =IF(D24="",0,D24/$D$12) -> 0 | F24: =IF(D24="",0,E24/($D$10*$D$11)) -> 0 | G24: =IF($D$8="Hourly",F24*$D$10*$D$11,IF($D$8="Monthly",E24,IF(D24="",0,D24/$D$12))) -> 0 | H24: =IF(C24="",0,C24*G24) -> 0 | I24: spare row — add roles as team shape is refined
E25: =IF(D25="",0,D25/$D$12) -> 0 | F25: =IF(D25="",0,E25/($D$10*$D$11)) -> 0 | G25: =IF($D$8="Hourly",F25*$D$10*$D$11,IF($D$8="Monthly",E25,IF(D25="",0,D25/$D$12))) -> 0 | H25: =IF(C25="",0,C25*G25) -> 0 | I25: spare row — add roles as team shape is refined
E26: =IF(D26="",0,D26/$D$12) -> 0 | F26: =IF(D26="",0,E26/($D$10*$D$11)) -> 0 | G26: =IF($D$8="Hourly",F26*$D$10*$D$11,IF($D$8="Monthly",E26,IF(D26="",0,D26/$D$12))) -> 0 | H26: =IF(C26="",0,C26*G26) -> 0 | I26: spare row — add roles as team shape is refined
B27: Total standard team | C27: =SUM(C17:C26) -> 10 | H27: =SUM(H17:H26) -> 149583.33
B29: BLENDED RATE — per team member | G29: =IF(C27=0,0,H27/C27) -> 14958.333 | H29: $/person/month | I29: Weighted average monthly cost of one member of the standard team. Initiative milestone tables use this unless a rate override is entered.
G30: =G29*$D$12 -> 179500 | H30: $/person/year
G31: =G29/($D$10*$D$11) -> 89.037698 | H31: $/person/hour
B33: 3. CONTINGENCY FACTOR REFERENCE
B35: Complexity / risk level | C35: Factor | F35: Based on the complexity and risks to deliver the milestone.
B36: Low | C36: 0.1
B37: Medium | C37: 0.15
B38: High | C38: 0.2
B39: Very high | C39: 0.5
B42: 4. CAPITALIZATION POLICY (labor) — default % of milestone labor capitalizable
B44: Milestone | C44: Cap % | F44: Share of labor cost treated as CapEx (feeds WAVE 'Capital Expenditures'); remainder is expensed one-time cost (WAVE 'OTC'). Defaults follow a typical internal-use software policy (ASC 350-40): application development/build stage capitalizable, planning and post-launch expensed. CONFIRM WITH FINANCE — initiative models reference these cells, override there if needed.
B45: Plan / Design | C45: 0
B46: Build / Test | C46: 0.8
B47: Pilot / Change Mgmt. | C47: 0
B48: Scale / Run | C48: 0
B49: Non-labor one-time (default) | C49: 0
B51: 5. NOTES
B52: • Role rates are PLACEHOLDERS — replace with the PayPal/FP&A rate card. For reference, the Servicing S2 model uses a $200,000/yr blended loaded delivery FTE rate (+10% delivery risk) and $180,000/yr for run-team FTEs.
B53: • Team composition mirrors the standard AAO delivery-pod thinking; add/remove roles as the initiative team shapes firm up (spare rows provided).
B54: • Build/Test capitalization default of 80% follows a typical internal-use software policy (application development stage capitalizable) — CONFIRM WITH FINANCE before S3.

Sheet Summary
B2: SDLC WORKSTREAM — PORTFOLIO SUMMARY ($M)
B3: All figures link to the initiative WAVE sheets. Payback/NPV per WAVE Section IV.
B5: Initiative | C5: NRB run rate | D5: NRB 2026 | E5: NRB 2027 | F5: NRB 2028 | G5: NRB 2029 | H5: NRB 2030 | I5: One-time cost (5yr) | J5: Run cost 2030 | K5: NPV (5yr) | L5: Payback (yrs)
B6: SDLC-1 — Agentic Loop Engineering | C6: ='SDLC-1 WAVE'!$K$117 -> 0 | D6: ='SDLC-1 WAVE'!$L$117 -> 0 | E6: ='SDLC-1 WAVE'!$M$117 -> 0 | F6: ='SDLC-1 WAVE'!$N$117 -> 0 | G6: ='SDLC-1 WAVE'!$O$117 -> 0 | H6: ='SDLC-1 WAVE'!$P$117 -> 0 | I6: =SUM('SDLC-1 WAVE'!$L$147:$P$147) -> 1.5247089 | J6: ='SDLC-1 WAVE'!$P$115 -> 0 | K6: ='SDLC-1 WAVE'!$G$168 -> -1.2988552 | L6: ='SDLC-1 WAVE'!$G$165 -> >5
B7: SDLC-2 — PDLC Re-imagination | C7: ='SDLC-2 WAVE'!$K$117 -> 0 | D7: ='SDLC-2 WAVE'!$L$117 -> 0 | E7: ='SDLC-2 WAVE'!$M$117 -> 0 | F7: ='SDLC-2 WAVE'!$N$117 -> 0 | G7: ='SDLC-2 WAVE'!$O$117 -> 0 | H7: ='SDLC-2 WAVE'!$P$117 -> 0 | I7: =SUM('SDLC-2 WAVE'!$L$147:$P$147) -> 1.5247089 | J7: ='SDLC-2 WAVE'!$P$115 -> 0 | K7: ='SDLC-2 WAVE'!$G$168 -> -1.2863017 | L7: ='SDLC-2 WAVE'!$G$165 -> >5
B8: TOTAL — SDLC WORKSTREAM | C8: =SUM(C6:C7) -> 0 | D8: =SUM(D6:D7) -> 0 | E8: =SUM(E6:E7) -> 0 | F8: =SUM(F6:F7) -> 0 | G8: =SUM(G6:G7) -> 0 | H8: =SUM(H6:H7) -> 0 | I8: =SUM(I6:I7) -> 3.0494178 | J8: =SUM(J6:J7) -> 0
B10: Note: NPV and payback are not additive across initiatives; totals shown for benefit/cost columns only.
B11: Capitalization policy note: this file defaults Build/Test labor to 80% capitalizable (Rate Card) pending Finance sign-off; the Servicing file defaults to 0% to mirror the S2 model's all-cash treatment. Align the policy across workstreams with Finance before the S2 gate.

Sheet SDLC-1 Model
B2: SDLC-1 — Agentic Loop Engineering | INITIATIVE MODEL
B3: Workstream: SDLC (ELT sponsor: Srini | WSL: Pooja | IOs: Pooja, Aruna) • Model status: Structure ready; baselines PENDING data requests — see open items
T5: 2026 | U5: 2026 | V5: 2026 | W5: 2026 | X5: 2026 | Y5: 2026 | Z5: 2026 | AA5: 2026 | AB5: 2026 | AC5: 2026 | AD5: 2026 | AE5: 2026 | AF5: 2027 | AG5: 2027 | AH5: 2027 | AI5: 2027 | AJ5: 2027 | AK5: 2027 | AL5: 2027 | AM5: 2027 | AN5: 2027 | AO5: 2027 | AP5: 2027 | AQ5: 2027 | AR5: 2028 | AS5: 2028 | AT5: 2028 | AU5: 2028 | AV5: 2028 | AW5: 2028 | AX5: 2028 | AY5: 2028 | AZ5: 2028 | BA5: 2028 | BB5: 2028 | BC5: 2028 | BD5: 2029 | BE5: 2029 | BF5: 2029 | BG5: 2029 | BH5: 2029 | BI5: 2029 | BJ5: 2029 | BK5: 2029 | BL5: 2029 | BM5: 2029 | BN5: 2029 | BO5: 2029 | BP5: 2030 | BQ5: 2030 | BR5: 2030 | BS5: 2030 | BT5: 2030 | BU5: 2030 | BV5: 2030 | BW5: 2030 | BX5: 2030 | BY5: 2030 | BZ5: 2030 | CA5: 2030
B6: Monthly grid (Jan-26 → Dec-30) → | K6: Run rate | L6: 2026 | M6: 2027 | N6: 2028 | O6: 2029 | P6: 2030 | T6: =DATE(2026,1,31) -> 46053 | U6: =EOMONTH(T6,1) -> 46081 | V6: =EOMONTH(U6,1) -> 46112 | W6: =EOMONTH(V6,1) -> 46142 | X6: =EOMONTH(W6,1) -> 46173 | Y6: =EOMONTH(X6,1) -> 46203 | Z6: =EOMONTH(Y6,1) -> 46234 | AA6: =EOMONTH(Z6,1) -> 46265 | AB6: =EOMONTH(AA6,1) -> 46295 | ... CA6: =EOMONTH(BZ6,1) -> 47848
B8: 0. INITIATIVE & STATUS
B10: Initiative name | D10: Agentic loop engineering — raise engineering throughput on the residual addressable base
B11: Initiative owner | D11: Pooja (WSL) — initiative owner TBC | I11: confirm with workstream lead
B12: Impacted BU | D12: CTO / SDLC
B13: Go-live / Estimated L4 date | D13: =DATE(2027,5,1) -> 46508 | I13: Benefit ramp is gated on this date.
B15: Source: Workplan: 'Project Zenith Automation workplan and data requests vS_1.xlsx', SDLC tab + SDLC Data Requests tab
B16: Source: Impact ranges: Aug 13 deck pp. 9, 19–21; Board deck pp. 12, 22 (preliminary — Finance to validate)
B17: Open items to refine with initiative owner:
B18: – FTE/CW population and fully loaded cost baseline pending (SDLC data request #1 — Thom/Thanh (SDLC), ETO (PDLC)); all baseline inputs below are 0 until received.
B19: – Banked Code Assist savings to reconcile so the residual addressable base nets them out (W3 objective).
B20: – Adoption ramp by domain/role pending (request #3); 20-domain harness build plan shared by Pooja (request #12).
B21: – Token consumption benchmark by role shared for SDLC (request #11) — to be validated, then wire into run costs.
B22: – Build shape below mirrors the Servicing S2 delivery pod as a placeholder — refine with IOs before S3.
B24: 1. SIZING ASSUMPTIONS (blue = inputs — refine with initiative owner)
B26: Baseline / denominator (PENDING data request #1)
B27: CTO SWE IC FTE population — in scope | D27: 0 | E27: # FTE | F27: PENDING — placeholder, not data. Data request #1 (Thom/Thanh)
B28: CTO SWE CW population — in scope | D28: 0 | E28: # CW | F28: PENDING — placeholder, not data. Data request #1
B29: Avg fully loaded cost per SWE FTE | D29: 0 | E29: $/yr | F29: PENDING — placeholder, not data. Data request #1
B30: Avg fully loaded cost per CW | D30: 0 | E30: $/yr | F30: PENDING — placeholder, not data. Data request #1
B31: Code Assist savings already banked (annual) | D31: 0 | E31: $/yr | F31: PENDING — placeholder, not data. Reconcile with Finance; netted out of the addressable base to avoid double count
B32: Impact drivers (Aug 13 deck pp. 9, 19–21 — preliminary, Finance to validate)
B33: Incremental productivity uplift on residual base | D33: 0.15 | E33: % | F33: PLACEHOLDER pending validation — source materials cite ~$173–204M total SDLC opportunity
B34: Steady-state adoption (share of population on harness) | D34: 0.8 | E34: % | F34: PLACEHOLDER — adoption ramp by domain/role pending (request #3)
B35: Capture rate — capacity converted to bankable cost | D35: 0.65 | E35: % | F35: PLACEHOLDER — capacity-to-cost capture and redeployment logic to agree with Finance
B36: Investment uplifts (consistent with Servicing S2 standard)
B37: Programme management, % of build | D37: 0.08 | E37: % | F37: Same standard as Servicing S2 (8%)
B38: Contingency, % of build incl. PM | D38: 0.1 | E38: % | F38: Same standard as Servicing S2 (10%)
B39: (spare assumption row)
B40: (spare assumption row)
B42: 2. BENEFIT CALCULATION (steady-state annual run-rate)
B44: Total in-scope engineering labor base | D44: =($D$27*$D$29+$D$28*$D$30) -> 0 | E44: $/yr | F44: FTE x cost + CW x cost
B45: Residual addressable base (net of banked Code Assist) | D45: =MAX($D$44-$D$31,0) -> 0 | E45: $/yr
B46: Gross capacity value created | D46: =$D$45*$D$33*$D$34 -> 0 | E46: $/yr | F46: Residual base x productivity uplift x adoption
B47: Bankable annual benefit (steady state) | D47: =$D$46*$D$35 -> 0 | E47: $/yr | F47: x capture rate — the benefit line that feeds WAVE
B49: 3. RAMP & PHASING
B51: Months to full run rate after go-live (linear ramp) | D51: 12 | F51: Benefit starts at go-live and ramps linearly to steady state over this many months.
...

Sheet SDLC-1 WAVE
L1: 1 | M1: 2 | N1: 3 | O1: 4 | P1: 5 | R1: =COUNTIFS($R$66:$R$117, "Error") -> 0 | T1: 2026 | U1: 2026 | V1: 2026 | W1: 2026 | X1: 2026 | Y1: 2026 | Z1: 2026 | AA1: 2026 | AB1: 2026 | AC1: 2026 | AD1: 2026 | AE1: 2026 | AF1: 2027 | AG1: 2027 | AH1: 2027 | AI1: 2027 | AJ1: 2027 | AK1: 2027 | AL1: 2027 | AM1: 2027 | AN1: 2027 | AO1: 2027 | AP1: 2027 | AQ1: 2027 | AR1: 2028 | AS1: 2028 | AT1: 2028 | AU1: 2028 | AV1: 2028 | AW1: 2028 | AX1: 2028 | AY1: 2028 | AZ1: 2028 | BA1: 2028 | BB1: 2028 | BC1: 2028 | BD1: 2029 | BE1: 2029 | BF1: 2029 | BG1: 2029 | BH1: 2029 | BI1: 2029 | BJ1: 2029 | BK1: 2029 | BL1: 2029 | BM1: 2029 | BN1: 2029 | BO1: 2029 | BP1: 2030 | BQ1: 2030 | BR1: 2030 | BS1: 2030 | BT1: 2030 | BU1: 2030 | BV1: 2030 | BW1: 2030 | BX1: 2030 | BY1: 2030 | BZ1: 2030 | CA1: 2030 | CI1: =COUNTIFS(CI$66:CI$149, "FALSE") -> 0 | CJ1: =COUNTIFS(CJ$66:CJ$149, "FALSE") -> 0 | CK1: =COUNTIFS(CK$66:CK$149, "FALSE") -> 0 | CL1: =COUNTIFS(CL$66:CL$149, "FALSE") -> 0 | CM1: =COUNTIFS(CM$66:CM$149, "FALSE") -> 0
C2: ="#"&$F$6&" Initiative Business Case" -> #TBD Initiative Business Case
C4: INPUTS & ASSUMPTIONS
D6: Initiative # | F6: TBD
D7: Initiative Owner | F7: Pooja (WSL) — initiative owner TBC
D8: Initiative Name | F8: Agentic loop engineering — raise engineering throughput on the residual addressable base
D11: Estimated L4 date | F11: ='SDLC-1 Model'!$D$13 -> 46508
D12: Net Recurring Benefit ($M) | F12: =$K$117 -> 0
C14: SECTION I - PRIMARY VALUE DRIVER (ILLUSTRATIVE)
D16: Primary value driver — linked to the Model sheet; refine with the initiative owner
D17: Baseline | H17: Period | I17: KPI | J17: Inputs
E18: Total in-scope engineering labor base | H18: TTM 6/1/26 | I18: $USD M | J18: ='SDLC-1 Model'!$D$44/1000000 -> 0
E19: Code Assist savings already banked | H19: TTM 6/1/26 | I19: $USD M | J19: ='SDLC-1 Model'!$D$31/1000000 -> 0
E20: Residual addressable base | H20: TTM 6/1/26 | I20: $USD M | J20: ='SDLC-1 Model'!$D$45/1000000 -> 0
D23: Goal
E24: Productivity uplift x steady-state adoption | H24: Steady state | I24: % | J24: ='SDLC-1 Model'!$D$33*'SDLC-1 Model'!$D$34 -> 0.12
E25: Capture rate to bankable cost | H25: Steady state | I25: % | J25: ='SDLC-1 Model'!$D$35 -> 0.65
D28: Incremental Improvement
E29: Bankable annual benefit (run rate) | I29: $USD M | J29: ='SDLC-1 Model'!$D$47/1000000 -> 0
C60: SECTION II - NET RECURRING BENEFITS | CC60: ANNUAL SUMMARY | CI60: CHECK CELLS
T62: 2026 | AF62: 2027 | AR62: 2028 | BD62: 2029 | BP62: 2030 | CI62: CHECK
D63: RECURRING BENEFITS | H63: Comment | I63: Baseline | J63: Goal | K63: Ann. Run Rate | L63: 2026 | M63: =L63+1 -> 2027 | N63: =M63+1 -> 2028 | O63: =N63+1 -> 2029 | P63: =O63+1 -> 2030 | Q63: Impacted BU | R63: Check | T63: 46023 | U63: =EOMONTH(T63, 1) -> 46081 | V63: =EOMONTH(U63, 1) -> 46112 | W63: =EOMONTH(V63, 1) -> 46142 | X63: =EOMONTH(W63, 1) -> 46173 | Y63: =EOMONTH(X63, 1) -> 46203 | Z63: =EOMONTH(Y63, 1) -> 46234 | AA63: =EOMONTH(Z63, 1) -> 46265 | AB63: =EOMONTH(AA63, 1) -> 46295 | ... CA63: =EOMONTH(BZ63, 1) -> 47848 | CC63: 2026 | CD63: =CC63+1 -> 2027 | CE63: =CD63+1 -> 2028 | CF63: =CE63+1 -> 2029 | CG63: =CF63+1 -> 2030 | CI63: 2026 | CJ63: =CI63+1 -> 2027 | CK63: =CJ63+1 -> 2028 | CL63: =CK63+1 -> 2029 | CM63: =CL63+1 -> 2030
E64: $USD M | I64: =$H$18 -> TTM 6/1/26 | J64: Future State | K64: Increment
E65: Revenue
I66: 0 | J66: 0 | K66: =J66-I66 -> 0 | R66: =IF(K66=P66, "", "Error") | CC66: =SUMIFS($T66:$CA66, $T$1:$CA$1, CC$63) -> 0 | CD66: =SUMIFS($T66:$CA66, $T$1:$CA$1, CD$63) -> 0 | CE66: =SUMIFS($T66:$CA66, $T$1:$CA$1, CE$63) -> 0 | CF66: =SUMIFS($T66:$CA66, $T$1:$CA$1, CF$63) -> 0 | CG66: =SUMIFS($T66:$CA66, $T$1:$CA$1, CG$63) -> 0 | CI66: =CC66=L66 -> 1 | CJ66: =CD66=M66 -> 1 | CK66: =CE66=N66 -> 1 | CL66: =CF66=O66 -> 1 | CM66: =CG66=P66 -> 1
I67: 0 | J67: 0 | K67: =J67-I67 -> 0 | R67: =IF(K67=P67, "", "Error") | CC67: =SUMIFS($T67:$CA67, $T$1:$CA$1, CC$63) -> 0 | CD67: =SUMIFS($T67:$CA67, $T$1:$CA$1, CD$63) -> 0 | CE67: =SUMIFS($T67:$CA67, $T$1:$CA$1, CE$63) -> 0 | CF67: =SUMIFS($T67:$CA67, $T$1:$CA$1, CF$63) -> 0 | CG67: =SUMIFS($T67:$CA67, $T$1:$CA$1, CG$63) -> 0 | CI67: =CC67=L67 -> 1 | CJ67: =CD67=M67 -> 1 | CK67: =CE67=N67 -> 1 | CL67: =CF67=O67 -> 1 | CM67: =CG67=P67 -> 1
E68: Revenue Subtotal | I68: =SUM(I66:I67) -> 0 | J68: =SUM(J66:J67) -> 0 | K68: =SUM(K66:K67) -> 0 | L68: =SUM(L66:L67) -> 0 | M68: =SUM(M66:M67) -> 0 | N68: =SUM(N66:N67) -> 0 | O68: =SUM(O66:O67) -> 0 | P68: =SUM(P66:P67) -> 0 | T68: =SUM(T66:T67) -> 0 | U68: =SUM(U66:U67) -> 0 | V68: =SUM(V66:V67) -> 0 | W68: =SUM(W66:W67) -> 0 | X68: =SUM(X66:X67) -> 0 | Y68: =SUM(Y66:Y67) -> 0 | Z68: =SUM(Z66:Z67) -> 0 | AA68: =SUM(AA66:AA67) -> 0 | ... CA68: =SUM(CA66:CA67) -> 0 | CC68: =SUM(CC66:CC67) -> 0 | CD68: =SUM(CD66:CD67) -> 0 | CE68: =SUM(CE66:CE67) -> 0 | CF68: =SUM(CF66:CF67) -> 0 | CG68: =SUM(CG66:CG67) -> 0 | CI68: =CC68=L68 -> 1 | CJ68: =CD68=M68 -> 1 | CK68: =CE68=N68 -> 1 | CL68: =CF68=O68 -> 1 | CM68: =CG68=P68 -> 1
E70: Cost of Sales
K71: =I71-J71 -> 0 | R71: =IF(K71=P71, "", "Error") | CC71: =SUMIFS($T71:$CA71, $T$1:$CA$1, CC$63) -> 0 | CD71: =SUMIFS($T71:$CA71, $T$1:$CA$1, CD$63) -> 0 | CE71: =SUMIFS($T71:$CA71, $T$1:$CA$1, CE$63) -> 0 | CF71: =SUMIFS($T71:$CA71, $T$1:$CA$1, CF$63) -> 0 | CG71: =SUMIFS($T71:$CA71, $T$1:$CA$1, CG$63) -> 0 | CI71: =CC71=L71 -> 1 | CJ71: =CD71=M71 -> 1 | CK71: =CE71=N71 -> 1 | CL71: =CF71=O71 -> 1 | CM71: =CG71=P71 -> 1
I72: 0 | J72: 0 | K72: =I72-J72 -> 0 | R72: =IF(K72=P72, "", "Error") | CC72: =SUMIFS($T72:$CA72, $T$1:$CA$1, CC$63) -> 0 | CD72: =SUMIFS($T72:$CA72, $T$1:$CA$1, CD$63) -> 0 | CE72: =SUMIFS($T72:$CA72, $T$1:$CA$1, CE$63) -> 0 | CF72: =SUMIFS($T72:$CA72, $T$1:$CA$1, CF$63) -> 0 | CG72: =SUMIFS($T72:$CA72, $T$1:$CA$1, CG$63) -> 0 | CI72: =CC72=L72 -> 1 | CJ72: =CD72=M72 -> 1 | CK72: =CE72=N72 -> 1 | CL72: =CF72=O72 -> 1 | CM72: =CG72=P72 -> 1
I73: 0 | J73: 0 | K73: =I73-J73 -> 0 | R73: =IF(K73=P73, "", "Error") | CC73: =SUMIFS($T73:$CA73, $T$1:$CA$1, CC$63) -> 0 | CD73: =SUMIFS($T73:$CA73, $T$1:$CA$1, CD$63) -> 0 | CE73: =SUMIFS($T73:$CA73, $T$1:$CA$1, CE$63) -> 0 | CF73: =SUMIFS($T73:$CA73, $T$1:$CA$1, CF$63) -> 0 | CG73: =SUMIFS($T73:$CA73, $T$1:$CA$1, CG$63) -> 0 | CI73: =CC73=L73 -> 1 | CJ73: =CD73=M73 -> 1 | CK73: =CE73=N73 -> 1 | CL73: =CF73=O73 -> 1 | CM73: =CG73=P73 -> 1
I74: 0 | J74: 0 | K74: =I74-J74 -> 0 | R74: =IF(K74=P74, "", "Error") | CC74: =SUMIFS($T74:$CA74, $T$1:$CA$1, CC$63) -> 0 | CD74: =SUMIFS($T74:$CA74, $T$1:$CA$1, CD$63) -> 0 | CE74: =SUMIFS($T74:$CA74, $T$1:$CA$1, CE$63) -> 0 | CF74: =SUMIFS($T74:$CA74, $T$1:$CA$1, CF$63) -> 0 | CG74: =SUMIFS($T74:$CA74, $T$1:$CA$1, CG$63) -> 0 | CI74: =CC74=L74 -> 1 | CJ74: =CD74=M74 -> 1 | CK74: =CE74=N74 -> 1 | CL74: =CF74=O74 -> 1 | CM74: =CG74=P74 -> 1
K75: =I75-J75 -> 0 | R75: =IF(K75=P75, "", "Error") | CC75: =SUMIFS($T75:$CA75, $T$1:$CA$1, CC$63) -> 0 | CD75: =SUMIFS($T75:$CA75, $T$1:$CA$1, CD$63) -> 0 | CE75: =SUMIFS($T75:$CA75, $T$1:$CA$1, CE$63) -> 0 | CF75: =SUMIFS($T75:$CA75, $T$1:$CA$1, CF$63) -> 0 | CG75: =SUMIFS($T75:$CA75, $T$1:$CA$1, CG$63) -> 0 | CI75: =CC75=L75 -> 1 | CJ75: =CD75=M75 -> 1 | CK75: =CE75=N75 -> 1 | CL75: =CF75=O75 -> 1 | CM75: =CG75=P75 -> 1
E76: Cost of Sales Subtotal | I76: =SUM(I71:I75) -> 0 | J76: =SUM(J71:J75) -> 0 | K76: =SUM(K71:K75) -> 0 | L76: =SUM(L71:L75) -> 0 | M76: =SUM(M71:M75) -> 0 | N76: =SUM(N71:N75) -> 0 | O76: =SUM(O71:O75) -> 0 | P76: =SUM(P71:P75) -> 0 | T76: =SUM(T71:T75) -> 0 | U76: =SUM(U71:U75) -> 0 | V76: =SUM(V71:V75) -> 0 | W76: =SUM(W71:W75) -> 0 | X76: =SUM(X71:X75) -> 0 | Y76: =SUM(Y71:Y75) -> 0 | Z76: =SUM(Z71:Z75) -> 0 | AA76: =SUM(AA71:AA75) -> 0 | ... CA76: =SUM(CA71:CA75) -> 0 | CC76: =SUM(CC71:CC75) -> 0 | CD76: =SUM(CD71:CD75) -> 0 | CE76: =SUM(CE71:CE75) -> 0 | CF76: =SUM(CF71:CF75) -> 0 | CG76: =SUM(CG71:CG75) -> 0 | CI76: =CC76=L76 -> 1 | CJ76: =CD76=M76 -> 1 | CK76: =CE76=N76 -> 1 | CL76: =CF76=O76 -> 1 | CM76: =CG76=P76 -> 1
E78: OPEX
E79: OPEX - Engineering capacity release (loop engineering) | H79: Bankable share of capacity created on the residual addressable base | I79: ='SDLC-1 Model'!$D$58 -> 0 | J79: =I79-'SDLC-1 Model'!$K$58 -> 0 | K79: ='SDLC-1 Model'!$K$58 -> 0 | L79: ='SDLC-1 Model'!L58 -> 0 | M79: ='SDLC-1 Model'!M58 -> 0 | N79: ='SDLC-1 Model'!N58 -> 0 | O79: ='SDLC-1 Model'!O58 -> 0 | P79: ='SDLC-1 Model'!P58 -> 0 | Q79: CTO / SDLC | R79: =IF(K79=P79, "", "Error") | T79: ='SDLC-1 Model'!T58 -> 0 | U79: ='SDLC-1 Model'!U58 -> 0 | V79: ='SDLC-1 Model'!V58 -> 0 | W79: ='SDLC-1 Model'!W58 -> 0 | X79: ='SDLC-1 Model'!X58 -> 0 | Y79: ='SDLC-1 Model'!Y58 -> 0 | Z79: ='SDLC-1 Model'!Z58 -> 0 | AA79: ='SDLC-1 Model'!AA58 -> 0 | ... CA79: ='SDLC-1 Model'!CA58 -> 0 | CC79: =SUMIFS($T79:$CA79, $T$1:$CA$1, CC$63) -> 0 | CD79: =SUMIFS($T79:$CA79, $T$1:$CA$1, CD$63) -> 0 | CE79: =SUMIFS($T79:$CA79, $T$1:$CA$1, CE$63) -> 0 | CF79: =SUMIFS($T79:$CA79, $T$1:$CA$1, CF$63) -> 0 | CG79: =SUMIFS($T79:$CA79, $T$1:$CA$1, CG$63) -> 0 | CI79: =CC79=L79 -> 1 | CJ79: =CD79=M79 -> 1 | CK79: =CE79=N79 -> 1 | CL79: =CF79=O79 -> 1 | CM79: =CG79=P79 -> 1
I80: 0 | J80: 0 | K80: =I80-J80 -> 0 | R80: =IF(K80=P80, "", "Error") | CC80: =SUMIFS($T80:$CA80, $T$1:$CA$1, CC$63) -> 0 | CD80: =SUMIFS($T80:$CA80, $T$1:$CA$1, CD$63) -> 0 | CE80: =SUMIFS($T80:$CA80, $T$1:$CA$1, CE$63) -> 0 | CF80: =SUMIFS($T80:$CA80, $T$1:$CA$1, CF$63) -> 0 | CG80: =SUMIFS($T80:$CA80, $T$1:$CA$1, CG$63) -> 0 | CI80: =CC80=L80 -> 1 | CJ80: =CD80=M80 -> 1 | CK80: =CE80=N80 -> 1 | CL80: =CF80=O80 -> 1 | CM80: =CG80=P80 -> 1
I81: 0 | J81: 0 | K81: =I81-J81 -> 0 | R81: =IF(K81=P81, "", "Error") | CC81: =SUMIFS($T81:$CA81, $T$1:$CA$1, CC$63) -> 0 | CD81: =SUMIFS($T81:$CA81, $T$1:$CA$1, CD$63) -> 0 | CE81: =SUMIFS($T81:$CA81, $T$1:$CA$1, CE$63) -> 0 | CF81: =SUMIFS($T81:$CA81, $T$1:$CA$1, CF$63) -> 0 | CG81: =SUMIFS($T81:$CA81, $T$1:$CA$1, CG$63) -> 0 | CI81: =CC81=L81 -> 1 | CJ81: =CD81=M81 -> 1 | CK81: =CE81=N81 -> 1 | CL81: =CF81=O81 -> 1 | CM81: =CG81=P81 -> 1
I82: 0 | J82: 0 | K82: =I82-J82 -> 0 | R82: =IF(K82=P82, "", "Error") | CC82: =SUMIFS($T82:$CA82, $T$1:$CA$1, CC$63) -> 0 | CD82: =SUMIFS($T82:$CA82, $T$1:$CA$1, CD$63) -> 0 | CE82: =SUMIFS($T82:$CA82, $T$1:$CA$1, CE$63) -> 0 | CF82: =SUMIFS($T82:$CA82, $T$1:$CA$1, CF$63) -> 0 | CG82: =SUMIFS($T82:$CA82, $T$1:$CA$1, CG$63) -> 0 | CI82: =CC82=L82 -> 1 | CJ82: =CD82=M82 -> 1 | CK82: =CE82=N82 -> 1 | CL82: =CF82=O82 -> 1 | CM82: =CG82=P82 -> 1
I83: 0 | J83: 0 | K83: =I83-J83 -> 0 | R83: =IF(K83=P83, "", "Error") | CC83: =SUMIFS($T83:$CA83, $T$1:$CA$1, CC$63) -> 0 | CD83: =SUMIFS($T83:$CA83, $T$1:$CA$1, CD$63) -> 0 | CE83: =SUMIFS($T83:$CA83, $T$1:$CA$1, CE$63) -> 0 | CF83: =SUMIFS($T83:$CA83, $T$1:$CA$1, CF$63) -> 0 | CG83: =SUMIFS($T83:$CA83, $T$1:$CA$1, CG$63) -> 0 | CI83: =CC83=L83 -> 1 | CJ83: =CD83=M83 -> 1 | CK83: =CE83=N83 -> 1 | CL83: =CF83=O83 -> 1 | CM83: =CG83=P83 -> 1
...

Sheet SDLC-2 Model
B2: SDLC-2 — PDLC Re-imagination | INITIATIVE MODEL
B3: Workstream: SDLC (ELT sponsor: Srini | WSL: Pooja | IOs: Pooja, Aruna) • Model status: Structure ready; baselines PENDING data requests — see open items
T5: 2026 | U5: 2026 | V5: 2026 | W5: 2026 | X5: 2026 | Y5: 2026 | Z5: 2026 | AA5: 2026 | AB5: 2026 | AC5: 2026 | AD5: 2026 | AE5: 2026 | AF5: 2027 | AG5: 2027 | AH5: 2027 | AI5: 2027 | AJ5: 2027 | AK5: 2027 | AL5: 2027 | AM5: 2027 | AN5: 2027 | AO5: 2027 | AP5: 2027 | AQ5: 2027 | AR5: 2028 | AS5: 2028 | AT5: 2028 | AU5: 2028 | AV5: 2028 | AW5: 2028 | AX5: 2028 | AY5: 2028 | AZ5: 2028 | BA5: 2028 | BB5: 2028 | BC5: 2028 | BD5: 2029 | BE5: 2029 | BF5: 2029 | BG5: 2029 | BH5: 2029 | BI5: 2029 | BJ5: 2029 | BK5: 2029 | BL5: 2029 | BM5: 2029 | BN5: 2029 | BO5: 2029 | BP5: 2030 | BQ5: 2030 | BR5: 2030 | BS5: 2030 | BT5: 2030 | BU5: 2030 | BV5: 2030 | BW5: 2030 | BX5: 2030 | BY5: 2030 | BZ5: 2030 | CA5: 2030
B6: Monthly grid (Jan-26 → Dec-30) → | K6: Run rate | L6: 2026 | M6: 2027 | N6: 2028 | O6: 2029 | P6: 2030 | T6: =DATE(2026,1,31) -> 46053 | U6: =EOMONTH(T6,1) -> 46081 | V6: =EOMONTH(U6,1) -> 46112 | W6: =EOMONTH(V6,1) -> 46142 | X6: =EOMONTH(W6,1) -> 46173 | Y6: =EOMONTH(X6,1) -> 46203 | Z6: =EOMONTH(Y6,1) -> 46234 | AA6: =EOMONTH(Z6,1) -> 46265 | AB6: =EOMONTH(AA6,1) -> 46295 | ... CA6: =EOMONTH(BZ6,1) -> 47848
B8: 0. INITIATIVE & STATUS
B10: Initiative name | D10: PDLC re-imagination — agentic product development lifecycle across product, program and design
B11: Initiative owner | D11: Aruna (IO) — TBC | I11: confirm with workstream lead
B12: Impacted BU | D12: CTO / SDLC
B13: Go-live / Estimated L4 date | D13: =DATE(2027,6,1) -> 46539 | I13: Benefit ramp is gated on this date.
B15: Source: Workplan: 'Project Zenith Automation workplan and data requests vS_1.xlsx', SDLC tab + SDLC Data Requests tab
B16: Source: Impact ranges: Aug 13 deck pp. 9, 19–21; Board deck pp. 12, 22 (preliminary — Finance to validate)
B17: Open items to refine with initiative owner:
B18: – Product/program/design FTE population and cost pending (SDLC data request #1, PDLC side — ETO; 'back on McK' for time-spent validation, request #2).
B19: – PDLC output baseline (PRDs, epics, specs, releases) pending — request #4; converts uplift to capacity.
B20: – PDLC tooling & spend baseline (Figma, PRD gen, Jira) pending — request #5; sizes investment and nets run cost.
B21: – Build shape mirrors the Servicing S2 delivery pod as a placeholder — refine with IOs before S3.
B23: 1. SIZING ASSUMPTIONS (blue = inputs — refine with initiative owner)
B25: Baseline / denominator (PENDING data request #1 — PDLC side)
B26: Product + program + design FTE population — in scope | D26: 0 | E26: # FTE | F26: PENDING — placeholder, not data. Data request #1 (ETO)
B27: Avg fully loaded cost per PDLC FTE | D27: 0 | E27: $/yr | F27: PENDING — placeholder, not data. Data request #1
B28: Impact drivers (Aug 13 deck pp. 9, 19–21 — preliminary)
B29: PDLC productivity lift across product/program/design | D29: 0.2 | E29: % | F29: PLACEHOLDER — refine with time-spent-by-activity data (request #2)
B30: Steady-state adoption | D30: 0.75 | E30: % | F30: PLACEHOLDER
B31: Capture rate — capacity converted to bankable cost | D31: 0.65 | E31: % | F31: PLACEHOLDER — align with SDLC-1 capture logic
B32: Investment uplifts (consistent with Servicing S2 standard)
B33: Programme management, % of build | D33: 0.08 | E33: %
B34: Contingency, % of build incl. PM | D34: 0.1 | E34: %
B35: (spare assumption row)
B36: (spare assumption row)
B38: 2. BENEFIT CALCULATION (steady-state annual run-rate)
B40: Total in-scope PDLC labor base | D40: =$D$26*$D$27 -> 0 | E40: $/yr
B41: Gross capacity value created | D41: =$D$40*$D$29*$D$30 -> 0 | E41: $/yr
B42: Bankable annual benefit (steady state) | D42: =$D$41*$D$31 -> 0 | E42: $/yr | F42: Feeds WAVE benefit line
B44: 3. RAMP & PHASING
B46: Months to full run rate after go-live (linear ramp) | D46: 12 | F46: Benefit starts at go-live and ramps linearly to steady state over this many months.
B47: Monthly ramp % (run-rate captured in month) | T47: =MIN(1,MAX(0,((YEAR(T$6)-YEAR($D$13))*12+MONTH(T$6)-MONTH($D$13)+0.5)/MAX($D$46,0.5))) -> 0 | U47: =MIN(1,MAX(0,((YEAR(U$6)-YEAR($D$13))*12+MONTH(U$6)-MONTH($D$13)+0.5)/MAX($D$46,0.5))) -> 0 | V47: =MIN(1,MAX(0,((YEAR(V$6)-YEAR($D$13))*12+MONTH(V$6)-MONTH($D$13)+0.5)/MAX($D$46,0.5))) -> 0 | W47: =MIN(1,MAX(0,((YEAR(W$6)-YEAR($D$13))*12+MONTH(W$6)-MONTH($D$13)+0.5)/MAX($D$46,0.5))) -> 0 | X47: =MIN(1,MAX(0,((YEAR(X$6)-YEAR($D$13))*12+MONTH(X$6)-MONTH($D$13)+0.5)/MAX($D$46,0.5))) -> 0 | Y47: =MIN(1,MAX(0,((YEAR(Y$6)-YEAR($D$13))*12+MONTH(Y$6)-MONTH($D$13)+0.5)/MAX($D$46,0.5))) -> 0 | Z47: =MIN(1,MAX(0,((YEAR(Z$6)-YEAR($D$13))*12+MONTH(Z$6)-MONTH($D$13)+0.5)/MAX($D$46,0.5))) -> 0 | AA47: =MIN(1,MAX(0,((YEAR(AA$6)-YEAR($D$13))*12+MONTH(AA$6)-MONTH($D$13)+0.5)/MAX($D$46,0.5))) -> 0 | ... CA47: =MIN(1,MAX(0,((YEAR(CA$6)-YEAR($D$13))*12+MONTH(CA$6)-MONTH($D$13)+0.5)/MAX($D$46,0.5))) -> 1
B48: Resulting average ramp % by year (info) | L48: =SUMIFS($T47:$CA47,$T$5:$CA$5,2026)/12 -> 0 | M48: =SUMIFS($T47:$CA47,$T$5:$CA$5,2027)/12 -> 0.17013889 | N48: =SUMIFS($T47:$CA47,$T$5:$CA$5,2028)/12 -> 0.91319444 | O48: =SUMIFS($T47:$CA47,$T$5:$CA$5,2029)/12 -> 1 | P48: =SUMIFS($T47:$CA47,$T$5:$CA$5,2030)/12 -> 1
B50: 4. RECURRING BENEFIT LINES ($M — these rows feed the WAVE sheet)
B52: Line (WAVE category) | D52: Baseline $M | K52: Run rate
B53: OPEX - Product/program/design capacity release (PDLC) [OPEX] | D53: =$D$40/1000000 -> 0 | K53: =SUMIFS($T53:$CA53,$T$5:$CA$5,2030) -> 0 | L53: =SUMIFS($T53:$CA53,$T$5:$CA$5,2026) -> 0 | M53: =SUMIFS($T53:$CA53,$T$5:$CA$5,2027) -> 0 | N53: =SUMIFS($T53:$CA53,$T$5:$CA$5,2028) -> 0 | O53: =SUMIFS($T53:$CA53,$T$5:$CA$5,2029) -> 0 | P53: =SUMIFS($T53:$CA53,$T$5:$CA$5,2030) -> 0 | T53: =($D$42)/1000000/12*T$47 -> 0 | U53: =($D$42)/1000000/12*U$47 -> 0 | V53: =($D$42)/1000000/12*V$47 -> 0 | W53: =($D$42)/1000000/12*W$47 -> 0 | X53: =($D$42)/1000000/12*X$47 -> 0 | Y53: =($D$42)/1000000/12*Y$47 -> 0 | Z53: =($D$42)/1000000/12*Z$47 -> 0 | AA53: =($D$42)/1000000/12*AA$47 -> 0 | ... CA53: =($D$42)/1000000/12*CA$47 -> 0
...

Sheet SDLC-2 WAVE
L1: 1 | M1: 2 | N1: 3 | O1: 4 | P1: 5 | R1: =COUNTIFS($R$66:$R$117, "Error") -> 0 | T1: 2026 | U1: 2026 | V1: 2026 | W1: 2026 | X1: 2026 | Y1: 2026 | Z1: 2026 | AA1: 2026 | AB1: 2026 | AC1: 2026 | AD1: 2026 | AE1: 2026 | AF1: 2027 | AG1: 2027 | AH1: 2027 | AI1: 2027 | AJ1: 2027 | AK1: 2027 | AL1: 2027 | AM1: 2027 | AN1: 2027 | AO1: 2027 | AP1: 2027 | AQ1: 2027 | AR1: 2028 | AS1: 2028 | AT1: 2028 | AU1: 2028 | AV1: 2028 | AW1: 2028 | AX1: 2028 | AY1: 2028 | AZ1: 2028 | BA1: 2028 | BB1: 2028 | BC1: 2028 | BD1: 2029 | BE1: 2029 | BF1: 2029 | BG1: 2029 | BH1: 2029 | BI1: 2029 | BJ1: 2029 | BK1: 2029 | BL1: 2029 | BM1: 2029 | BN1: 2029 | BO1: 2029 | BP1: 2030 | BQ1: 2030 | BR1: 2030 | BS1: 2030 | BT1: 2030 | BU1: 2030 | BV1: 2030 | BW1: 2030 | BX1: 2030 | BY1: 2030 | BZ1: 2030 | CA1: 2030 | CI1: =COUNTIFS(CI$66:CI$149, "FALSE") -> 0 | CJ1: =COUNTIFS(CJ$66:CJ$149, "FALSE") -> 0 | CK1: =COUNTIFS(CK$66:CK$149, "FALSE") -> 0 | CL1: =COUNTIFS(CL$66:CL$149, "FALSE") -> 0 | CM1: =COUNTIFS(CM$66:CM$149, "FALSE") -> 0
C2: ="#"&$F$6&" Initiative Business Case" -> #TBD Initiative Business Case
C4: INPUTS & ASSUMPTIONS
D6: Initiative # | F6: TBD
D7: Initiative Owner | F7: Aruna (IO) — TBC
D8: Initiative Name | F8: PDLC re-imagination — agentic product development lifecycle across product, program and design
D11: Estimated L4 date | F11: ='SDLC-2 Model'!$D$13 -> 46539
D12: Net Recurring Benefit ($M) | F12: =$K$117 -> 0
C14: SECTION I - PRIMARY VALUE DRIVER (ILLUSTRATIVE)
D16: Primary value driver — linked to the Model sheet; refine with the initiative owner
D17: Baseline | H17: Period | I17: KPI | J17: Inputs
E18: Product/program/design FTE in scope | H18: TTM 6/1/26 | I18: # FTE | J18: ='SDLC-2 Model'!$D$26 -> 0
E19: Avg fully loaded cost per PDLC FTE | H19: TTM 6/1/26 | I19: $ / FTE | J19: ='SDLC-2 Model'!$D$27 -> 0
E20: Total in-scope PDLC labor base | H20: TTM 6/1/26 | I20: $USD M | J20: ='SDLC-2 Model'!$D$40/1000000 -> 0
D23: Goal
E24: PDLC lift x steady-state adoption | H24: Steady state | I24: % | J24: ='SDLC-2 Model'!$D$29*'SDLC-2 Model'!$D$30 -> 0.15
E25: Capture rate to bankable cost | H25: Steady state | I25: % | J25: ='SDLC-2 Model'!$D$31 -> 0.65
D28: Incremental Improvement
E29: Bankable annual benefit (run rate) | I29: $USD M | J29: ='SDLC-2 Model'!$D$42/1000000 -> 0
C60: SECTION II - NET RECURRING BENEFITS | CC60: ANNUAL SUMMARY | CI60: CHECK CELLS
T62: 2026 | AF62: 2027 | AR62: 2028 | BD62: 2029 | BP62: 2030 | CI62: CHECK
D63: RECURRING BENEFITS | H63: Comment | I63: Baseline | J63: Goal | K63: Ann. Run Rate | L63: 2026 | M63: =L63+1 -> 2027 | N63: =M63+1 -> 2028 | O63: =N63+1 -> 2029 | P63: =O63+1 -> 2030 | Q63: Impacted BU | R63: Check | T63: 46023 | U63: =EOMONTH(T63, 1) -> 46081 | V63: =EOMONTH(U63, 1) -> 46112 | W63: =EOMONTH(V63, 1) -> 46142 | X63: =EOMONTH(W63, 1) -> 46173 | Y63: =EOMONTH(X63, 1) -> 46203 | Z63: =EOMONTH(Y63, 1) -> 46234 | AA63: =EOMONTH(Z63, 1) -> 46265 | AB63: =EOMONTH(AA63, 1) -> 46295 | ... CA63: =EOMONTH(BZ63, 1) -> 47848 | CC63: 2026 | CD63: =CC63+1 -> 2027 | CE63: =CD63+1 -> 2028 | CF63: =CE63+1 -> 2029 | CG63: =CF63+1 -> 2030 | CI63: 2026 | CJ63: =CI63+1 -> 2027 | CK63: =CJ63+1 -> 2028 | CL63: =CK63+1 -> 2029 | CM63: =CL63+1 -> 2030
E64: $USD M | I64: =$H$18 -> TTM 6/1/26 | J64: Future State | K64: Increment
E65: Revenue
I66: 0 | J66: 0 | K66: =J66-I66 -> 0 | R66: =IF(K66=P66, "", "Error") | CC66: =SUMIFS($T66:$CA66, $T$1:$CA$1, CC$63) -> 0 | CD66: =SUMIFS($T66:$CA66, $T$1:$CA$1, CD$63) -> 0 | CE66: =SUMIFS($T66:$CA66, $T$1:$CA$1, CE$63) -> 0 | CF66: =SUMIFS($T66:$CA66, $T$1:$CA$1, CF$63) -> 0 | CG66: =SUMIFS($T66:$CA66, $T$1:$CA$1, CG$63) -> 0 | CI66: =CC66=L66 -> 1 | CJ66: =CD66=M66 -> 1 | CK66: =CE66=N66 -> 1 | CL66: =CF66=O66 -> 1 | CM66: =CG66=P66 -> 1
I67: 0 | J67: 0 | K67: =J67-I67 -> 0 | R67: =IF(K67=P67, "", "Error") | CC67: =SUMIFS($T67:$CA67, $T$1:$CA$1, CC$63) -> 0 | CD67: =SUMIFS($T67:$CA67, $T$1:$CA$1, CD$63) -> 0 | CE67: =SUMIFS($T67:$CA67, $T$1:$CA$1, CE$63) -> 0 | CF67: =SUMIFS($T67:$CA67, $T$1:$CA$1, CF$63) -> 0 | CG67: =SUMIFS($T67:$CA67, $T$1:$CA$1, CG$63) -> 0 | CI67: =CC67=L67 -> 1 | CJ67: =CD67=M67 -> 1 | CK67: =CE67=N67 -> 1 | CL67: =CF67=O67 -> 1 | CM67: =CG67=P67 -> 1
E68: Revenue Subtotal | I68: =SUM(I66:I67) -> 0 | J68: =SUM(J66:J67) -> 0 | K68: =SUM(K66:K67) -> 0 | L68: =SUM(L66:L67) -> 0 | M68: =SUM(M66:M67) -> 0 | N68: =SUM(N66:N67) -> 0 | O68: =SUM(O66:O67) -> 0 | P68: =SUM(P66:P67) -> 0 | T68: =SUM(T66:T67) -> 0 | U68: =SUM(U66:U67) -> 0 | V68: =SUM(V66:V67) -> 0 | W68: =SUM(W66:W67) -> 0 | X68: =SUM(X66:X67) -> 0 | Y68: =SUM(Y66:Y67) -> 0 | Z68: =SUM(Z66:Z67) -> 0 | AA68: =SUM(AA66:AA67) -> 0 | ... CA68: =SUM(CA66:CA67) -> 0 | CC68: =SUM(CC66:CC67) -> 0 | CD68: =SUM(CD66:CD67) -> 0 | CE68: =SUM(CE66:CE67) -> 0 | CF68: =SUM(CF66:CF67) -> 0 | CG68: =SUM(CG66:CG67) -> 0 | CI68: =CC68=L68 -> 1 | CJ68: =CD68=M68 -> 1 | CK68: =CE68=N68 -> 1 | CL68: =CF68=O68 -> 1 | CM68: =CG68=P68 -> 1
E70: Cost of Sales
K71: =I71-J71 -> 0 | R71: =IF(K71=P71, "", "Error") | CC71: =SUMIFS($T71:$CA71, $T$1:$CA$1, CC$63) -> 0 | CD71: =SUMIFS($T71:$CA71, $T$1:$CA$1, CD$63) -> 0 | CE71: =SUMIFS($T71:$CA71, $T$1:$CA$1, CE$63) -> 0 | CF71: =SUMIFS($T71:$CA71, $T$1:$CA$1, CF$63) -> 0 | CG71: =SUMIFS($T71:$CA71, $T$1:$CA$1, CG$63) -> 0 | CI71: =CC71=L71 -> 1 | CJ71: =CD71=M71 -> 1 | CK71: =CE71=N71 -> 1 | CL71: =CF71=O71 -> 1 | CM71: =CG71=P71 -> 1
I72: 0 | J72: 0 | K72: =I72-J72 -> 0 | R72: =IF(K72=P72, "", "Error") | CC72: =SUMIFS($T72:$CA72, $T$1:$CA$1, CC$63) -> 0 | CD72: =SUMIFS($T72:$CA72, $T$1:$CA$1, CD$63) -> 0 | CE72: =SUMIFS($T72:$CA72, $T$1:$CA$1, CE$63) -> 0 | CF72: =SUMIFS($T72:$CA72, $T$1:$CA$1, CF$63) -> 0 | CG72: =SUMIFS($T72:$CA72, $T$1:$CA$1, CG$63) -> 0 | CI72: =CC72=L72 -> 1 | CJ72: =CD72=M72 -> 1 | CK72: =CE72=N72 -> 1 | CL72: =CF72=O72 -> 1 | CM72: =CG72=P72 -> 1
I73: 0 | J73: 0 | K73: =I73-J73 -> 0 | R73: =IF(K73=P73, "", "Error") | CC73: =SUMIFS($T73:$CA73, $T$1:$CA$1, CC$63) -> 0 | CD73: =SUMIFS($T73:$CA73, $T$1:$CA$1, CD$63) -> 0 | CE73: =SUMIFS($T73:$CA73, $T$1:$CA$1, CE$63) -> 0 | CF73: =SUMIFS($T73:$CA73, $T$1:$CA$1, CF$63) -> 0 | CG73: =SUMIFS($T73:$CA73, $T$1:$CA$1, CG$63) -> 0 | CI73: =CC73=L73 -> 1 | CJ73: =CD73=M73 -> 1 | CK73: =CE73=N73 -> 1 | CL73: =CF73=O73 -> 1 | CM73: =CG73=P73 -> 1
I74: 0 | J74: 0 | K74: =I74-J74 -> 0 | R74: =IF(K74=P74, "", "Error") | CC74: =SUMIFS($T74:$CA74, $T$1:$CA$1, CC$63) -> 0 | CD74: =SUMIFS($T74:$CA74, $T$1:$CA$1, CD$63) -> 0 | CE74: =SUMIFS($T74:$CA74, $T$1:$CA$1, CE$63) -> 0 | CF74: =SUMIFS($T74:$CA74, $T$1:$CA$1, CF$63) -> 0 | CG74: =SUMIFS($T74:$CA74, $T$1:$CA$1, CG$63) -> 0 | CI74: =CC74=L74 -> 1 | CJ74: =CD74=M74 -> 1 | CK74: =CE74=N74 -> 1 | CL74: =CF74=O74 -> 1 | CM74: =CG74=P74 -> 1
K75: =I75-J75 -> 0 | R75: =IF(K75=P75, "", "Error") | CC75: =SUMIFS($T75:$CA75, $T$1:$CA$1, CC$63) -> 0 | CD75: =SUMIFS($T75:$CA75, $T$1:$CA$1, CD$63) -> 0 | CE75: =SUMIFS($T75:$CA75, $T$1:$CA$1, CE$63) -> 0 | CF75: =SUMIFS($T75:$CA75, $T$1:$CA$1, CF$63) -> 0 | CG75: =SUMIFS($T75:$CA75, $T$1:$CA$1, CG$63) -> 0 | CI75: =CC75=L75 -> 1 | CJ75: =CD75=M75 -> 1 | CK75: =CE75=N75 -> 1 | CL75: =CF75=O75 -> 1 | CM75: =CG75=P75 -> 1
E76: Cost of Sales Subtotal | I76: =SUM(I71:I75) -> 0 | J76: =SUM(J71:J75) -> 0 | K76: =SUM(K71:K75) -> 0 | L76: =SUM(L71:L75) -> 0 | M76: =SUM(M71:M75) -> 0 | N76: =SUM(N71:N75) -> 0 | O76: =SUM(O71:O75) -> 0 | P76: =SUM(P71:P75) -> 0 | T76: =SUM(T71:T75) -> 0 | U76: =SUM(U71:U75) -> 0 | V76: =SUM(V71:V75) -> 0 | W76: =SUM(W71:W75) -> 0 | X76: =SUM(X71:X75) -> 0 | Y76: =SUM(Y71:Y75) -> 0 | Z76: =SUM(Z71:Z75) -> 0 | AA76: =SUM(AA71:AA75) -> 0 | ... CA76: =SUM(CA71:CA75) -> 0 | CC76: =SUM(CC71:CC75) -> 0 | CD76: =SUM(CD71:CD75) -> 0 | CE76: =SUM(CE71:CE75) -> 0 | CF76: =SUM(CF71:CF75) -> 0 | CG76: =SUM(CG71:CG75) -> 0 | CI76: =CC76=L76 -> 1 | CJ76: =CD76=M76 -> 1 | CK76: =CE76=N76 -> 1 | CL76: =CF76=O76 -> 1 | CM76: =CG76=P76 -> 1
E78: OPEX
E79: OPEX - Product/program/design capacity release (PDLC) | H79: Bankable share of PDLC capacity created | I79: ='SDLC-2 Model'!$D$53 -> 0 | J79: =I79-'SDLC-2 Model'!$K$53 -> 0 | K79: ='SDLC-2 Model'!$K$53 -> 0 | L79: ='SDLC-2 Model'!L53 -> 0 | M79: ='SDLC-2 Model'!M53 -> 0 | N79: ='SDLC-2 Model'!N53 -> 0 | O79: ='SDLC-2 Model'!O53 -> 0 | P79: ='SDLC-2 Model'!P53 -> 0 | Q79: CTO / SDLC | R79: =IF(K79=P79, "", "Error") | T79: ='SDLC-2 Model'!T53 -> 0 | U79: ='SDLC-2 Model'!U53 -> 0 | V79: ='SDLC-2 Model'!V53 -> 0 | W79: ='SDLC-2 Model'!W53 -> 0 | X79: ='SDLC-2 Model'!X53 -> 0 | Y79: ='SDLC-2 Model'!Y53 -> 0 | Z79: ='SDLC-2 Model'!Z53 -> 0 | AA79: ='SDLC-2 Model'!AA53 -> 0 | ... CA79: ='SDLC-2 Model'!CA53 -> 0 | CC79: =SUMIFS($T79:$CA79, $T$1:$CA$1, CC$63) -> 0 | CD79: =SUMIFS($T79:$CA79, $T$1:$CA$1, CD$63) -> 0 | CE79: =SUMIFS($T79:$CA79, $T$1:$CA$1, CE$63) -> 0 | CF79: =SUMIFS($T79:$CA79, $T$1:$CA$1, CF$63) -> 0 | CG79: =SUMIFS($T79:$CA79, $T$1:$CA$1, CG$63) -> 0 | CI79: =CC79=L79 -> 1 | CJ79: =CD79=M79 -> 1 | CK79: =CE79=N79 -> 1 | CL79: =CF79=O79 -> 1 | CM79: =CG79=P79 -> 1
I80: 0 | J80: 0 | K80: =I80-J80 -> 0 | R80: =IF(K80=P80, "", "Error") | CC80: =SUMIFS($T80:$CA80, $T$1:$CA$1, CC$63) -> 0 | CD80: =SUMIFS($T80:$CA80, $T$1:$CA$1, CD$63) -> 0 | CE80: =SUMIFS($T80:$CA80, $T$1:$CA$1, CE$63) -> 0 | CF80: =SUMIFS($T80:$CA80, $T$1:$CA$1, CF$63) -> 0 | CG80: =SUMIFS($T80:$CA80, $T$1:$CA$1, CG$63) -> 0 | CI80: =CC80=L80 -> 1 | CJ80: =CD80=M80 -> 1 | CK80: =CE80=N80 -> 1 | CL80: =CF80=O80 -> 1 | CM80: =CG80=P80 -> 1
I81: 0 | J81: 0 | K81: =I81-J81 -> 0 | R81: =IF(K81=P81, "", "Error") | CC81: =SUMIFS($T81:$CA81, $T$1:$CA$1, CC$63) -> 0 | CD81: =SUMIFS($T81:$CA81, $T$1:$CA$1, CD$63) -> 0 | CE81: =SUMIFS($T81:$CA81, $T$1:$CA$1, CE$63) -> 0 | CF81: =SUMIFS($T81:$CA81, $T$1:$CA$1, CF$63) -> 0 | CG81: =SUMIFS($T81:$CA81, $T$1:$CA$1, CG$63) -> 0 | CI81: =CC81=L81 -> 1 | CJ81: =CD81=M81 -> 1 | CK81: =CE81=N81 -> 1 | CL81: =CF81=O81 -> 1 | CM81: =CG81=P81 -> 1
I82: 0 | J82: 0 | K82: =I82-J82 -> 0 | R82: =IF(K82=P82, "", "Error") | CC82: =SUMIFS($T82:$CA82, $T$1:$CA$1, CC$63) -> 0 | CD82: =SUMIFS($T82:$CA82, $T$1:$CA$1, CD$63) -> 0 | CE82: =SUMIFS($T82:$CA82, $T$1:$CA$1, CE$63) -> 0 | CF82: =SUMIFS($T82:$CA82, $T$1:$CA$1, CF$63) -> 0 | CG82: =SUMIFS($T82:$CA82, $T$1:$CA$1, CG$63) -> 0 | CI82: =CC82=L82 -> 1 | CJ82: =CD82=M82 -> 1 | CK82: =CE82=N82 -> 1 | CL82: =CF82=O82 -> 1 | CM82: =CG82=P82 -> 1
I83: 0 | J83: 0 | K83: =I83-J83 -> 0 | R83: =IF(K83=P83, "", "Error") | CC83: =SUMIFS($T83:$CA83, $T$1:$CA$1, CC$63) -> 0 | CD83: =SUMIFS($T83:$CA83, $T$1:$CA$1, CD$63) -> 0 | CE83: =SUMIFS($T83:$CA83, $T$1:$CA$1, CE$63) -> 0 | CF83: =SUMIFS($T83:$CA83, $T$1:$CA$1, CF$63) -> 0 | CG83: =SUMIFS($T83:$CA83, $T$1:$CA$1, CG$63) -> 0 | CI83: =CC83=L83 -> 1 | CJ83: =CD83=M83 -> 1 | CK83: =CE83=N83 -> 1 | CL83: =CF83=O83 -> 1 | CM83: =CG83=P83 -> 1
...

Sheet Standard Template
L1: 1 | M1: 2 | N1: 3 | O1: 4 | P1: 5 | R1: =COUNTIFS($R$66:$R$117, "Error") -> 0 | T1: 2026 | U1: 2026 | V1: 2026 | W1: 2026 | X1: 2026 | Y1: 2026 | Z1: 2026 | AA1: 2026 | AB1: 2026 | AC1: 2026 | AD1: 2026 | AE1: 2026 | AF1: 2027 | AG1: 2027 | AH1: 2027 | AI1: 2027 | AJ1: 2027 | AK1: 2027 | AL1: 2027 | AM1: 2027 | AN1: 2027 | AO1: 2027 | AP1: 2027 | AQ1: 2027 | AR1: 2028 | AS1: 2028 | AT1: 2028 | AU1: 2028 | AV1: 2028 | AW1: 2028 | AX1: 2028 | AY1: 2028 | AZ1: 2028 | BA1: 2028 | BB1: 2028 | BC1: 2028 | BD1: 2029 | BE1: 2029 | BF1: 2029 | BG1: 2029 | BH1: 2029 | BI1: 2029 | BJ1: 2029 | BK1: 2029 | BL1: 2029 | BM1: 2029 | BN1: 2029 | BO1: 2029 | BP1: 2030 | BQ1: 2030 | BR1: 2030 | BS1: 2030 | BT1: 2030 | BU1: 2030 | BV1: 2030 | BW1: 2030 | BX1: 2030 | BY1: 2030 | BZ1: 2030 | CA1: 2030 | CI1: =COUNTIFS(CI$66:CI$149, "FALSE") -> 0 | CJ1: =COUNTIFS(CJ$66:CJ$149, "FALSE") -> 0 | CK1: =COUNTIFS(CK$66:CK$149, "FALSE") -> 0 | CL1: =COUNTIFS(CL$66:CL$149, "FALSE") -> 0 | CM1: =COUNTIFS(CM$66:CM$149, "FALSE") -> 0
C2: ="#"&$F$6&" Initiative Business Case" -> # Initiative Business Case
C4: INPUTS & ASSUMPTIONS
D6: Initiative #
D7: Initiative Owner
D8: Initiative Name
D11: Estimated L4 date
D12: Net Recurring Benefit ($M) | F12: =$K$117 -> 0
C14: SECTION I - PRIMARY VALUE DRIVER (ILLUSTRATIVE)
D16: Illustrative example of value driver explanation - please edit fields to reflect value drivers for your Initiative
D17: Baseline | H17: Period | I17: KPI | J17: Inputs
E18: # CW headcount | H18: TTM 6/1/26 | I18: # CW
E19: Average hourly cost for CW | H19: =$H$18 -> TTM 6/1/26 | I19: $USD / # hr
E20: Average utliization hours for CW - annual | H20: =$H$18 -> TTM 6/1/26 | I20: # hr
E21: Total CW spend | H21: =$H$18 -> TTM 6/1/26 | I21: $USD M | J21: =(J18*J19*J20)/1000000 -> 0
D23: Goal
E24: # FTE headcount - lower cost location | H24: FY2026 | I24: # FTE's
E25: Average fully loaded annual cost per FTE - lower cost location | H25: FY2026 | I25: $ / FTE
E26: Total personnel spend for BU | H26: FY2026 | I26: $USD | J26: =(J24*J25)/1000000 -> 0
D28: Incremental Improvement
E29: Total personnel spend for X business unit | I29: $USD | J29: =J21-J26 -> 0
D31: Baseline | H31: Period | I31: $USD M | J31: Inputs
E32: # xxxx | H32: =$H$18 -> TTM 6/1/26 | I32: # xxxx | J32: 0
E33: xxxx unit cost | G33: [A] | H33: FY2025 | I33: $ xxxx | J33: 0
E34: xxxx total spend | G34: [B] | H34: FY2025 | I34: $USD K | J34: =(J32*J33)/1000 -> 0
D36: Goal
E37: # xxxx | H37: FY2025 | I37: # xxxx | J37: =$J$18 -> 0
E38: xxxx unit cost | G38: [C] | H38: FY2026 | I38: $ xxxx | J38: 0
E39: xxxx total spend | G39: [D] | H39: FY2026 | I39: $USD K | J39: =(J37*J38)/1000 -> 0
D41: Incremental Improvement
E42: =E38 -> xxxx unit cost | G42: [A]-[C] | I42: $ / xxxx | J42: =J33-J38 -> 0
E43: =E39 -> xxxx total spend | G43: [B]-[D] | I43: $USD K | J43: =J34-J39 -> 0
D45: Baseline | H45: Period | I45: KPI | J45: Inputs
E46: # xxxx | H46: FY2025 | I46: # xxxx | J46: 0
E47: xxxx unit cost | G47: [A] | H47: FY2025 | I47: $ xxxx | J47: 0
E48: xxxx total spend | G48: [B] | H48: FY2025 | I48: $USD K | J48: =(J46*J47)/1000 -> 0
D50: Goal
E51: # xxxx | H51: FY2025 | I51: # xxxx | J51: =$J$18 -> 0
E52: xxxx unit cost | G52: [C] | H52: FY2026 | I52: $ xxxx | J52: 0
E53: xxxx total spend | G53: [D] | H53: FY2026 | I53: $USD K | J53: =(J51*J52)/1000 -> 0
...
