Workbook

Sheet Cover
B2: PROJECT ZENITH — SERVICING WORKSTREAM | INITIATIVE MODELS & WAVE TEMPLATES
B4: Workstream | C4: Servicing — Improve NPS and eliminate avoidable contacts through Prevent, Self-Serve and Optimize. ELT sponsor: Aaron | WSL: Tahira Adatia | IOs: Jackie Yu, Matt Anderson, Bob Hurst.
B5: Purpose | C5: One file per workstream: the six S2 initiatives, each with a Model sheet (distilled from the S2 sizing model, tier-level) formula-linked into its own copy of the standard WAVE template. S2 submission: Fri 4 Sep 2026.
B6: Version / status | C6: v1 — seeded 1:1 from the S2 sizing model vDraft5 (Base scenario, 28 Aug 2026). All initiative benefits, one-time and run costs tie to S2 to the cent at seed values (see tie-out targets on each model sheet).
B7: Prepared | C7: Prepared by AAO model build, 31 Aug 2026. Sources: 20260828_Servicing_S2sizing_vDraft5.xlsb; Project Zenith workplan vS_1; Zenith Business Case Template by Lever (WAVE).
B8: Sources | C8: S2 sizing model vDraft5 (77-intent L2 engine, A0–A6 waterfall, C1–C3 investment); distillation is at difficulty-tier level with per-tier bases and effective rates reproducing the L2 engine exactly at seed values.
B10: HOW THIS FILE IS ORGANIZED
B12: Cover | C12: This sheet — orientation, legend, deviations, open items.
B13: Instructions | C13: The WAVE template's own instruction sheet (as uploaded; dead broken-reference drop-down cells cleared).
B14: Rate Card | C14: Shared people-cost engine — S2 8-FTE pod at $200k/yr blended (ties to S2 C2); contingency reference; capitalization policy (0% = S2 cash treatment).
B15: Summary | C15: Portfolio roll-up of all six initiatives (links to WAVE sheets).
B16: SVC-1 Model / WAVE | C16: Contact Avoidance (S2 lever A1) — $12.84M.
B17: SVC-2 Model / WAVE | C17: Enhanced Chat / Self-Serve (A2) — $14.77M.
B18: SVC-3 Model / WAVE | C18: Agentic Voice & AI Co-pilot (A3a + A3b) — $35.25M.
B19: SVC-4 Model / WAVE | C19: AI Workforce Management (A4a + A4b) — $7.65M.
B20: SVC-5 Model / WAVE | C20: Back-Office Automation (A5) — $6.83M.
B21: SVC-6 Model / WAVE | C21: Non-FTE Savings flow-through (A6) — $4.04M; FTE inputs link to the other five models.
B22: Standard Template | C22: Reference copy of the standard WAVE template (only error-guard fixes applied — see deviations).
B24: COLOR LEGEND
B26: Input — change freely
B27: Formula — do not overwrite
B28: Link to another sheet
B29: Section band
B31: MODEL -> WAVE LINKING
B33: • Each initiative has a '<code> Model' sheet (all logic and inputs) and a '<code> WAVE' sheet (the standard template). The WAVE sheet contains NO hardcoded numbers for this initiative — its benefit/cost rows link (green) to the Model sheet's feed rows in $M.
B34: • Model sheets use the same time grid as WAVE: columns L:P = FY2026–2030 annual, columns T:CA = Jan-2026..Dec-2030 monthly. Annual cells are SUMIFS of the monthly grid, so the WAVE monthly-vs-annual checks (CI1:CM1) pass by construction.
B35: • The 'Ann. Run Rate' (K) on feed rows is defined as the 2030 value, matching the WAVE rule 'Annualized Run Rate (K) = 2030 Value (P)'. Keep ramps reaching 100% before 2030.
B36: • Benefits ramp linearly from the go-live date over 'months to full run rate' — same convention as the Servicing S2 model. One-time costs spread evenly over each milestone's billing months.
B37: • People costs: milestone labor = Team size x Billing months x blended monthly rate (Rate Card) x (1 + contingency). Capitalization: each milestone carries a Cap % (default from Rate Card policy) that splits labor into WAVE CapEx vs OTC rows. Same for non-labor one-time items.
B38: • Waterfall de-duplication: each model's opening cost is the prior lever's closing baseline (S2 stacking order). Openings are seeded inputs — refresh from the S2 L2 engine if upstream levers or intent tiering change (tier-level bases cannot re-derive themselves).
... B57: • FTE-impacted figures use the S2 'A0 basis' (as consumed by the non-FTE flow-through); residual-basis reductions are lower (S2 QC flag) — do not mix bases when quoting headcount.

Sheet Instructions
L1: 1 | M1: 2 | N1: 3 | O1: 4 | P1: 5 | R1: =COUNTIFS($R$78:$R$128, "Error") -> 0 | T1: 2026 | U1: 2026 | V1: 2026 | W1: 2026 | X1: 2026 | Y1: 2026 | Z1: 2026 | AA1: 2026 | AB1: 2026 | AC1: 2026 | AD1: 2026 | AE1: 2026 | AF1: 2027 | AG1: 2027 | AH1: 2027 | AI1: 2027 | AJ1: 2027 | AK1: 2027 | AL1: 2027 | AM1: 2027 | AN1: 2027 | AO1: 2027 | AP1: 2027 | AQ1: 2027 | AR1: 2028 | AS1: 2028 | AT1: 2028 | AU1: 2028 | AV1: 2028 | AW1: 2028 | AX1: 2028 | AY1: 2028 | AZ1: 2028 | BA1: 2028 | BB1: 2028 | BC1: 2028 | BD1: 2029 | BE1: 2029 | BF1: 2029 | BG1: 2029 | BH1: 2029 | BI1: 2029 | BJ1: 2029 | BK1: 2029 | BL1: 2029 | BM1: 2029 | BN1: 2029 | BO1: 2029 | BP1: 2030 | BQ1: 2030 | BR1: 2030 | BS1: 2030 | BT1: 2030 | BU1: 2030 | BV1: 2030 | BW1: 2030 | BX1: 2030 | BY1: 2030 | BZ1: 2030 | CA1: 2030 | CI1: =COUNTIFS(CI$78:CI$159, "FALSE") -> 0 | CJ1: =COUNTIFS(CJ$78:CJ$159, "FALSE") -> 4 | CK1: =COUNTIFS(CK$78:CK$159, "FALSE") -> 4 | CL1: =COUNTIFS(CL$78:CL$159, "FALSE") -> 0 | CM1: =COUNTIFS(CM$78:CM$159, "FALSE") -> 0
C9: ="#"&$F$13&" Initiative Business Case" -> #123456 Initiative Business Case
C11: INPUTS & ASSUMPTIONS
D13: Initiative # | F13: 123456
D14: Initiative Owner | F14: John Smith
D15: Initiative Name | F15: Leverage agentic AI for customer service and care centers, reducing number of calls handled by live customer care agents and increasing productivity | I15: Names - 5-7 words
I16: Descriptions - 10-20 words
D18: Estimated L4 date | F18: 46736
D19: Net Recurring Benefit ($M) | F19: =$K$128 -> 7.2
C21: SECTION I - PRIMARY VALUE DRIVER (ILLUSTRATIVE) | L21: CHECKS
D23: Illustrative example of value driver explanation - please edit fields to reflect value drivers for your Initiative | L23: Criteria (Column Reference) | P23: Check | Q23: Troubleshoot:
D24: Baseline | H24: Period | I24: KPI | J24: Inputs | L24: (A) Annualized Run Rate (K) = 2030 Value (P) | P24: =IF($R$1=0, "PASS", "ERROR") -> PASS | Q24: =IF(P24="Error", "Check column R for errors", "")
E25: # of calls handled by live agents | G25: [A] | H25: FY2025 | I25: # of calls | J25: 6000 | L25: (B) 2026 Value (L) = Sum of Monthly 2026 Values (CC) | P25: =IF($CI$1=0, "PASS", "ERROR") -> PASS | Q25: =IF(P25="Error", "Check column CI for errors", "")
E26: AHT | G26: [B] | H26: FY 2026 | I26: Seconds | J26: 150 | L26: (C) 2027 Value (M) = Sum of Monthly 2027 Values (CD) | P26: =IF($CJ$1=0, "PASS", "ERROR") -> ERROR | Q26: =IF(P26="Error", "Check column CJ for errors", "") -> Check column CJ for errors
E27: # of live agents handling calls | G27: [C] | H27: FY 2025 | I27: # of live agents | J27: 500 | L27: (D) 2028 Value (N) = Sum of Monthly 2028 Values (CE) | P27: =IF($CK$1=0, "PASS", "ERROR") -> ERROR | Q27: =IF(P27="Error", "Check column CK for errors", "") -> Check column CK for errors
E28: Average cost per agent | H28: FY 2026 | I28: $ / agent | J28: 50000 | L28: (E) 2029 Value (O) = Sum of Monthly 2029 Values (CF) | P28: =IF($CL$1=0, "PASS", "ERROR") -> PASS | Q28: =IF(P28="Error", "Check column CL for errors", "")
E29: Total spend on contact center for queue X | G29: [D] | H29: FY2025 | I29: $USD M | J29: =(J27*J28)/1000000 -> 25 | L29: (F) 2030 Value (P) = Sum of Monthly 2030 Values (CG) | P29: =IF($CM$1=0, "PASS", "ERROR") -> PASS | Q29: =IF(P29="Error", "Check column CM for errors", "")
D31: Goal | Y31: D
E32: # of calls handled by live agents | G32: [E] | I32: # of calls | J32: 4000
E33: AHT | G33: [F] | I33: Seconds | J33: 120
E34: # of live agents handling calls | G34: [G] | I34: # of live agents | J34: 260
E35: Average cost per agent | I35: $ / agent | J35: =J28 -> 50000
E36: Total spend on contact center for queue X | G36: [H] | H36: FY2026 | I36: $USD M | J36: =(J34*J35)/1000000 -> 13
D38: Incremental Improvement
E39: # of calls handled by live agents | G39: [A]-[E] | I39: # of calls | J39: =J25-J32 -> 2000
E40: AHT | G40: [B]-[F] | I40: Seconds | J40: =J26-J33 -> 30
E41: # of live agents handling calls | G41: [C]-[G] | I41: # of live agents | J41: =J27-J34 -> 240
E42: Total spend on contact center queue X | G42: [D]-[H] | I42: USD M | J42: =J29-J36 -> 12
D43: Baseline | H43: Period | I43: $USD M | J43: Inputs
E44: # xxxx | H44: FY2025 | I44: # xxxx | J44: 12000000
E45: xxxx unit cost | G45: [A] | H45: FY2025 | I45: $ xxxx | J45: 0.14
E46: xxxx total spend | G46: [B] | H46: FY2025 | I46: $USD K | J46: =(J44*J45)/1000 -> 1680
D48: Goal
E49: # xxxx | H49: FY2025 | I49: # xxxx | J49: =$J$25 -> 6000
E50: xxxx unit cost | G50: [C] | H50: FY2026 | I50: $ xxxx | J50: 0.1
E51: xxxx total spend | G51: [D] | H51: FY2026 | I51: $USD K | J51: =(J49*J50)/1000 -> 0.6
D53: Incremental Improvement
E54: =E50 -> xxxx unit cost | G54: [A]-[C] | I54: $ / xxxx | J54: =J45-J50 -> 0.04
E55: =E51 -> xxxx total spend | G55: [B]-[D] | I55: $USD K | J55: =J46-J51 -> 1679.4
D58: Baseline | H58: Period | I58: KPI | J58: Inputs
...

Sheet Rate Card
B2: RATE CARD — people-cost engine (shared by all initiative models)
B4: Blue cells with yellow fill = inputs you can change. Black = formulas. All initiative models pull the blended rate and policy tables from this sheet.
B6: 1. RATE BASIS
B8: Rate basis for people costs | D8: Yearly | F8: Choose how role rates are quoted, then TYPE YOUR RATES in the matching column of the role table below (Yearly->col D, Monthly->col E, Hourly->col F). The other columns show derived equivalents until you overwrite them. Hourly => monthly = $/hr x hours/day x days/month.
B10: Working hours per day | D10: 8 | F10: Used only when rate basis = Hourly.
B11: Billable days per month | D11: 21
B12: Months per year (for yearly basis) | D12: 12
B14: 2. STANDARD TEAM COMPOSITION & BLENDED RATE
B16: Role | C16: # in std team | D16: Yearly rate ($/yr) | E16: Monthly rate ($/mo) | F16: Hourly rate ($/hr) | G16: Monthly used ($/mo) | H16: Team cost ($/mo) | I16: Source / notes
B17: Product Owner | C17: 1 | D17: 200000 | E17: =IF(D17="",0,D17/$D$12) -> 16666.667 | F17: =IF(D17="",0,E17/($D$10*$D$11)) -> 99.206349 | G17: =IF($D$8="Hourly",F17*$D$10*$D$11,IF($D$8="Monthly",E17,IF(D17="",0,D17/$D$12))) -> 16666.667 | H17: =IF(C17="",0,C17*G17) -> 16666.667
B18: PM / Scrum Master | C18: 1 | D18: 200000 | E18: =IF(D18="",0,D18/$D$12) -> 16666.667 | F18: =IF(D18="",0,E18/($D$10*$D$11)) -> 99.206349 | G18: =IF($D$8="Hourly",F18*$D$10*$D$11,IF($D$8="Monthly",E18,IF(D18="",0,D18/$D$12))) -> 16666.667 | H18: =IF(C18="",0,C18*G18) -> 16666.667
B19: Tech Lead | C19: 1 | D19: 200000 | E19: =IF(D19="",0,D19/$D$12) -> 16666.667 | F19: =IF(D19="",0,E19/($D$10*$D$11)) -> 99.206349 | G19: =IF($D$8="Hourly",F19*$D$10*$D$11,IF($D$8="Monthly",E19,IF(D19="",0,D19/$D$12))) -> 16666.667 | H19: =IF(C19="",0,C19*G19) -> 16666.667
B20: AI Engineer | C20: 2 | D20: 200000 | E20: =IF(D20="",0,D20/$D$12) -> 16666.667 | F20: =IF(D20="",0,E20/($D$10*$D$11)) -> 99.206349 | G20: =IF($D$8="Hourly",F20*$D$10*$D$11,IF($D$8="Monthly",E20,IF(D20="",0,D20/$D$12))) -> 16666.667 | H20: =IF(C20="",0,C20*G20) -> 33333.333
B21: DevOps Engineer | C21: 1 | D21: 200000 | E21: =IF(D21="",0,D21/$D$12) -> 16666.667 | F21: =IF(D21="",0,E21/($D$10*$D$11)) -> 99.206349 | G21: =IF($D$8="Hourly",F21*$D$10*$D$11,IF($D$8="Monthly",E21,IF(D21="",0,D21/$D$12))) -> 16666.667 | H21: =IF(C21="",0,C21*G21) -> 16666.667
B22: QA Engineer | C22: 1 | D22: 200000 | E22: =IF(D22="",0,D22/$D$12) -> 16666.667 | F22: =IF(D22="",0,E22/($D$10*$D$11)) -> 99.206349 | G22: =IF($D$8="Hourly",F22*$D$10*$D$11,IF($D$8="Monthly",E22,IF(D22="",0,D22/$D$12))) -> 16666.667 | H22: =IF(C22="",0,C22*G22) -> 16666.667
B23: FA / UX | C23: 1 | D23: 200000 | E23: =IF(D23="",0,D23/$D$12) -> 16666.667 | F23: =IF(D23="",0,E23/($D$10*$D$11)) -> 99.206349 | G23: =IF($D$8="Hourly",F23*$D$10*$D$11,IF($D$8="Monthly",E23,IF(D23="",0,D23/$D$12))) -> 16666.667 | H23: =IF(C23="",0,C23*G23) -> 16666.667
E24: =IF(D24="",0,D24/$D$12) -> 0 | F24: =IF(D24="",0,E24/($D$10*$D$11)) -> 0 | G24: =IF($D$8="Hourly",F24*$D$10*$D$11,IF($D$8="Monthly",E24,IF(D24="",0,D24/$D$12))) -> 0 | H24: =IF(C24="",0,C24*G24) -> 0 | I24: spare row — add roles as team shape is refined
E25: =IF(D25="",0,D25/$D$12) -> 0 | F25: =IF(D25="",0,E25/($D$10*$D$11)) -> 0 | G25: =IF($D$8="Hourly",F25*$D$10*$D$11,IF($D$8="Monthly",E25,IF(D25="",0,D25/$D$12))) -> 0 | H25: =IF(C25="",0,C25*G25) -> 0 | I25: spare row — add roles as team shape is refined
E26: =IF(D26="",0,D26/$D$12) -> 0 | F26: =IF(D26="",0,E26/($D$10*$D$11)) -> 0 | G26: =IF($D$8="Hourly",F26*$D$10*$D$11,IF($D$8="Monthly",E26,IF(D26="",0,D26/$D$12))) -> 0 | H26: =IF(C26="",0,C26*G26) -> 0 | I26: spare row — add roles as team shape is refined
B27: Total standard team | C27: =SUM(C17:C26) -> 8 | H27: =SUM(H17:H26) -> 133333.33
B29: BLENDED RATE — per team member | G29: =IF(C27=0,0,H27/C27) -> 16666.667 | H29: $/person/month | I29: Weighted average monthly cost of one member of the standard team. Initiative milestone tables use this unless a rate override is entered.
G30: =G29*$D$12 -> 200000 | H30: $/person/year
G31: =G29/($D$10*$D$11) -> 99.206349 | H31: $/person/hour
B33: 3. CONTINGENCY FACTOR REFERENCE
B35: Complexity / risk level | C35: Factor | F35: Based on the complexity and risks to deliver the milestone.
B36: Low | C36: 0.1
B37: Medium | C37: 0.15
B38: High | C38: 0.2
B39: Very high | C39: 0.5
B42: 4. CAPITALIZATION POLICY (labor) — default % of milestone labor capitalizable
B44: Milestone | C44: Cap % | F44: Share of labor cost treated as CapEx (feeds WAVE 'Capital Expenditures'); remainder is expensed one-time cost (WAVE 'OTC'). Defaults follow a typical internal-use software policy (ASC 350-40): application development/build stage capitalizable, planning and post-launch expensed. CONFIRM WITH FINANCE — initiative models reference these cells, override there if needed.
B45: Plan / Design | C45: 0
B46: Build / Test | C46: 0
B47: Pilot / Change Mgmt. | C47: 0
B48: Scale / Run | C48: 0
B49: Non-labor one-time (default) | C49: 0
B51: 5. NOTES
B52: • Roles = the S2 model's standard 8-FTE build pod; every role priced at the S2 blended loaded delivery rate of $200,000/yr, so the blended rate ties to the S2 investment build exactly. Differentiate role rates here once the client rate card arrives (C1–C3 were designed for a rate-card drop-in).
B53: • Milestone contingency of 10% in the initiative models = the S2 'risk adjustment on delivery labour'. PM (8%) and contingency (10%) uplifts are separate formula lines in each model's one-time non-labor table — total one-time per initiative ties to S2 C2 row 35.
B54: • Capitalization defaults are 0% because the S2 model treats all one-time spend as cash/expensed (no CapEx split anywhere in C1–C3). Set Build/Test cap % here (e.g. 80%) once Finance confirms treatment — the CapEx/OTC split then flows to the WAVE sheets automatically.
...

Sheet Summary
B2: SERVICING WORKSTREAM — PORTFOLIO SUMMARY ($M)
B3: All figures link to the initiative WAVE sheets. Payback/NPV per WAVE Section IV.
B5: Initiative | C5: NRB run rate | D5: NRB 2026 | E5: NRB 2027 | F5: NRB 2028 | G5: NRB 2029 | H5: NRB 2030 | I5: One-time cost (5yr) | J5: Run cost 2030 | K5: NPV (5yr) | L5: Payback (yrs)
B6: SVC-1 — Contact Avoidance | C6: ='SVC-1 WAVE'!$K$117 -> 12.338616 | D6: ='SVC-1 WAVE'!$L$117 -> 0 | E6: ='SVC-1 WAVE'!$M$117 -> 2.0205931 | F6: ='SVC-1 WAVE'!$N$117 -> 12.249459 | G6: ='SVC-1 WAVE'!$O$117 -> 12.338616 | H6: ='SVC-1 WAVE'!$P$117 -> 12.338616 | I6: =SUM('SVC-1 WAVE'!$L$147:$P$147) -> 1.9602 | J6: ='SVC-1 WAVE'!$P$115 -> 0.5 | K6: ='SVC-1 WAVE'!$G$168 -> 25.80883 | L6: ='SVC-1 WAVE'!$G$165 -> 0
B7: SVC-2 — Enhanced Chat / Self-Serve | C7: ='SVC-2 WAVE'!$K$117 -> 12.43123 | D7: ='SVC-2 WAVE'!$L$117 -> 0 | E7: ='SVC-2 WAVE'!$M$117 -> 0.91249807 | F7: ='SVC-2 WAVE'!$N$117 -> 11.7042 | G7: ='SVC-2 WAVE'!$O$117 -> 12.43123 | H7: ='SVC-2 WAVE'!$P$117 -> 12.43123 | I7: =SUM('SVC-2 WAVE'!$L$147:$P$147) -> 2.5047 | J7: ='SVC-2 WAVE'!$P$115 -> 2.34 | K7: ='SVC-2 WAVE'!$G$168 -> 24.155774 | L7: ='SVC-2 WAVE'!$G$165 -> 1.1090693
B8: SVC-3 — Agentic Voice & AI Co-pilot | C8: ='SVC-3 WAVE'!$K$117 -> 29.700739 | D8: ='SVC-3 WAVE'!$L$117 -> 0 | E8: ='SVC-3 WAVE'!$M$117 -> 1.9375616 | F8: ='SVC-3 WAVE'!$N$117 -> 27.046511 | G8: ='SVC-3 WAVE'!$O$117 -> 29.700739 | H8: ='SVC-3 WAVE'!$P$117 -> 29.700739 | I8: =SUM('SVC-3 WAVE'!$L$147:$P$147) -> 4.90644 | J8: ='SVC-3 WAVE'!$P$115 -> 5.55 | K8: ='SVC-3 WAVE'!$G$168 -> 57.697013 | L8: ='SVC-3 WAVE'!$G$165 -> 1.0877635
B9: SVC-4 — AI Workforce Management | C9: ='SVC-4 WAVE'!$K$117 -> 6.3044496 | D9: ='SVC-4 WAVE'!$L$117 -> 0 | E9: ='SVC-4 WAVE'!$M$117 -> 1.2386124 | F9: ='SVC-4 WAVE'!$N$117 -> 6.3044496 | G9: ='SVC-4 WAVE'!$O$117 -> 6.3044496 | H9: ='SVC-4 WAVE'!$P$117 -> 6.3044496 | I9: =SUM('SVC-4 WAVE'!$L$147:$P$147) -> 3.53628 | J9: ='SVC-4 WAVE'!$P$115 -> 1.35 | K9: ='SVC-4 WAVE'!$G$168 -> 11.275502 | L9: ='SVC-4 WAVE'!$G$165 -> 1.3644517
B10: SVC-5 — Back-Office Automation | C10: ='SVC-5 WAVE'!$K$117 -> 5.5535036 | D10: ='SVC-5 WAVE'!$L$117 -> 0 | E10: ='SVC-5 WAVE'!$M$117 -> 0.24279197 | F10: ='SVC-5 WAVE'!$N$117 -> 5.0173783 | G10: ='SVC-5 WAVE'!$O$117 -> 5.5535036 | H10: ='SVC-5 WAVE'!$P$117 -> 5.5535036 | I10: =SUM('SVC-5 WAVE'!$L$147:$P$147) -> 2.72052 | J10: ='SVC-5 WAVE'!$P$115 -> 1.28 | K10: ='SVC-5 WAVE'!$G$168 -> 9.1799853 | L10: ='SVC-5 WAVE'!$G$165 -> 1.4409851
B11: SVC-6 — Non-FTE Savings | C11: ='SVC-6 WAVE'!$K$117 -> 4.0395467 | D11: ='SVC-6 WAVE'!$L$117 -> 0 | E11: ='SVC-6 WAVE'!$M$117 -> 0.67325778 | F11: ='SVC-6 WAVE'!$N$117 -> 3.8712322 | G11: ='SVC-6 WAVE'!$O$117 -> 4.0395467 | H11: ='SVC-6 WAVE'!$P$117 -> 4.0395467 | I11: =SUM('SVC-6 WAVE'!$L$147:$P$147) -> 0 | J11: ='SVC-6 WAVE'!$P$115 -> 0 | K11: ='SVC-6 WAVE'!$G$168 -> 8.88588 | L11: ='SVC-6 WAVE'!$G$165 -> 0
B12: TOTAL — SERVICING WORKSTREAM | C12: =SUM(C6:C11) -> 70.368085 | D12: =SUM(D6:D11) -> 0 | E12: =SUM(E6:E11) -> 7.0253149 | F12: =SUM(F6:F11) -> 66.19323 | G12: =SUM(G6:G11) -> 70.368085 | H12: =SUM(H6:H11) -> 70.368085 | I12: =SUM(I6:I11) -> 15.62814 | J12: =SUM(J6:J11) -> 11.02
B14: Note: NPV and payback are not additive across initiatives; totals shown for benefit/cost columns only.
B15: Capitalization policy note: this file defaults ALL cap % to 0% to mirror the S2 model's all-cash treatment; the SDLC/Sales files default Build/Test labor to 80%. Align the policy across workstreams with Finance before the S2 gate.

Sheet SVC-1 Model
B2: SVC-1 — Contact Avoidance | INITIATIVE MODEL
B3: Workstream: Servicing (ELT sponsor: Aaron | WSL: Tahira | IOs: Jackie Yu, Matt Anderson, Bob Hurst) • Model status: Seeded 1:1 from S2 vDraft5 (Base) — benefit ties to $12.84M
T5: 2026 | U5: 2026 | V5: 2026 | W5: 2026 | X5: 2026 | Y5: 2026 | Z5: 2026 | AA5: 2026 | AB5: 2026 | AC5: 2026 | AD5: 2026 | AE5: 2026 | AF5: 2027 | AG5: 2027 | AH5: 2027 | AI5: 2027 | AJ5: 2027 | AK5: 2027 | AL5: 2027 | AM5: 2027 | AN5: 2027 | AO5: 2027 | AP5: 2027 | AQ5: 2027 | AR5: 2028 | AS5: 2028 | AT5: 2028 | AU5: 2028 | AV5: 2028 | AW5: 2028 | AX5: 2028 | AY5: 2028 | AZ5: 2028 | BA5: 2028 | BB5: 2028 | BC5: 2028 | BD5: 2029 | BE5: 2029 | BF5: 2029 | BG5: 2029 | BH5: 2029 | BI5: 2029 | BJ5: 2029 | BK5: 2029 | BL5: 2029 | BM5: 2029 | BN5: 2029 | BO5: 2029 | BP5: 2030 | BQ5: 2030 | BR5: 2030 | BS5: 2030 | BT5: 2030 | BU5: 2030 | BV5: 2030 | BW5: 2030 | BX5: 2030 | BY5: 2030 | BZ5: 2030 | CA5: 2030
B6: Monthly grid (Jan-26 → Dec-30) → | K6: Run rate | L6: 2026 | M6: 2027 | N6: 2028 | O6: 2029 | P6: 2030 | T6: =DATE(2026,1,31) -> 46053 | U6: =EOMONTH(T6,1) -> 46081 | V6: =EOMONTH(U6,1) -> 46112 | W6: =EOMONTH(V6,1) -> 46142 | X6: =EOMONTH(W6,1) -> 46173 | Y6: =EOMONTH(X6,1) -> 46203 | Z6: =EOMONTH(Y6,1) -> 46234 | AA6: =EOMONTH(Z6,1) -> 46265 | AB6: =EOMONTH(AA6,1) -> 46295 | ... CA6: =EOMONTH(BZ6,1) -> 47848
B8: 0. INITIATIVE & STATUS
B10: Initiative name | D10: Prevent avoidable contacts at source through product fixes and upstream journey improvements
B11: Initiative owner | D11: Servicing IO — TBC (pool: Jackie Yu, Matt Anderson, Bob Hurst) | I11: confirm with workstream lead
B12: Impacted BU | D12: Global Servicing
B13: Go-live / Estimated L4 date | D13: =DATE(2027,8,1) -> 46600 | I13: Benefit ramp is gated on this date.
B15: Source: Servicing S2 sizing model vDraft5 (28 Aug 2026), Base scenario. Distilled to tier level; per-tier eligible bases and effective rates reproduce the S2 L2-intent engine output exactly (verified).
B16: Source: Workplan: 'Project Zenith Automation workplan and data requests vS_1.xlsx', Servicing tabs
B17: Open items to refine with initiative owner:
B18: – Tier rates are the S2 assumptions (Easy 20% / Medium 10% / Hard 5% of eligible contacts); scenario variants in S2: Upside 28/18/8, Downside 12/7/3.
B19: – $31.4M of opening cost is ineligible (NEI + unmappable 'Others' + no-product-fix rows) — ~20% of the front-office base carries zero avoidance benefit; upside if taxonomy improves.
B20: – S2 contact baseline is 37.7M offered contacts annualized from 7 months (x12/7), ~5% above the $148M FP&A reference — FP&A to confirm; workplan cites a different 20.4M baseline (basis differs).
B22: 1. SIZING ASSUMPTIONS (blue = inputs — refine with initiative owner)
B24: Opening baseline (S2 waterfall position: first lever, opens on A0 baseline)
B25: Opening front-office cost baseline | D25: 1.5602454e+08 | E25: $/yr | F25: Servicing S2 sizing model vDraft5 (28 Aug 2026), Base scenario. A0 intent cost baseline (annualized 7-mo actuals x 12/7). Opening cost follows the S2 stacking waterfall (each lever opens on the prior lever's closing baseline; order: 1 Avoidance → 2 Chat → 3a Voice → 3b Co-pilot → 4a SBR → 4b Utilisation). Tier-level bases below are snapshots of the S2 L2 engine — refresh them from the S2 model if upstream levers or tiering change.
B26: Investment uplifts (S2 standard)
B27: Programme management, % of build | D27: 0.08 | E27: % | F27: S2 COST_PMO
B28: Contingency, % of build incl. PM | D28: 0.1 | E28: % | F28: S2 COST_CONT
B29: Run team headcount | D29: 2 | E29: # FTE | F29: S2 C3: keep-the-lights-on
B30: Run team loaded rate | D30: 180000 | E30: $/FTE/yr | F30: S2 COST_RUN_RATE
B31: (spare assumption row)
B32: (spare assumption row)
B34: Eligible opening cost by difficulty tier (S2 Intent Tiering, avoidance column)
B35: Tier | D35: Eligible cost base ($/yr) | F35: Effective rate | H35: Benefit ($/yr) | J35: FTE base | K35: FTE released | M35: Rates = S2 tier assumptions (CA_*). Bases = S2 eligible opening cost aggregated from the 77-intent engine.
B36: Easy (12 L2 intents) | D36: 15982020 | F36: 0.2 | H36: =D36*F36 -> 3196403.9 | J36: 738.162 | K36: =J36*F36 -> 147.6324 | M36: S2 rate: 20% of contacts avoidable
B37: Medium (43 L2 intents) | D37: 84197500 | F37: 0.1 | H37: =D37*F37 -> 8419750 | J37: 3579.664 | K37: =J37*F37 -> 357.9664 | M37: S2 rate: 10%
B38: Hard (19 L2 intents) | D38: 24449246 | F38: 0.05 | H38: =D38*F38 -> 1222462.3 | J38: 705.871 | K38: =J38*F38 -> 35.29355 | M38: S2 rate: 5%
B39: Ineligible (NEI / unmappable / no product fix) | D39: 31395771 | F39: 0 | H39: =D39*F39 -> 0 | J39: 897.612 | K39: =J39*F39 -> 0 | M39: H='No' rows + NEI + 'Others' — no benefit booked
B40: Subtotal — Eligible opening cost by difficulty tier | D40: =SUM(D36:D39) -> 1.5602454e+08 | H40: =SUM(H36:H39) -> 12838616 | J40: =SUM(J36:J39) -> 5921.309 | K40: =SUM(K36:K39) -> 540.89235
B42: 2. BENEFIT CALCULATION (steady-state annual run-rate)
B44: Total annual benefit (steady state) | D44: =$H$40 -> 12838616 | E44: $/yr | F44: Ties to S2 A1 benefit $12,838,616
B45: FTE impacted (feeds Non-FTE model SVC-6) | D45: =$K$40 -> 540.89235 | E45: # FTE | F45: Ties to S2: 540.9 FTE
B46: Closing cost (hand-off baseline to SVC-2) | D46: =$D$25-$D$44 -> 1.4318592e+08 | E46: $/yr | F46: S2: $143,185,920
B48: 3. RAMP & PHASING
B50: Months to full run rate after go-live (linear ramp) | D50: 6 | F50: Benefit starts at go-live and ramps linearly to steady state over this many months.
B51: Monthly ramp % (run-rate captured in month) | T51: =MIN(1,MAX(0,((YEAR(T$6)-YEAR($D$13))*12+MONTH(T$6)-MONTH($D$13)+0.5)/MAX($D$50,0.5))) -> 0 | U51: =MIN(1,MAX(0,((YEAR(U$6)-YEAR($D$13))*12+MONTH(U$6)-MONTH($D$13)+0.5)/MAX($D$50,0.5))) -> 0 | V51: =MIN(1,MAX(0,((YEAR(V$6)-YEAR($D$13))*12+MONTH(V$6)-MONTH($D$13)+0.5)/MAX($D$50,0.5))) -> 0 | W51: =MIN(1,MAX(0,((YEAR(W$6)-YEAR($D$13))*12+MONTH(W$6)-MONTH($D$13)+0.5)/MAX($D$50,0.5))) -> 0 | X51: =MIN(1,MAX(0,((YEAR(X$6)-YEAR($D$13))*12+MONTH(X$6)-MONTH($D$13)+0.5)/MAX($D$50,0.5))) -> 0 | Y51: =MIN(1,MAX(0,((YEAR(Y$6)-YEAR($D$13))*12+MONTH(Y$6)-MONTH($D$13)+0.5)/MAX($D$50,0.5))) -> 0 | Z51: =MIN(1,MAX(0,((YEAR(Z$6)-YEAR($D$13))*12+MONTH(Z$6)-MONTH($D$13)+0.5)/MAX($D$50,0.5))) -> 0 | AA51: =MIN(1,MAX(0,((YEAR(AA$6)-YEAR($D$13))*12+MONTH(AA$6)-MONTH($D$13)+0.5)/MAX($D$50,0.5))) -> 0 | ... CA51: =MIN(1,MAX(0,((YEAR(CA$6)-YEAR($D$13))*12+MONTH(CA$6)-MONTH($D$13)+0.5)/MAX($D$50,0.5))) -> 1
B52: Resulting average ramp % by year (info) | L52: =SUMIFS($T51:$CA51,$T$5:$CA$5,2026)/12 -> 0 | M52: =SUMIFS($T51:$CA51,$T$5:$CA$5,2027)/12 -> 0.17361111 | N52: =SUMIFS($T51:$CA51,$T$5:$CA$5,2028)/12 -> 0.99305556 | O52: =SUMIFS($T51:$CA51,$T$5:$CA$5,2029)/12 -> 1 | P52: =SUMIFS($T51:$CA51,$T$5:$CA$5,2030)/12 -> 1
...

Sheet SVC-1 WAVE
L1: 1 | M1: 2 | N1: 3 | O1: 4 | P1: 5 | R1: =COUNTIFS($R$66:$R$117, "Error") -> 0 | T1: 2026 | U1: 2026 | V1: 2026 | W1: 2026 | X1: 2026 | Y1: 2026 | Z1: 2026 | AA1: 2026 | AB1: 2026 | AC1: 2026 | AD1: 2026 | AE1: 2026 | AF1: 2027 | AG1: 2027 | AH1: 2027 | AI1: 2027 | AJ1: 2027 | AK1: 2027 | AL1: 2027 | AM1: 2027 | AN1: 2027 | AO1: 2027 | AP1: 2027 | AQ1: 2027 | AR1: 2028 | AS1: 2028 | AT1: 2028 | AU1: 2028 | AV1: 2028 | AW1: 2028 | AX1: 2028 | AY1: 2028 | AZ1: 2028 | BA1: 2028 | BB1: 2028 | BC1: 2028 | BD1: 2029 | BE1: 2029 | BF1: 2029 | BG1: 2029 | BH1: 2029 | BI1: 2029 | BJ1: 2029 | BK1: 2029 | BL1: 2029 | BM1: 2029 | BN1: 2029 | BO1: 2029 | BP1: 2030 | BQ1: 2030 | BR1: 2030 | BS1: 2030 | BT1: 2030 | BU1: 2030 | BV1: 2030 | BW1: 2030 | BX1: 2030 | BY1: 2030 | BZ1: 2030 | CA1: 2030 | CI1: =COUNTIFS(CI$66:CI$149, "FALSE") -> 0 | CJ1: =COUNTIFS(CJ$66:CJ$149, "FALSE") -> 0 | CK1: =COUNTIFS(CK$66:CK$149, "FALSE") -> 0 | CL1: =COUNTIFS(CL$66:CL$149, "FALSE") -> 0 | CM1: =COUNTIFS(CM$66:CM$149, "FALSE") -> 0
C2: ="#"&$F$6&" Initiative Business Case" -> #TBD Initiative Business Case
C4: INPUTS & ASSUMPTIONS
D6: Initiative # | F6: TBD
D7: Initiative Owner | F7: Servicing IO — TBC (pool: Jackie Yu, Matt Anderson, Bob Hurst)
D8: Initiative Name | F8: Prevent avoidable contacts at source through product fixes and upstream journey improvements
D11: Estimated L4 date | F11: ='SVC-1 Model'!$D$13 -> 46600
D12: Net Recurring Benefit ($M) | F12: =$K$117 -> 12.338616
C14: SECTION I - PRIMARY VALUE DRIVER (ILLUSTRATIVE)
D16: Primary value driver — linked to the Model sheet; refine with the initiative owner
D17: Baseline | H17: Period | I17: KPI | J17: Inputs
E18: Front-office servicing cost baseline (annualized) | H18: Jan–Jul 2026 x 12/7 | I18: $USD M | J18: ='SVC-1 Model'!$D$25/1000000 -> 156.02454
E19: Eligible base (Easy+Medium+Hard tiers) | H19: same | I19: $USD M | J19: =('SVC-1 Model'!$D$25-'SVC-1 Model'!$D$39)/1000000 -> 124.62877
E20: Implied front-office FTE (S2 A0) | H20: same | I20: # FTE | J20: ='SVC-1 Model'!$J$40 -> 5921.309
D23: Goal
E24: Blended avoidance rate on opening cost | H24: Steady state | I24: % | J24: ='SVC-1 Model'!$D$44/'SVC-1 Model'!$D$25 -> 0.082285879
E25: FTE impacted | H25: Steady state | I25: # FTE | J25: ='SVC-1 Model'!$D$45 -> 540.89235
D28: Incremental Improvement
E29: Annual benefit (run rate) | I29: $USD M | J29: ='SVC-1 Model'!$D$44/1000000 -> 12.838616
C60: SECTION II - NET RECURRING BENEFITS | CC60: ANNUAL SUMMARY | CI60: CHECK CELLS
T62: 2026 | AF62: 2027 | AR62: 2028 | BD62: 2029 | BP62: 2030 | CI62: CHECK
D63: RECURRING BENEFITS | H63: Comment | I63: Baseline | J63: Goal | K63: Ann. Run Rate | L63: 2026 | M63: =L63+1 -> 2027 | N63: =M63+1 -> 2028 | O63: =N63+1 -> 2029 | P63: =O63+1 -> 2030 | Q63: Impacted BU | R63: Check | T63: 46023 | U63: =EOMONTH(T63, 1) -> 46081 | V63: =EOMONTH(U63, 1) -> 46112 | W63: =EOMONTH(V63, 1) -> 46142 | X63: =EOMONTH(W63, 1) -> 46173 | Y63: =EOMONTH(X63, 1) -> 46203 | Z63: =EOMONTH(Y63, 1) -> 46234 | AA63: =EOMONTH(Z63, 1) -> 46265 | AB63: =EOMONTH(AA63, 1) -> 46295 | ... CA63: =EOMONTH(BZ63, 1) -> 47848 | CC63: 2026 | CD63: =CC63+1 -> 2027 | CE63: =CD63+1 -> 2028 | CF63: =CE63+1 -> 2029 | CG63: =CF63+1 -> 2030 | CI63: 2026 | CJ63: =CI63+1 -> 2027 | CK63: =CJ63+1 -> 2028 | CL63: =CK63+1 -> 2029 | CM63: =CL63+1 -> 2030
E64: $USD M | I64: =$H$18 -> Jan–Jul 2026 x 12/7 | J64: Future State | K64: Increment
E65: Revenue
I66: 0 | J66: 0 | K66: =J66-I66 -> 0 | R66: =IF(K66=P66, "", "Error") | CC66: =SUMIFS($T66:$CA66, $T$1:$CA$1, CC$63) -> 0 | CD66: =SUMIFS($T66:$CA66, $T$1:$CA$1, CD$63) -> 0 | CE66: =SUMIFS($T66:$CA66, $T$1:$CA$1, CE$63) -> 0 | CF66: =SUMIFS($T66:$CA66, $T$1:$CA$1, CF$63) -> 0 | CG66: =SUMIFS($T66:$CA66, $T$1:$CA$1, CG$63) -> 0 | CI66: =CC66=L66 -> 1 | CJ66: =CD66=M66 -> 1 | CK66: =CE66=N66 -> 1 | CL66: =CF66=O66 -> 1 | CM66: =CG66=P66 -> 1
I67: 0 | J67: 0 | K67: =J67-I67 -> 0 | R67: =IF(K67=P67, "", "Error") | CC67: =SUMIFS($T67:$CA67, $T$1:$CA$1, CC$63) -> 0 | CD67: =SUMIFS($T67:$CA67, $T$1:$CA$1, CD$63) -> 0 | CE67: =SUMIFS($T67:$CA67, $T$1:$CA$1, CE$63) -> 0 | CF67: =SUMIFS($T67:$CA67, $T$1:$CA$1, CF$63) -> 0 | CG67: =SUMIFS($T67:$CA67, $T$1:$CA$1, CG$63) -> 0 | CI67: =CC67=L67 -> 1 | CJ67: =CD67=M67 -> 1 | CK67: =CE67=N67 -> 1 | CL67: =CF67=O67 -> 1 | CM67: =CG67=P67 -> 1
E68: Revenue Subtotal | I68: =SUM(I66:I67) -> 0 | J68: =SUM(J66:J67) -> 0 | K68: =SUM(K66:K67) -> 0 | L68: =SUM(L66:L67) -> 0 | M68: =SUM(M66:M67) -> 0 | N68: =SUM(N66:N67) -> 0 | O68: =SUM(O66:O67) -> 0 | P68: =SUM(P66:P67) -> 0 | T68: =SUM(T66:T67) -> 0 | U68: =SUM(U66:U67) -> 0 | V68: =SUM(V66:V67) -> 0 | W68: =SUM(W66:W67) -> 0 | X68: =SUM(X66:X67) -> 0 | Y68: =SUM(Y66:Y67) -> 0 | Z68: =SUM(Z66:Z67) -> 0 | AA68: =SUM(AA66:AA67) -> 0 | ... CA68: =SUM(CA66:CA67) -> 0 | CC68: =SUM(CC66:CC67) -> 0 | CD68: =SUM(CD66:CD67) -> 0 | CE68: =SUM(CE66:CE67) -> 0 | CF68: =SUM(CF66:CF67) -> 0 | CG68: =SUM(CG66:CG67) -> 0 | CI68: =CC68=L68 -> 1 | CJ68: =CD68=M68 -> 1 | CK68: =CE68=N68 -> 1 | CL68: =CF68=O68 -> 1 | CM68: =CG68=P68 -> 1
E70: Cost of Sales
K71: =I71-J71 -> 0 | R71: =IF(K71=P71, "", "Error") | CC71: =SUMIFS($T71:$CA71, $T$1:$CA$1, CC$63) -> 0 | CD71: =SUMIFS($T71:$CA71, $T$1:$CA$1, CD$63) -> 0 | CE71: =SUMIFS($T71:$CA71, $T$1:$CA$1, CE$63) -> 0 | CF71: =SUMIFS($T71:$CA71, $T$1:$CA$1, CF$63) -> 0 | CG71: =SUMIFS($T71:$CA71, $T$1:$CA$1, CG$63) -> 0 | CI71: =CC71=L71 -> 1 | CJ71: =CD71=M71 -> 1 | CK71: =CE71=N71 -> 1 | CL71: =CF71=O71 -> 1 | CM71: =CG71=P71 -> 1
I72: 0 | J72: 0 | K72: =I72-J72 -> 0 | R72: =IF(K72=P72, "", "Error") | CC72: =SUMIFS($T72:$CA72, $T$1:$CA$1, CC$63) -> 0 | CD72: =SUMIFS($T72:$CA72, $T$1:$CA$1, CD$63) -> 0 | CE72: =SUMIFS($T72:$CA72, $T$1:$CA$1, CE$63) -> 0 | CF72: =SUMIFS($T72:$CA72, $T$1:$CA$1, CF$63) -> 0 | CG72: =SUMIFS($T72:$CA72, $T$1:$CA$1, CG$63) -> 0 | CI72: =CC72=L72 -> 1 | CJ72: =CD72=M72 -> 1 | CK72: =CE72=N72 -> 1 | CL72: =CF72=O72 -> 1 | CM72: =CG72=P72 -> 1
I73: 0 | J73: 0 | K73: =I73-J73 -> 0 | R73: =IF(K73=P73, "", "Error") | CC73: =SUMIFS($T73:$CA73, $T$1:$CA$1, CC$63) -> 0 | CD73: =SUMIFS($T73:$CA73, $T$1:$CA$1, CD$63) -> 0 | CE73: =SUMIFS($T73:$CA73, $T$1:$CA$1, CE$63) -> 0 | CF73: =SUMIFS($T73:$CA73, $T$1:$CA$1, CF$63) -> 0 | CG73: =SUMIFS($T73:$CA73, $T$1:$CA$1, CG$63) -> 0 | CI73: =CC73=L73 -> 1 | CJ73: =CD73=M73 -> 1 | CK73: =CE73=N73 -> 1 | CL73: =CF73=O73 -> 1 | CM73: =CG73=P73 -> 1
I74: 0 | J74: 0 | K74: =I74-J74 -> 0 | R74: =IF(K74=P74, "", "Error") | CC74: =SUMIFS($T74:$CA74, $T$1:$CA$1, CC$63) -> 0 | CD74: =SUMIFS($T74:$CA74, $T$1:$CA$1, CD$63) -> 0 | CE74: =SUMIFS($T74:$CA74, $T$1:$CA$1, CE$63) -> 0 | CF74: =SUMIFS($T74:$CA74, $T$1:$CA$1, CF$63) -> 0 | CG74: =SUMIFS($T74:$CA74, $T$1:$CA$1, CG$63) -> 0 | CI74: =CC74=L74 -> 1 | CJ74: =CD74=M74 -> 1 | CK74: =CE74=N74 -> 1 | CL74: =CF74=O74 -> 1 | CM74: =CG74=P74 -> 1
K75: =I75-J75 -> 0 | R75: =IF(K75=P75, "", "Error") | CC75: =SUMIFS($T75:$CA75, $T$1:$CA$1, CC$63) -> 0 | CD75: =SUMIFS($T75:$CA75, $T$1:$CA$1, CD$63) -> 0 | CE75: =SUMIFS($T75:$CA75, $T$1:$CA$1, CE$63) -> 0 | CF75: =SUMIFS($T75:$CA75, $T$1:$CA$1, CF$63) -> 0 | CG75: =SUMIFS($T75:$CA75, $T$1:$CA$1, CG$63) -> 0 | CI75: =CC75=L75 -> 1 | CJ75: =CD75=M75 -> 1 | CK75: =CE75=N75 -> 1 | CL75: =CF75=O75 -> 1 | CM75: =CG75=P75 -> 1
E76: Cost of Sales Subtotal | I76: =SUM(I71:I75) -> 0 | J76: =SUM(J71:J75) -> 0 | K76: =SUM(K71:K75) -> 0 | L76: =SUM(L71:L75) -> 0 | M76: =SUM(M71:M75) -> 0 | N76: =SUM(N71:N75) -> 0 | O76: =SUM(O71:O75) -> 0 | P76: =SUM(P71:P75) -> 0 | T76: =SUM(T71:T75) -> 0 | U76: =SUM(U71:U75) -> 0 | V76: =SUM(V71:V75) -> 0 | W76: =SUM(W71:W75) -> 0 | X76: =SUM(X71:X75) -> 0 | Y76: =SUM(Y71:Y75) -> 0 | Z76: =SUM(Z71:Z75) -> 0 | AA76: =SUM(AA71:AA75) -> 0 | ... CA76: =SUM(CA71:CA75) -> 0 | CC76: =SUM(CC71:CC75) -> 0 | CD76: =SUM(CD71:CD75) -> 0 | CE76: =SUM(CE71:CE75) -> 0 | CF76: =SUM(CF71:CF75) -> 0 | CG76: =SUM(CG71:CG75) -> 0 | CI76: =CC76=L76 -> 1 | CJ76: =CD76=M76 -> 1 | CK76: =CE76=N76 -> 1 | CL76: =CF76=O76 -> 1 | CM76: =CG76=P76 -> 1
E78: OPEX
E79: OPEX - Front-office cost reduction (avoided contacts) | H79: Eligible cost x tier avoidance rates (S2 tier engine, distilled) | I79: ='SVC-1 Model'!$D$57 -> 156.02454 | J79: =I79-'SVC-1 Model'!$K$57 -> 143.18592 | K79: ='SVC-1 Model'!$K$57 -> 12.838616 | L79: ='SVC-1 Model'!L57 -> 0 | M79: ='SVC-1 Model'!M57 -> 2.2289264 | N79: ='SVC-1 Model'!N57 -> 12.749459 | O79: ='SVC-1 Model'!O57 -> 12.838616 | P79: ='SVC-1 Model'!P57 -> 12.838616 | Q79: Global Servicing | R79: =IF(K79=P79, "", "Error") | T79: ='SVC-1 Model'!T57 -> 0 | U79: ='SVC-1 Model'!U57 -> 0 | V79: ='SVC-1 Model'!V57 -> 0 | W79: ='SVC-1 Model'!W57 -> 0 | X79: ='SVC-1 Model'!X57 -> 0 | Y79: ='SVC-1 Model'!Y57 -> 0 | Z79: ='SVC-1 Model'!Z57 -> 0 | AA79: ='SVC-1 Model'!AA57 -> 0 | ... CA79: ='SVC-1 Model'!CA57 -> 1.0698847 | CC79: =SUMIFS($T79:$CA79, $T$1:$CA$1, CC$63) -> 0 | CD79: =SUMIFS($T79:$CA79, $T$1:$CA$1, CD$63) -> 2.2289264 | CE79: =SUMIFS($T79:$CA79, $T$1:$CA$1, CE$63) -> 12.749459 | CF79: =SUMIFS($T79:$CA79, $T$1:$CA$1, CF$63) -> 12.838616 | CG79: =SUMIFS($T79:$CA79, $T$1:$CA$1, CG$63) -> 12.838616 | CI79: =CC79=L79 -> 1 | CJ79: =CD79=M79 -> 1 | CK79: =CE79=N79 -> 1 | CL79: =CF79=O79 -> 1 | CM79: =CG79=P79 -> 1
I80: 0 | J80: 0 | K80: =I80-J80 -> 0 | R80: =IF(K80=P80, "", "Error") | CC80: =SUMIFS($T80:$CA80, $T$1:$CA$1, CC$63) -> 0 | CD80: =SUMIFS($T80:$CA80, $T$1:$CA$1, CD$63) -> 0 | CE80: =SUMIFS($T80:$CA80, $T$1:$CA$1, CE$63) -> 0 | CF80: =SUMIFS($T80:$CA80, $T$1:$CA$1, CF$63) -> 0 | CG80: =SUMIFS($T80:$CA80, $T$1:$CA$1, CG$63) -> 0 | CI80: =CC80=L80 -> 1 | CJ80: =CD80=M80 -> 1 | CK80: =CE80=N80 -> 1 | CL80: =CF80=O80 -> 1 | CM80: =CG80=P80 -> 1
I81: 0 | J81: 0 | K81: =I81-J81 -> 0 | R81: =IF(K81=P81, "", "Error") | CC81: =SUMIFS($T81:$CA81, $T$1:$CA$1, CC$63) -> 0 | CD81: =SUMIFS($T81:$CA81, $T$1:$CA$1, CD$63) -> 0 | CE81: =SUMIFS($T81:$CA81, $T$1:$CA$1, CE$63) -> 0 | CF81: =SUMIFS($T81:$CA81, $T$1:$CA$1, CF$63) -> 0 | CG81: =SUMIFS($T81:$CA81, $T$1:$CA$1, CG$63) -> 0 | CI81: =CC81=L81 -> 1 | CJ81: =CD81=M81 -> 1 | CK81: =CE81=N81 -> 1 | CL81: =CF81=O81 -> 1 | CM81: =CG81=P81 -> 1
I82: 0 | J82: 0 | K82: =I82-J82 -> 0 | R82: =IF(K82=P82, "", "Error") | CC82: =SUMIFS($T82:$CA82, $T$1:$CA$1, CC$63) -> 0 | CD82: =SUMIFS($T82:$CA82, $T$1:$CA$1, CD$63) -> 0 | CE82: =SUMIFS($T82:$CA82, $T$1:$CA$1, CE$63) -> 0 | CF82: =SUMIFS($T82:$CA82, $T$1:$CA$1, CF$63) -> 0 | CG82: =SUMIFS($T82:$CA82, $T$1:$CA$1, CG$63) -> 0 | CI82: =CC82=L82 -> 1 | CJ82: =CD82=M82 -> 1 | CK82: =CE82=N82 -> 1 | CL82: =CF82=O82 -> 1 | CM82: =CG82=P82 -> 1
I83: 0 | J83: 0 | K83: =I83-J83 -> 0 | R83: =IF(K83=P83, "", "Error") | CC83: =SUMIFS($T83:$CA83, $T$1:$CA$1, CC$63) -> 0 | CD83: =SUMIFS($T83:$CA83, $T$1:$CA$1, CD$63) -> 0 | CE83: =SUMIFS($T83:$CA83, $T$1:$CA$1, CE$63) -> 0 | CF83: =SUMIFS($T83:$CA83, $T$1:$CA$1, CF$63) -> 0 | CG83: =SUMIFS($T83:$CA83, $T$1:$CA$1, CG$63) -> 0 | CI83: =CC83=L83 -> 1 | CJ83: =CD83=M83 -> 1 | CK83: =CE83=N83 -> 1 | CL83: =CF83=O83 -> 1 | CM83: =CG83=P83 -> 1
...

Sheet SVC-2 Model
B2: SVC-2 — Enhanced Chat / Self-Serve | INITIATIVE MODEL
B3: Workstream: Servicing (ELT sponsor: Aaron | WSL: Tahira | IOs: Jackie Yu, Matt Anderson, Bob Hurst) • Model status: Seeded 1:1 from S2 vDraft5 (Base) — benefit ties to $14.77M
T5: 2026 | U5: 2026 | V5: 2026 | W5: 2026 | X5: 2026 | Y5: 2026 | Z5: 2026 | AA5: 2026 | AB5: 2026 | AC5: 2026 | AD5: 2026 | AE5: 2026 | AF5: 2027 | AG5: 2027 | AH5: 2027 | AI5: 2027 | AJ5: 2027 | AK5: 2027 | AL5: 2027 | AM5: 2027 | AN5: 2027 | AO5: 2027 | AP5: 2027 | AQ5: 2027 | AR5: 2028 | AS5: 2028 | AT5: 2028 | AU5: 2028 | AV5: 2028 | AW5: 2028 | AX5: 2028 | AY5: 2028 | AZ5: 2028 | BA5: 2028 | BB5: 2028 | BC5: 2028 | BD5: 2029 | BE5: 2029 | BF5: 2029 | BG5: 2029 | BH5: 2029 | BI5: 2029 | BJ5: 2029 | BK5: 2029 | BL5: 2029 | BM5: 2029 | BN5: 2029 | BO5: 2029 | BP5: 2030 | BQ5: 2030 | BR5: 2030 | BS5: 2030 | BT5: 2030 | BU5: 2030 | BV5: 2030 | BW5: 2030 | BX5: 2030 | BY5: 2030 | BZ5: 2030 | CA5: 2030
B6: Monthly grid (Jan-26 → Dec-30) → | K6: Run rate | L6: 2026 | M6: 2027 | N6: 2028 | O6: 2029 | P6: 2030 | T6: =DATE(2026,1,31) -> 46053 | U6: =EOMONTH(T6,1) -> 46081 | V6: =EOMONTH(U6,1) -> 46112 | W6: =EOMONTH(V6,1) -> 46142 | X6: =EOMONTH(W6,1) -> 46173 | Y6: =EOMONTH(X6,1) -> 46203 | Z6: =EOMONTH(Y6,1) -> 46234 | AA6: =EOMONTH(Z6,1) -> 46265 | AB6: =EOMONTH(AA6,1) -> 46295 | ... CA6: =EOMONTH(BZ6,1) -> 47848
B8: 0. INITIATIVE & STATUS
B10: Initiative name | D10: Enhanced chat and self-serve containment on messaging and email demand
B11: Initiative owner | D11: Servicing IO — TBC (pool: Jackie Yu, Matt Anderson, Bob Hurst) | I11: confirm with workstream lead
B12: Impacted BU | D12: Global Servicing
B13: Go-live / Estimated L4 date | D13: =DATE(2027,9,1) -> 46631 | I13: Benefit ramp is gated on this date.
B15: Source: Servicing S2 sizing model vDraft5 (28 Aug 2026), Base scenario. Distilled to tier level; per-tier eligible bases and effective rates reproduce the S2 L2-intent engine output exactly (verified).
B16: Source: Workplan: 'Project Zenith Automation workplan and data requests vS_1.xlsx', Servicing tabs
B17: Open items to refine with initiative owner:
B18: – Voice channel is out of scope for this lever (S2 channel gate: chat acts on messaging + email only — $39.0M of the $143.2M opening baseline).
B19: – Effective rates embed the S2 ceiling logic (target containment capped at 90% of demand) and the 30% funnel-hardening haircut — underlying target rates: Easy 50% / Medium 40% / Hard 20% of escalated demand.
B20: – S2 books nothing where current PPA containment already beats the tier ceiling (2 intents).
B22: 1. SIZING ASSUMPTIONS (blue = inputs — refine with initiative owner)
B24: Opening baseline (S2 waterfall: opens on SVC-1 closing)
B25: Opening cost baseline (all channels) | D25: 1.4318592e+08 | E25: $/yr | F25: Servicing S2 sizing model vDraft5 (28 Aug 2026), Base scenario. Opening cost follows the S2 stacking waterfall (each lever opens on the prior lever's closing baseline; order: 1 Avoidance → 2 Chat → 3a Voice → 3b Co-pilot → 4a SBR → 4b Utilisation). Tier-level bases below are snapshots of the S2 L2 engine — refresh them from the S2 model if upstream levers or tiering change.
B26: Investment uplifts (S2 standard)
B27: Programme management, % of build | D27: 0.08 | E27: %
B28: Contingency, % of build incl. PM | D28: 0.1 | E28: %
B29: Run team headcount | D29: 3 | E29: # FTE | F29: S2 C3
B30: Run team loaded rate | D30: 180000 | E30: $/FTE/yr
B31: FTE impacted (A0 basis — feeds SVC-6) | D31: 867.7176 | E31: # FTE | F31: S2 A2 'Resource impacted' (V column, A0 basis). Residual-basis reduction is 779.7 — S2 uses the A0 basis in the non-FTE flow-through; refresh from S2 if rates change
B32: (spare assumption row)
B33: (spare assumption row)
B35: Eligible opening cost by tier — messaging + email channels only (S2 chat-tier column)
B36: Tier | D36: Eligible cost base ($/yr) | F36: Effective rate | H36: Benefit ($/yr) | M36: Effective rates implied from the S2 engine (benefit / eligible base per tier) — they bundle target rate, 90% containment ceiling and funnel hardening. Edit to test different containment ambitions.
B37: Easy (68 L2 intents) | D37: 27286882 | F37: 0.43111287 | H37: =D37*F37 -> 11763726 | M37: S2 target 50% of escalated demand; ceiling 90% binds on many rows -> effective 43.1%
B38: Medium (6 L2 intents) | D38: 3525444.7 | F38: 0.3886587 | H38: =D38*F38 -> 1370194.8 | M38: S2 target 40%; effective 38.9% after ceiling/hardening
B39: Hard (3 L2 intents) | D39: 8186544.4 | F39: 0.2 | H39: =D39*F39 -> 1637308.9 | M39: S2 target 20%
B40: Subtotal — Eligible opening cost by tier — messaging + email channels only | D40: =SUM(D37:D39) -> 38998872 | H40: =SUM(H37:H39) -> 14771230
B42: 2. BENEFIT CALCULATION (steady-state annual run-rate)
B44: Total annual benefit (steady state) | D44: =$H$40 -> 14771230 | E44: $/yr | F44: Ties to S2 A2 benefit $14,771,230
B45: Closing cost (hand-off baseline to SVC-3) | D45: =$D$25-$D$44 -> 1.2841469e+08 | E45: $/yr | F45: S2: $128,414,690
B47: 3. RAMP & PHASING
B49: Months to full run rate after go-live (linear ramp) | D49: 7 | F49: Benefit starts at go-live and ramps linearly to steady state over this many months.
B50: Monthly ramp % (run-rate captured in month) | T50: =MIN(1,MAX(0,((YEAR(T$6)-YEAR($D$13))*12+MONTH(T$6)-MONTH($D$13)+0.5)/MAX($D$49,0.5))) -> 0 | U50: =MIN(1,MAX(0,((YEAR(U$6)-YEAR($D$13))*12+MONTH(U$6)-MONTH($D$13)+0.5)/MAX($D$49,0.5))) -> 0 | V50: =MIN(1,MAX(0,((YEAR(V$6)-YEAR($D$13))*12+MONTH(V$6)-MONTH($D$13)+0.5)/MAX($D$49,0.5))) -> 0 | W50: =MIN(1,MAX(0,((YEAR(W$6)-YEAR($D$13))*12+MONTH(W$6)-MONTH($D$13)+0.5)/MAX($D$49,0.5))) -> 0 | X50: =MIN(1,MAX(0,((YEAR(X$6)-YEAR($D$13))*12+MONTH(X$6)-MONTH($D$13)+0.5)/MAX($D$49,0.5))) -> 0 | Y50: =MIN(1,MAX(0,((YEAR(Y$6)-YEAR($D$13))*12+MONTH(Y$6)-MONTH($D$13)+0.5)/MAX($D$49,0.5))) -> 0 | Z50: =MIN(1,MAX(0,((YEAR(Z$6)-YEAR($D$13))*12+MONTH(Z$6)-MONTH($D$13)+0.5)/MAX($D$49,0.5))) -> 0 | AA50: =MIN(1,MAX(0,((YEAR(AA$6)-YEAR($D$13))*12+MONTH(AA$6)-MONTH($D$13)+0.5)/MAX($D$49,0.5))) -> 0 | ... CA50: =MIN(1,MAX(0,((YEAR(CA$6)-YEAR($D$13))*12+MONTH(CA$6)-MONTH($D$13)+0.5)/MAX($D$49,0.5))) -> 1
B51: Resulting average ramp % by year (info) | L51: =SUMIFS($T50:$CA50,$T$5:$CA$5,2026)/12 -> 0 | M51: =SUMIFS($T50:$CA50,$T$5:$CA$5,2027)/12 -> 0.095238095 | N51: =SUMIFS($T50:$CA50,$T$5:$CA$5,2028)/12 -> 0.94642857 | O51: =SUMIFS($T50:$CA50,$T$5:$CA$5,2029)/12 -> 1 | P51: =SUMIFS($T50:$CA50,$T$5:$CA$5,2030)/12 -> 1
B53: 4. RECURRING BENEFIT LINES ($M — these rows feed the WAVE sheet)
...

Sheet SVC-2 WAVE
L1: 1 | M1: 2 | N1: 3 | O1: 4 | P1: 5 | R1: =COUNTIFS($R$66:$R$117, "Error") -> 0 | T1: 2026 | U1: 2026 | V1: 2026 | W1: 2026 | X1: 2026 | Y1: 2026 | Z1: 2026 | AA1: 2026 | AB1: 2026 | AC1: 2026 | AD1: 2026 | AE1: 2026 | AF1: 2027 | AG1: 2027 | AH1: 2027 | AI1: 2027 | AJ1: 2027 | AK1: 2027 | AL1: 2027 | AM1: 2027 | AN1: 2027 | AO1: 2027 | AP1: 2027 | AQ1: 2027 | AR1: 2028 | AS1: 2028 | AT1: 2028 | AU1: 2028 | AV1: 2028 | AW1: 2028 | AX1: 2028 | AY1: 2028 | AZ1: 2028 | BA1: 2028 | BB1: 2028 | BC1: 2028 | BD1: 2029 | BE1: 2029 | BF1: 2029 | BG1: 2029 | BH1: 2029 | BI1: 2029 | BJ1: 2029 | BK1: 2029 | BL1: 2029 | BM1: 2029 | BN1: 2029 | BO1: 2029 | BP1: 2030 | BQ1: 2030 | BR1: 2030 | BS1: 2030 | BT1: 2030 | BU1: 2030 | BV1: 2030 | BW1: 2030 | BX1: 2030 | BY1: 2030 | BZ1: 2030 | CA1: 2030 | CI1: =COUNTIFS(CI$66:CI$149, "FALSE") -> 0 | CJ1: =COUNTIFS(CJ$66:CJ$149, "FALSE") -> 0 | CK1: =COUNTIFS(CK$66:CK$149, "FALSE") -> 0 | CL1: =COUNTIFS(CL$66:CL$149, "FALSE") -> 0 | CM1: =COUNTIFS(CM$66:CM$149, "FALSE") -> 0
C2: ="#"&$F$6&" Initiative Business Case" -> #TBD Initiative Business Case
C4: INPUTS & ASSUMPTIONS
D6: Initiative # | F6: TBD
D7: Initiative Owner | F7: Servicing IO — TBC (pool: Jackie Yu, Matt Anderson, Bob Hurst)
D8: Initiative Name | F8: Enhanced chat and self-serve containment on messaging and email demand
D11: Estimated L4 date | F11: ='SVC-2 Model'!$D$13 -> 46631
D12: Net Recurring Benefit ($M) | F12: =$K$117 -> 12.43123
C14: SECTION I - PRIMARY VALUE DRIVER (ILLUSTRATIVE)
D16: Primary value driver — linked to the Model sheet; refine with the initiative owner
D17: Baseline | H17: Period | I17: KPI | J17: Inputs
E18: Opening cost baseline (post contact-avoidance) | H18: Post-upstream levers (S2 waterfall) | I18: $USD M | J18: ='SVC-2 Model'!$D$25/1000000 -> 143.18592
E19: In-scope base (messaging + email) | H19: same | I19: $USD M | J19: =('SVC-2 Model'!$D$40)/1000000 -> 38.998872
D23: Goal
E24: Blended containment uplift on in-scope base | H24: Steady state | I24: % | J24: ='SVC-2 Model'!$D$44/'SVC-2 Model'!$D$40 -> 0.37876044
E25: FTE impacted (A0 basis) | H25: Steady state | I25: # FTE | J25: ='SVC-2 Model'!$D$31 -> 867.7176
D28: Incremental Improvement
E29: Annual benefit (run rate) | I29: $USD M | J29: ='SVC-2 Model'!$D$44/1000000 -> 14.77123
C60: SECTION II - NET RECURRING BENEFITS | CC60: ANNUAL SUMMARY | CI60: CHECK CELLS
T62: 2026 | AF62: 2027 | AR62: 2028 | BD62: 2029 | BP62: 2030 | CI62: CHECK
D63: RECURRING BENEFITS | H63: Comment | I63: Baseline | J63: Goal | K63: Ann. Run Rate | L63: 2026 | M63: =L63+1 -> 2027 | N63: =M63+1 -> 2028 | O63: =N63+1 -> 2029 | P63: =O63+1 -> 2030 | Q63: Impacted BU | R63: Check | T63: 46023 | U63: =EOMONTH(T63, 1) -> 46081 | V63: =EOMONTH(U63, 1) -> 46112 | W63: =EOMONTH(V63, 1) -> 46142 | X63: =EOMONTH(W63, 1) -> 46173 | Y63: =EOMONTH(X63, 1) -> 46203 | Z63: =EOMONTH(Y63, 1) -> 46234 | AA63: =EOMONTH(Z63, 1) -> 46265 | AB63: =EOMONTH(AA63, 1) -> 46295 | ... CA63: =EOMONTH(BZ63, 1) -> 47848 | CC63: 2026 | CD63: =CC63+1 -> 2027 | CE63: =CD63+1 -> 2028 | CF63: =CE63+1 -> 2029 | CG63: =CF63+1 -> 2030 | CI63: 2026 | CJ63: =CI63+1 -> 2027 | CK63: =CJ63+1 -> 2028 | CL63: =CK63+1 -> 2029 | CM63: =CL63+1 -> 2030
E64: $USD M | I64: =$H$18 -> Post-upstream levers (S2 waterfall) | J64: Future State | K64: Increment
E65: Revenue
I66: 0 | J66: 0 | K66: =J66-I66 -> 0 | R66: =IF(K66=P66, "", "Error") | CC66: =SUMIFS($T66:$CA66, $T$1:$CA$1, CC$63) -> 0 | CD66: =SUMIFS($T66:$CA66, $T$1:$CA$1, CD$63) -> 0 | CE66: =SUMIFS($T66:$CA66, $T$1:$CA$1, CE$63) -> 0 | CF66: =SUMIFS($T66:$CA66, $T$1:$CA$1, CF$63) -> 0 | CG66: =SUMIFS($T66:$CA66, $T$1:$CA$1, CG$63) -> 0 | CI66: =CC66=L66 -> 1 | CJ66: =CD66=M66 -> 1 | CK66: =CE66=N66 -> 1 | CL66: =CF66=O66 -> 1 | CM66: =CG66=P66 -> 1
I67: 0 | J67: 0 | K67: =J67-I67 -> 0 | R67: =IF(K67=P67, "", "Error") | CC67: =SUMIFS($T67:$CA67, $T$1:$CA$1, CC$63) -> 0 | CD67: =SUMIFS($T67:$CA67, $T$1:$CA$1, CD$63) -> 0 | CE67: =SUMIFS($T67:$CA67, $T$1:$CA$1, CE$63) -> 0 | CF67: =SUMIFS($T67:$CA67, $T$1:$CA$1, CF$63) -> 0 | CG67: =SUMIFS($T67:$CA67, $T$1:$CA$1, CG$63) -> 0 | CI67: =CC67=L67 -> 1 | CJ67: =CD67=M67 -> 1 | CK67: =CE67=N67 -> 1 | CL67: =CF67=O67 -> 1 | CM67: =CG67=P67 -> 1
E68: Revenue Subtotal | I68: =SUM(I66:I67) -> 0 | J68: =SUM(J66:J67) -> 0 | K68: =SUM(K66:K67) -> 0 | L68: =SUM(L66:L67) -> 0 | M68: =SUM(M66:M67) -> 0 | N68: =SUM(N66:N67) -> 0 | O68: =SUM(O66:O67) -> 0 | P68: =SUM(P66:P67) -> 0 | T68: =SUM(T66:T67) -> 0 | U68: =SUM(U66:U67) -> 0 | V68: =SUM(V66:V67) -> 0 | W68: =SUM(W66:W67) -> 0 | X68: =SUM(X66:X67) -> 0 | Y68: =SUM(Y66:Y67) -> 0 | Z68: =SUM(Z66:Z67) -> 0 | AA68: =SUM(AA66:AA67) -> 0 | ... CA68: =SUM(CA66:CA67) -> 0 | CC68: =SUM(CC66:CC67) -> 0 | CD68: =SUM(CD66:CD67) -> 0 | CE68: =SUM(CE66:CE67) -> 0 | CF68: =SUM(CF66:CF67) -> 0 | CG68: =SUM(CG66:CG67) -> 0 | CI68: =CC68=L68 -> 1 | CJ68: =CD68=M68 -> 1 | CK68: =CE68=N68 -> 1 | CL68: =CF68=O68 -> 1 | CM68: =CG68=P68 -> 1
E70: Cost of Sales
K71: =I71-J71 -> 0 | R71: =IF(K71=P71, "", "Error") | CC71: =SUMIFS($T71:$CA71, $T$1:$CA$1, CC$63) -> 0 | CD71: =SUMIFS($T71:$CA71, $T$1:$CA$1, CD$63) -> 0 | CE71: =SUMIFS($T71:$CA71, $T$1:$CA$1, CE$63) -> 0 | CF71: =SUMIFS($T71:$CA71, $T$1:$CA$1, CF$63) -> 0 | CG71: =SUMIFS($T71:$CA71, $T$1:$CA$1, CG$63) -> 0 | CI71: =CC71=L71 -> 1 | CJ71: =CD71=M71 -> 1 | CK71: =CE71=N71 -> 1 | CL71: =CF71=O71 -> 1 | CM71: =CG71=P71 -> 1
I72: 0 | J72: 0 | K72: =I72-J72 -> 0 | R72: =IF(K72=P72, "", "Error") | CC72: =SUMIFS($T72:$CA72, $T$1:$CA$1, CC$63) -> 0 | CD72: =SUMIFS($T72:$CA72, $T$1:$CA$1, CD$63) -> 0 | CE72: =SUMIFS($T72:$CA72, $T$1:$CA$1, CE$63) -> 0 | CF72: =SUMIFS($T72:$CA72, $T$1:$CA$1, CF$63) -> 0 | CG72: =SUMIFS($T72:$CA72, $T$1:$CA$1, CG$63) -> 0 | CI72: =CC72=L72 -> 1 | CJ72: =CD72=M72 -> 1 | CK72: =CE72=N72 -> 1 | CL72: =CF72=O72 -> 1 | CM72: =CG72=P72 -> 1
I73: 0 | J73: 0 | K73: =I73-J73 -> 0 | R73: =IF(K73=P73, "", "Error") | CC73: =SUMIFS($T73:$CA73, $T$1:$CA$1, CC$63) -> 0 | CD73: =SUMIFS($T73:$CA73, $T$1:$CA$1, CD$63) -> 0 | CE73: =SUMIFS($T73:$CA73, $T$1:$CA$1, CE$63) -> 0 | CF73: =SUMIFS($T73:$CA73, $T$1:$CA$1, CF$63) -> 0 | CG73: =SUMIFS($T73:$CA73, $T$1:$CA$1, CG$63) -> 0 | CI73: =CC73=L73 -> 1 | CJ73: =CD73=M73 -> 1 | CK73: =CE73=N73 -> 1 | CL73: =CF73=O73 -> 1 | CM73: =CG73=P73 -> 1
I74: 0 | J74: 0 | K74: =I74-J74 -> 0 | R74: =IF(K74=P74, "", "Error") | CC74: =SUMIFS($T74:$CA74, $T$1:$CA$1, CC$63) -> 0 | CD74: =SUMIFS($T74:$CA74, $T$1:$CA$1, CD$63) -> 0 | CE74: =SUMIFS($T74:$CA74, $T$1:$CA$1, CE$63) -> 0 | CF74: =SUMIFS($T74:$CA74, $T$1:$CA$1, CF$63) -> 0 | CG74: =SUMIFS($T74:$CA74, $T$1:$CA$1, CG$63) -> 0 | CI74: =CC74=L74 -> 1 | CJ74: =CD74=M74 -> 1 | CK74: =CE74=N74 -> 1 | CL74: =CF74=O74 -> 1 | CM74: =CG74=P74 -> 1
K75: =I75-J75 -> 0 | R75: =IF(K75=P75, "", "Error") | CC75: =SUMIFS($T75:$CA75, $T$1:$CA$1, CC$63) -> 0 | CD75: =SUMIFS($T75:$CA75, $T$1:$CA$1, CD$63) -> 0 | CE75: =SUMIFS($T75:$CA75, $T$1:$CA$1, CE$63) -> 0 | CF75: =SUMIFS($T75:$CA75, $T$1:$CA$1, CF$63) -> 0 | CG75: =SUMIFS($T75:$CA75, $T$1:$CA$1, CG$63) -> 0 | CI75: =CC75=L75 -> 1 | CJ75: =CD75=M75 -> 1 | CK75: =CE75=N75 -> 1 | CL75: =CF75=O75 -> 1 | CM75: =CG75=P75 -> 1
E76: Cost of Sales Subtotal | I76: =SUM(I71:I75) -> 0 | J76: =SUM(J71:J75) -> 0 | K76: =SUM(K71:K75) -> 0 | L76: =SUM(L71:L75) -> 0 | M76: =SUM(M71:M75) -> 0 | N76: =SUM(N71:N75) -> 0 | O76: =SUM(O71:O75) -> 0 | P76: =SUM(P71:P75) -> 0 | T76: =SUM(T71:T75) -> 0 | U76: =SUM(U71:U75) -> 0 | V76: =SUM(V71:V75) -> 0 | W76: =SUM(W71:W75) -> 0 | X76: =SUM(X71:X75) -> 0 | Y76: =SUM(Y71:Y75) -> 0 | Z76: =SUM(Z71:Z75) -> 0 | AA76: =SUM(AA71:AA75) -> 0 | ... CA76: =SUM(CA71:CA75) -> 0 | CC76: =SUM(CC71:CC75) -> 0 | CD76: =SUM(CD71:CD75) -> 0 | CE76: =SUM(CE71:CE75) -> 0 | CF76: =SUM(CF71:CF75) -> 0 | CG76: =SUM(CG71:CG75) -> 0 | CI76: =CC76=L76 -> 1 | CJ76: =CD76=M76 -> 1 | CK76: =CE76=N76 -> 1 | CL76: =CF76=O76 -> 1 | CM76: =CG76=P76 -> 1
E78: OPEX
E79: OPEX - Front-office cost reduction (chat/self-serve containment) | H79: Messaging+email eligible cost x tier containment rates (S2 engine, distilled) | I79: ='SVC-2 Model'!$D$56 -> 143.18592 | J79: =I79-'SVC-2 Model'!$K$56 -> 128.41469 | K79: ='SVC-2 Model'!$K$56 -> 14.77123 | L79: ='SVC-2 Model'!L56 -> 0 | M79: ='SVC-2 Model'!M56 -> 1.4067838 | N79: ='SVC-2 Model'!N56 -> 13.979914 | O79: ='SVC-2 Model'!O56 -> 14.77123 | P79: ='SVC-2 Model'!P56 -> 14.77123 | Q79: Global Servicing | R79: =IF(K79=P79, "", "Error") | T79: ='SVC-2 Model'!T56 -> 0 | U79: ='SVC-2 Model'!U56 -> 0 | V79: ='SVC-2 Model'!V56 -> 0 | W79: ='SVC-2 Model'!W56 -> 0 | X79: ='SVC-2 Model'!X56 -> 0 | Y79: ='SVC-2 Model'!Y56 -> 0 | Z79: ='SVC-2 Model'!Z56 -> 0 | AA79: ='SVC-2 Model'!AA56 -> 0 | ... CA79: ='SVC-2 Model'!CA56 -> 1.2309358 | CC79: =SUMIFS($T79:$CA79, $T$1:$CA$1, CC$63) -> 0 | CD79: =SUMIFS($T79:$CA79, $T$1:$CA$1, CD$63) -> 1.4067838 | CE79: =SUMIFS($T79:$CA79, $T$1:$CA$1, CE$63) -> 13.979914 | CF79: =SUMIFS($T79:$CA79, $T$1:$CA$1, CF$63) -> 14.77123 | CG79: =SUMIFS($T79:$CA79, $T$1:$CA$1, CG$63) -> 14.77123 | CI79: =CC79=L79 -> 1 | CJ79: =CD79=M79 -> 1 | CK79: =CE79=N79 -> 1 | CL79: =CF79=O79 -> 1 | CM79: =CG79=P79 -> 1
I80: 0 | J80: 0 | K80: =I80-J80 -> 0 | R80: =IF(K80=P80, "", "Error") | CC80: =SUMIFS($T80:$CA80, $T$1:$CA$1, CC$63) -> 0 | CD80: =SUMIFS($T80:$CA80, $T$1:$CA$1, CD$63) -> 0 | CE80: =SUMIFS($T80:$CA80, $T$1:$CA$1, CE$63) -> 0 | CF80: =SUMIFS($T80:$CA80, $T$1:$CA$1, CF$63) -> 0 | CG80: =SUMIFS($T80:$CA80, $T$1:$CA$1, CG$63) -> 0 | CI80: =CC80=L80 -> 1 | CJ80: =CD80=M80 -> 1 | CK80: =CE80=N80 -> 1 | CL80: =CF80=O80 -> 1 | CM80: =CG80=P80 -> 1
I81: 0 | J81: 0 | K81: =I81-J81 -> 0 | R81: =IF(K81=P81, "", "Error") | CC81: =SUMIFS($T81:$CA81, $T$1:$CA$1, CC$63) -> 0 | CD81: =SUMIFS($T81:$CA81, $T$1:$CA$1, CD$63) -> 0 | CE81: =SUMIFS($T81:$CA81, $T$1:$CA$1, CE$63) -> 0 | CF81: =SUMIFS($T81:$CA81, $T$1:$CA$1, CF$63) -> 0 | CG81: =SUMIFS($T81:$CA81, $T$1:$CA$1, CG$63) -> 0 | CI81: =CC81=L81 -> 1 | CJ81: =CD81=M81 -> 1 | CK81: =CE81=N81 -> 1 | CL81: =CF81=O81 -> 1 | CM81: =CG81=P81 -> 1
I82: 0 | J82: 0 | K82: =I82-J82 -> 0 | R82: =IF(K82=P82, "", "Error") | CC82: =SUMIFS($T82:$CA82, $T$1:$CA$1, CC$63) -> 0 | CD82: =SUMIFS($T82:$CA82, $T$1:$CA$1, CD$63) -> 0 | CE82: =SUMIFS($T82:$CA82, $T$1:$CA$1, CE$63) -> 0 | CF82: =SUMIFS($T82:$CA82, $T$1:$CA$1, CF$63) -> 0 | CG82: =SUMIFS($T82:$CA82, $T$1:$CA$1, CG$63) -> 0 | CI82: =CC82=L82 -> 1 | CJ82: =CD82=M82 -> 1 | CK82: =CE82=N82 -> 1 | CL82: =CF82=O82 -> 1 | CM82: =CG82=P82 -> 1
I83: 0 | J83: 0 | K83: =I83-J83 -> 0 | R83: =IF(K83=P83, "", "Error") | CC83: =SUMIFS($T83:$CA83, $T$1:$CA$1, CC$63) -> 0 | CD83: =SUMIFS($T83:$CA83, $T$1:$CA$1, CD$63) -> 0 | CE83: =SUMIFS($T83:$CA83, $T$1:$CA$1, CE$63) -> 0 | CF83: =SUMIFS($T83:$CA83, $T$1:$CA$1, CF$63) -> 0 | CG83: =SUMIFS($T83:$CA83, $T$1:$CA$1, CG$63) -> 0 | CI83: =CC83=L83 -> 1 | CJ83: =CD83=M83 -> 1 | CK83: =CE83=N83 -> 1 | CL83: =CF83=O83 -> 1 | CM83: =CG83=P83 -> 1
E84: OpEx subtotal | I84: =SUM(I79:I83) -> 143.18592 | J84: =SUM(J79:J83) -> 128.41469 | K84: =SUM(K79:K83) -> 14.77123 | L84: =SUM(L79:L83) -> 0 | M84: =SUM(M79:M83) -> 1.4067838 | N84: =SUM(N79:N83) -> 13.979914 | O84: =SUM(O79:O83) -> 14.77123 | P84: =SUM(P79:P83) -> 14.77123 | T84: =SUM(T79:T83) -> 0 | U84: =SUM(U79:U83) -> 0 | V84: =SUM(V79:V83) -> 0 | W84: =SUM(W79:W83) -> 0 | X84: =SUM(X79:X83) -> 0 | Y84: =SUM(Y79:Y83) -> 0 | Z84: =SUM(Z79:Z83) -> 0 | AA84: =SUM(AA79:AA83) -> 0 | ... CA84: =SUM(CA79:CA83) -> 1.2309358 | CC84: =SUM(CC79:CC83) -> 0 | CD84: =SUM(CD79:CD83) -> 1.4067838 | CE84: =SUM(CE79:CE83) -> 13.979914 | CF84: =SUM(CF79:CF83) -> 14.77123 | CG84: =SUM(CG79:CG83) -> 14.77123 | CI84: =CC84=L84 -> 1 | CJ84: =CD84=M84 -> 1 | CK84: =CE84=N84 -> 1 | CL84: =CF84=O84 -> 1 | CM84: =CG84=P84 -> 1
...

Sheet SVC-3 Model
B2: SVC-3 — Agentic Voice & AI Co-pilot | INITIATIVE MODEL
B3: Workstream: Servicing (ELT sponsor: Aaron | WSL: Tahira | IOs: Jackie Yu, Matt Anderson, Bob Hurst) • Model status: Seeded 1:1 from S2 vDraft5 (Base) — benefit ties to $35.25M (3a $26.95M + 3b $8.30M)
T5: 2026 | U5: 2026 | V5: 2026 | W5: 2026 | X5: 2026 | Y5: 2026 | Z5: 2026 | AA5: 2026 | AB5: 2026 | AC5: 2026 | AD5: 2026 | AE5: 2026 | AF5: 2027 | AG5: 2027 | AH5: 2027 | AI5: 2027 | AJ5: 2027 | AK5: 2027 | AL5: 2027 | AM5: 2027 | AN5: 2027 | AO5: 2027 | AP5: 2027 | AQ5: 2027 | AR5: 2028 | AS5: 2028 | AT5: 2028 | AU5: 2028 | AV5: 2028 | AW5: 2028 | AX5: 2028 | AY5: 2028 | AZ5: 2028 | BA5: 2028 | BB5: 2028 | BC5: 2028 | BD5: 2029 | BE5: 2029 | BF5: 2029 | BG5: 2029 | BH5: 2029 | BI5: 2029 | BJ5: 2029 | BK5: 2029 | BL5: 2029 | BM5: 2029 | BN5: 2029 | BO5: 2029 | BP5: 2030 | BQ5: 2030 | BR5: 2030 | BS5: 2030 | BT5: 2030 | BU5: 2030 | BV5: 2030 | BW5: 2030 | BX5: 2030 | BY5: 2030 | BZ5: 2030 | CA5: 2030
B6: Monthly grid (Jan-26 → Dec-30) → | K6: Run rate | L6: 2026 | M6: 2027 | N6: 2028 | O6: 2029 | P6: 2030 | T6: =DATE(2026,1,31) -> 46053 | U6: =EOMONTH(T6,1) -> 46081 | V6: =EOMONTH(U6,1) -> 46112 | W6: =EOMONTH(V6,1) -> 46142 | X6: =EOMONTH(W6,1) -> 46173 | Y6: =EOMONTH(X6,1) -> 46203 | Z6: =EOMONTH(Y6,1) -> 46234 | AA6: =EOMONTH(Z6,1) -> 46265 | AB6: =EOMONTH(AA6,1) -> 46295 | ... CA6: =EOMONTH(BZ6,1) -> 47848
B8: 0. INITIATIVE & STATUS
B10: Initiative name | D10: Agentic AI voice — end-to-end contact resolution plus AI co-pilot agent assist
B11: Initiative owner | D11: Servicing IO — TBC (pool: Jackie Yu, Matt Anderson, Bob Hurst) | I11: confirm with workstream lead
B12: Impacted BU | D12: Global Servicing
B13: Go-live / Estimated L4 date | D13: =DATE(2027,9,1) -> 46631 | I13: Benefit ramp is gated on this date.
B15: Source: Servicing S2 sizing model vDraft5 (28 Aug 2026), Base scenario. Distilled to tier level; per-tier eligible bases and effective rates reproduce the S2 L2-intent engine output exactly (verified).
B16: Source: Workplan: 'Project Zenith Automation workplan and data requests vS_1.xlsx', Servicing tabs
B17: Open items to refine with initiative owner:
B18: – S2 splits this initiative into 3a (contact resolution/abatement, voice only) and 3b (co-pilot handle-time reduction on residual + text); check #9 in S2 enforces that they sum to the combined voice benefit. Both sub-levers modeled below; WAVE carries them as two benefit lines.
B19: – 3b QC from S2: after-call-work share is zero on every intent (M10 split carries no ACW minutes) — co-pilot voice rates are built from talk+hold only; 6 intents have talk shares >1 (data fault); 5 intents ride flat fallback rates incl. the largest single voice benefit ($0.7M).
B20: – Sensitivity (S2): voice resolution rates ±30% swing total benefit $13.5M — largest driver in the model.
B22: 1. SIZING ASSUMPTIONS (blue = inputs — refine with initiative owner)
B24: Opening baselines (S2 waterfall: 3a opens on SVC-2 closing; 3b on 3a closing)
B25: Opening cost — 3a (all channels) | D25: 1.2841469e+08 | E25: $/yr | F25: Servicing S2 sizing model vDraft5 (28 Aug 2026), Base scenario. Opening cost follows the S2 stacking waterfall (each lever opens on the prior lever's closing baseline; order: 1 Avoidance → 2 Chat → 3a Voice → 3b Co-pilot → 4a SBR → 4b Utilisation). Tier-level bases below are snapshots of the S2 L2 engine — refresh them from the S2 model if upstream levers or tiering change.
B26: Opening cost — 3b (post-3a residual) | D26: 1.0146563e+08 | E26: $/yr | F26: Equals 3a closing; refresh if 3a changes
B27: Investment uplifts (S2 standard)
B28: Programme management, % of build | D28: 0.08 | E28: %
B29: Contingency, % of build incl. PM | D29: 0.1 | E29: %
B30: Run team headcount (3a + 3b consolidated) | D30: 5.5 | E30: # FTE | F30: S2 C3: 3.0 (3a) + 2.5 (3b)
B31: Run team loaded rate | D31: 180000 | E31: $/FTE/yr
B32: FTE impacted — 3a (A0 basis, feeds SVC-6) | D32: 1017.2846 | E32: # FTE | F32: S2 A3a V102
B33: FTE impacted — 3b (A0 basis, feeds SVC-6) | D33: 528.2645 | E33: # FTE | F33: S2 A3b V102
B34: (spare assumption row)
B35: (spare assumption row)
B37: S2 lever 3a — Agentic voice: voice-channel eligible cost by tier (voice-tier column)
B38: Tier | D38: Eligible cost base ($/yr) | F38: Effective rate | H38: Benefit ($/yr) | M38: Voice channel only (messaging/email pass through). Effective rates implied from the S2 engine — bundle target rate, 80% ceiling, funnel hardening.
B39: Easy (27 L2 intents) | D39: 22606259 | F39: 0.35948695 | H39: =D39*F39 -> 8126655.2 | M39: S2 target 40% of escalated voice demand; 80% ceiling + hardening -> effective 35.9%
B40: Medium (37 L2 intents) | D40: 51560922 | F40: 0.28011012 | H40: =D40*F40 -> 14442736 | M40: S2 target 30%; effective 28.0%
B41: Hard (13 L2 intents) | D41: 30019867 | F41: 0.14589229 | H41: =D41*F41 -> 4379667.2 | M41: S2 target 15%; effective 14.6%
B42: Subtotal — S2 lever 3a — Agentic voice: voice-channel eligible cost by tier | D42: =SUM(D39:D41) -> 1.0418705e+08 | H42: =SUM(H39:H41) -> 26949059
B44: S2 lever 3b — AI co-pilot: voice residual (post-3a) cost by tier
B45: Tier | D45: Eligible cost base ($/yr) | F45: Effective rate | H45: Benefit ($/yr) | M45: Handle-time reduction on contacts that still reach an agent (voice).
