Workbook

Sheet Cover
B2: PROJECT ZENITH — SALES WORKSTREAM | INITIATIVE MODELS & WAVE TEMPLATES
B4: Workstream | C4: Sales — 2 priority initiatives: (1) Underwriting & Pricing for front book, (2) SMB Long Tail — Partner. ELT sponsor: Susan | WSL: Selwyn. LE and MM initiatives follow the Track 2 timeline.
B5: Purpose | C5: One file per workstream: each initiative has a Model sheet (all logic and inputs) formula-linked into its own copy of the standard WAVE business-case template. S2 submission: Sep 4; S3: Sep 18.
B6: Version / status | C6: v1 — structure complete; impact-driver rates seeded from Aug 13 / Board decks (midpoints), revenue/seller baselines to be populated from received + pending datasets (models compute $0 until baselines are entered).
B7: Prepared | C7: Prepared by AAO model build, 31 Aug 2026. Sources: Project Zenith workplan vS_1; Zenith Business Case Template by Lever (WAVE); Aug 13 deck pp. 6, 14–15; Board deck pp. 9, 20, 52.
B8: Sources | C8: Workplan Sales tab (initiative-specific data POV); Sales Data Requests tab (4 of 6 received); WAVE standard template (reference copy at the end of this file).
B10: HOW THIS FILE IS ORGANIZED
B12: Cover | C12: This sheet — orientation, legend, deviations, open items.
B13: Instructions | C13: The WAVE template's own instruction sheet (as uploaded; dead broken-reference drop-down cells cleared).
B14: Rate Card | C14: Shared people-cost engine: rate basis, role table + blended rate, contingency reference, capitalization policy.
B15: Summary | C15: Portfolio roll-up of both initiatives (links to WAVE sheets).
B16: SALES-1 Model / SALES-1 WAVE | C16: Underwriting & Pricing front book — model + linked WAVE template.
B17: SALES-2 Model / SALES-2 WAVE | C17: SMB Long Tail — Partner — model + linked WAVE template.
B18: Standard Template | C18: Reference copy of the standard WAVE template (only error-guard fixes applied — see deviations).
B20: COLOR LEGEND
B22: Input — change freely
B23: Formula — do not overwrite
B24: Link to another sheet
B25: Section band
B27: MODEL -> WAVE LINKING
B29: • Each initiative has a '<code> Model' sheet (all logic and inputs) and a '<code> WAVE' sheet (the standard template). The WAVE sheet contains NO hardcoded numbers for this initiative — its benefit/cost rows link (green) to the Model sheet's feed rows in $M.
B30: • Model sheets use the same time grid as WAVE: columns L:P = FY2026–2030 annual, columns T:CA = Jan-2026..Dec-2030 monthly. Annual cells are SUMIFS of the monthly grid, so the WAVE monthly-vs-annual checks (CI1:CM1) pass by construction.
B31: • The 'Ann. Run Rate' (K) on feed rows is defined as the 2030 value, matching the WAVE rule 'Annualized Run Rate (K) = 2030 Value (P)'. Keep ramps reaching 100% before 2030.
B32: • Benefits ramp linearly from the go-live date over 'months to full run rate' — same convention as the Servicing S2 model. One-time costs spread evenly over each milestone's billing months.
B33: • People costs: milestone labor = Team size x Billing months x blended monthly rate (Rate Card) x (1 + contingency). Capitalization: each milestone carries a Cap % (default from Rate Card policy) that splits labor into WAVE CapEx vs OTC rows. Same for non-labor one-time items.
B35: DEVIATIONS FROM THE STANDARD WAVE TEMPLATE (documented fixes)
... B52: • Rate Card role rates are placeholders; capitalization defaults need Finance sign-off.

Sheet Instructions
L1: 1 | M1: 2 | N1: 3 | O1: 4 | P1: 5 | R1: =COUNTIFS($R$78:$R$128, "Error") -> 0 | T1: 2026 | U1: 2026 | V1: 2026 | W1: 2026 | X1: 2026 | Y1: 2026 | Z1: 2026 | AA1: 2026 | AB1: 2026 | AC1: 2026 | AD1: 2026 | AE1: 2026 | AF1: 2027 | AG1: 2027 | AH1: 2027 | AI1: 2027 | AJ1: 2027 | AK1: 2027 | AL1: 2027 | AM1: 2027 | AN1: 2027 | AO1: 2027 | AP1: 2027 | AQ1: 2027 | AR1: 2028 | AS1: 2028 | AT1: 2028 | AU1: 2028 | AV1: 2028 | AW1: 2028 | AX1: 2028 | AY1: 2028 | AZ1: 2028 | BA1: 2028 | BB1: 2028 | BC1: 2028 | BD1: 2029 | BE1: 2029 | BF1: 2029 | BG1: 2029 | BH1: 2029 | BI1: 2029 | BJ1: 2029 | BK1: 2029 | BL1: 2029 | BM1: 2029 | BN1: 2029 | BO1: 2029 | BP1: 2030 | BQ1: 2030 | BR1: 2030 | BS1: 2030 | BT1: 2030 | BU1: 2030 | BV1: 2030 | BW1: 2030 | BX1: 2030 | BY1: 2030 | BZ1: 2030 | CA1: 2030 | CI1: =COUNTIFS(CI$78:CI$159, "FALSE") -> 0 | CJ1: =COUNTIFS(CJ$78:CJ$159, "FALSE") -> 4 | CK1: =COUNTIFS(CK$78:CK$159, "FALSE") -> 4 | CL1: =COUNTIFS(CL$78:CL$159, "FALSE") -> 0 | CM1: =COUNTIFS(CM$78:CM$159, "FALSE") -> 0
C9: ="#"&$F$13&" Initiative Business Case" -> #123456 Initiative Business Case
C11: INPUTS & ASSUMPTIONS
D13: Initiative # | F13: 123456
D14: Initiative Owner | F14: John Smith
D15: Initiative Name | F15: Leverage agentic AI for customer service and care centers, reducing number of calls handled by live customer care agents and increasing productivity | I15: Names - 5-7 words
I16: Descriptions - 10-20 words
D18: Estimated L4 date | F18: 46736
D19: Net Recurring Benefit ($M) | F19: =$K$128 -> 7.2
C21: SECTION I - PRIMARY VALUE DRIVER (ILLUSTRATIVE) | L21: CHECKS
D23: Illustrative example of value driver explanation - please edit fields to reflect value drivers for your Initiative | L23: Criteria (Column Reference) | P23: Check | Q23: Troubleshoot:
D24: Baseline | H24: Period | I24: KPI | J24: Inputs | L24: (A) Annualized Run Rate (K) = 2030 Value (P) | P24: =IF($R$1=0, "PASS", "ERROR") -> PASS | Q24: =IF(P24="Error", "Check column R for errors", "")
E25: # of calls handled by live agents | G25: [A] | H25: FY2025 | I25: # of calls | J25: 6000 | L25: (B) 2026 Value (L) = Sum of Monthly 2026 Values (CC) | P25: =IF($CI$1=0, "PASS", "ERROR") -> PASS | Q25: =IF(P25="Error", "Check column CI for errors", "")
E26: AHT | G26: [B] | H26: FY 2026 | I26: Seconds | J26: 150 | L26: (C) 2027 Value (M) = Sum of Monthly 2027 Values (CD) | P26: =IF($CJ$1=0, "PASS", "ERROR") -> ERROR | Q26: =IF(P26="Error", "Check column CJ for errors", "") -> Check column CJ for errors
E27: # of live agents handling calls | G27: [C] | H27: FY 2025 | I27: # of live agents | J27: 500 | L27: (D) 2028 Value (N) = Sum of Monthly 2028 Values (CE) | P27: =IF($CK$1=0, "PASS", "ERROR") -> ERROR | Q27: =IF(P27="Error", "Check column CK for errors", "") -> Check column CK for errors
E28: Average cost per agent | H28: FY 2026 | I28: $ / agent | J28: 50000 | L28: (E) 2029 Value (O) = Sum of Monthly 2029 Values (CF) | P28: =IF($CL$1=0, "PASS", "ERROR") -> PASS | Q28: =IF(P28="Error", "Check column CL for errors", "")
E29: Total spend on contact center for queue X | G29: [D] | H29: FY2025 | I29: $USD M | J29: =(J27*J28)/1000000 -> 25 | L29: (F) 2030 Value (P) = Sum of Monthly 2030 Values (CG) | P29: =IF($CM$1=0, "PASS", "ERROR") -> PASS | Q29: =IF(P29="Error", "Check column CM for errors", "")
D31: Goal | Y31: D
E32: # of calls handled by live agents | G32: [E] | I32: # of calls | J32: 4000
E33: AHT | G33: [F] | I33: Seconds | J33: 120
E34: # of live agents handling calls | G34: [G] | I34: # of live agents | J34: 260
E35: Average cost per agent | I35: $ / agent | J35: =J28 -> 50000
E36: Total spend on contact center for queue X | G36: [H] | H36: FY2026 | I36: $USD M | J36: =(J34*J35)/1000000 -> 13
D38: Incremental Improvement
E39: # of calls handled by live agents | G39: [A]-[E] | I39: # of calls | J39: =J25-J32 -> 2000
E40: AHT | G40: [B]-[F] | I40: Seconds | J40: =J26-J33 -> 30
E41: # of live agents handling calls | G41: [C]-[G] | I41: # of live agents | J41: =J27-J34 -> 240
E42: Total spend on contact center queue X | G42: [D]-[H] | I42: USD M | J42: =J29-J36 -> 12
D43: Baseline | H43: Period | I43: $USD M | J43: Inputs
E44: # xxxx | H44: FY2025 | I44: # xxxx | J44: 12000000
E45: xxxx unit cost | G45: [A] | H45: FY2025 | I45: $ xxxx | J45: 0.14
E46: xxxx total spend | G46: [B] | H46: FY2025 | I46: $USD K | J46: =(J44*J45)/1000 -> 1680
D48: Goal
E49: # xxxx | H49: FY2025 | I49: # xxxx | J49: =$J$25 -> 6000
E50: xxxx unit cost | G50: [C] | H50: FY2026 | I50: $ xxxx | J50: 0.1
E51: xxxx total spend | G51: [D] | H51: FY2026 | I51: $USD K | J51: =(J49*J50)/1000 -> 0.6
D53: Incremental Improvement
E54: =E50 -> xxxx unit cost | G54: [A]-[C] | I54: $ / xxxx | J54: =J45-J50 -> 0.04
E55: =E51 -> xxxx total spend | G55: [B]-[D] | I55: $USD K | J55: =J46-J51 -> 1679.4
D58: Baseline | H58: Period | I58: KPI | J58: Inputs
...

Sheet Rate Card
B2: RATE CARD — people-cost engine (shared by all initiative models)
B4: Blue cells with yellow fill = inputs you can change. Black = formulas. All initiative models pull the blended rate and policy tables from this sheet.
B6: 1. RATE BASIS
B8: Rate basis for people costs | D8: Yearly | F8: Choose how role rates are quoted, then TYPE YOUR RATES in the matching column of the role table below (Yearly->col D, Monthly->col E, Hourly->col F). The other columns show derived equivalents until you overwrite them. Hourly => monthly = $/hr x hours/day x days/month.
B10: Working hours per day | D10: 8 | F10: Used only when rate basis = Hourly.
B11: Billable days per month | D11: 21
B12: Months per year (for yearly basis) | D12: 12
B14: 2. STANDARD TEAM COMPOSITION & BLENDED RATE
B16: Role | C16: # in std team | D16: Yearly rate ($/yr) | E16: Monthly rate ($/mo) | F16: Hourly rate ($/hr) | G16: Monthly used ($/mo) | H16: Team cost ($/mo) | I16: Source / notes
B17: Engineer | C17: 3 | D17: 180000 | E17: =IF(D17="",0,D17/$D$12) -> 15000 | F17: =IF(D17="",0,E17/($D$10*$D$11)) -> 89.285714 | G17: =IF($D$8="Hourly",F17*$D$10*$D$11,IF($D$8="Monthly",E17,IF(D17="",0,D17/$D$12))) -> 15000 | H17: =IF(C17="",0,C17*G17) -> 45000
B18: QA Engineer | C18: 2 | D18: 140000 | E18: =IF(D18="",0,D18/$D$12) -> 11666.667 | F18: =IF(D18="",0,E18/($D$10*$D$11)) -> 69.444444 | G18: =IF($D$8="Hourly",F18*$D$10*$D$11,IF($D$8="Monthly",E18,IF(D18="",0,D18/$D$12))) -> 11666.667 | H18: =IF(C18="",0,C18*G18) -> 23333.333
B19: Solution Architect | C19: 1 | D19: 220000 | E19: =IF(D19="",0,D19/$D$12) -> 18333.333 | F19: =IF(D19="",0,E19/($D$10*$D$11)) -> 109.12698 | G19: =IF($D$8="Hourly",F19*$D$10*$D$11,IF($D$8="Monthly",E19,IF(D19="",0,D19/$D$12))) -> 18333.333 | H19: =IF(C19="",0,C19*G19) -> 18333.333
B20: Product Manager | C20: 1 | D20: 190000 | E20: =IF(D20="",0,D20/$D$12) -> 15833.333 | F20: =IF(D20="",0,E20/($D$10*$D$11)) -> 94.246032 | G20: =IF($D$8="Hourly",F20*$D$10*$D$11,IF($D$8="Monthly",E20,IF(D20="",0,D20/$D$12))) -> 15833.333 | H20: =IF(C20="",0,C20*G20) -> 15833.333
B21: Data Engineer | C21: 1 | D21: 185000 | E21: =IF(D21="",0,D21/$D$12) -> 15416.667 | F21: =IF(D21="",0,E21/($D$10*$D$11)) -> 91.765873 | G21: =IF($D$8="Hourly",F21*$D$10*$D$11,IF($D$8="Monthly",E21,IF(D21="",0,D21/$D$12))) -> 15416.667 | H21: =IF(C21="",0,C21*G21) -> 15416.667
B22: ML Engineer | C22: 1 | D22: 210000 | E22: =IF(D22="",0,D22/$D$12) -> 17500 | F22: =IF(D22="",0,E22/($D$10*$D$11)) -> 104.16667 | G22: =IF($D$8="Hourly",F22*$D$10*$D$11,IF($D$8="Monthly",E22,IF(D22="",0,D22/$D$12))) -> 17500 | H22: =IF(C22="",0,C22*G22) -> 17500
B23: Program Manager | C23: 1 | D23: 170000 | E23: =IF(D23="",0,D23/$D$12) -> 14166.667 | F23: =IF(D23="",0,E23/($D$10*$D$11)) -> 84.325397 | G23: =IF($D$8="Hourly",F23*$D$10*$D$11,IF($D$8="Monthly",E23,IF(D23="",0,D23/$D$12))) -> 14166.667 | H23: =IF(C23="",0,C23*G23) -> 14166.667
E24: =IF(D24="",0,D24/$D$12) -> 0 | F24: =IF(D24="",0,E24/($D$10*$D$11)) -> 0 | G24: =IF($D$8="Hourly",F24*$D$10*$D$11,IF($D$8="Monthly",E24,IF(D24="",0,D24/$D$12))) -> 0 | H24: =IF(C24="",0,C24*G24) -> 0 | I24: spare row — add roles as team shape is refined
E25: =IF(D25="",0,D25/$D$12) -> 0 | F25: =IF(D25="",0,E25/($D$10*$D$11)) -> 0 | G25: =IF($D$8="Hourly",F25*$D$10*$D$11,IF($D$8="Monthly",E25,IF(D25="",0,D25/$D$12))) -> 0 | H25: =IF(C25="",0,C25*G25) -> 0 | I25: spare row — add roles as team shape is refined
E26: =IF(D26="",0,D26/$D$12) -> 0 | F26: =IF(D26="",0,E26/($D$10*$D$11)) -> 0 | G26: =IF($D$8="Hourly",F26*$D$10*$D$11,IF($D$8="Monthly",E26,IF(D26="",0,D26/$D$12))) -> 0 | H26: =IF(C26="",0,C26*G26) -> 0 | I26: spare row — add roles as team shape is refined
B27: Total standard team | C27: =SUM(C17:C26) -> 10 | H27: =SUM(H17:H26) -> 149583.33
B29: BLENDED RATE — per team member | G29: =IF(C27=0,0,H27/C27) -> 14958.333 | H29: $/person/month | I29: Weighted average monthly cost of one member of the standard team. Initiative milestone tables use this unless a rate override is entered.
G30: =G29*$D$12 -> 179500 | H30: $/person/year
G31: =G29/($D$10*$D$11) -> 89.037698 | H31: $/person/hour
B33: 3. CONTINGENCY FACTOR REFERENCE
B35: Complexity / risk level | C35: Factor | F35: Based on the complexity and risks to deliver the milestone.
B36: Low | C36: 0.1
B37: Medium | C37: 0.15
B38: High | C38: 0.2
B39: Very high | C39: 0.5
B42: 4. CAPITALIZATION POLICY (labor) — default % of milestone labor capitalizable
B44: Milestone | C44: Cap % | F44: Share of labor cost treated as CapEx (feeds WAVE 'Capital Expenditures'); remainder is expensed one-time cost (WAVE 'OTC'). Defaults follow a typical internal-use software policy (ASC 350-40): application development/build stage capitalizable, planning and post-launch expensed. CONFIRM WITH FINANCE — initiative models reference these cells, override there if needed.
B45: Plan / Design | C45: 0
B46: Build / Test | C46: 0.8
B47: Pilot / Change Mgmt. | C47: 0
B48: Scale / Run | C48: 0
B49: Non-labor one-time (default) | C49: 0
B51: 5. NOTES
B52: • Role rates are PLACEHOLDERS — replace with the PayPal/FP&A rate card. Servicing S2 reference: $200,000/yr blended loaded delivery FTE (+10% delivery risk), $180,000/yr run-team FTE.
B53: • Team composition mirrors the standard AAO delivery-pod thinking; adjust for vendor-heavy builds (PRM/orchestration) where internal pod may be smaller.
B54: • Build/Test capitalization default of 80% follows a typical internal-use software policy — CONFIRM WITH FINANCE, especially for vendor/SaaS-heavy builds where treatment differs.

Sheet Summary
B2: SALES WORKSTREAM — PORTFOLIO SUMMARY ($M)
B3: All figures link to the initiative WAVE sheets. Payback/NPV per WAVE Section IV.
B5: Initiative | C5: NRB run rate | D5: NRB 2026 | E5: NRB 2027 | F5: NRB 2028 | G5: NRB 2029 | H5: NRB 2030 | I5: One-time cost (5yr) | J5: Run cost 2030 | K5: NPV (5yr) | L5: Payback (yrs)
B6: SALES-1 — Underwriting & Pricing — Front Book | C6: ='SALES-1 WAVE'!$K$117 -> 0 | D6: ='SALES-1 WAVE'!$L$117 -> 0 | E6: ='SALES-1 WAVE'!$M$117 -> 0 | F6: ='SALES-1 WAVE'!$N$117 -> 0 | G6: ='SALES-1 WAVE'!$O$117 -> 0 | H6: ='SALES-1 WAVE'!$P$117 -> 0 | I6: =SUM('SALES-1 WAVE'!$L$147:$P$147) -> 1.5247089 | J6: ='SALES-1 WAVE'!$P$115 -> 0 | K6: ='SALES-1 WAVE'!$G$168 -> -1.2988552 | L6: ='SALES-1 WAVE'!$G$165 -> >5
B7: SALES-2 — SMB Long Tail — Partner | C7: ='SALES-2 WAVE'!$K$117 -> 0 | D7: ='SALES-2 WAVE'!$L$117 -> 0 | E7: ='SALES-2 WAVE'!$M$117 -> 0 | F7: ='SALES-2 WAVE'!$N$117 -> 0 | G7: ='SALES-2 WAVE'!$O$117 -> 0 | H7: ='SALES-2 WAVE'!$P$117 -> 0 | I7: =SUM('SALES-2 WAVE'!$L$147:$P$147) -> 1.5247089 | J7: ='SALES-2 WAVE'!$P$115 -> 0 | K7: ='SALES-2 WAVE'!$G$168 -> -1.2988552 | L7: ='SALES-2 WAVE'!$G$165 -> >5
B8: TOTAL — SALES WORKSTREAM | C8: =SUM(C6:C7) -> 0 | D8: =SUM(D6:D7) -> 0 | E8: =SUM(E6:E7) -> 0 | F8: =SUM(F6:F7) -> 0 | G8: =SUM(G6:G7) -> 0 | H8: =SUM(H6:H7) -> 0 | I8: =SUM(I6:I7) -> 3.0494178 | J8: =SUM(J6:J7) -> 0
B10: Note: NPV and payback are not additive across initiatives; totals shown for benefit/cost columns only.
B11: Capitalization policy note: this file defaults Build/Test labor to 80% capitalizable (Rate Card) pending Finance sign-off; the Servicing file defaults to 0% to mirror the S2 model's all-cash treatment. Align the policy across workstreams with Finance before the S2 gate.

Sheet SALES-1 Model
B2: SALES-1 — Underwriting & Pricing — Front Book | INITIATIVE MODEL
B3: Workstream: Sales (ELT sponsor: Susan | WSL: Selwyn) • Model status: Structure ready; NSR/seller baselines to populate from received datasets — see open items
T5: 2026 | U5: 2026 | V5: 2026 | W5: 2026 | X5: 2026 | Y5: 2026 | Z5: 2026 | AA5: 2026 | AB5: 2026 | AC5: 2026 | AD5: 2026 | AE5: 2026 | AF5: 2027 | AG5: 2027 | AH5: 2027 | AI5: 2027 | AJ5: 2027 | AK5: 2027 | AL5: 2027 | AM5: 2027 | AN5: 2027 | AO5: 2027 | AP5: 2027 | AQ5: 2027 | AR5: 2028 | AS5: 2028 | AT5: 2028 | AU5: 2028 | AV5: 2028 | AW5: 2028 | AX5: 2028 | AY5: 2028 | AZ5: 2028 | BA5: 2028 | BB5: 2028 | BC5: 2028 | BD5: 2029 | BE5: 2029 | BF5: 2029 | BG5: 2029 | BH5: 2029 | BI5: 2029 | BJ5: 2029 | BK5: 2029 | BL5: 2029 | BM5: 2029 | BN5: 2029 | BO5: 2029 | BP5: 2030 | BQ5: 2030 | BR5: 2030 | BS5: 2030 | BT5: 2030 | BU5: 2030 | BV5: 2030 | BW5: 2030 | BX5: 2030 | BY5: 2030 | BZ5: 2030 | CA5: 2030
B6: Monthly grid (Jan-26 → Dec-30) → | K6: Run rate | L6: 2026 | M6: 2027 | N6: 2028 | O6: 2029 | P6: 2030 | T6: =DATE(2026,1,31) -> 46053 | U6: =EOMONTH(T6,1) -> 46081 | V6: =EOMONTH(U6,1) -> 46112 | W6: =EOMONTH(V6,1) -> 46142 | X6: =EOMONTH(W6,1) -> 46173 | Y6: =EOMONTH(X6,1) -> 46203 | Z6: =EOMONTH(Y6,1) -> 46234 | AA6: =EOMONTH(Z6,1) -> 46265 | AB6: =EOMONTH(AA6,1) -> 46295 | ... CA6: =EOMONTH(BZ6,1) -> 47848
B8: 0. INITIATIVE & STATUS
B10: Initiative name | D10: Agentic underwriting and pricing for the front book — faster cycle times, freed seller capacity, RoS uplift
B11: Initiative owner | D11: Sales initiative owner — TBC | I11: confirm with workstream lead
B12: Impacted BU | D12: Global Sales
B13: Go-live / Estimated L4 date | D13: =DATE(2027,4,1) -> 46478 | I13: Benefit ramp is gated on this date.
B15: Source: Workplan: 'Project Zenith Automation workplan and data requests vS_1.xlsx', Sales tab + Sales Data Requests tab
B16: Source: Impact ranges: Aug 13 deck pp. 6, 14–15; Board deck pp. 9, 20, 52 (preliminary — Finance to validate)
B17: Open items to refine with initiative owner:
B18: – Baselines to populate: front-book NSR by segment (pending), TM% by BU/region (received 8/20 — reflects CEO ask on revenue-quality differences), FLC by region (received 8/21), seller counts & time-on-UW split (pending).
B19: – Revenue-acceleration conversion factor (cycle time -> incremental NSR) must be defined with Finance — incremental vs pull-forward treatment per the Finance approval package requirements.
B20: – Sales/Risk attribution and Risk & Compliance dependency (underwriting, credit decisioning, risk-based pricing) to be resolved.
B21: – Interviews in flight (Pricing 8/27, Underwriting 8/27, Tech 8/26); build shape below is the standard AAO pod PLACEHOLDER — refine after tech workshop (W6).
B23: 1. SIZING ASSUMPTIONS (blue = inputs — refine with initiative owner)
B25: Baseline / denominator (populate from received datasets + pending requests)
B26: Front-book NSR in scope (annual) | D26: 0 | E26: $/yr | F26: PENDING — placeholder, not data. NSR by segment — pending
B27: Transaction margin (TM % of NSR) — blended in scope | D27: 0 | E27: % | F27: Received 8/20 by BU/region — populate blended in-scope value
B28: # sellers in scope (UW/pricing-involved) | D28: 0 | E28: # FTE | F28: PENDING — placeholder, not data. Seller counts by segment — pending
B29: Avg fully loaded cost per seller | D29: 0 | E29: $/yr | F29: FLC by region received 8/21 — populate blended value
B30: % of seller time on UW, pricing & related activities | D30: 0 | E30: % | F30: PENDING — placeholder, not data. Seller time-allocation — pending
B31: Impact drivers (Aug 13 deck pp. 6, 14 — preliminary ranges, midpoints seeded)
B32: UW cycle-time reduction | D32: 0.7 | E32: % | F32: Source: 70%
B33: Pricing cycle-time reduction | D33: 0.25 | E33: % | F33: Source: 20–30% — midpoint
B34: Revenue-acceleration conversion (% incremental NSR from faster cycles) | D34: 0 | E34: % | F34: PENDING — placeholder, not data. Define with Finance: converts cycle-time reduction into incremental NSR; keep incremental vs pull-forward split explicit
B35: Capture rate — revenue acceleration | D35: 0.75 | E35: % | F35: Source: 75%
B36: RoS / margin uplift | D36: 0.025 | E36: % | F36: Source: 2–3% — midpoint
B37: Capture rate — RoS uplift | D37: 0.75 | E37: % | F37: Assumed same as pricing capture — confirm
B38: Seller capacity freed — UW | D38: 0.35 | E38: % | F38: Source: 30–40% — midpoint
B39: Seller capacity freed — pricing | D39: 0.3 | E39: % | F39: Source: 25–35% — midpoint
B40: Capture rate — seller capacity to cost | D40: 0.65 | E40: % | F40: Source: 65%
B41: Investment uplifts (consistent with Servicing S2 standard)
B42: Programme management, % of build | D42: 0.08 | E42: %
B43: Contingency, % of build incl. PM | D43: 0.1 | E43: %
B44: (spare assumption row)
B45: (spare assumption row)
B47: 2. BENEFIT CALCULATION (steady-state annual run-rate)
B49: In-scope margin base (NSR x TM%) | D49: =$D$26*$D$27 -> 0 | E49: $/yr
...

Sheet SALES-1 WAVE
L1: 1 | M1: 2 | N1: 3 | O1: 4 | P1: 5 | R1: =COUNTIFS($R$66:$R$117, "Error") -> 0 | T1: 2026 | U1: 2026 | V1: 2026 | W1: 2026 | X1: 2026 | Y1: 2026 | Z1: 2026 | AA1: 2026 | AB1: 2026 | AC1: 2026 | AD1: 2026 | AE1: 2026 | AF1: 2027 | AG1: 2027 | AH1: 2027 | AI1: 2027 | AJ1: 2027 | AK1: 2027 | AL1: 2027 | AM1: 2027 | AN1: 2027 | AO1: 2027 | AP1: 2027 | AQ1: 2027 | AR1: 2028 | AS1: 2028 | AT1: 2028 | AU1: 2028 | AV1: 2028 | AW1: 2028 | AX1: 2028 | AY1: 2028 | AZ1: 2028 | BA1: 2028 | BB1: 2028 | BC1: 2028 | BD1: 2029 | BE1: 2029 | BF1: 2029 | BG1: 2029 | BH1: 2029 | BI1: 2029 | BJ1: 2029 | BK1: 2029 | BL1: 2029 | BM1: 2029 | BN1: 2029 | BO1: 2029 | BP1: 2030 | BQ1: 2030 | BR1: 2030 | BS1: 2030 | BT1: 2030 | BU1: 2030 | BV1: 2030 | BW1: 2030 | BX1: 2030 | BY1: 2030 | BZ1: 2030 | CA1: 2030 | CI1: =COUNTIFS(CI$66:CI$149, "FALSE") -> 0 | CJ1: =COUNTIFS(CJ$66:CJ$149, "FALSE") -> 0 | CK1: =COUNTIFS(CK$66:CK$149, "FALSE") -> 0 | CL1: =COUNTIFS(CL$66:CL$149, "FALSE") -> 0 | CM1: =COUNTIFS(CM$66:CM$149, "FALSE") -> 0
C2: ="#"&$F$6&" Initiative Business Case" -> #TBD Initiative Business Case
C4: INPUTS & ASSUMPTIONS
D6: Initiative # | F6: TBD
D7: Initiative Owner | F7: Sales initiative owner — TBC
D8: Initiative Name | F8: Agentic underwriting and pricing for the front book — faster cycle times, freed seller capacity, RoS uplift
D11: Estimated L4 date | F11: ='SALES-1 Model'!$D$13 -> 46478
D12: Net Recurring Benefit ($M) | F12: =$K$117 -> 0
C14: SECTION I - PRIMARY VALUE DRIVER (ILLUSTRATIVE)
D16: Primary value driver — linked to the Model sheet; refine with the initiative owner
D17: Baseline | H17: Period | I17: KPI | J17: Inputs
E18: Front-book NSR in scope | H18: TTM 6/1/26 | I18: $USD M | J18: ='SALES-1 Model'!$D$26/1000000 -> 0
E19: Transaction margin (TM % of NSR) | H19: TTM 6/1/26 | I19: % | J19: ='SALES-1 Model'!$D$27 -> 0
E20: In-scope margin base | H20: TTM 6/1/26 | I20: $USD M | J20: ='SALES-1 Model'!$D$49/1000000 -> 0
E21: Sellers in scope x FLC | H21: TTM 6/1/26 | I21: $USD M | J21: ='SALES-1 Model'!$D$28*'SALES-1 Model'!$D$29/1000000 -> 0
D23: Goal
E24: UW / pricing cycle-time reduction | H24: Steady state | I24: % (UW) | J24: ='SALES-1 Model'!$D$32 -> 0.7
E25: Seller capacity freed x capture | H25: Steady state | I25: % | J25: =(('SALES-1 Model'!$D$38+'SALES-1 Model'!$D$39)/2)*'SALES-1 Model'!$D$40 -> 0.21125
D28: Incremental Improvement
E29: Total annual benefit (run rate) | I29: $USD M | J29: =('SALES-1 Model'!$D$50+'SALES-1 Model'!$D$51+'SALES-1 Model'!$D$52)/1000000 -> 0
C60: SECTION II - NET RECURRING BENEFITS | CC60: ANNUAL SUMMARY | CI60: CHECK CELLS
T62: 2026 | AF62: 2027 | AR62: 2028 | BD62: 2029 | BP62: 2030 | CI62: CHECK
D63: RECURRING BENEFITS | H63: Comment | I63: Baseline | J63: Goal | K63: Ann. Run Rate | L63: 2026 | M63: =L63+1 -> 2027 | N63: =M63+1 -> 2028 | O63: =N63+1 -> 2029 | P63: =O63+1 -> 2030 | Q63: Impacted BU | R63: Check | T63: 46023 | U63: =EOMONTH(T63, 1) -> 46081 | V63: =EOMONTH(U63, 1) -> 46112 | W63: =EOMONTH(V63, 1) -> 46142 | X63: =EOMONTH(W63, 1) -> 46173 | Y63: =EOMONTH(X63, 1) -> 46203 | Z63: =EOMONTH(Y63, 1) -> 46234 | AA63: =EOMONTH(Z63, 1) -> 46265 | AB63: =EOMONTH(AA63, 1) -> 46295 | ... CA63: =EOMONTH(BZ63, 1) -> 47848 | CC63: 2026 | CD63: =CC63+1 -> 2027 | CE63: =CD63+1 -> 2028 | CF63: =CE63+1 -> 2029 | CG63: =CF63+1 -> 2030 | CI63: 2026 | CJ63: =CI63+1 -> 2027 | CK63: =CJ63+1 -> 2028 | CL63: =CK63+1 -> 2029 | CM63: =CL63+1 -> 2030
E64: $USD M | I64: =$H$18 -> TTM 6/1/26 | J64: Future State | K64: Increment
E65: Revenue
E66: Revenue - Acceleration from UW & pricing cycle time | H66: Margin base uplift from faster cycle times (incremental share only) | I66: ='SALES-1 Model'!$D$63 -> 0 | J66: =I66+'SALES-1 Model'!$K$63 -> 0 | K66: ='SALES-1 Model'!$K$63 -> 0 | L66: ='SALES-1 Model'!L63 -> 0 | M66: ='SALES-1 Model'!M63 -> 0 | N66: ='SALES-1 Model'!N63 -> 0 | O66: ='SALES-1 Model'!O63 -> 0 | P66: ='SALES-1 Model'!P63 -> 0 | Q66: Global Sales | R66: =IF(K66=P66, "", "Error") | T66: ='SALES-1 Model'!T63 -> 0 | U66: ='SALES-1 Model'!U63 -> 0 | V66: ='SALES-1 Model'!V63 -> 0 | W66: ='SALES-1 Model'!W63 -> 0 | X66: ='SALES-1 Model'!X63 -> 0 | Y66: ='SALES-1 Model'!Y63 -> 0 | Z66: ='SALES-1 Model'!Z63 -> 0 | AA66: ='SALES-1 Model'!AA63 -> 0 | ... CA66: ='SALES-1 Model'!CA63 -> 0 | CC66: =SUMIFS($T66:$CA66, $T$1:$CA$1, CC$63) -> 0 | CD66: =SUMIFS($T66:$CA66, $T$1:$CA$1, CD$63) -> 0 | CE66: =SUMIFS($T66:$CA66, $T$1:$CA$1, CE$63) -> 0 | CF66: =SUMIFS($T66:$CA66, $T$1:$CA$1, CF$63) -> 0 | CG66: =SUMIFS($T66:$CA66, $T$1:$CA$1, CG$63) -> 0 | CI66: =CC66=L66 -> 1 | CJ66: =CD66=M66 -> 1 | CK66: =CE66=N66 -> 1 | CL66: =CF66=O66 -> 1 | CM66: =CG66=P66 -> 1
E67: Revenue - RoS / pricing uplift | H67: 2–3% RoS uplift at 75% capture (midpoint seeded) | I67: ='SALES-1 Model'!$D$64 -> 0 | J67: =I67+'SALES-1 Model'!$K$64 -> 0 | K67: ='SALES-1 Model'!$K$64 -> 0 | L67: ='SALES-1 Model'!L64 -> 0 | M67: ='SALES-1 Model'!M64 -> 0 | N67: ='SALES-1 Model'!N64 -> 0 | O67: ='SALES-1 Model'!O64 -> 0 | P67: ='SALES-1 Model'!P64 -> 0 | Q67: Global Sales | R67: =IF(K67=P67, "", "Error") | T67: ='SALES-1 Model'!T64 -> 0 | U67: ='SALES-1 Model'!U64 -> 0 | V67: ='SALES-1 Model'!V64 -> 0 | W67: ='SALES-1 Model'!W64 -> 0 | X67: ='SALES-1 Model'!X64 -> 0 | Y67: ='SALES-1 Model'!Y64 -> 0 | Z67: ='SALES-1 Model'!Z64 -> 0 | AA67: ='SALES-1 Model'!AA64 -> 0 | ... CA67: ='SALES-1 Model'!CA64 -> 0 | CC67: =SUMIFS($T67:$CA67, $T$1:$CA$1, CC$63) -> 0 | CD67: =SUMIFS($T67:$CA67, $T$1:$CA$1, CD$63) -> 0 | CE67: =SUMIFS($T67:$CA67, $T$1:$CA$1, CE$63) -> 0 | CF67: =SUMIFS($T67:$CA67, $T$1:$CA$1, CF$63) -> 0 | CG67: =SUMIFS($T67:$CA67, $T$1:$CA$1, CG$63) -> 0 | CI67: =CC67=L67 -> 1 | CJ67: =CD67=M67 -> 1 | CK67: =CE67=N67 -> 1 | CL67: =CF67=O67 -> 1 | CM67: =CG67=P67 -> 1
E68: Revenue Subtotal | I68: =SUM(I66:I67) -> 0 | J68: =SUM(J66:J67) -> 0 | K68: =SUM(K66:K67) -> 0 | L68: =SUM(L66:L67) -> 0 | M68: =SUM(M66:M67) -> 0 | N68: =SUM(N66:N67) -> 0 | O68: =SUM(O66:O67) -> 0 | P68: =SUM(P66:P67) -> 0 | T68: =SUM(T66:T67) -> 0 | U68: =SUM(U66:U67) -> 0 | V68: =SUM(V66:V67) -> 0 | W68: =SUM(W66:W67) -> 0 | X68: =SUM(X66:X67) -> 0 | Y68: =SUM(Y66:Y67) -> 0 | Z68: =SUM(Z66:Z67) -> 0 | AA68: =SUM(AA66:AA67) -> 0 | ... CA68: =SUM(CA66:CA67) -> 0 | CC68: =SUM(CC66:CC67) -> 0 | CD68: =SUM(CD66:CD67) -> 0 | CE68: =SUM(CE66:CE67) -> 0 | CF68: =SUM(CF66:CF67) -> 0 | CG68: =SUM(CG66:CG67) -> 0 | CI68: =CC68=L68 -> 1 | CJ68: =CD68=M68 -> 1 | CK68: =CE68=N68 -> 1 | CL68: =CF68=O68 -> 1 | CM68: =CG68=P68 -> 1
E70: Cost of Sales
K71: =I71-J71 -> 0 | R71: =IF(K71=P71, "", "Error") | CC71: =SUMIFS($T71:$CA71, $T$1:$CA$1, CC$63) -> 0 | CD71: =SUMIFS($T71:$CA71, $T$1:$CA$1, CD$63) -> 0 | CE71: =SUMIFS($T71:$CA71, $T$1:$CA$1, CE$63) -> 0 | CF71: =SUMIFS($T71:$CA71, $T$1:$CA$1, CF$63) -> 0 | CG71: =SUMIFS($T71:$CA71, $T$1:$CA$1, CG$63) -> 0 | CI71: =CC71=L71 -> 1 | CJ71: =CD71=M71 -> 1 | CK71: =CE71=N71 -> 1 | CL71: =CF71=O71 -> 1 | CM71: =CG71=P71 -> 1
I72: 0 | J72: 0 | K72: =I72-J72 -> 0 | R72: =IF(K72=P72, "", "Error") | CC72: =SUMIFS($T72:$CA72, $T$1:$CA$1, CC$63) -> 0 | CD72: =SUMIFS($T72:$CA72, $T$1:$CA$1, CD$63) -> 0 | CE72: =SUMIFS($T72:$CA72, $T$1:$CA$1, CE$63) -> 0 | CF72: =SUMIFS($T72:$CA72, $T$1:$CA$1, CF$63) -> 0 | CG72: =SUMIFS($T72:$CA72, $T$1:$CA$1, CG$63) -> 0 | CI72: =CC72=L72 -> 1 | CJ72: =CD72=M72 -> 1 | CK72: =CE72=N72 -> 1 | CL72: =CF72=O72 -> 1 | CM72: =CG72=P72 -> 1
I73: 0 | J73: 0 | K73: =I73-J73 -> 0 | R73: =IF(K73=P73, "", "Error") | CC73: =SUMIFS($T73:$CA73, $T$1:$CA$1, CC$63) -> 0 | CD73: =SUMIFS($T73:$CA73, $T$1:$CA$1, CD$63) -> 0 | CE73: =SUMIFS($T73:$CA73, $T$1:$CA$1, CE$63) -> 0 | CF73: =SUMIFS($T73:$CA73, $T$1:$CA$1, CF$63) -> 0 | CG73: =SUMIFS($T73:$CA73, $T$1:$CA$1, CG$63) -> 0 | CI73: =CC73=L73 -> 1 | CJ73: =CD73=M73 -> 1 | CK73: =CE73=N73 -> 1 | CL73: =CF73=O73 -> 1 | CM73: =CG73=P73 -> 1
I74: 0 | J74: 0 | K74: =I74-J74 -> 0 | R74: =IF(K74=P74, "", "Error") | CC74: =SUMIFS($T74:$CA74, $T$1:$CA$1, CC$63) -> 0 | CD74: =SUMIFS($T74:$CA74, $T$1:$CA$1, CD$63) -> 0 | CE74: =SUMIFS($T74:$CA74, $T$1:$CA$1, CE$63) -> 0 | CF74: =SUMIFS($T74:$CA74, $T$1:$CA$1, CF$63) -> 0 | CG74: =SUMIFS($T74:$CA74, $T$1:$CA$1, CG$63) -> 0 | CI74: =CC74=L74 -> 1 | CJ74: =CD74=M74 -> 1 | CK74: =CE74=N74 -> 1 | CL74: =CF74=O74 -> 1 | CM74: =CG74=P74 -> 1
K75: =I75-J75 -> 0 | R75: =IF(K75=P75, "", "Error") | CC75: =SUMIFS($T75:$CA75, $T$1:$CA$1, CC$63) -> 0 | CD75: =SUMIFS($T75:$CA75, $T$1:$CA$1, CD$63) -> 0 | CE75: =SUMIFS($T75:$CA75, $T$1:$CA$1, CE$63) -> 0 | CF75: =SUMIFS($T75:$CA75, $T$1:$CA$1, CF$63) -> 0 | CG75: =SUMIFS($T75:$CA75, $T$1:$CA$1, CG$63) -> 0 | CI75: =CC75=L75 -> 1 | CJ75: =CD75=M75 -> 1 | CK75: =CE75=N75 -> 1 | CL75: =CF75=O75 -> 1 | CM75: =CG75=P75 -> 1
E76: Cost of Sales Subtotal | I76: =SUM(I71:I75) -> 0 | J76: =SUM(J71:J75) -> 0 | K76: =SUM(K71:K75) -> 0 | L76: =SUM(L71:L75) -> 0 | M76: =SUM(M71:M75) -> 0 | N76: =SUM(N71:N75) -> 0 | O76: =SUM(O71:O75) -> 0 | P76: =SUM(P71:P75) -> 0 | T76: =SUM(T71:T75) -> 0 | U76: =SUM(U71:U75) -> 0 | V76: =SUM(V71:V75) -> 0 | W76: =SUM(W71:W75) -> 0 | X76: =SUM(X71:X75) -> 0 | Y76: =SUM(Y71:Y75) -> 0 | Z76: =SUM(Z71:Z75) -> 0 | AA76: =SUM(AA71:AA75) -> 0 | ... CA76: =SUM(CA71:CA75) -> 0 | CC76: =SUM(CC71:CC75) -> 0 | CD76: =SUM(CD71:CD75) -> 0 | CE76: =SUM(CE71:CE75) -> 0 | CF76: =SUM(CF71:CF75) -> 0 | CG76: =SUM(CG71:CG75) -> 0 | CI76: =CC76=L76 -> 1 | CJ76: =CD76=M76 -> 1 | CK76: =CE76=N76 -> 1 | CL76: =CF76=O76 -> 1 | CM76: =CG76=P76 -> 1
E78: OPEX
E79: OPEX - Seller capacity freed (UW & pricing) | H79: 30–40% (UW) / 25–35% (pricing) seller capacity freed at 65% capture | I79: ='SALES-1 Model'!$D$65 -> 0 | J79: =I79-'SALES-1 Model'!$K$65 -> 0 | K79: ='SALES-1 Model'!$K$65 -> 0 | L79: ='SALES-1 Model'!L65 -> 0 | M79: ='SALES-1 Model'!M65 -> 0 | N79: ='SALES-1 Model'!N65 -> 0 | O79: ='SALES-1 Model'!O65 -> 0 | P79: ='SALES-1 Model'!P65 -> 0 | Q79: Global Sales | R79: =IF(K79=P79, "", "Error") | T79: ='SALES-1 Model'!T65 -> 0 | U79: ='SALES-1 Model'!U65 -> 0 | V79: ='SALES-1 Model'!V65 -> 0 | W79: ='SALES-1 Model'!W65 -> 0 | X79: ='SALES-1 Model'!X65 -> 0 | Y79: ='SALES-1 Model'!Y65 -> 0 | Z79: ='SALES-1 Model'!Z65 -> 0 | AA79: ='SALES-1 Model'!AA65 -> 0 | ... CA79: ='SALES-1 Model'!CA65 -> 0 | CC79: =SUMIFS($T79:$CA79, $T$1:$CA$1, CC$63) -> 0 | CD79: =SUMIFS($T79:$CA79, $T$1:$CA$1, CD$63) -> 0 | CE79: =SUMIFS($T79:$CA79, $T$1:$CA$1, CE$63) -> 0 | CF79: =SUMIFS($T79:$CA79, $T$1:$CA$1, CF$63) -> 0 | CG79: =SUMIFS($T79:$CA79, $T$1:$CA$1, CG$63) -> 0 | CI79: =CC79=L79 -> 1 | CJ79: =CD79=M79 -> 1 | CK79: =CE79=N79 -> 1 | CL79: =CF79=O79 -> 1 | CM79: =CG79=P79 -> 1
I80: 0 | J80: 0 | K80: =I80-J80 -> 0 | R80: =IF(K80=P80, "", "Error") | CC80: =SUMIFS($T80:$CA80, $T$1:$CA$1, CC$63) -> 0 | CD80: =SUMIFS($T80:$CA80, $T$1:$CA$1, CD$63) -> 0 | CE80: =SUMIFS($T80:$CA80, $T$1:$CA$1, CE$63) -> 0 | CF80: =SUMIFS($T80:$CA80, $T$1:$CA$1, CF$63) -> 0 | CG80: =SUMIFS($T80:$CA80, $T$1:$CA$1, CG$63) -> 0 | CI80: =CC80=L80 -> 1 | CJ80: =CD80=M80 -> 1 | CK80: =CE80=N80 -> 1 | CL80: =CF80=O80 -> 1 | CM80: =CG80=P80 -> 1
I81: 0 | J81: 0 | K81: =I81-J81 -> 0 | R81: =IF(K81=P81, "", "Error") | CC81: =SUMIFS($T81:$CA81, $T$1:$CA$1, CC$63) -> 0 | CD81: =SUMIFS($T81:$CA81, $T$1:$CA$1, CD$63) -> 0 | CE81: =SUMIFS($T81:$CA81, $T$1:$CA$1, CE$63) -> 0 | CF81: =SUMIFS($T81:$CA81, $T$1:$CA$1, CF$63) -> 0 | CG81: =SUMIFS($T81:$CA81, $T$1:$CA$1, CG$63) -> 0 | CI81: =CC81=L81 -> 1 | CJ81: =CD81=M81 -> 1 | CK81: =CE81=N81 -> 1 | CL81: =CF81=O81 -> 1 | CM81: =CG81=P81 -> 1
I82: 0 | J82: 0 | K82: =I82-J82 -> 0 | R82: =IF(K82=P82, "", "Error") | CC82: =SUMIFS($T82:$CA82, $T$1:$CA$1, CC$63) -> 0 | CD82: =SUMIFS($T82:$CA82, $T$1:$CA$1, CD$63) -> 0 | CE82: =SUMIFS($T82:$CA82, $T$1:$CA$1, CE$63) -> 0 | CF82: =SUMIFS($T82:$CA82, $T$1:$CA$1, CF$63) -> 0 | CG82: =SUMIFS($T82:$CA82, $T$1:$CA$1, CG$63) -> 0 | CI82: =CC82=L82 -> 1 | CJ82: =CD82=M82 -> 1 | CK82: =CE82=N82 -> 1 | CL82: =CF82=O82 -> 1 | CM82: =CG82=P82 -> 1
...

Sheet SALES-2 Model
B2: SALES-2 — SMB Long Tail — Partner | INITIATIVE MODEL
B3: Workstream: Sales (ELT sponsor: Susan | WSL: Selwyn) • Model status: Structure ready; partner/SDR baselines to populate — see open items
T5: 2026 | U5: 2026 | V5: 2026 | W5: 2026 | X5: 2026 | Y5: 2026 | Z5: 2026 | AA5: 2026 | AB5: 2026 | AC5: 2026 | AD5: 2026 | AE5: 2026 | AF5: 2027 | AG5: 2027 | AH5: 2027 | AI5: 2027 | AJ5: 2027 | AK5: 2027 | AL5: 2027 | AM5: 2027 | AN5: 2027 | AO5: 2027 | AP5: 2027 | AQ5: 2027 | AR5: 2028 | AS5: 2028 | AT5: 2028 | AU5: 2028 | AV5: 2028 | AW5: 2028 | AX5: 2028 | AY5: 2028 | AZ5: 2028 | BA5: 2028 | BB5: 2028 | BC5: 2028 | BD5: 2029 | BE5: 2029 | BF5: 2029 | BG5: 2029 | BH5: 2029 | BI5: 2029 | BJ5: 2029 | BK5: 2029 | BL5: 2029 | BM5: 2029 | BN5: 2029 | BO5: 2029 | BP5: 2030 | BQ5: 2030 | BR5: 2030 | BS5: 2030 | BT5: 2030 | BU5: 2030 | BV5: 2030 | BW5: 2030 | BX5: 2030 | BY5: 2030 | BZ5: 2030 | CA5: 2030
B6: Monthly grid (Jan-26 → Dec-30) → | K6: Run rate | L6: 2026 | M6: 2027 | N6: 2028 | O6: 2029 | P6: 2030 | T6: =DATE(2026,1,31) -> 46053 | U6: =EOMONTH(T6,1) -> 46081 | V6: =EOMONTH(U6,1) -> 46112 | W6: =EOMONTH(V6,1) -> 46142 | X6: =EOMONTH(W6,1) -> 46173 | Y6: =EOMONTH(X6,1) -> 46203 | Z6: =EOMONTH(Y6,1) -> 46234 | AA6: =EOMONTH(Z6,1) -> 46265 | AB6: =EOMONTH(AA6,1) -> 46295 | ... CA6: =EOMONTH(BZ6,1) -> 47848
B8: 0. INITIATIVE & STATUS
B10: Initiative name | D10: SMB long-tail growth through partner-channel scaling and autonomous SDR outreach
B11: Initiative owner | D11: Sales initiative owner — TBC | I11: confirm with workstream lead
B12: Impacted BU | D12: Global Sales
B13: Go-live / Estimated L4 date | D13: =DATE(2027,4,1) -> 46478 | I13: Benefit ramp is gated on this date.
B15: Source: Workplan: 'Project Zenith Automation workplan and data requests vS_1.xlsx', Sales tab + Sales Data Requests tab
B16: Source: Impact ranges: Aug 13 deck pp. 6, 14–15; Board deck pp. 9, 20, 52 (preliminary — Finance to validate)
B17: Open items to refine with initiative owner:
B18: – Partner-channel revenue % received 8/24 — populate the $ base. Attach-rate quartile distribution and partner SME interview still pending (requests #5–#6).
B19: – Incrementality / cannibalization logic must be defined with Finance before S2 sign-off.
B20: – SDR conversion & cycle-time baselines pending; seller time on lead mgmt pending.
B21: – Cross-functional dependency: partner/channel org + PRM platform; watch overlap with broader SMB front-book growth (workplan flag).
B22: – Seller time saved on lead mgmt is flagged as an ENABLER in source materials — confirm bankability before counting it in the S2 number.
B24: 1. SIZING ASSUMPTIONS (blue = inputs — refine with initiative owner)
B26: Baseline / denominator (populate from received datasets + pending requests)
B27: Partner/referral-channel revenue (annual NSR) | D27: 0 | E27: $/yr | F27: % revenue via partner received 8/24 — populate $ base
B28: Transaction margin (TM % of NSR) — SMB blended | D28: 0 | E28: % | F28: From TM% dataset received 8/20
B29: SDR-influenced revenue base (annual NSR) | D29: 0 | E29: $/yr | F29: PENDING — placeholder, not data. SDR conversion & funnel data — pending
B30: # SMB sellers on lead management | D30: 0 | E30: # FTE | F30: PENDING — placeholder, not data.
B31: Avg fully loaded cost per SMB seller | D31: 0 | E31: $/yr | F31: From FLC by region (received 8/21)
B32: % of seller time on lead mgmt & related | D32: 0 | E32: % | F32: PENDING — placeholder, not data.
B33: Impact drivers (Aug 13 deck pp. 6, 14–15 — preliminary ranges, midpoints seeded)
B34: Partner-channel share uplift | D34: 1 | E34: % | F34: Source: ~100% partner-channel share uplift
B35: Incrementality factor (net of cannibalization) | D35: 0 | E35: % | F35: PENDING — placeholder, not data. Define with Finance — cannibalization treatment required for approval package
B36: SDR autonomous-outreach conversion uplift | D36: 0.15 | E36: % | F36: Source: ~15%
B37: Capture rate — SDR uplift | D37: 0.72 | E37: % | F37: Source: 72%
B38: Cycle-time pull-forward | D38: 12 | E38: days | F38: Source: ~12 days revenue acceleration — treat as timing unless Finance agrees incremental; fold agreed value into the SDR line
B39: Seller time saved on lead management | D39: 0.375 | E39: % | F39: Source: 35–40% — midpoint. ENABLER — confirm bankability
B40: Capture rate — seller time saved | D40: 0.65 | E40: % | F40: Assumed consistent with U&P seller capture — confirm
B41: Investment uplifts (consistent with Servicing S2 standard)
B42: Programme management, % of build | D42: 0.08 | E42: %
B43: Contingency, % of build incl. PM | D43: 0.1 | E43: %
B44: (spare assumption row)
B45: (spare assumption row)
B47: 2. BENEFIT CALCULATION (steady-state annual run-rate)
B49: Partner-channel share uplift benefit (margin) | D49: =$D$27*$D$28*$D$34*$D$35 -> 0 | E49: $/yr | F49: Partner margin base x share uplift x incrementality (net of cannibalization)
...

Sheet SALES-2 WAVE
L1: 1 | M1: 2 | N1: 3 | O1: 4 | P1: 5 | R1: =COUNTIFS($R$66:$R$117, "Error") -> 0 | T1: 2026 | U1: 2026 | V1: 2026 | W1: 2026 | X1: 2026 | Y1: 2026 | Z1: 2026 | AA1: 2026 | AB1: 2026 | AC1: 2026 | AD1: 2026 | AE1: 2026 | AF1: 2027 | AG1: 2027 | AH1: 2027 | AI1: 2027 | AJ1: 2027 | AK1: 2027 | AL1: 2027 | AM1: 2027 | AN1: 2027 | AO1: 2027 | AP1: 2027 | AQ1: 2027 | AR1: 2028 | AS1: 2028 | AT1: 2028 | AU1: 2028 | AV1: 2028 | AW1: 2028 | AX1: 2028 | AY1: 2028 | AZ1: 2028 | BA1: 2028 | BB1: 2028 | BC1: 2028 | BD1: 2029 | BE1: 2029 | BF1: 2029 | BG1: 2029 | BH1: 2029 | BI1: 2029 | BJ1: 2029 | BK1: 2029 | BL1: 2029 | BM1: 2029 | BN1: 2029 | BO1: 2029 | BP1: 2030 | BQ1: 2030 | BR1: 2030 | BS1: 2030 | BT1: 2030 | BU1: 2030 | BV1: 2030 | BW1: 2030 | BX1: 2030 | BY1: 2030 | BZ1: 2030 | CA1: 2030 | CI1: =COUNTIFS(CI$66:CI$149, "FALSE") -> 0 | CJ1: =COUNTIFS(CJ$66:CJ$149, "FALSE") -> 0 | CK1: =COUNTIFS(CK$66:CK$149, "FALSE") -> 0 | CL1: =COUNTIFS(CL$66:CL$149, "FALSE") -> 0 | CM1: =COUNTIFS(CM$66:CM$149, "FALSE") -> 0
C2: ="#"&$F$6&" Initiative Business Case" -> #TBD Initiative Business Case
C4: INPUTS & ASSUMPTIONS
D6: Initiative # | F6: TBD
D7: Initiative Owner | F7: Sales initiative owner — TBC
D8: Initiative Name | F8: SMB long-tail growth through partner-channel scaling and autonomous SDR outreach
D11: Estimated L4 date | F11: ='SALES-2 Model'!$D$13 -> 46478
D12: Net Recurring Benefit ($M) | F12: =$K$117 -> 0
C14: SECTION I - PRIMARY VALUE DRIVER (ILLUSTRATIVE)
D16: Primary value driver — linked to the Model sheet; refine with the initiative owner
D17: Baseline | H17: Period | I17: KPI | J17: Inputs
E18: Partner/referral-channel NSR | H18: TTM 6/1/26 | I18: $USD M | J18: ='SALES-2 Model'!$D$27/1000000 -> 0
E19: SDR-influenced NSR base | H19: TTM 6/1/26 | I19: $USD M | J19: ='SALES-2 Model'!$D$29/1000000 -> 0
E20: TM % of NSR (SMB blended) | H20: TTM 6/1/26 | I20: % | J20: ='SALES-2 Model'!$D$28 -> 0
D23: Goal
E24: Partner share uplift x incrementality | H24: Steady state | I24: % | J24: ='SALES-2 Model'!$D$34*'SALES-2 Model'!$D$35 -> 0
E25: SDR conversion uplift x capture | H25: Steady state | I25: % | J25: ='SALES-2 Model'!$D$36*'SALES-2 Model'!$D$37 -> 0.108
D28: Incremental Improvement
E29: Total annual benefit (run rate) | I29: $USD M | J29: =('SALES-2 Model'!$D$49+'SALES-2 Model'!$D$50+'SALES-2 Model'!$D$51)/1000000 -> 0
C60: SECTION II - NET RECURRING BENEFITS | CC60: ANNUAL SUMMARY | CI60: CHECK CELLS
T62: 2026 | AF62: 2027 | AR62: 2028 | BD62: 2029 | BP62: 2030 | CI62: CHECK
D63: RECURRING BENEFITS | H63: Comment | I63: Baseline | J63: Goal | K63: Ann. Run Rate | L63: 2026 | M63: =L63+1 -> 2027 | N63: =M63+1 -> 2028 | O63: =N63+1 -> 2029 | P63: =O63+1 -> 2030 | Q63: Impacted BU | R63: Check | T63: 46023 | U63: =EOMONTH(T63, 1) -> 46081 | V63: =EOMONTH(U63, 1) -> 46112 | W63: =EOMONTH(V63, 1) -> 46142 | X63: =EOMONTH(W63, 1) -> 46173 | Y63: =EOMONTH(X63, 1) -> 46203 | Z63: =EOMONTH(Y63, 1) -> 46234 | AA63: =EOMONTH(Z63, 1) -> 46265 | AB63: =EOMONTH(AA63, 1) -> 46295 | ... CA63: =EOMONTH(BZ63, 1) -> 47848 | CC63: 2026 | CD63: =CC63+1 -> 2027 | CE63: =CD63+1 -> 2028 | CF63: =CE63+1 -> 2029 | CG63: =CF63+1 -> 2030 | CI63: 2026 | CJ63: =CI63+1 -> 2027 | CK63: =CJ63+1 -> 2028 | CL63: =CK63+1 -> 2029 | CM63: =CL63+1 -> 2030
E64: $USD M | I64: =$H$18 -> TTM 6/1/26 | J64: Future State | K64: Increment
E65: Revenue
E66: Revenue - Partner-channel share uplift | H66: ~100% share uplift x incrementality (net of cannibalization — Finance to agree) | I66: ='SALES-2 Model'!$D$62 -> 0 | J66: =I66+'SALES-2 Model'!$K$62 -> 0 | K66: ='SALES-2 Model'!$K$62 -> 0 | L66: ='SALES-2 Model'!L62 -> 0 | M66: ='SALES-2 Model'!M62 -> 0 | N66: ='SALES-2 Model'!N62 -> 0 | O66: ='SALES-2 Model'!O62 -> 0 | P66: ='SALES-2 Model'!P62 -> 0 | Q66: Global Sales | R66: =IF(K66=P66, "", "Error") | T66: ='SALES-2 Model'!T62 -> 0 | U66: ='SALES-2 Model'!U62 -> 0 | V66: ='SALES-2 Model'!V62 -> 0 | W66: ='SALES-2 Model'!W62 -> 0 | X66: ='SALES-2 Model'!X62 -> 0 | Y66: ='SALES-2 Model'!Y62 -> 0 | Z66: ='SALES-2 Model'!Z62 -> 0 | AA66: ='SALES-2 Model'!AA62 -> 0 | ... CA66: ='SALES-2 Model'!CA62 -> 0 | CC66: =SUMIFS($T66:$CA66, $T$1:$CA$1, CC$63) -> 0 | CD66: =SUMIFS($T66:$CA66, $T$1:$CA$1, CD$63) -> 0 | CE66: =SUMIFS($T66:$CA66, $T$1:$CA$1, CE$63) -> 0 | CF66: =SUMIFS($T66:$CA66, $T$1:$CA$1, CF$63) -> 0 | CG66: =SUMIFS($T66:$CA66, $T$1:$CA$1, CG$63) -> 0 | CI66: =CC66=L66 -> 1 | CJ66: =CD66=M66 -> 1 | CK66: =CE66=N66 -> 1 | CL66: =CF66=O66 -> 1 | CM66: =CG66=P66 -> 1
E67: Revenue - SDR agent uplift (conversion + acceleration) | H67: ~15% conversion uplift at 72% capture; ~12-day pull-forward folded in once agreed | I67: ='SALES-2 Model'!$D$63 -> 0 | J67: =I67+'SALES-2 Model'!$K$63 -> 0 | K67: ='SALES-2 Model'!$K$63 -> 0 | L67: ='SALES-2 Model'!L63 -> 0 | M67: ='SALES-2 Model'!M63 -> 0 | N67: ='SALES-2 Model'!N63 -> 0 | O67: ='SALES-2 Model'!O63 -> 0 | P67: ='SALES-2 Model'!P63 -> 0 | Q67: Global Sales | R67: =IF(K67=P67, "", "Error") | T67: ='SALES-2 Model'!T63 -> 0 | U67: ='SALES-2 Model'!U63 -> 0 | V67: ='SALES-2 Model'!V63 -> 0 | W67: ='SALES-2 Model'!W63 -> 0 | X67: ='SALES-2 Model'!X63 -> 0 | Y67: ='SALES-2 Model'!Y63 -> 0 | Z67: ='SALES-2 Model'!Z63 -> 0 | AA67: ='SALES-2 Model'!AA63 -> 0 | ... CA67: ='SALES-2 Model'!CA63 -> 0 | CC67: =SUMIFS($T67:$CA67, $T$1:$CA$1, CC$63) -> 0 | CD67: =SUMIFS($T67:$CA67, $T$1:$CA$1, CD$63) -> 0 | CE67: =SUMIFS($T67:$CA67, $T$1:$CA$1, CE$63) -> 0 | CF67: =SUMIFS($T67:$CA67, $T$1:$CA$1, CF$63) -> 0 | CG67: =SUMIFS($T67:$CA67, $T$1:$CA$1, CG$63) -> 0 | CI67: =CC67=L67 -> 1 | CJ67: =CD67=M67 -> 1 | CK67: =CE67=N67 -> 1 | CL67: =CF67=O67 -> 1 | CM67: =CG67=P67 -> 1
E68: Revenue Subtotal | I68: =SUM(I66:I67) -> 0 | J68: =SUM(J66:J67) -> 0 | K68: =SUM(K66:K67) -> 0 | L68: =SUM(L66:L67) -> 0 | M68: =SUM(M66:M67) -> 0 | N68: =SUM(N66:N67) -> 0 | O68: =SUM(O66:O67) -> 0 | P68: =SUM(P66:P67) -> 0 | T68: =SUM(T66:T67) -> 0 | U68: =SUM(U66:U67) -> 0 | V68: =SUM(V66:V67) -> 0 | W68: =SUM(W66:W67) -> 0 | X68: =SUM(X66:X67) -> 0 | Y68: =SUM(Y66:Y67) -> 0 | Z68: =SUM(Z66:Z67) -> 0 | AA68: =SUM(AA66:AA67) -> 0 | ... CA68: =SUM(CA66:CA67) -> 0 | CC68: =SUM(CC66:CC67) -> 0 | CD68: =SUM(CD66:CD67) -> 0 | CE68: =SUM(CE66:CE67) -> 0 | CF68: =SUM(CF66:CF67) -> 0 | CG68: =SUM(CG66:CG67) -> 0 | CI68: =CC68=L68 -> 1 | CJ68: =CD68=M68 -> 1 | CK68: =CE68=N68 -> 1 | CL68: =CF68=O68 -> 1 | CM68: =CG68=P68 -> 1
E70: Cost of Sales
K71: =I71-J71 -> 0 | R71: =IF(K71=P71, "", "Error") | CC71: =SUMIFS($T71:$CA71, $T$1:$CA$1, CC$63) -> 0 | CD71: =SUMIFS($T71:$CA71, $T$1:$CA$1, CD$63) -> 0 | CE71: =SUMIFS($T71:$CA71, $T$1:$CA$1, CE$63) -> 0 | CF71: =SUMIFS($T71:$CA71, $T$1:$CA$1, CF$63) -> 0 | CG71: =SUMIFS($T71:$CA71, $T$1:$CA$1, CG$63) -> 0 | CI71: =CC71=L71 -> 1 | CJ71: =CD71=M71 -> 1 | CK71: =CE71=N71 -> 1 | CL71: =CF71=O71 -> 1 | CM71: =CG71=P71 -> 1
I72: 0 | J72: 0 | K72: =I72-J72 -> 0 | R72: =IF(K72=P72, "", "Error") | CC72: =SUMIFS($T72:$CA72, $T$1:$CA$1, CC$63) -> 0 | CD72: =SUMIFS($T72:$CA72, $T$1:$CA$1, CD$63) -> 0 | CE72: =SUMIFS($T72:$CA72, $T$1:$CA$1, CE$63) -> 0 | CF72: =SUMIFS($T72:$CA72, $T$1:$CA$1, CF$63) -> 0 | CG72: =SUMIFS($T72:$CA72, $T$1:$CA$1, CG$63) -> 0 | CI72: =CC72=L72 -> 1 | CJ72: =CD72=M72 -> 1 | CK72: =CE72=N72 -> 1 | CL72: =CF72=O72 -> 1 | CM72: =CG72=P72 -> 1
I73: 0 | J73: 0 | K73: =I73-J73 -> 0 | R73: =IF(K73=P73, "", "Error") | CC73: =SUMIFS($T73:$CA73, $T$1:$CA$1, CC$63) -> 0 | CD73: =SUMIFS($T73:$CA73, $T$1:$CA$1, CD$63) -> 0 | CE73: =SUMIFS($T73:$CA73, $T$1:$CA$1, CE$63) -> 0 | CF73: =SUMIFS($T73:$CA73, $T$1:$CA$1, CF$63) -> 0 | CG73: =SUMIFS($T73:$CA73, $T$1:$CA$1, CG$63) -> 0 | CI73: =CC73=L73 -> 1 | CJ73: =CD73=M73 -> 1 | CK73: =CE73=N73 -> 1 | CL73: =CF73=O73 -> 1 | CM73: =CG73=P73 -> 1
I74: 0 | J74: 0 | K74: =I74-J74 -> 0 | R74: =IF(K74=P74, "", "Error") | CC74: =SUMIFS($T74:$CA74, $T$1:$CA$1, CC$63) -> 0 | CD74: =SUMIFS($T74:$CA74, $T$1:$CA$1, CD$63) -> 0 | CE74: =SUMIFS($T74:$CA74, $T$1:$CA$1, CE$63) -> 0 | CF74: =SUMIFS($T74:$CA74, $T$1:$CA$1, CF$63) -> 0 | CG74: =SUMIFS($T74:$CA74, $T$1:$CA$1, CG$63) -> 0 | CI74: =CC74=L74 -> 1 | CJ74: =CD74=M74 -> 1 | CK74: =CE74=N74 -> 1 | CL74: =CF74=O74 -> 1 | CM74: =CG74=P74 -> 1
K75: =I75-J75 -> 0 | R75: =IF(K75=P75, "", "Error") | CC75: =SUMIFS($T75:$CA75, $T$1:$CA$1, CC$63) -> 0 | CD75: =SUMIFS($T75:$CA75, $T$1:$CA$1, CD$63) -> 0 | CE75: =SUMIFS($T75:$CA75, $T$1:$CA$1, CE$63) -> 0 | CF75: =SUMIFS($T75:$CA75, $T$1:$CA$1, CF$63) -> 0 | CG75: =SUMIFS($T75:$CA75, $T$1:$CA$1, CG$63) -> 0 | CI75: =CC75=L75 -> 1 | CJ75: =CD75=M75 -> 1 | CK75: =CE75=N75 -> 1 | CL75: =CF75=O75 -> 1 | CM75: =CG75=P75 -> 1
E76: Cost of Sales Subtotal | I76: =SUM(I71:I75) -> 0 | J76: =SUM(J71:J75) -> 0 | K76: =SUM(K71:K75) -> 0 | L76: =SUM(L71:L75) -> 0 | M76: =SUM(M71:M75) -> 0 | N76: =SUM(N71:N75) -> 0 | O76: =SUM(O71:O75) -> 0 | P76: =SUM(P71:P75) -> 0 | T76: =SUM(T71:T75) -> 0 | U76: =SUM(U71:U75) -> 0 | V76: =SUM(V71:V75) -> 0 | W76: =SUM(W71:W75) -> 0 | X76: =SUM(X71:X75) -> 0 | Y76: =SUM(Y71:Y75) -> 0 | Z76: =SUM(Z71:Z75) -> 0 | AA76: =SUM(AA71:AA75) -> 0 | ... CA76: =SUM(CA71:CA75) -> 0 | CC76: =SUM(CC71:CC75) -> 0 | CD76: =SUM(CD71:CD75) -> 0 | CE76: =SUM(CE71:CE75) -> 0 | CF76: =SUM(CF71:CF75) -> 0 | CG76: =SUM(CG71:CG75) -> 0 | CI76: =CC76=L76 -> 1 | CJ76: =CD76=M76 -> 1 | CK76: =CE76=N76 -> 1 | CL76: =CF76=O76 -> 1 | CM76: =CG76=P76 -> 1
E78: OPEX
E79: OPEX - Seller time saved on lead management (enabler) | H79: 35–40% time saved at 65% capture — enabler; confirm bankability | I79: ='SALES-2 Model'!$D$64 -> 0 | J79: =I79-'SALES-2 Model'!$K$64 -> 0 | K79: ='SALES-2 Model'!$K$64 -> 0 | L79: ='SALES-2 Model'!L64 -> 0 | M79: ='SALES-2 Model'!M64 -> 0 | N79: ='SALES-2 Model'!N64 -> 0 | O79: ='SALES-2 Model'!O64 -> 0 | P79: ='SALES-2 Model'!P64 -> 0 | Q79: Global Sales | R79: =IF(K79=P79, "", "Error") | T79: ='SALES-2 Model'!T64 -> 0 | U79: ='SALES-2 Model'!U64 -> 0 | V79: ='SALES-2 Model'!V64 -> 0 | W79: ='SALES-2 Model'!W64 -> 0 | X79: ='SALES-2 Model'!X64 -> 0 | Y79: ='SALES-2 Model'!Y64 -> 0 | Z79: ='SALES-2 Model'!Z64 -> 0 | AA79: ='SALES-2 Model'!AA64 -> 0 | ... CA79: ='SALES-2 Model'!CA64 -> 0 | CC79: =SUMIFS($T79:$CA79, $T$1:$CA$1, CC$63) -> 0 | CD79: =SUMIFS($T79:$CA79, $T$1:$CA$1, CD$63) -> 0 | CE79: =SUMIFS($T79:$CA79, $T$1:$CA$1, CE$63) -> 0 | CF79: =SUMIFS($T79:$CA79, $T$1:$CA$1, CF$63) -> 0 | CG79: =SUMIFS($T79:$CA79, $T$1:$CA$1, CG$63) -> 0 | CI79: =CC79=L79 -> 1 | CJ79: =CD79=M79 -> 1 | CK79: =CE79=N79 -> 1 | CL79: =CF79=O79 -> 1 | CM79: =CG79=P79 -> 1
I80: 0 | J80: 0 | K80: =I80-J80 -> 0 | R80: =IF(K80=P80, "", "Error") | CC80: =SUMIFS($T80:$CA80, $T$1:$CA$1, CC$63) -> 0 | CD80: =SUMIFS($T80:$CA80, $T$1:$CA$1, CD$63) -> 0 | CE80: =SUMIFS($T80:$CA80, $T$1:$CA$1, CE$63) -> 0 | CF80: =SUMIFS($T80:$CA80, $T$1:$CA$1, CF$63) -> 0 | CG80: =SUMIFS($T80:$CA80, $T$1:$CA$1, CG$63) -> 0 | CI80: =CC80=L80 -> 1 | CJ80: =CD80=M80 -> 1 | CK80: =CE80=N80 -> 1 | CL80: =CF80=O80 -> 1 | CM80: =CG80=P80 -> 1
I81: 0 | J81: 0 | K81: =I81-J81 -> 0 | R81: =IF(K81=P81, "", "Error") | CC81: =SUMIFS($T81:$CA81, $T$1:$CA$1, CC$63) -> 0 | CD81: =SUMIFS($T81:$CA81, $T$1:$CA$1, CD$63) -> 0 | CE81: =SUMIFS($T81:$CA81, $T$1:$CA$1, CE$63) -> 0 | CF81: =SUMIFS($T81:$CA81, $T$1:$CA$1, CF$63) -> 0 | CG81: =SUMIFS($T81:$CA81, $T$1:$CA$1, CG$63) -> 0 | CI81: =CC81=L81 -> 1 | CJ81: =CD81=M81 -> 1 | CK81: =CE81=N81 -> 1 | CL81: =CF81=O81 -> 1 | CM81: =CG81=P81 -> 1
I82: 0 | J82: 0 | K82: =I82-J82 -> 0 | R82: =IF(K82=P82, "", "Error") | CC82: =SUMIFS($T82:$CA82, $T$1:$CA$1, CC$63) -> 0 | CD82: =SUMIFS($T82:$CA82, $T$1:$CA$1, CD$63) -> 0 | CE82: =SUMIFS($T82:$CA82, $T$1:$CA$1, CE$63) -> 0 | CF82: =SUMIFS($T82:$CA82, $T$1:$CA$1, CF$63) -> 0 | CG82: =SUMIFS($T82:$CA82, $T$1:$CA$1, CG$63) -> 0 | CI82: =CC82=L82 -> 1 | CJ82: =CD82=M82 -> 1 | CK82: =CE82=N82 -> 1 | CL82: =CF82=O82 -> 1 | CM82: =CG82=P82 -> 1
I83: 0 | J83: 0 | K83: =I83-J83 -> 0 | R83: =IF(K83=P83, "", "Error") | CC83: =SUMIFS($T83:$CA83, $T$1:$CA$1, CC$63) -> 0 | CD83: =SUMIFS($T83:$CA83, $T$1:$CA$1, CD$63) -> 0 | CE83: =SUMIFS($T83:$CA83, $T$1:$CA$1, CE$63) -> 0 | CF83: =SUMIFS($T83:$CA83, $T$1:$CA$1, CF$63) -> 0 | CG83: =SUMIFS($T83:$CA83, $T$1:$CA$1, CG$63) -> 0 | CI83: =CC83=L83 -> 1 | CJ83: =CD83=M83 -> 1 | CK83: =CE83=N83 -> 1 | CL83: =CF83=O83 -> 1 | CM83: =CG83=P83 -> 1
...

Sheet Standard Template
L1: 1 | M1: 2 | N1: 3 | O1: 4 | P1: 5 | R1: =COUNTIFS($R$66:$R$117, "Error") -> 0 | T1: 2026 | U1: 2026 | V1: 2026 | W1: 2026 | X1: 2026 | Y1: 2026 | Z1: 2026 | AA1: 2026 | AB1: 2026 | AC1: 2026 | AD1: 2026 | AE1: 2026 | AF1: 2027 | AG1: 2027 | AH1: 2027 | AI1: 2027 | AJ1: 2027 | AK1: 2027 | AL1: 2027 | AM1: 2027 | AN1: 2027 | AO1: 2027 | AP1: 2027 | AQ1: 2027 | AR1: 2028 | AS1: 2028 | AT1: 2028 | AU1: 2028 | AV1: 2028 | AW1: 2028 | AX1: 2028 | AY1: 2028 | AZ1: 2028 | BA1: 2028 | BB1: 2028 | BC1: 2028 | BD1: 2029 | BE1: 2029 | BF1: 2029 | BG1: 2029 | BH1: 2029 | BI1: 2029 | BJ1: 2029 | BK1: 2029 | BL1: 2029 | BM1: 2029 | BN1: 2029 | BO1: 2029 | BP1: 2030 | BQ1: 2030 | BR1: 2030 | BS1: 2030 | BT1: 2030 | BU1: 2030 | BV1: 2030 | BW1: 2030 | BX1: 2030 | BY1: 2030 | BZ1: 2030 | CA1: 2030 | CI1: =COUNTIFS(CI$66:CI$149, "FALSE") -> 0 | CJ1: =COUNTIFS(CJ$66:CJ$149, "FALSE") -> 0 | CK1: =COUNTIFS(CK$66:CK$149, "FALSE") -> 0 | CL1: =COUNTIFS(CL$66:CL$149, "FALSE") -> 0 | CM1: =COUNTIFS(CM$66:CM$149, "FALSE") -> 0
C2: ="#"&$F$6&" Initiative Business Case" -> # Initiative Business Case
C4: INPUTS & ASSUMPTIONS
D6: Initiative #
D7: Initiative Owner
D8: Initiative Name
D11: Estimated L4 date
D12: Net Recurring Benefit ($M) | F12: =$K$117 -> 0
C14: SECTION I - PRIMARY VALUE DRIVER (ILLUSTRATIVE)
D16: Illustrative example of value driver explanation - please edit fields to reflect value drivers for your Initiative
D17: Baseline | H17: Period | I17: KPI | J17: Inputs
E18: # CW headcount | H18: TTM 6/1/26 | I18: # CW
E19: Average hourly cost for CW | H19: =$H$18 -> TTM 6/1/26 | I19: $USD / # hr
E20: Average utliization hours for CW - annual | H20: =$H$18 -> TTM 6/1/26 | I20: # hr
E21: Total CW spend | H21: =$H$18 -> TTM 6/1/26 | I21: $USD M | J21: =(J18*J19*J20)/1000000 -> 0
D23: Goal
E24: # FTE headcount - lower cost location | H24: FY2026 | I24: # FTE's
E25: Average fully loaded annual cost per FTE - lower cost location | H25: FY2026 | I25: $ / FTE
E26: Total personnel spend for BU | H26: FY2026 | I26: $USD | J26: =(J24*J25)/1000000 -> 0
D28: Incremental Improvement
E29: Total personnel spend for X business unit | I29: $USD | J29: =J21-J26 -> 0
D31: Baseline | H31: Period | I31: $USD M | J31: Inputs
E32: # xxxx | H32: =$H$18 -> TTM 6/1/26 | I32: # xxxx | J32: 0
E33: xxxx unit cost | G33: [A] | H33: FY2025 | I33: $ xxxx | J33: 0
E34: xxxx total spend | G34: [B] | H34: FY2025 | I34: $USD K | J34: =(J32*J33)/1000 -> 0
D36: Goal
E37: # xxxx | H37: FY2025 | I37: # xxxx | J37: =$J$18 -> 0
E38: xxxx unit cost | G38: [C] | H38: FY2026 | I38: $ xxxx | J38: 0
E39: xxxx total spend | G39: [D] | H39: FY2026 | I39: $USD K | J39: =(J37*J38)/1000 -> 0
D41: Incremental Improvement
E42: =E38 -> xxxx unit cost | G42: [A]-[C] | I42: $ / xxxx | J42: =J33-J38 -> 0
E43: =E39 -> xxxx total spend | G43: [B]-[D] | I43: $USD K | J43: =J34-J39 -> 0
D45: Baseline | H45: Period | I45: KPI | J45: Inputs
E46: # xxxx | H46: FY2025 | I46: # xxxx | J46: 0
E47: xxxx unit cost | G47: [A] | H47: FY2025 | I47: $ xxxx | J47: 0
E48: xxxx total spend | G48: [B] | H48: FY2025 | I48: $USD K | J48: =(J46*J47)/1000 -> 0
D50: Goal
E51: # xxxx | H51: FY2025 | I51: # xxxx | J51: =$J$18 -> 0
E52: xxxx unit cost | G52: [C] | H52: FY2026 | I52: $ xxxx | J52: 0
E53: xxxx total spend | G53: [D] | H53: FY2026 | I53: $USD K | J53: =(J51*J52)/1000 -> 0
...
