Workbook

Sheet Summary
A1: Platform Assessment — Summary
A2: Tranche roll-up by capability and sub-capability — counts update automatically from each tab.
A4: How it works:
A5: • Every capability tab has a tracker at the top — click a sub-capability to jump straight to its section; each section links back.
A6: • For each platform pick a State: Target state and Exception rows gray out automatically and drop off the matrix; Non-target rows stay lit.
A7: • Score Imperative to exit and Exit complexity (High / Medium / Low) — the Tranche column computes itself and the matrix bubbles (① + platform name) re-plot live.
A8: • Tranche rules: Low complexity → Tranche 1 · Medium complexity → Tranche 2 · High complexity + High imperative → Tranche 3 · Low imperative (or Medium imperative + High complexity) → no tranche.
A9: • Payment Processing → Gateway is pre-seeded with the slide's illustrative examples — replace them with real data.
A10: • Built for desktop Excel 2016 or later (no macros).
A12: # | B12: Capability | C12: Sub-capability | D12: Platforms listed | E12: Tranche 1 | F12: Tranche 2 | G12: Tranche 3 | H12: Open
A13: 1 | B13: Boarding | C13: Boarding Experience | D13: =COUNTA('Boarding'!$B$14:$B$23) | E13: =COUNTIF('Boarding'!$G$14:$G$23,"Tranche 1") | F13: =COUNTIF('Boarding'!$G$14:$G$23,"Tranche 2") | G13: =COUNTIF('Boarding'!$G$14:$G$23,"Tranche 3") | H13: =HYPERLINK("#'Boarding'!A12","Open →")
A14: 2 | C14: Ingress | D14: =COUNTA('Boarding'!$B$28:$B$37) | E14: =COUNTIF('Boarding'!$G$28:$G$37,"Tranche 1") | F14: =COUNTIF('Boarding'!$G$28:$G$37,"Tranche 2") | G14: =COUNTIF('Boarding'!$G$28:$G$37,"Tranche 3") | H14: =HYPERLINK("#'Boarding'!A26","Open →")
A15: 3 | C15: Boarding Orchestration | D15: =COUNTA('Boarding'!$B$42:$B$51) | E15: =COUNTIF('Boarding'!$G$42:$G$51,"Tranche 1") | F15: =COUNTIF('Boarding'!$G$42:$G$51,"Tranche 2") | G15: =COUNTIF('Boarding'!$G$42:$G$51,"Tranche 3") | H15: =HYPERLINK("#'Boarding'!A40","Open →")
A16: 4 | C16: Integration & Messaging | D16: =COUNTA('Boarding'!$B$56:$B$65) | E16: =COUNTIF('Boarding'!$G$56:$G$65,"Tranche 1") | F16: =COUNTIF('Boarding'!$G$56:$G$65,"Tranche 2") | G16: =COUNTIF('Boarding'!$G$56:$G$65,"Tranche 3") | H16: =HYPERLINK("#'Boarding'!A54","Open →")
A17: 5 | C17: Credit & Underwriting | D17: =COUNTA('Boarding'!$B$70:$B$79) | E17: =COUNTIF('Boarding'!$G$70:$G$79,"Tranche 1") | F17: =COUNTIF('Boarding'!$G$70:$G$79,"Tranche 2") | G17: =COUNTIF('Boarding'!$G$70:$G$79,"Tranche 3") | H17: =HYPERLINK("#'Boarding'!A68","Open →")
A18: 6 | C18: CPQ / Quote-pricing | D18: =COUNTA('Boarding'!$B$84:$B$93) | E18: =COUNTIF('Boarding'!$G$84:$G$93,"Tranche 1") | F18: =COUNTIF('Boarding'!$G$84:$G$93,"Tranche 2") | G18: =COUNTIF('Boarding'!$G$84:$G$93,"Tranche 3") | H18: =HYPERLINK("#'Boarding'!A82","Open →")
A19: 7 | B19: Single-in | C19: Global API | D19: =COUNTA('Single-in'!$B$13:$B$22) | E19: =COUNTIF('Single-in'!$G$13:$G$22,"Tranche 1") | F19: =COUNTIF('Single-in'!$G$13:$G$22,"Tranche 2") | G19: =COUNTIF('Single-in'!$G$13:$G$22,"Tranche 3") | H19: =HYPERLINK("#'Single-in'!A11","Open →")
A20: 8 | C20: Payment Apps & SDKs | D20: =COUNTA('Single-in'!$B$27:$B$36) | E20: =COUNTIF('Single-in'!$G$27:$G$36,"Tranche 1") | F20: =COUNTIF('Single-in'!$G$27:$G$36,"Tranche 2") | G20: =COUNTIF('Single-in'!$G$27:$G$36,"Tranche 3") | H20: =HYPERLINK("#'Single-in'!A25","Open →")
A21: 9 | C21: Developer Experience | D21: =COUNTA('Single-in'!$B$41:$B$50) | E21: =COUNTIF('Single-in'!$G$41:$G$50,"Tranche 1") | F21: =COUNTIF('Single-in'!$G$41:$G$50,"Tranche 2") | G21: =COUNTIF('Single-in'!$G$41:$G$50,"Tranche 3") | H21: =HYPERLINK("#'Single-in'!A39","Open →")
A22: 10 | C22: Hosted Solutions | D22: =COUNTA('Single-in'!$B$55:$B$64) | E22: =COUNTIF('Single-in'!$G$55:$G$64,"Tranche 1") | F22: =COUNTIF('Single-in'!$G$55:$G$64,"Tranche 2") | G22: =COUNTIF('Single-in'!$G$55:$G$64,"Tranche 3") | H22: =HYPERLINK("#'Single-in'!A53","Open →")
A23: 11 | C23: Unified Proposition | D23: =COUNTA('Single-in'!$B$69:$B$78) | E23: =COUNTIF('Single-in'!$G$69:$G$78,"Tranche 1") | F23: =COUNTIF('Single-in'!$G$69:$G$78,"Tranche 2") | G23: =COUNTIF('Single-in'!$G$69:$G$78,"Tranche 3") | H23: =HYPERLINK("#'Single-in'!A67","Open →")
A24: 12 | B24: Sales & Servicing | C24: CRM | D24: =COUNTA('Sales & Servicing'!$B$12:$B$21) | E24: =COUNTIF('Sales & Servicing'!$G$12:$G$21,"Tranche 1") | F24: =COUNTIF('Sales & Servicing'!$G$12:$G$21,"Tranche 2") | G24: =COUNTIF('Sales & Servicing'!$G$12:$G$21,"Tranche 3") | H24: =HYPERLINK("#'Sales & Servicing'!A10","Open →")
A25: 13 | C25: Servicing Tools | D25: =COUNTA('Sales & Servicing'!$B$26:$B$35) | E25: =COUNTIF('Sales & Servicing'!$G$26:$G$35,"Tranche 1") | F25: =COUNTIF('Sales & Servicing'!$G$26:$G$35,"Tranche 2") | G25: =COUNTIF('Sales & Servicing'!$G$26:$G$35,"Tranche 3") | H25: =HYPERLINK("#'Sales & Servicing'!A24","Open →")
A26: 14 | C26: Sales Automation | D26: =COUNTA('Sales & Servicing'!$B$40:$B$49) | E26: =COUNTIF('Sales & Servicing'!$G$40:$G$49,"Tranche 1") | F26: =COUNTIF('Sales & Servicing'!$G$40:$G$49,"Tranche 2") | G26: =COUNTIF('Sales & Servicing'!$G$40:$G$49,"Tranche 3") | H26: =HYPERLINK("#'Sales & Servicing'!A38","Open →")
A27: 15 | C27: Risks | D27: =COUNTA('Sales & Servicing'!$B$54:$B$63) | E27: =COUNTIF('Sales & Servicing'!$G$54:$G$63,"Tranche 1") | F27: =COUNTIF('Sales & Servicing'!$G$54:$G$63,"Tranche 2") | G27: =COUNTIF('Sales & Servicing'!$G$54:$G$63,"Tranche 3") | H27: =HYPERLINK("#'Sales & Servicing'!A52","Open →")
A28: 16 | B28: Payment Processing | C28: Gateway | D28: =COUNTA('Payment Processing'!$B$14:$B$23) | E28: =COUNTIF('Payment Processing'!$G$14:$G$23,"Tranche 1") | F28: =COUNTIF('Payment Processing'!$G$14:$G$23,"Tranche 2") | G28: =COUNTIF('Payment Processing'!$G$14:$G$23,"Tranche 3") | H28: =HYPERLINK("#'Payment Processing'!A12","Open →")
A29: 17 | C29: Switch | D29: =COUNTA('Payment Processing'!$B$28:$B$37) | E29: =COUNTIF('Payment Processing'!$G$28:$G$37,"Tranche 1") | F29: =COUNTIF('Payment Processing'!$G$28:$G$37,"Tranche 2") | G29: =COUNTIF('Payment Processing'!$G$28:$G$37,"Tranche 3") | H29: =HYPERLINK("#'Payment Processing'!A26","Open →")
A30: 18 | C30: Clearing Back-end | D30: =COUNTA('Payment Processing'!$B$42:$B$51) | E30: =COUNTIF('Payment Processing'!$G$42:$G$51,"Tranche 1") | F30: =COUNTIF('Payment Processing'!$G$42:$G$51,"Tranche 2") | G30: =COUNTIF('Payment Processing'!$G$42:$G$51,"Tranche 3") | H30: =HYPERLINK("#'Payment Processing'!A40","Open →")
A31: 19 | C31: Authorization Host | D31: =COUNTA('Payment Processing'!$B$56:$B$65) | E31: =COUNTIF('Payment Processing'!$G$56:$G$65,"Tranche 1") | F31: =COUNTIF('Payment Processing'!$G$56:$G$65,"Tranche 2") | G31: =COUNTIF('Payment Processing'!$G$56:$G$65,"Tranche 3") | H31: =HYPERLINK("#'Payment Processing'!A54","Open →")
A32: 20 | C32: Transaction monitoring | D32: =COUNTA('Payment Processing'!$B$70:$B$79) | E32: =COUNTIF('Payment Processing'!$G$70:$G$79,"Tranche 1") | F32: =COUNTIF('Payment Processing'!$G$70:$G$79,"Tranche 2") | G32: =COUNTIF('Payment Processing'!$G$70:$G$79,"Tranche 3") | H32: =HYPERLINK("#'Payment Processing'!A68","Open →")
A33: 21 | C33: APMs/LPMs | D33: =COUNTA('Payment Processing'!$B$84:$B$93) | E33: =COUNTIF('Payment Processing'!$G$84:$G$93,"Tranche 1") | F33: =COUNTIF('Payment Processing'!$G$84:$G$93,"Tranche 2") | G33: =COUNTIF('Payment Processing'!$G$84:$G$93,"Tranche 3") | H33: =HYPERLINK("#'Payment Processing'!A82","Open →")
A34: 22 | B34: VAS | C34: Routing | D34: =COUNTA('VAS'!$B$17:$B$26) | E34: =COUNTIF('VAS'!$G$17:$G$26,"Tranche 1") | F34: =COUNTIF('VAS'!$G$17:$G$26,"Tranche 2") | G34: =COUNTIF('VAS'!$G$17:$G$26,"Tranche 3") | H34: =HYPERLINK("#'VAS'!A15","Open →")
A35: 23 | C35: Networking Payment Tokens | D35: =COUNTA('VAS'!$B$31:$B$40) | E35: =COUNTIF('VAS'!$G$31:$G$40,"Tranche 1") | F35: =COUNTIF('VAS'!$G$31:$G$40,"Tranche 2") | G35: =COUNTIF('VAS'!$G$31:$G$40,"Tranche 3") | H35: =HYPERLINK("#'VAS'!A29","Open →")
A36: 24 | C36: DCC eDCC | D36: =COUNTA('VAS'!$B$45:$B$54) | E36: =COUNTIF('VAS'!$G$45:$G$54,"Tranche 1") | F36: =COUNTIF('VAS'!$G$45:$G$54,"Tranche 2") | G36: =COUNTIF('VAS'!$G$45:$G$54,"Tranche 3") | H36: =HYPERLINK("#'VAS'!A43","Open →")
A37: 25 | C37: Fraud | D37: =COUNTA('VAS'!$B$59:$B$68) | E37: =COUNTIF('VAS'!$G$59:$G$68,"Tranche 1") | F37: =COUNTIF('VAS'!$G$59:$G$68,"Tranche 2") | G37: =COUNTIF('VAS'!$G$59:$G$68,"Tranche 3") | H37: =HYPERLINK("#'VAS'!A57","Open →")
A38: 26 | C38: Credential Management | D38: =COUNTA('VAS'!$B$73:$B$82) | E38: =COUNTIF('VAS'!$G$73:$G$82,"Tranche 1") | F38: =COUNTIF('VAS'!$G$73:$G$82,"Tranche 2") | G38: =COUNTIF('VAS'!$G$73:$G$82,"Tranche 3") | H38: =HYPERLINK("#'VAS'!A71","Open →")
A39: 27 | C39: Gifts | D39: =COUNTA('VAS'!$B$87:$B$96) | E39: =COUNTIF('VAS'!$G$87:$G$96,"Tranche 1") | F39: =COUNTIF('VAS'!$G$87:$G$96,"Tranche 2") | G39: =COUNTIF('VAS'!$G$87:$G$96,"Tranche 3") | H39: =HYPERLINK("#'VAS'!A85","Open →")
A40: 28 | C40: Managed Optimization | D40: =COUNTA('VAS'!$B$101:$B$110) | E40: =COUNTIF('VAS'!$G$101:$G$110,"Tranche 1") | F40: =COUNTIF('VAS'!$G$101:$G$110,"Tranche 2") | G40: =COUNTIF('VAS'!$G$101:$G$110,"Tranche 3") | H40: =HYPERLINK("#'VAS'!A99","Open →")
A41: 29 | C41: 3DS / exemptions | D41: =COUNTA('VAS'!$B$115:$B$124) | E41: =COUNTIF('VAS'!$G$115:$G$124,"Tranche 1") | F41: =COUNTIF('VAS'!$G$115:$G$124,"Tranche 2") | G41: =COUNTIF('VAS'!$G$115:$G$124,"Tranche 3") | H41: =HYPERLINK("#'VAS'!A113","Open →")
A42: 30 | C42: FX | D42: =COUNTA('VAS'!$B$129:$B$138) | E42: =COUNTIF('VAS'!$G$129:$G$138,"Tranche 1") | F42: =COUNTIF('VAS'!$G$129:$G$138,"Tranche 2") | G42: =COUNTIF('VAS'!$G$129:$G$138,"Tranche 3") | H42: =HYPERLINK("#'VAS'!A127","Open →")
...

Sheet Boarding
A1: Boarding — Platform Assessment
A2: =HYPERLINK("#'Summary'!A1","← Back to Summary") | C2: Pick a State, score High / Medium / Low — the tranche, the matrix and the Summary update automatically.
A4: Tracker — jump to a sub-capability:
A5: 1. | B5: =HYPERLINK("#'Boarding'!A12","Boarding Experience")
A6: 2. | B6: =HYPERLINK("#'Boarding'!A26","Ingress")
A7: 3. | B7: =HYPERLINK("#'Boarding'!A40","Boarding Orchestration")
A8: 4. | B8: =HYPERLINK("#'Boarding'!A54","Integration & Messaging")
A9: 5. | B9: =HYPERLINK("#'Boarding'!A68","Credit & Underwriting")
A10: 6. | B10: =HYPERLINK("#'Boarding'!A82","CPQ / Quote-pricing")
A12: Boarding Experience | G12: =HYPERLINK("#'Boarding'!A4","▲ tracker") | K12: Assessment Outcome
A13: # | B13: Platform | C13: State | D13: Imperative to exit | E13: Exit complexity | F13: Supporting facts | G13: Tranche (auto) | K13: Low | L13: Medium | M13: High
A14: ① | G14: =IF(OR($B14="",$D14="",$E14=""),"",IF(OR($C14="Target state",$C14="Exception"),"Out of scope",IF($D14="Low","No tranche",IF($E14="Low","Tranche 1",IF($E14="Medium","Tranche 2",IF($D14="High","Tranche 3","No tranche")))))) | I14: Benefits | J14: High | K14: ="Tranche 1"&CHAR(10)&_xlfn.TEXTJOIN(CHAR(10),TRUE,O$14:O$23) | L14: ="Tranche 2"&CHAR(10)&_xlfn.TEXTJOIN(CHAR(10),TRUE,P$14:P$23) | M14: ="Tranche 3"&CHAR(10)&_xlfn.TEXTJOIN(CHAR(10),TRUE,Q$14:Q$23) | O14: =IF(AND($B14<>"",$C14<>"Target state",$C14<>"Exception",$D14="High",$E14="Low"),$A14&" "&$B14,"") | P14: =IF(AND($B14<>"",$C14<>"Target state",$C14<>"Exception",$D14="High",$E14="Medium"),$A14&" "&$B14,"") | Q14: =IF(AND($B14<>"",$C14<>"Target state",$C14<>"Exception",$D14="High",$E14="High"),$A14&" "&$B14,"") | R14: =IF(AND($B14<>"",$C14<>"Target state",$C14<>"Exception",$D14="Medium",$E14="Low"),$A14&" "&$B14,"") | S14: =IF(AND($B14<>"",$C14<>"Target state",$C14<>"Exception",$D14="Medium",$E14="Medium"),$A14&" "&$B14,"") | T14: =IF(AND($B14<>"",$C14<>"Target state",$C14<>"Exception",$D14="Medium",$E14="High"),$A14&" "&$B14,"") | U14: =IF(AND($B14<>"",$C14<>"Target state",$C14<>"Exception",$D14="Low",$E14="Low"),$A14&" "&$B14,"") | V14: =IF(AND($B14<>"",$C14<>"Target state",$C14<>"Exception",$D14="Low",$E14="Medium"),$A14&" "&$B14,"") | W14: =IF(AND($B14<>"",$C14<>"Target state",$C14<>"Exception",$D14="Low",$E14="High"),$A14&" "&$B14,"")
A15: ② | G15: =IF(OR($B15="",$D15="",$E15=""),"",IF(OR($C15="Target state",$C15="Exception"),"Out of scope",IF($D15="Low","No tranche",IF($E15="Low","Tranche 1",IF($E15="Medium","Tranche 2",IF($D15="High","Tranche 3","No tranche")))))) | O15: =IF(AND($B15<>"",$C15<>"Target state",$C15<>"Exception",$D15="High",$E15="Low"),$A15&" "&$B15,"") | P15: =IF(AND($B15<>"",$C15<>"Target state",$C15<>"Exception",$D15="High",$E15="Medium"),$A15&" "&$B15,"") | Q15: =IF(AND($B15<>"",$C15<>"Target state",$C15<>"Exception",$D15="High",$E15="High"),$A15&" "&$B15,"") | R15: =IF(AND($B15<>"",$C15<>"Target state",$C15<>"Exception",$D15="Medium",$E15="Low"),$A15&" "&$B15,"") | S15: =IF(AND($B15<>"",$C15<>"Target state",$C15<>"Exception",$D15="Medium",$E15="Medium"),$A15&" "&$B15,"") | T15: =IF(AND($B15<>"",$C15<>"Target state",$C15<>"Exception",$D15="Medium",$E15="High"),$A15&" "&$B15,"") | U15: =IF(AND($B15<>"",$C15<>"Target state",$C15<>"Exception",$D15="Low",$E15="Low"),$A15&" "&$B15,"") | V15: =IF(AND($B15<>"",$C15<>"Target state",$C15<>"Exception",$D15="Low",$E15="Medium"),$A15&" "&$B15,"") | W15: =IF(AND($B15<>"",$C15<>"Target state",$C15<>"Exception",$D15="Low",$E15="High"),$A15&" "&$B15,"")
A16: ③ | G16: =IF(OR($B16="",$D16="",$E16=""),"",IF(OR($C16="Target state",$C16="Exception"),"Out of scope",IF($D16="Low","No tranche",IF($E16="Low","Tranche 1",IF($E16="Medium","Tranche 2",IF($D16="High","Tranche 3","No tranche")))))) | O16: =IF(AND($B16<>"",$C16<>"Target state",$C16<>"Exception",$D16="High",$E16="Low"),$A16&" "&$B16,"") | P16: =IF(AND($B16<>"",$C16<>"Target state",$C16<>"Exception",$D16="High",$E16="Medium"),$A16&" "&$B16,"") | Q16: =IF(AND($B16<>"",$C16<>"Target state",$C16<>"Exception",$D16="High",$E16="High"),$A16&" "&$B16,"") | R16: =IF(AND($B16<>"",$C16<>"Target state",$C16<>"Exception",$D16="Medium",$E16="Low"),$A16&" "&$B16,"") | S16: =IF(AND($B16<>"",$C16<>"Target state",$C16<>"Exception",$D16="Medium",$E16="Medium"),$A16&" "&$B16,"") | T16: =IF(AND($B16<>"",$C16<>"Target state",$C16<>"Exception",$D16="Medium",$E16="High"),$A16&" "&$B16,"") | U16: =IF(AND($B16<>"",$C16<>"Target state",$C16<>"Exception",$D16="Low",$E16="Low"),$A16&" "&$B16,"") | V16: =IF(AND($B16<>"",$C16<>"Target state",$C16<>"Exception",$D16="Low",$E16="Medium"),$A16&" "&$B16,"") | W16: =IF(AND($B16<>"",$C16<>"Target state",$C16<>"Exception",$D16="Low",$E16="High"),$A16&" "&$B16,"")
A17: ④ | G17: =IF(OR($B17="",$D17="",$E17=""),"",IF(OR($C17="Target state",$C17="Exception"),"Out of scope",IF($D17="Low","No tranche",IF($E17="Low","Tranche 1",IF($E17="Medium","Tranche 2",IF($D17="High","Tranche 3","No tranche")))))) | J17: Medium | K17: ="Tranche 1"&CHAR(10)&_xlfn.TEXTJOIN(CHAR(10),TRUE,R$14:R$23) | L17: ="Tranche 2"&CHAR(10)&_xlfn.TEXTJOIN(CHAR(10),TRUE,S$14:S$23) | M17: =_xlfn.TEXTJOIN(CHAR(10),TRUE,T$14:T$23) | O17: =IF(AND($B17<>"",$C17<>"Target state",$C17<>"Exception",$D17="High",$E17="Low"),$A17&" "&$B17,"") | P17: =IF(AND($B17<>"",$C17<>"Target state",$C17<>"Exception",$D17="High",$E17="Medium"),$A17&" "&$B17,"") | Q17: =IF(AND($B17<>"",$C17<>"Target state",$C17<>"Exception",$D17="High",$E17="High"),$A17&" "&$B17,"") | R17: =IF(AND($B17<>"",$C17<>"Target state",$C17<>"Exception",$D17="Medium",$E17="Low"),$A17&" "&$B17,"") | S17: =IF(AND($B17<>"",$C17<>"Target state",$C17<>"Exception",$D17="Medium",$E17="Medium"),$A17&" "&$B17,"") | T17: =IF(AND($B17<>"",$C17<>"Target state",$C17<>"Exception",$D17="Medium",$E17="High"),$A17&" "&$B17,"") | U17: =IF(AND($B17<>"",$C17<>"Target state",$C17<>"Exception",$D17="Low",$E17="Low"),$A17&" "&$B17,"") | V17: =IF(AND($B17<>"",$C17<>"Target state",$C17<>"Exception",$D17="Low",$E17="Medium"),$A17&" "&$B17,"") | W17: =IF(AND($B17<>"",$C17<>"Target state",$C17<>"Exception",$D17="Low",$E17="High"),$A17&" "&$B17,"")
A18: ⑤ | G18: =IF(OR($B18="",$D18="",$E18=""),"",IF(OR($C18="Target state",$C18="Exception"),"Out of scope",IF($D18="Low","No tranche",IF($E18="Low","Tranche 1",IF($E18="Medium","Tranche 2",IF($D18="High","Tranche 3","No tranche")))))) | O18: =IF(AND($B18<>"",$C18<>"Target state",$C18<>"Exception",$D18="High",$E18="Low"),$A18&" "&$B18,"") | P18: =IF(AND($B18<>"",$C18<>"Target state",$C18<>"Exception",$D18="High",$E18="Medium"),$A18&" "&$B18,"") | Q18: =IF(AND($B18<>"",$C18<>"Target state",$C18<>"Exception",$D18="High",$E18="High"),$A18&" "&$B18,"") | R18: =IF(AND($B18<>"",$C18<>"Target state",$C18<>"Exception",$D18="Medium",$E18="Low"),$A18&" "&$B18,"") | S18: =IF(AND($B18<>"",$C18<>"Target state",$C18<>"Exception",$D18="Medium",$E18="Medium"),$A18&" "&$B18,"") | T18: =IF(AND($B18<>"",$C18<>"Target state",$C18<>"Exception",$D18="Medium",$E18="High"),$A18&" "&$B18,"") | U18: =IF(AND($B18<>"",$C18<>"Target state",$C18<>"Exception",$D18="Low",$E18="Low"),$A18&" "&$B18,"") | V18: =IF(AND($B18<>"",$C18<>"Target state",$C18<>"Exception",$D18="Low",$E18="Medium"),$A18&" "&$B18,"") | W18: =IF(AND($B18<>"",$C18<>"Target state",$C18<>"Exception",$D18="Low",$E18="High"),$A18&" "&$B18,"")
A19: ⑥ | G19: =IF(OR($B19="",$D19="",$E19=""),"",IF(OR($C19="Target state",$C19="Exception"),"Out of scope",IF($D19="Low","No tranche",IF($E19="Low","Tranche 1",IF($E19="Medium","Tranche 2",IF($D19="High","Tranche 3","No tranche")))))) | O19: =IF(AND($B19<>"",$C19<>"Target state",$C19<>"Exception",$D19="High",$E19="Low"),$A19&" "&$B19,"") | P19: =IF(AND($B19<>"",$C19<>"Target state",$C19<>"Exception",$D19="High",$E19="Medium"),$A19&" "&$B19,"") | Q19: =IF(AND($B19<>"",$C19<>"Target state",$C19<>"Exception",$D19="High",$E19="High"),$A19&" "&$B19,"") | R19: =IF(AND($B19<>"",$C19<>"Target state",$C19<>"Exception",$D19="Medium",$E19="Low"),$A19&" "&$B19,"") | S19: =IF(AND($B19<>"",$C19<>"Target state",$C19<>"Exception",$D19="Medium",$E19="Medium"),$A19&" "&$B19,"") | T19: =IF(AND($B19<>"",$C19<>"Target state",$C19<>"Exception",$D19="Medium",$E19="High"),$A19&" "&$B19,"") | U19: =IF(AND($B19<>"",$C19<>"Target state",$C19<>"Exception",$D19="Low",$E19="Low"),$A19&" "&$B19,"") | V19: =IF(AND($B19<>"",$C19<>"Target state",$C19<>"Exception",$D19="Low",$E19="Medium"),$A19&" "&$B19,"") | W19: =IF(AND($B19<>"",$C19<>"Target state",$C19<>"Exception",$D19="Low",$E19="High"),$A19&" "&$B19,"")
A20: ⑦ | G20: =IF(OR($B20="",$D20="",$E20=""),"",IF(OR($C20="Target state",$C20="Exception"),"Out of scope",IF($D20="Low","No tranche",IF($E20="Low","Tranche 1",IF($E20="Medium","Tranche 2",IF($D20="High","Tranche 3","No tranche")))))) | J20: Low | K20: =_xlfn.TEXTJOIN(CHAR(10),TRUE,U$14:U$23) | L20: =_xlfn.TEXTJOIN(CHAR(10),TRUE,V$14:V$23) | M20: =_xlfn.TEXTJOIN(CHAR(10),TRUE,W$14:W$23) | O20: =IF(AND($B20<>"",$C20<>"Target state",$C20<>"Exception",$D20="High",$E20="Low"),$A20&" "&$B20,"") | P20: =IF(AND($B20<>"",$C20<>"Target state",$C20<>"Exception",$D20="High",$E20="Medium"),$A20&" "&$B20,"") | Q20: =IF(AND($B20<>"",$C20<>"Target state",$C20<>"Exception",$D20="High",$E20="High"),$A20&" "&$B20,"") | R20: =IF(AND($B20<>"",$C20<>"Target state",$C20<>"Exception",$D20="Medium",$E20="Low"),$A20&" "&$B20,"") | S20: =IF(AND($B20<>"",$C20<>"Target state",$C20<>"Exception",$D20="Medium",$E20="Medium"),$A20&" "&$B20,"") | T20: =IF(AND($B20<>"",$C20<>"Target state",$C20<>"Exception",$D20="Medium",$E20="High"),$A20&" "&$B20,"") | U20: =IF(AND($B20<>"",$C20<>"Target state",$C20<>"Exception",$D20="Low",$E20="Low"),$A20&" "&$B20,"") | V20: =IF(AND($B20<>"",$C20<>"Target state",$C20<>"Exception",$D20="Low",$E20="Medium"),$A20&" "&$B20,"") | W20: =IF(AND($B20<>"",$C20<>"Target state",$C20<>"Exception",$D20="Low",$E20="High"),$A20&" "&$B20,"")
A21: ⑧ | G21: =IF(OR($B21="",$D21="",$E21=""),"",IF(OR($C21="Target state",$C21="Exception"),"Out of scope",IF($D21="Low","No tranche",IF($E21="Low","Tranche 1",IF($E21="Medium","Tranche 2",IF($D21="High","Tranche 3","No tranche")))))) | O21: =IF(AND($B21<>"",$C21<>"Target state",$C21<>"Exception",$D21="High",$E21="Low"),$A21&" "&$B21,"") | P21: =IF(AND($B21<>"",$C21<>"Target state",$C21<>"Exception",$D21="High",$E21="Medium"),$A21&" "&$B21,"") | Q21: =IF(AND($B21<>"",$C21<>"Target state",$C21<>"Exception",$D21="High",$E21="High"),$A21&" "&$B21,"") | R21: =IF(AND($B21<>"",$C21<>"Target state",$C21<>"Exception",$D21="Medium",$E21="Low"),$A21&" "&$B21,"") | S21: =IF(AND($B21<>"",$C21<>"Target state",$C21<>"Exception",$D21="Medium",$E21="Medium"),$A21&" "&$B21,"") | T21: =IF(AND($B21<>"",$C21<>"Target state",$C21<>"Exception",$D21="Medium",$E21="High"),$A21&" "&$B21,"") | U21: =IF(AND($B21<>"",$C21<>"Target state",$C21<>"Exception",$D21="Low",$E21="Low"),$A21&" "&$B21,"") | V21: =IF(AND($B21<>"",$C21<>"Target state",$C21<>"Exception",$D21="Low",$E21="Medium"),$A21&" "&$B21,"") | W21: =IF(AND($B21<>"",$C21<>"Target state",$C21<>"Exception",$D21="Low",$E21="High"),$A21&" "&$B21,"")
A22: ⑨ | G22: =IF(OR($B22="",$D22="",$E22=""),"",IF(OR($C22="Target state",$C22="Exception"),"Out of scope",IF($D22="Low","No tranche",IF($E22="Low","Tranche 1",IF($E22="Medium","Tranche 2",IF($D22="High","Tranche 3","No tranche")))))) | O22: =IF(AND($B22<>"",$C22<>"Target state",$C22<>"Exception",$D22="High",$E22="Low"),$A22&" "&$B22,"") | P22: =IF(AND($B22<>"",$C22<>"Target state",$C22<>"Exception",$D22="High",$E22="Medium"),$A22&" "&$B22,"") | Q22: =IF(AND($B22<>"",$C22<>"Target state",$C22<>"Exception",$D22="High",$E22="High"),$A22&" "&$B22,"") | R22: =IF(AND($B22<>"",$C22<>"Target state",$C22<>"Exception",$D22="Medium",$E22="Low"),$A22&" "&$B22,"") | S22: =IF(AND($B22<>"",$C22<>"Target state",$C22<>"Exception",$D22="Medium",$E22="Medium"),$A22&" "&$B22,"") | T22: =IF(AND($B22<>"",$C22<>"Target state",$C22<>"Exception",$D22="Medium",$E22="High"),$A22&" "&$B22,"") | U22: =IF(AND($B22<>"",$C22<>"Target state",$C22<>"Exception",$D22="Low",$E22="Low"),$A22&" "&$B22,"") | V22: =IF(AND($B22<>"",$C22<>"Target state",$C22<>"Exception",$D22="Low",$E22="Medium"),$A22&" "&$B22,"") | W22: =IF(AND($B22<>"",$C22<>"Target state",$C22<>"Exception",$D22="Low",$E22="High"),$A22&" "&$B22,"")
A23: ⑩ | G23: =IF(OR($B23="",$D23="",$E23=""),"",IF(OR($C23="Target state",$C23="Exception"),"Out of scope",IF($D23="Low","No tranche",IF($E23="Low","Tranche 1",IF($E23="Medium","Tranche 2",IF($D23="High","Tranche 3","No tranche")))))) | K23: Complexity | O23: =IF(AND($B23<>"",$C23<>"Target state",$C23<>"Exception",$D23="High",$E23="Low"),$A23&" "&$B23,"") | P23: =IF(AND($B23<>"",$C23<>"Target state",$C23<>"Exception",$D23="High",$E23="Medium"),$A23&" "&$B23,"") | Q23: =IF(AND($B23<>"",$C23<>"Target state",$C23<>"Exception",$D23="High",$E23="High"),$A23&" "&$B23,"") | R23: =IF(AND($B23<>"",$C23<>"Target state",$C23<>"Exception",$D23="Medium",$E23="Low"),$A23&" "&$B23,"") | S23: =IF(AND($B23<>"",$C23<>"Target state",$C23<>"Exception",$D23="Medium",$E23="Medium"),$A23&" "&$B23,"") | T23: =IF(AND($B23<>"",$C23<>"Target state",$C23<>"Exception",$D23="Medium",$E23="High"),$A23&" "&$B23,"") | U23: =IF(AND($B23<>"",$C23<>"Target state",$C23<>"Exception",$D23="Low",$E23="Low"),$A23&" "&$B23,"") | V23: =IF(AND($B23<>"",$C23<>"Target state",$C23<>"Exception",$D23="Low",$E23="Medium"),$A23&" "&$B23,"") | W23: =IF(AND($B23<>"",$C23<>"Target state",$C23<>"Exception",$D23="Low",$E23="High"),$A23&" "&$B23,"")
A26: Ingress | G26: =HYPERLINK("#'Boarding'!A4","▲ tracker") | K26: Assessment Outcome
A27: # | B27: Platform | C27: State | D27: Imperative to exit | E27: Exit complexity | F27: Supporting facts | G27: Tranche (auto) | K27: Low | L27: Medium | M27: High
A28: ① | G28: =IF(OR($B28="",$D28="",$E28=""),"",IF(OR($C28="Target state",$C28="Exception"),"Out of scope",IF($D28="Low","No tranche",IF($E28="Low","Tranche 1",IF($E28="Medium","Tranche 2",IF($D28="High","Tranche 3","No tranche")))))) | I28: Benefits | J28: High | K28: ="Tranche 1"&CHAR(10)&_xlfn.TEXTJOIN(CHAR(10),TRUE,O$28:O$37) | L28: ="Tranche 2"&CHAR(10)&_xlfn.TEXTJOIN(CHAR(10),TRUE,P$28:P$37) | M28: ="Tranche 3"&CHAR(10)&_xlfn.TEXTJOIN(CHAR(10),TRUE,Q$28:Q$37) | O28: =IF(AND($B28<>"",$C28<>"Target state",$C28<>"Exception",$D28="High",$E28="Low"),$A28&" "&$B28,"") | P28: =IF(AND($B28<>"",$C28<>"Target state",$C28<>"Exception",$D28="High",$E28="Medium"),$A28&" "&$B28,"") | Q28: =IF(AND($B28<>"",$C28<>"Target state",$C28<>"Exception",$D28="High",$E28="High"),$A28&" "&$B28,"") | R28: =IF(AND($B28<>"",$C28<>"Target state",$C28<>"Exception",$D28="Medium",$E28="Low"),$A28&" "&$B28,"") | S28: =IF(AND($B28<>"",$C28<>"Target state",$C28<>"Exception",$D28="Medium",$E28="Medium"),$A28&" "&$B28,"") | T28: =IF(AND($B28<>"",$C28<>"Target state",$C28<>"Exception",$D28="Medium",$E28="High"),$A28&" "&$B28,"") | U28: =IF(AND($B28<>"",$C28<>"Target state",$C28<>"Exception",$D28="Low",$E28="Low"),$A28&" "&$B28,"") | V28: =IF(AND($B28<>"",$C28<>"Target state",$C28<>"Exception",$D28="Low",$E28="Medium"),$A28&" "&$B28,"") | W28: =IF(AND($B28<>"",$C28<>"Target state",$C28<>"Exception",$D28="Low",$E28="High"),$A28&" "&$B28,"")
A29: ② | G29: =IF(OR($B29="",$D29="",$E29=""),"",IF(OR($C29="Target state",$C29="Exception"),"Out of scope",IF($D29="Low","No tranche",IF($E29="Low","Tranche 1",IF($E29="Medium","Tranche 2",IF($D29="High","Tranche 3","No tranche")))))) | O29: =IF(AND($B29<>"",$C29<>"Target state",$C29<>"Exception",$D29="High",$E29="Low"),$A29&" "&$B29,"") | P29: =IF(AND($B29<>"",$C29<>"Target state",$C29<>"Exception",$D29="High",$E29="Medium"),$A29&" "&$B29,"") | Q29: =IF(AND($B29<>"",$C29<>"Target state",$C29<>"Exception",$D29="High",$E29="High"),$A29&" "&$B29,"") | R29: =IF(AND($B29<>"",$C29<>"Target state",$C29<>"Exception",$D29="Medium",$E29="Low"),$A29&" "&$B29,"") | S29: =IF(AND($B29<>"",$C29<>"Target state",$C29<>"Exception",$D29="Medium",$E29="Medium"),$A29&" "&$B29,"") | T29: =IF(AND($B29<>"",$C29<>"Target state",$C29<>"Exception",$D29="Medium",$E29="High"),$A29&" "&$B29,"") | U29: =IF(AND($B29<>"",$C29<>"Target state",$C29<>"Exception",$D29="Low",$E29="Low"),$A29&" "&$B29,"") | V29: =IF(AND($B29<>"",$C29<>"Target state",$C29<>"Exception",$D29="Low",$E29="Medium"),$A29&" "&$B29,"") | W29: =IF(AND($B29<>"",$C29<>"Target state",$C29<>"Exception",$D29="Low",$E29="High"),$A29&" "&$B29,"")
A30: ③ | G30: =IF(OR($B30="",$D30="",$E30=""),"",IF(OR($C30="Target state",$C30="Exception"),"Out of scope",IF($D30="Low","No tranche",IF($E30="Low","Tranche 1",IF($E30="Medium","Tranche 2",IF($D30="High","Tranche 3","No tranche")))))) | O30: =IF(AND($B30<>"",$C30<>"Target state",$C30<>"Exception",$D30="High",$E30="Low"),$A30&" "&$B30,"") | P30: =IF(AND($B30<>"",$C30<>"Target state",$C30<>"Exception",$D30="High",$E30="Medium"),$A30&" "&$B30,"") | Q30: =IF(AND($B30<>"",$C30<>"Target state",$C30<>"Exception",$D30="High",$E30="High"),$A30&" "&$B30,"") | R30: =IF(AND($B30<>"",$C30<>"Target state",$C30<>"Exception",$D30="Medium",$E30="Low"),$A30&" "&$B30,"") | S30: =IF(AND($B30<>"",$C30<>"Target state",$C30<>"Exception",$D30="Medium",$E30="Medium"),$A30&" "&$B30,"") | T30: =IF(AND($B30<>"",$C30<>"Target state",$C30<>"Exception",$D30="Medium",$E30="High"),$A30&" "&$B30,"") | U30: =IF(AND($B30<>"",$C30<>"Target state",$C30<>"Exception",$D30="Low",$E30="Low"),$A30&" "&$B30,"") | V30: =IF(AND($B30<>"",$C30<>"Target state",$C30<>"Exception",$D30="Low",$E30="Medium"),$A30&" "&$B30,"") | W30: =IF(AND($B30<>"",$C30<>"Target state",$C30<>"Exception",$D30="Low",$E30="High"),$A30&" "&$B30,"")
A31: ④ | G31: =IF(OR($B31="",$D31="",$E31=""),"",IF(OR($C31="Target state",$C31="Exception"),"Out of scope",IF($D31="Low","No tranche",IF($E31="Low","Tranche 1",IF($E31="Medium","Tranche 2",IF($D31="High","Tranche 3","No tranche")))))) | J31: Medium | K31: ="Tranche 1"&CHAR(10)&_xlfn.TEXTJOIN(CHAR(10),TRUE,R$28:R$37) | L31: ="Tranche 2"&CHAR(10)&_xlfn.TEXTJOIN(CHAR(10),TRUE,S$28:S$37) | M31: =_xlfn.TEXTJOIN(CHAR(10),TRUE,T$28:T$37) | O31: =IF(AND($B31<>"",$C31<>"Target state",$C31<>"Exception",$D31="High",$E31="Low"),$A31&" "&$B31,"") | P31: =IF(AND($B31<>"",$C31<>"Target state",$C31<>"Exception",$D31="High",$E31="Medium"),$A31&" "&$B31,"") | Q31: =IF(AND($B31<>"",$C31<>"Target state",$C31<>"Exception",$D31="High",$E31="High"),$A31&" "&$B31,"") | R31: =IF(AND($B31<>"",$C31<>"Target state",$C31<>"Exception",$D31="Medium",$E31="Low"),$A31&" "&$B31,"") | S31: =IF(AND($B31<>"",$C31<>"Target state",$C31<>"Exception",$D31="Medium",$E31="Medium"),$A31&" "&$B31,"") | T31: =IF(AND($B31<>"",$C31<>"Target state",$C31<>"Exception",$D31="Medium",$E31="High"),$A31&" "&$B31,"") | U31: =IF(AND($B31<>"",$C31<>"Target state",$C31<>"Exception",$D31="Low",$E31="Low"),$A31&" "&$B31,"") | V31: =IF(AND($B31<>"",$C31<>"Target state",$C31<>"Exception",$D31="Low",$E31="Medium"),$A31&" "&$B31,"") | W31: =IF(AND($B31<>"",$C31<>"Target state",$C31<>"Exception",$D31="Low",$E31="High"),$A31&" "&$B31,"")
A32: ⑤ | G32: =IF(OR($B32="",$D32="",$E32=""),"",IF(OR($C32="Target state",$C32="Exception"),"Out of scope",IF($D32="Low","No tranche",IF($E32="Low","Tranche 1",IF($E32="Medium","Tranche 2",IF($D32="High","Tranche 3","No tranche")))))) | O32: =IF(AND($B32<>"",$C32<>"Target state",$C32<>"Exception",$D32="High",$E32="Low"),$A32&" "&$B32,"") | P32: =IF(AND($B32<>"",$C32<>"Target state",$C32<>"Exception",$D32="High",$E32="Medium"),$A32&" "&$B32,"") | Q32: =IF(AND($B32<>"",$C32<>"Target state",$C32<>"Exception",$D32="High",$E32="High"),$A32&" "&$B32,"") | R32: =IF(AND($B32<>"",$C32<>"Target state",$C32<>"Exception",$D32="Medium",$E32="Low"),$A32&" "&$B32,"") | S32: =IF(AND($B32<>"",$C32<>"Target state",$C32<>"Exception",$D32="Medium",$E32="Medium"),$A32&" "&$B32,"") | T32: =IF(AND($B32<>"",$C32<>"Target state",$C32<>"Exception",$D32="Medium",$E32="High"),$A32&" "&$B32,"") | U32: =IF(AND($B32<>"",$C32<>"Target state",$C32<>"Exception",$D32="Low",$E32="Low"),$A32&" "&$B32,"") | V32: =IF(AND($B32<>"",$C32<>"Target state",$C32<>"Exception",$D32="Low",$E32="Medium"),$A32&" "&$B32,"") | W32: =IF(AND($B32<>"",$C32<>"Target state",$C32<>"Exception",$D32="Low",$E32="High"),$A32&" "&$B32,"")
A33: ⑥ | G33: =IF(OR($B33="",$D33="",$E33=""),"",IF(OR($C33="Target state",$C33="Exception"),"Out of scope",IF($D33="Low","No tranche",IF($E33="Low","Tranche 1",IF($E33="Medium","Tranche 2",IF($D33="High","Tranche 3","No tranche")))))) | O33: =IF(AND($B33<>"",$C33<>"Target state",$C33<>"Exception",$D33="High",$E33="Low"),$A33&" "&$B33,"") | P33: =IF(AND($B33<>"",$C33<>"Target state",$C33<>"Exception",$D33="High",$E33="Medium"),$A33&" "&$B33,"") | Q33: =IF(AND($B33<>"",$C33<>"Target state",$C33<>"Exception",$D33="High",$E33="High"),$A33&" "&$B33,"") | R33: =IF(AND($B33<>"",$C33<>"Target state",$C33<>"Exception",$D33="Medium",$E33="Low"),$A33&" "&$B33,"") | S33: =IF(AND($B33<>"",$C33<>"Target state",$C33<>"Exception",$D33="Medium",$E33="Medium"),$A33&" "&$B33,"") | T33: =IF(AND($B33<>"",$C33<>"Target state",$C33<>"Exception",$D33="Medium",$E33="High"),$A33&" "&$B33,"") | U33: =IF(AND($B33<>"",$C33<>"Target state",$C33<>"Exception",$D33="Low",$E33="Low"),$A33&" "&$B33,"") | V33: =IF(AND($B33<>"",$C33<>"Target state",$C33<>"Exception",$D33="Low",$E33="Medium"),$A33&" "&$B33,"") | W33: =IF(AND($B33<>"",$C33<>"Target state",$C33<>"Exception",$D33="Low",$E33="High"),$A33&" "&$B33,"")
A34: ⑦ | G34: =IF(OR($B34="",$D34="",$E34=""),"",IF(OR($C34="Target state",$C34="Exception"),"Out of scope",IF($D34="Low","No tranche",IF($E34="Low","Tranche 1",IF($E34="Medium","Tranche 2",IF($D34="High","Tranche 3","No tranche")))))) | J34: Low | K34: =_xlfn.TEXTJOIN(CHAR(10),TRUE,U$28:U$37) | L34: =_xlfn.TEXTJOIN(CHAR(10),TRUE,V$28:V$37) | M34: =_xlfn.TEXTJOIN(CHAR(10),TRUE,W$28:W$37) | O34: =IF(AND($B34<>"",$C34<>"Target state",$C34<>"Exception",$D34="High",$E34="Low"),$A34&" "&$B34,"") | P34: =IF(AND($B34<>"",$C34<>"Target state",$C34<>"Exception",$D34="High",$E34="Medium"),$A34&" "&$B34,"") | Q34: =IF(AND($B34<>"",$C34<>"Target state",$C34<>"Exception",$D34="High",$E34="High"),$A34&" "&$B34,"") | R34: =IF(AND($B34<>"",$C34<>"Target state",$C34<>"Exception",$D34="Medium",$E34="Low"),$A34&" "&$B34,"") | S34: =IF(AND($B34<>"",$C34<>"Target state",$C34<>"Exception",$D34="Medium",$E34="Medium"),$A34&" "&$B34,"") | T34: =IF(AND($B34<>"",$C34<>"Target state",$C34<>"Exception",$D34="Medium",$E34="High"),$A34&" "&$B34,"") | U34: =IF(AND($B34<>"",$C34<>"Target state",$C34<>"Exception",$D34="Low",$E34="Low"),$A34&" "&$B34,"") | V34: =IF(AND($B34<>"",$C34<>"Target state",$C34<>"Exception",$D34="Low",$E34="Medium"),$A34&" "&$B34,"") | W34: =IF(AND($B34<>"",$C34<>"Target state",$C34<>"Exception",$D34="Low",$E34="High"),$A34&" "&$B34,"")
A35: ⑧ | G35: =IF(OR($B35="",$D35="",$E35=""),"",IF(OR($C35="Target state",$C35="Exception"),"Out of scope",IF($D35="Low","No tranche",IF($E35="Low","Tranche 1",IF($E35="Medium","Tranche 2",IF($D35="High","Tranche 3","No tranche")))))) | O35: =IF(AND($B35<>"",$C35<>"Target state",$C35<>"Exception",$D35="High",$E35="Low"),$A35&" "&$B35,"") | P35: =IF(AND($B35<>"",$C35<>"Target state",$C35<>"Exception",$D35="High",$E35="Medium"),$A35&" "&$B35,"") | Q35: =IF(AND($B35<>"",$C35<>"Target state",$C35<>"Exception",$D35="High",$E35="High"),$A35&" "&$B35,"") | R35: =IF(AND($B35<>"",$C35<>"Target state",$C35<>"Exception",$D35="Medium",$E35="Low"),$A35&" "&$B35,"") | S35: =IF(AND($B35<>"",$C35<>"Target state",$C35<>"Exception",$D35="Medium",$E35="Medium"),$A35&" "&$B35,"") | T35: =IF(AND($B35<>"",$C35<>"Target state",$C35<>"Exception",$D35="Medium",$E35="High"),$A35&" "&$B35,"") | U35: =IF(AND($B35<>"",$C35<>"Target state",$C35<>"Exception",$D35="Low",$E35="Low"),$A35&" "&$B35,"") | V35: =IF(AND($B35<>"",$C35<>"Target state",$C35<>"Exception",$D35="Low",$E35="Medium"),$A35&" "&$B35,"") | W35: =IF(AND($B35<>"",$C35<>"Target state",$C35<>"Exception",$D35="Low",$E35="High"),$A35&" "&$B35,"")
A36: ⑨ | G36: =IF(OR($B36="",$D36="",$E36=""),"",IF(OR($C36="Target state",$C36="Exception"),"Out of scope",IF($D36="Low","No tranche",IF($E36="Low","Tranche 1",IF($E36="Medium","Tranche 2",IF($D36="High","Tranche 3","No tranche")))))) | O36: =IF(AND($B36<>"",$C36<>"Target state",$C36<>"Exception",$D36="High",$E36="Low"),$A36&" "&$B36,"") | P36: =IF(AND($B36<>"",$C36<>"Target state",$C36<>"Exception",$D36="High",$E36="Medium"),$A36&" "&$B36,"") | Q36: =IF(AND($B36<>"",$C36<>"Target state",$C36<>"Exception",$D36="High",$E36="High"),$A36&" "&$B36,"") | R36: =IF(AND($B36<>"",$C36<>"Target state",$C36<>"Exception",$D36="Medium",$E36="Low"),$A36&" "&$B36,"") | S36: =IF(AND($B36<>"",$C36<>"Target state",$C36<>"Exception",$D36="Medium",$E36="Medium"),$A36&" "&$B36,"") | T36: =IF(AND($B36<>"",$C36<>"Target state",$C36<>"Exception",$D36="Medium",$E36="High"),$A36&" "&$B36,"") | U36: =IF(AND($B36<>"",$C36<>"Target state",$C36<>"Exception",$D36="Low",$E36="Low"),$A36&" "&$B36,"") | V36: =IF(AND($B36<>"",$C36<>"Target state",$C36<>"Exception",$D36="Low",$E36="Medium"),$A36&" "&$B36,"") | W36: =IF(AND($B36<>"",$C36<>"Target state",$C36<>"Exception",$D36="Low",$E36="High"),$A36&" "&$B36,"")
A37: ⑩ | G37: =IF(OR($B37="",$D37="",$E37=""),"",IF(OR($C37="Target state",$C37="Exception"),"Out of scope",IF($D37="Low","No tranche",IF($E37="Low","Tranche 1",IF($E37="Medium","Tranche 2",IF($D37="High","Tranche 3","No tranche")))))) | K37: Complexity | O37: =IF(AND($B37<>"",$C37<>"Target state",$C37<>"Exception",$D37="High",$E37="Low"),$A37&" "&$B37,"") | P37: =IF(AND($B37<>"",$C37<>"Target state",$C37<>"Exception",$D37="High",$E37="Medium"),$A37&" "&$B37,"") | Q37: =IF(AND($B37<>"",$C37<>"Target state",$C37<>"Exception",$D37="High",$E37="High"),$A37&" "&$B37,"") | R37: =IF(AND($B37<>"",$C37<>"Target state",$C37<>"Exception",$D37="Medium",$E37="Low"),$A37&" "&$B37,"") | S37: =IF(AND($B37<>"",$C37<>"Target state",$C37<>"Exception",$D37="Medium",$E37="Medium"),$A37&" "&$B37,"") | T37: =IF(AND($B37<>"",$C37<>"Target state",$C37<>"Exception",$D37="Medium",$E37="High"),$A37&" "&$B37,"") | U37: =IF(AND($B37<>"",$C37<>"Target state",$C37<>"Exception",$D37="Low",$E37="Low"),$A37&" "&$B37,"") | V37: =IF(AND($B37<>"",$C37<>"Target state",$C37<>"Exception",$D37="Low",$E37="Medium"),$A37&" "&$B37,"") | W37: =IF(AND($B37<>"",$C37<>"Target state",$C37<>"Exception",$D37="Low",$E37="High"),$A37&" "&$B37,"")
A40: Boarding Orchestration | G40: =HYPERLINK("#'Boarding'!A4","▲ tracker") | K40: Assessment Outcome
A41: # | B41: Platform | C41: State | D41: Imperative to exit | E41: Exit complexity | F41: Supporting facts | G41: Tranche (auto) | K41: Low | L41: Medium | M41: High
A42: ① | G42: =IF(OR($B42="",$D42="",$E42=""),"",IF(OR($C42="Target state",$C42="Exception"),"Out of scope",IF($D42="Low","No tranche",IF($E42="Low","Tranche 1",IF($E42="Medium","Tranche 2",IF($D42="High","Tranche 3","No tranche")))))) | I42: Benefits | J42: High | K42: ="Tranche 1"&CHAR(10)&_xlfn.TEXTJOIN(CHAR(10),TRUE,O$42:O$51) | L42: ="Tranche 2"&CHAR(10)&_xlfn.TEXTJOIN(CHAR(10),TRUE,P$42:P$51) | M42: ="Tranche 3"&CHAR(10)&_xlfn.TEXTJOIN(CHAR(10),TRUE,Q$42:Q$51) | O42: =IF(AND($B42<>"",$C42<>"Target state",$C42<>"Exception",$D42="High",$E42="Low"),$A42&" "&$B42,"") | P42: =IF(AND($B42<>"",$C42<>"Target state",$C42<>"Exception",$D42="High",$E42="Medium"),$A42&" "&$B42,"") | Q42: =IF(AND($B42<>"",$C42<>"Target state",$C42<>"Exception",$D42="High",$E42="High"),$A42&" "&$B42,"") | R42: =IF(AND($B42<>"",$C42<>"Target state",$C42<>"Exception",$D42="Medium",$E42="Low"),$A42&" "&$B42,"") | S42: =IF(AND($B42<>"",$C42<>"Target state",$C42<>"Exception",$D42="Medium",$E42="Medium"),$A42&" "&$B42,"") | T42: =IF(AND($B42<>"",$C42<>"Target state",$C42<>"Exception",$D42="Medium",$E42="High"),$A42&" "&$B42,"") | U42: =IF(AND($B42<>"",$C42<>"Target state",$C42<>"Exception",$D42="Low",$E42="Low"),$A42&" "&$B42,"") | V42: =IF(AND($B42<>"",$C42<>"Target state",$C42<>"Exception",$D42="Low",$E42="Medium"),$A42&" "&$B42,"") | W42: =IF(AND($B42<>"",$C42<>"Target state",$C42<>"Exception",$D42="Low",$E42="High"),$A42&" "&$B42,"")
A43: ② | G43: =IF(OR($B43="",$D43="",$E43=""),"",IF(OR($C43="Target state",$C43="Exception"),"Out of scope",IF($D43="Low","No tranche",IF($E43="Low","Tranche 1",IF($E43="Medium","Tranche 2",IF($D43="High","Tranche 3","No tranche")))))) | O43: =IF(AND($B43<>"",$C43<>"Target state",$C43<>"Exception",$D43="High",$E43="Low"),$A43&" "&$B43,"") | P43: =IF(AND($B43<>"",$C43<>"Target state",$C43<>"Exception",$D43="High",$E43="Medium"),$A43&" "&$B43,"") | Q43: =IF(AND($B43<>"",$C43<>"Target state",$C43<>"Exception",$D43="High",$E43="High"),$A43&" "&$B43,"") | R43: =IF(AND($B43<>"",$C43<>"Target state",$C43<>"Exception",$D43="Medium",$E43="Low"),$A43&" "&$B43,"") | S43: =IF(AND($B43<>"",$C43<>"Target state",$C43<>"Exception",$D43="Medium",$E43="Medium"),$A43&" "&$B43,"") | T43: =IF(AND($B43<>"",$C43<>"Target state",$C43<>"Exception",$D43="Medium",$E43="High"),$A43&" "&$B43,"") | U43: =IF(AND($B43<>"",$C43<>"Target state",$C43<>"Exception",$D43="Low",$E43="Low"),$A43&" "&$B43,"") | V43: =IF(AND($B43<>"",$C43<>"Target state",$C43<>"Exception",$D43="Low",$E43="Medium"),$A43&" "&$B43,"") | W43: =IF(AND($B43<>"",$C43<>"Target state",$C43<>"Exception",$D43="Low",$E43="High"),$A43&" "&$B43,"")
A44: ③ | G44: =IF(OR($B44="",$D44="",$E44=""),"",IF(OR($C44="Target state",$C44="Exception"),"Out of scope",IF($D44="Low","No tranche",IF($E44="Low","Tranche 1",IF($E44="Medium","Tranche 2",IF($D44="High","Tranche 3","No tranche")))))) | O44: =IF(AND($B44<>"",$C44<>"Target state",$C44<>"Exception",$D44="High",$E44="Low"),$A44&" "&$B44,"") | P44: =IF(AND($B44<>"",$C44<>"Target state",$C44<>"Exception",$D44="High",$E44="Medium"),$A44&" "&$B44,"") | Q44: =IF(AND($B44<>"",$C44<>"Target state",$C44<>"Exception",$D44="High",$E44="High"),$A44&" "&$B44,"") | R44: =IF(AND($B44<>"",$C44<>"Target state",$C44<>"Exception",$D44="Medium",$E44="Low"),$A44&" "&$B44,"") | S44: =IF(AND($B44<>"",$C44<>"Target state",$C44<>"Exception",$D44="Medium",$E44="Medium"),$A44&" "&$B44,"") | T44: =IF(AND($B44<>"",$C44<>"Target state",$C44<>"Exception",$D44="Medium",$E44="High"),$A44&" "&$B44,"") | U44: =IF(AND($B44<>"",$C44<>"Target state",$C44<>"Exception",$D44="Low",$E44="Low"),$A44&" "&$B44,"") | V44: =IF(AND($B44<>"",$C44<>"Target state",$C44<>"Exception",$D44="Low",$E44="Medium"),$A44&" "&$B44,"") | W44: =IF(AND($B44<>"",$C44<>"Target state",$C44<>"Exception",$D44="Low",$E44="High"),$A44&" "&$B44,"")
A45: ④ | G45: =IF(OR($B45="",$D45="",$E45=""),"",IF(OR($C45="Target state",$C45="Exception"),"Out of scope",IF($D45="Low","No tranche",IF($E45="Low","Tranche 1",IF($E45="Medium","Tranche 2",IF($D45="High","Tranche 3","No tranche")))))) | J45: Medium | K45: ="Tranche 1"&CHAR(10)&_xlfn.TEXTJOIN(CHAR(10),TRUE,R$42:R$51) | L45: ="Tranche 2"&CHAR(10)&_xlfn.TEXTJOIN(CHAR(10),TRUE,S$42:S$51) | M45: =_xlfn.TEXTJOIN(CHAR(10),TRUE,T$42:T$51) | O45: =IF(AND($B45<>"",$C45<>"Target state",$C45<>"Exception",$D45="High",$E45="Low"),$A45&" "&$B45,"") | P45: =IF(AND($B45<>"",$C45<>"Target state",$C45<>"Exception",$D45="High",$E45="Medium"),$A45&" "&$B45,"") | Q45: =IF(AND($B45<>"",$C45<>"Target state",$C45<>"Exception",$D45="High",$E45="High"),$A45&" "&$B45,"") | R45: =IF(AND($B45<>"",$C45<>"Target state",$C45<>"Exception",$D45="Medium",$E45="Low"),$A45&" "&$B45,"") | S45: =IF(AND($B45<>"",$C45<>"Target state",$C45<>"Exception",$D45="Medium",$E45="Medium"),$A45&" "&$B45,"") | T45: =IF(AND($B45<>"",$C45<>"Target state",$C45<>"Exception",$D45="Medium",$E45="High"),$A45&" "&$B45,"") | U45: =IF(AND($B45<>"",$C45<>"Target state",$C45<>"Exception",$D45="Low",$E45="Low"),$A45&" "&$B45,"") | V45: =IF(AND($B45<>"",$C45<>"Target state",$C45<>"Exception",$D45="Low",$E45="Medium"),$A45&" "&$B45,"") | W45: =IF(AND($B45<>"",$C45<>"Target state",$C45<>"Exception",$D45="Low",$E45="High"),$A45&" "&$B45,"")
A46: ⑤ | G46: =IF(OR($B46="",$D46="",$E46=""),"",IF(OR($C46="Target state",$C46="Exception"),"Out of scope",IF($D46="Low","No tranche",IF($E46="Low","Tranche 1",IF($E46="Medium","Tranche 2",IF($D46="High","Tranche 3","No tranche")))))) | O46: =IF(AND($B46<>"",$C46<>"Target state",$C46<>"Exception",$D46="High",$E46="Low"),$A46&" "&$B46,"") | P46: =IF(AND($B46<>"",$C46<>"Target state",$C46<>"Exception",$D46="High",$E46="Medium"),$A46&" "&$B46,"") | Q46: =IF(AND($B46<>"",$C46<>"Target state",$C46<>"Exception",$D46="High",$E46="High"),$A46&" "&$B46,"") | R46: =IF(AND($B46<>"",$C46<>"Target state",$C46<>"Exception",$D46="Medium",$E46="Low"),$A46&" "&$B46,"") | S46: =IF(AND($B46<>"",$C46<>"Target state",$C46<>"Exception",$D46="Medium",$E46="Medium"),$A46&" "&$B46,"") | T46: =IF(AND($B46<>"",$C46<>"Target state",$C46<>"Exception",$D46="Medium",$E46="High"),$A46&" "&$B46,"") | U46: =IF(AND($B46<>"",$C46<>"Target state",$C46<>"Exception",$D46="Low",$E46="Low"),$A46&" "&$B46,"") | V46: =IF(AND($B46<>"",$C46<>"Target state",$C46<>"Exception",$D46="Low",$E46="Medium"),$A46&" "&$B46,"") | W46: =IF(AND($B46<>"",$C46<>"Target state",$C46<>"Exception",$D46="Low",$E46="High"),$A46&" "&$B46,"")
...

Sheet Single-in
A1: Single-in — Platform Assessment
A2: =HYPERLINK("#'Summary'!A1","← Back to Summary") | C2: Pick a State, score High / Medium / Low — the tranche, the matrix and the Summary update automatically.
A4: Tracker — jump to a sub-capability:
A5: 1. | B5: =HYPERLINK("#'Single-in'!A11","Global API")
A6: 2. | B6: =HYPERLINK("#'Single-in'!A25","Payment Apps & SDKs")
A7: 3. | B7: =HYPERLINK("#'Single-in'!A39","Developer Experience")
A8: 4. | B8: =HYPERLINK("#'Single-in'!A53","Hosted Solutions")
A9: 5. | B9: =HYPERLINK("#'Single-in'!A67","Unified Proposition")
A11: Global API | G11: =HYPERLINK("#'Single-in'!A4","▲ tracker") | K11: Assessment Outcome
A12: # | B12: Platform | C12: State | D12: Imperative to exit | E12: Exit complexity | F12: Supporting facts | G12: Tranche (auto) | K12: Low | L12: Medium | M12: High
A13: ① | G13: =IF(OR($B13="",$D13="",$E13=""),"",IF(OR($C13="Target state",$C13="Exception"),"Out of scope",IF($D13="Low","No tranche",IF($E13="Low","Tranche 1",IF($E13="Medium","Tranche 2",IF($D13="High","Tranche 3","No tranche")))))) | I13: Benefits | J13: High | K13: ="Tranche 1"&CHAR(10)&_xlfn.TEXTJOIN(CHAR(10),TRUE,O$13:O$22) | L13: ="Tranche 2"&CHAR(10)&_xlfn.TEXTJOIN(CHAR(10),TRUE,P$13:P$22) | M13: ="Tranche 3"&CHAR(10)&_xlfn.TEXTJOIN(CHAR(10),TRUE,Q$13:Q$22) | O13: =IF(AND($B13<>"",$C13<>"Target state",$C13<>"Exception",$D13="High",$E13="Low"),$A13&" "&$B13,"") | P13: =IF(AND($B13<>"",$C13<>"Target state",$C13<>"Exception",$D13="High",$E13="Medium"),$A13&" "&$B13,"") | Q13: =IF(AND($B13<>"",$C13<>"Target state",$C13<>"Exception",$D13="High",$E13="High"),$A13&" "&$B13,"") | R13: =IF(AND($B13<>"",$C13<>"Target state",$C13<>"Exception",$D13="Medium",$E13="Low"),$A13&" "&$B13,"") | S13: =IF(AND($B13<>"",$C13<>"Target state",$C13<>"Exception",$D13="Medium",$E13="Medium"),$A13&" "&$B13,"") | T13: =IF(AND($B13<>"",$C13<>"Target state",$C13<>"Exception",$D13="Medium",$E13="High"),$A13&" "&$B13,"") | U13: =IF(AND($B13<>"",$C13<>"Target state",$C13<>"Exception",$D13="Low",$E13="Low"),$A13&" "&$B13,"") | V13: =IF(AND($B13<>"",$C13<>"Target state",$C13<>"Exception",$D13="Low",$E13="Medium"),$A13&" "&$B13,"") | W13: =IF(AND($B13<>"",$C13<>"Target state",$C13<>"Exception",$D13="Low",$E13="High"),$A13&" "&$B13,"")
A14: ② | G14: =IF(OR($B14="",$D14="",$E14=""),"",IF(OR($C14="Target state",$C14="Exception"),"Out of scope",IF($D14="Low","No tranche",IF($E14="Low","Tranche 1",IF($E14="Medium","Tranche 2",IF($D14="High","Tranche 3","No tranche")))))) | O14: =IF(AND($B14<>"",$C14<>"Target state",$C14<>"Exception",$D14="High",$E14="Low"),$A14&" "&$B14,"") | P14: =IF(AND($B14<>"",$C14<>"Target state",$C14<>"Exception",$D14="High",$E14="Medium"),$A14&" "&$B14,"") | Q14: =IF(AND($B14<>"",$C14<>"Target state",$C14<>"Exception",$D14="High",$E14="High"),$A14&" "&$B14,"") | R14: =IF(AND($B14<>"",$C14<>"Target state",$C14<>"Exception",$D14="Medium",$E14="Low"),$A14&" "&$B14,"") | S14: =IF(AND($B14<>"",$C14<>"Target state",$C14<>"Exception",$D14="Medium",$E14="Medium"),$A14&" "&$B14,"") | T14: =IF(AND($B14<>"",$C14<>"Target state",$C14<>"Exception",$D14="Medium",$E14="High"),$A14&" "&$B14,"") | U14: =IF(AND($B14<>"",$C14<>"Target state",$C14<>"Exception",$D14="Low",$E14="Low"),$A14&" "&$B14,"") | V14: =IF(AND($B14<>"",$C14<>"Target state",$C14<>"Exception",$D14="Low",$E14="Medium"),$A14&" "&$B14,"") | W14: =IF(AND($B14<>"",$C14<>"Target state",$C14<>"Exception",$D14="Low",$E14="High"),$A14&" "&$B14,"")
A15: ③ | G15: =IF(OR($B15="",$D15="",$E15=""),"",IF(OR($C15="Target state",$C15="Exception"),"Out of scope",IF($D15="Low","No tranche",IF($E15="Low","Tranche 1",IF($E15="Medium","Tranche 2",IF($D15="High","Tranche 3","No tranche")))))) | O15: =IF(AND($B15<>"",$C15<>"Target state",$C15<>"Exception",$D15="High",$E15="Low"),$A15&" "&$B15,"") | P15: =IF(AND($B15<>"",$C15<>"Target state",$C15<>"Exception",$D15="High",$E15="Medium"),$A15&" "&$B15,"") | Q15: =IF(AND($B15<>"",$C15<>"Target state",$C15<>"Exception",$D15="High",$E15="High"),$A15&" "&$B15,"") | R15: =IF(AND($B15<>"",$C15<>"Target state",$C15<>"Exception",$D15="Medium",$E15="Low"),$A15&" "&$B15,"") | S15: =IF(AND($B15<>"",$C15<>"Target state",$C15<>"Exception",$D15="Medium",$E15="Medium"),$A15&" "&$B15,"") | T15: =IF(AND($B15<>"",$C15<>"Target state",$C15<>"Exception",$D15="Medium",$E15="High"),$A15&" "&$B15,"") | U15: =IF(AND($B15<>"",$C15<>"Target state",$C15<>"Exception",$D15="Low",$E15="Low"),$A15&" "&$B15,"") | V15: =IF(AND($B15<>"",$C15<>"Target state",$C15<>"Exception",$D15="Low",$E15="Medium"),$A15&" "&$B15,"") | W15: =IF(AND($B15<>"",$C15<>"Target state",$C15<>"Exception",$D15="Low",$E15="High"),$A15&" "&$B15,"")
A16: ④ | G16: =IF(OR($B16="",$D16="",$E16=""),"",IF(OR($C16="Target state",$C16="Exception"),"Out of scope",IF($D16="Low","No tranche",IF($E16="Low","Tranche 1",IF($E16="Medium","Tranche 2",IF($D16="High","Tranche 3","No tranche")))))) | J16: Medium | K16: ="Tranche 1"&CHAR(10)&_xlfn.TEXTJOIN(CHAR(10),TRUE,R$13:R$22) | L16: ="Tranche 2"&CHAR(10)&_xlfn.TEXTJOIN(CHAR(10),TRUE,S$13:S$22) | M16: =_xlfn.TEXTJOIN(CHAR(10),TRUE,T$13:T$22) | O16: =IF(AND($B16<>"",$C16<>"Target state",$C16<>"Exception",$D16="High",$E16="Low"),$A16&" "&$B16,"") | P16: =IF(AND($B16<>"",$C16<>"Target state",$C16<>"Exception",$D16="High",$E16="Medium"),$A16&" "&$B16,"") | Q16: =IF(AND($B16<>"",$C16<>"Target state",$C16<>"Exception",$D16="High",$E16="High"),$A16&" "&$B16,"") | R16: =IF(AND($B16<>"",$C16<>"Target state",$C16<>"Exception",$D16="Medium",$E16="Low"),$A16&" "&$B16,"") | S16: =IF(AND($B16<>"",$C16<>"Target state",$C16<>"Exception",$D16="Medium",$E16="Medium"),$A16&" "&$B16,"") | T16: =IF(AND($B16<>"",$C16<>"Target state",$C16<>"Exception",$D16="Medium",$E16="High"),$A16&" "&$B16,"") | U16: =IF(AND($B16<>"",$C16<>"Target state",$C16<>"Exception",$D16="Low",$E16="Low"),$A16&" "&$B16,"") | V16: =IF(AND($B16<>"",$C16<>"Target state",$C16<>"Exception",$D16="Low",$E16="Medium"),$A16&" "&$B16,"") | W16: =IF(AND($B16<>"",$C16<>"Target state",$C16<>"Exception",$D16="Low",$E16="High"),$A16&" "&$B16,"")
A17: ⑤ | G17: =IF(OR($B17="",$D17="",$E17=""),"",IF(OR($C17="Target state",$C17="Exception"),"Out of scope",IF($D17="Low","No tranche",IF($E17="Low","Tranche 1",IF($E17="Medium","Tranche 2",IF($D17="High","Tranche 3","No tranche")))))) | O17: =IF(AND($B17<>"",$C17<>"Target state",$C17<>"Exception",$D17="High",$E17="Low"),$A17&" "&$B17,"") | P17: =IF(AND($B17<>"",$C17<>"Target state",$C17<>"Exception",$D17="High",$E17="Medium"),$A17&" "&$B17,"") | Q17: =IF(AND($B17<>"",$C17<>"Target state",$C17<>"Exception",$D17="High",$E17="High"),$A17&" "&$B17,"") | R17: =IF(AND($B17<>"",$C17<>"Target state",$C17<>"Exception",$D17="Medium",$E17="Low"),$A17&" "&$B17,"") | S17: =IF(AND($B17<>"",$C17<>"Target state",$C17<>"Exception",$D17="Medium",$E17="Medium"),$A17&" "&$B17,"") | T17: =IF(AND($B17<>"",$C17<>"Target state",$C17<>"Exception",$D17="Medium",$E17="High"),$A17&" "&$B17,"") | U17: =IF(AND($B17<>"",$C17<>"Target state",$C17<>"Exception",$D17="Low",$E17="Low"),$A17&" "&$B17,"") | V17: =IF(AND($B17<>"",$C17<>"Target state",$C17<>"Exception",$D17="Low",$E17="Medium"),$A17&" "&$B17,"") | W17: =IF(AND($B17<>"",$C17<>"Target state",$C17<>"Exception",$D17="Low",$E17="High"),$A17&" "&$B17,"")
A18: ⑥ | G18: =IF(OR($B18="",$D18="",$E18=""),"",IF(OR($C18="Target state",$C18="Exception"),"Out of scope",IF($D18="Low","No tranche",IF($E18="Low","Tranche 1",IF($E18="Medium","Tranche 2",IF($D18="High","Tranche 3","No tranche")))))) | O18: =IF(AND($B18<>"",$C18<>"Target state",$C18<>"Exception",$D18="High",$E18="Low"),$A18&" "&$B18,"") | P18: =IF(AND($B18<>"",$C18<>"Target state",$C18<>"Exception",$D18="High",$E18="Medium"),$A18&" "&$B18,"") | Q18: =IF(AND($B18<>"",$C18<>"Target state",$C18<>"Exception",$D18="High",$E18="High"),$A18&" "&$B18,"") | R18: =IF(AND($B18<>"",$C18<>"Target state",$C18<>"Exception",$D18="Medium",$E18="Low"),$A18&" "&$B18,"") | S18: =IF(AND($B18<>"",$C18<>"Target state",$C18<>"Exception",$D18="Medium",$E18="Medium"),$A18&" "&$B18,"") | T18: =IF(AND($B18<>"",$C18<>"Target state",$C18<>"Exception",$D18="Medium",$E18="High"),$A18&" "&$B18,"") | U18: =IF(AND($B18<>"",$C18<>"Target state",$C18<>"Exception",$D18="Low",$E18="Low"),$A18&" "&$B18,"") | V18: =IF(AND($B18<>"",$C18<>"Target state",$C18<>"Exception",$D18="Low",$E18="Medium"),$A18&" "&$B18,"") | W18: =IF(AND($B18<>"",$C18<>"Target state",$C18<>"Exception",$D18="Low",$E18="High"),$A18&" "&$B18,"")
A19: ⑦ | G19: =IF(OR($B19="",$D19="",$E19=""),"",IF(OR($C19="Target state",$C19="Exception"),"Out of scope",IF($D19="Low","No tranche",IF($E19="Low","Tranche 1",IF($E19="Medium","Tranche 2",IF($D19="High","Tranche 3","No tranche")))))) | J19: Low | K19: =_xlfn.TEXTJOIN(CHAR(10),TRUE,U$13:U$22) | L19: =_xlfn.TEXTJOIN(CHAR(10),TRUE,V$13:V$22) | M19: =_xlfn.TEXTJOIN(CHAR(10),TRUE,W$13:W$22) | O19: =IF(AND($B19<>"",$C19<>"Target state",$C19<>"Exception",$D19="High",$E19="Low"),$A19&" "&$B19,"") | P19: =IF(AND($B19<>"",$C19<>"Target state",$C19<>"Exception",$D19="High",$E19="Medium"),$A19&" "&$B19,"") | Q19: =IF(AND($B19<>"",$C19<>"Target state",$C19<>"Exception",$D19="High",$E19="High"),$A19&" "&$B19,"") | R19: =IF(AND($B19<>"",$C19<>"Target state",$C19<>"Exception",$D19="Medium",$E19="Low"),$A19&" "&$B19,"") | S19: =IF(AND($B19<>"",$C19<>"Target state",$C19<>"Exception",$D19="Medium",$E19="Medium"),$A19&" "&$B19,"") | T19: =IF(AND($B19<>"",$C19<>"Target state",$C19<>"Exception",$D19="Medium",$E19="High"),$A19&" "&$B19,"") | U19: =IF(AND($B19<>"",$C19<>"Target state",$C19<>"Exception",$D19="Low",$E19="Low"),$A19&" "&$B19,"") | V19: =IF(AND($B19<>"",$C19<>"Target state",$C19<>"Exception",$D19="Low",$E19="Medium"),$A19&" "&$B19,"") | W19: =IF(AND($B19<>"",$C19<>"Target state",$C19<>"Exception",$D19="Low",$E19="High"),$A19&" "&$B19,"")
A20: ⑧ | G20: =IF(OR($B20="",$D20="",$E20=""),"",IF(OR($C20="Target state",$C20="Exception"),"Out of scope",IF($D20="Low","No tranche",IF($E20="Low","Tranche 1",IF($E20="Medium","Tranche 2",IF($D20="High","Tranche 3","No tranche")))))) | O20: =IF(AND($B20<>"",$C20<>"Target state",$C20<>"Exception",$D20="High",$E20="Low"),$A20&" "&$B20,"") | P20: =IF(AND($B20<>"",$C20<>"Target state",$C20<>"Exception",$D20="High",$E20="Medium"),$A20&" "&$B20,"") | Q20: =IF(AND($B20<>"",$C20<>"Target state",$C20<>"Exception",$D20="High",$E20="High"),$A20&" "&$B20,"") | R20: =IF(AND($B20<>"",$C20<>"Target state",$C20<>"Exception",$D20="Medium",$E20="Low"),$A20&" "&$B20,"") | S20: =IF(AND($B20<>"",$C20<>"Target state",$C20<>"Exception",$D20="Medium",$E20="Medium"),$A20&" "&$B20,"") | T20: =IF(AND($B20<>"",$C20<>"Target state",$C20<>"Exception",$D20="Medium",$E20="High"),$A20&" "&$B20,"") | U20: =IF(AND($B20<>"",$C20<>"Target state",$C20<>"Exception",$D20="Low",$E20="Low"),$A20&" "&$B20,"") | V20: =IF(AND($B20<>"",$C20<>"Target state",$C20<>"Exception",$D20="Low",$E20="Medium"),$A20&" "&$B20,"") | W20: =IF(AND($B20<>"",$C20<>"Target state",$C20<>"Exception",$D20="Low",$E20="High"),$A20&" "&$B20,"")
A21: ⑨ | G21: =IF(OR($B21="",$D21="",$E21=""),"",IF(OR($C21="Target state",$C21="Exception"),"Out of scope",IF($D21="Low","No tranche",IF($E21="Low","Tranche 1",IF($E21="Medium","Tranche 2",IF($D21="High","Tranche 3","No tranche")))))) | O21: =IF(AND($B21<>"",$C21<>"Target state",$C21<>"Exception",$D21="High",$E21="Low"),$A21&" "&$B21,"") | P21: =IF(AND($B21<>"",$C21<>"Target state",$C21<>"Exception",$D21="High",$E21="Medium"),$A21&" "&$B21,"") | Q21: =IF(AND($B21<>"",$C21<>"Target state",$C21<>"Exception",$D21="High",$E21="High"),$A21&" "&$B21,"") | R21: =IF(AND($B21<>"",$C21<>"Target state",$C21<>"Exception",$D21="Medium",$E21="Low"),$A21&" "&$B21,"") | S21: =IF(AND($B21<>"",$C21<>"Target state",$C21<>"Exception",$D21="Medium",$E21="Medium"),$A21&" "&$B21,"") | T21: =IF(AND($B21<>"",$C21<>"Target state",$C21<>"Exception",$D21="Medium",$E21="High"),$A21&" "&$B21,"") | U21: =IF(AND($B21<>"",$C21<>"Target state",$C21<>"Exception",$D21="Low",$E21="Low"),$A21&" "&$B21,"") | V21: =IF(AND($B21<>"",$C21<>"Target state",$C21<>"Exception",$D21="Low",$E21="Medium"),$A21&" "&$B21,"") | W21: =IF(AND($B21<>"",$C21<>"Target state",$C21<>"Exception",$D21="Low",$E21="High"),$A21&" "&$B21,"")
A22: ⑩ | G22: =IF(OR($B22="",$D22="",$E22=""),"",IF(OR($C22="Target state",$C22="Exception"),"Out of scope",IF($D22="Low","No tranche",IF($E22="Low","Tranche 1",IF($E22="Medium","Tranche 2",IF($D22="High","Tranche 3","No tranche")))))) | K22: Complexity | O22: =IF(AND($B22<>"",$C22<>"Target state",$C22<>"Exception",$D22="High",$E22="Low"),$A22&" "&$B22,"") | P22: =IF(AND($B22<>"",$C22<>"Target state",$C22<>"Exception",$D22="High",$E22="Medium"),$A22&" "&$B22,"") | Q22: =IF(AND($B22<>"",$C22<>"Target state",$C22<>"Exception",$D22="High",$E22="High"),$A22&" "&$B22,"") | R22: =IF(AND($B22<>"",$C22<>"Target state",$C22<>"Exception",$D22="Medium",$E22="Low"),$A22&" "&$B22,"") | S22: =IF(AND($B22<>"",$C22<>"Target state",$C22<>"Exception",$D22="Medium",$E22="Medium"),$A22&" "&$B22,"") | T22: =IF(AND($B22<>"",$C22<>"Target state",$C22<>"Exception",$D22="Medium",$E22="High"),$A22&" "&$B22,"") | U22: =IF(AND($B22<>"",$C22<>"Target state",$C22<>"Exception",$D22="Low",$E22="Low"),$A22&" "&$B22,"") | V22: =IF(AND($B22<>"",$C22<>"Target state",$C22<>"Exception",$D22="Low",$E22="Medium"),$A22&" "&$B22,"") | W22: =IF(AND($B22<>"",$C22<>"Target state",$C22<>"Exception",$D22="Low",$E22="High"),$A22&" "&$B22,"")
A25: Payment Apps & SDKs | G25: =HYPERLINK("#'Single-in'!A4","▲ tracker") | K25: Assessment Outcome
A26: # | B26: Platform | C26: State | D26: Imperative to exit | E26: Exit complexity | F26: Supporting facts | G26: Tranche (auto) | K26: Low | L26: Medium | M26: High
A27: ① | G27: =IF(OR($B27="",$D27="",$E27=""),"",IF(OR($C27="Target state",$C27="Exception"),"Out of scope",IF($D27="Low","No tranche",IF($E27="Low","Tranche 1",IF($E27="Medium","Tranche 2",IF($D27="High","Tranche 3","No tranche")))))) | I27: Benefits | J27: High | K27: ="Tranche 1"&CHAR(10)&_xlfn.TEXTJOIN(CHAR(10),TRUE,O$27:O$36) | L27: ="Tranche 2"&CHAR(10)&_xlfn.TEXTJOIN(CHAR(10),TRUE,P$27:P$36) | M27: ="Tranche 3"&CHAR(10)&_xlfn.TEXTJOIN(CHAR(10),TRUE,Q$27:Q$36) | O27: =IF(AND($B27<>"",$C27<>"Target state",$C27<>"Exception",$D27="High",$E27="Low"),$A27&" "&$B27,"") | P27: =IF(AND($B27<>"",$C27<>"Target state",$C27<>"Exception",$D27="High",$E27="Medium"),$A27&" "&$B27,"") | Q27: =IF(AND($B27<>"",$C27<>"Target state",$C27<>"Exception",$D27="High",$E27="High"),$A27&" "&$B27,"") | R27: =IF(AND($B27<>"",$C27<>"Target state",$C27<>"Exception",$D27="Medium",$E27="Low"),$A27&" "&$B27,"") | S27: =IF(AND($B27<>"",$C27<>"Target state",$C27<>"Exception",$D27="Medium",$E27="Medium"),$A27&" "&$B27,"") | T27: =IF(AND($B27<>"",$C27<>"Target state",$C27<>"Exception",$D27="Medium",$E27="High"),$A27&" "&$B27,"") | U27: =IF(AND($B27<>"",$C27<>"Target state",$C27<>"Exception",$D27="Low",$E27="Low"),$A27&" "&$B27,"") | V27: =IF(AND($B27<>"",$C27<>"Target state",$C27<>"Exception",$D27="Low",$E27="Medium"),$A27&" "&$B27,"") | W27: =IF(AND($B27<>"",$C27<>"Target state",$C27<>"Exception",$D27="Low",$E27="High"),$A27&" "&$B27,"")
A28: ② | G28: =IF(OR($B28="",$D28="",$E28=""),"",IF(OR($C28="Target state",$C28="Exception"),"Out of scope",IF($D28="Low","No tranche",IF($E28="Low","Tranche 1",IF($E28="Medium","Tranche 2",IF($D28="High","Tranche 3","No tranche")))))) | O28: =IF(AND($B28<>"",$C28<>"Target state",$C28<>"Exception",$D28="High",$E28="Low"),$A28&" "&$B28,"") | P28: =IF(AND($B28<>"",$C28<>"Target state",$C28<>"Exception",$D28="High",$E28="Medium"),$A28&" "&$B28,"") | Q28: =IF(AND($B28<>"",$C28<>"Target state",$C28<>"Exception",$D28="High",$E28="High"),$A28&" "&$B28,"") | R28: =IF(AND($B28<>"",$C28<>"Target state",$C28<>"Exception",$D28="Medium",$E28="Low"),$A28&" "&$B28,"") | S28: =IF(AND($B28<>"",$C28<>"Target state",$C28<>"Exception",$D28="Medium",$E28="Medium"),$A28&" "&$B28,"") | T28: =IF(AND($B28<>"",$C28<>"Target state",$C28<>"Exception",$D28="Medium",$E28="High"),$A28&" "&$B28,"") | U28: =IF(AND($B28<>"",$C28<>"Target state",$C28<>"Exception",$D28="Low",$E28="Low"),$A28&" "&$B28,"") | V28: =IF(AND($B28<>"",$C28<>"Target state",$C28<>"Exception",$D28="Low",$E28="Medium"),$A28&" "&$B28,"") | W28: =IF(AND($B28<>"",$C28<>"Target state",$C28<>"Exception",$D28="Low",$E28="High"),$A28&" "&$B28,"")
