Workbook

Sheet Instructions
B1: Instructions
B3: Purpose and functionality of the workbook
B4: This workbook is designed to classify each TAM 2.0 non-target platform into 3 tranches based on imperative to exit and exit complexity
B6: Context
B29: Worksheet specific notes
B31: Summary sheet
B32: • One row per capability / sub-capability with the relevant SPOCs, the number of platforms listed, and live counts of platforms in Tranche 1, 2, and 3
B33: • Counts update automatically as the capability tabs are filled in; use the Open → links to jump straight to your section, and the tracker at the top of each tab to navigate within it
B34: Capability sheets (one tab per capability, one section per sub-capability)
B35: • List all current-state platforms in your domain
B36: • Set the State for each platform: Target state and Exceptions are not classified into tranches
B37: • For each non-target platform in your domain, classify the imperative to exit / benefits and exit complexity as High / Medium / Low
... B41: Note: Aim to be directionally correct not precise

Sheet Summary
A1: Platform Assessment — Summary
A2: Tranche roll-up by capability and sub-capability — counts update automatically from each tab.
A4: # | B4: Capability | C4: Sub-capability | D4: SPOCs | E4: Platforms listed | F4: Tranche 1 | G4: Tranche 2 | H4: Tranche 3 | I4: Link
A5: 1 | B5: Boarding | C5: Boarding Experience | D5: • Alan Johnson • Lindsay Guthmiller • Fredrick Mjema • David Pritchett | E5: =COUNTA('Boarding'!$B$14:$B$39) | F5: =COUNTIF('Boarding'!$G$14:$G$39,"Tranche 1") | G5: =COUNTIF('Boarding'!$G$14:$G$39,"Tranche 2") | H5: =COUNTIF('Boarding'!$G$14:$G$39,"Tranche 3") | I5: =HYPERLINK("#'Boarding'!A12","Open →")
A6: 2 | C6: Ingress | D6: • Alan Johnson • Fredrick Mjema • Vivek Pujeri • Patrick Bateman • Rebecca Fishel • Bradley Bossenbroek | E6: =COUNTA('Boarding'!$B$46:$B$55) | F6: =COUNTIF('Boarding'!$G$46:$G$55,"Tranche 1") | G6: =COUNTIF('Boarding'!$G$46:$G$55,"Tranche 2") | H6: =COUNTIF('Boarding'!$G$46:$G$55,"Tranche 3") | I6: =HYPERLINK("#'Boarding'!A44","Open →")
A7: 3 | C7: Boarding Orchestration | E7: =COUNTA('Boarding'!$B$62:$B$73) | F7: =COUNTIF('Boarding'!$G$62:$G$73,"Tranche 1") | G7: =COUNTIF('Boarding'!$G$62:$G$73,"Tranche 2") | H7: =COUNTIF('Boarding'!$G$62:$G$73,"Tranche 3") | I7: =HYPERLINK("#'Boarding'!A60","Open →")
A8: 4 | C8: Integration & Messaging | E8: =COUNTA('Boarding'!$B$80:$B$89) | F8: =COUNTIF('Boarding'!$G$80:$G$89,"Tranche 1") | G8: =COUNTIF('Boarding'!$G$80:$G$89,"Tranche 2") | H8: =COUNTIF('Boarding'!$G$80:$G$89,"Tranche 3") | I8: =HYPERLINK("#'Boarding'!A78","Open →")
A9: 5 | C9: Credit & Underwriting | E9: =COUNTA('Boarding'!$B$96:$B$105) | F9: =COUNTIF('Boarding'!$G$96:$G$105,"Tranche 1") | G9: =COUNTIF('Boarding'!$G$96:$G$105,"Tranche 2") | H9: =COUNTIF('Boarding'!$G$96:$G$105,"Tranche 3") | I9: =HYPERLINK("#'Boarding'!A94","Open →")
A10: 6 | C10: CPQ / Quote-pricing | D10: • Jake Gwynn • Vivek Pujeri | E10: =COUNTA('Boarding'!$B$112:$B$121) | F10: =COUNTIF('Boarding'!$G$112:$G$121,"Tranche 1") | G10: =COUNTIF('Boarding'!$G$112:$G$121,"Tranche 2") | H10: =COUNTIF('Boarding'!$G$112:$G$121,"Tranche 3") | I10: =HYPERLINK("#'Boarding'!A110","Open →")
A11: 7 | B11: Single-in | C11: Global API | D11: • Alexander Dewison | E11: =COUNTA('Single-in'!$B$13:$B$22) | F11: =COUNTIF('Single-in'!$G$13:$G$22,"Tranche 1") | G11: =COUNTIF('Single-in'!$G$13:$G$22,"Tranche 2") | H11: =COUNTIF('Single-in'!$G$13:$G$22,"Tranche 3") | I11: =HYPERLINK("#'Single-in'!A11","Open →")
A12: 8 | C12: Payment Apps & SDKs | D12: • Stuart Taylor • Scott Moser | E12: =COUNTA('Single-in'!$B$29:$B$51) | F12: =COUNTIF('Single-in'!$G$29:$G$51,"Tranche 1") | G12: =COUNTIF('Single-in'!$G$29:$G$51,"Tranche 2") | H12: =COUNTIF('Single-in'!$G$29:$G$51,"Tranche 3") | I12: =HYPERLINK("#'Single-in'!A27","Open →")
A13: 9 | C13: Developer Experience | D13: • Alexander Dewison | E13: =COUNTA('Single-in'!$B$58:$B$67) | F13: =COUNTIF('Single-in'!$G$58:$G$67,"Tranche 1") | G13: =COUNTIF('Single-in'!$G$58:$G$67,"Tranche 2") | H13: =COUNTIF('Single-in'!$G$58:$G$67,"Tranche 3") | I13: =HYPERLINK("#'Single-in'!A56","Open →")
A14: 10 | C14: Hosted Solutions | D14: • Alexander Dewison | E14: =COUNTA('Single-in'!$B$74:$B$83) | F14: =COUNTIF('Single-in'!$G$74:$G$83,"Tranche 1") | G14: =COUNTIF('Single-in'!$G$74:$G$83,"Tranche 2") | H14: =COUNTIF('Single-in'!$G$74:$G$83,"Tranche 3") | I14: =HYPERLINK("#'Single-in'!A72","Open →")
A15: 11 | C15: Unified Proposition | D15: • Alexander Dewison | E15: =COUNTA('Single-in'!$B$90:$B$99) | F15: =COUNTIF('Single-in'!$G$90:$G$99,"Tranche 1") | G15: =COUNTIF('Single-in'!$G$90:$G$99,"Tranche 2") | H15: =COUNTIF('Single-in'!$G$90:$G$99,"Tranche 3") | I15: =HYPERLINK("#'Single-in'!A88","Open →")
A16: 12 | B16: Sales & Servicing | C16: CRM | D16: • Khali White • Lindsay Guthmiller • Tuarai Girard • Vivek Pujeri • Charlie Wright • Jason Randall • David Pritchett | E16: =COUNTA('Sales & Servicing'!$B$12:$B$27) | F16: =COUNTIF('Sales & Servicing'!$G$12:$G$27,"Tranche 1") | G16: =COUNTIF('Sales & Servicing'!$G$12:$G$27,"Tranche 2") | H16: =COUNTIF('Sales & Servicing'!$G$12:$G$27,"Tranche 3") | I16: =HYPERLINK("#'Sales & Servicing'!A10","Open →")
A17: 13 | C17: Servicing Tools | E17: =COUNTA('Sales & Servicing'!$B$34:$B$49) | F17: =COUNTIF('Sales & Servicing'!$G$34:$G$49,"Tranche 1") | G17: =COUNTIF('Sales & Servicing'!$G$34:$G$49,"Tranche 2") | H17: =COUNTIF('Sales & Servicing'!$G$34:$G$49,"Tranche 3") | I17: =HYPERLINK("#'Sales & Servicing'!A32","Open →")
A18: 14 | C18: Sales Automation | E18: =COUNTA('Sales & Servicing'!$B$56:$B$65) | F18: =COUNTIF('Sales & Servicing'!$G$56:$G$65,"Tranche 1") | G18: =COUNTIF('Sales & Servicing'!$G$56:$G$65,"Tranche 2") | H18: =COUNTIF('Sales & Servicing'!$G$56:$G$65,"Tranche 3") | I18: =HYPERLINK("#'Sales & Servicing'!A54","Open →")
A19: 15 | C19: Risks | E19: =COUNTA('Sales & Servicing'!$B$72:$B$81) | F19: =COUNTIF('Sales & Servicing'!$G$72:$G$81,"Tranche 1") | G19: =COUNTIF('Sales & Servicing'!$G$72:$G$81,"Tranche 2") | H19: =COUNTIF('Sales & Servicing'!$G$72:$G$81,"Tranche 3") | I19: =HYPERLINK("#'Sales & Servicing'!A70","Open →")
A20: 16 | B20: Payment Processing | C20: Gateway | D20: • TBC | E20: =COUNTA('Payment Processing'!$B$14:$B$52) | F20: =COUNTIF('Payment Processing'!$G$14:$G$52,"Tranche 1") | G20: =COUNTIF('Payment Processing'!$G$14:$G$52,"Tranche 2") | H20: =COUNTIF('Payment Processing'!$G$14:$G$52,"Tranche 3") | I20: =HYPERLINK("#'Payment Processing'!A12","Open →")
A21: 17 | C21: Switch | E21: =COUNTA('Payment Processing'!$B$59:$B$68) | F21: =COUNTIF('Payment Processing'!$G$59:$G$68,"Tranche 1") | G21: =COUNTIF('Payment Processing'!$G$59:$G$68,"Tranche 2") | H21: =COUNTIF('Payment Processing'!$G$59:$G$68,"Tranche 3") | I21: =HYPERLINK("#'Payment Processing'!A57","Open →")
A22: 18 | C22: Clearing Back-end | D22: • Mike Clark • Philip Ringer • Jon Beere • Alan Bainbridge • Richard Jones • Peter Downey | E22: =COUNTA('Payment Processing'!$B$75:$B$89) | F22: =COUNTIF('Payment Processing'!$G$75:$G$89,"Tranche 1") | G22: =COUNTIF('Payment Processing'!$G$75:$G$89,"Tranche 2") | H22: =COUNTIF('Payment Processing'!$G$75:$G$89,"Tranche 3") | I22: =HYPERLINK("#'Payment Processing'!A73","Open →")
A23: 19 | C23: Authorization Host | D23: • Mike Clark • Philip Ringer • Jon Beere • Anushree Kolhe • James Annunziata | E23: =COUNTA('Payment Processing'!$B$96:$B$112) | F23: =COUNTIF('Payment Processing'!$G$96:$G$112,"Tranche 1") | G23: =COUNTIF('Payment Processing'!$G$96:$G$112,"Tranche 2") | H23: =COUNTIF('Payment Processing'!$G$96:$G$112,"Tranche 3") | I23: =HYPERLINK("#'Payment Processing'!A94","Open →")
A24: 20 | C24: Transaction monitoring | D24: • TBC | E24: =COUNTA('Payment Processing'!$B$119:$B$128) | F24: =COUNTIF('Payment Processing'!$G$119:$G$128,"Tranche 1") | G24: =COUNTIF('Payment Processing'!$G$119:$G$128,"Tranche 2") | H24: =COUNTIF('Payment Processing'!$G$119:$G$128,"Tranche 3") | I24: =HYPERLINK("#'Payment Processing'!A117","Open →")
A25: 21 | C25: APMs/LPMs | D25: • TBC | E25: =COUNTA('Payment Processing'!$B$135:$B$144) | F25: =COUNTIF('Payment Processing'!$G$135:$G$144,"Tranche 1") | G25: =COUNTIF('Payment Processing'!$G$135:$G$144,"Tranche 2") | H25: =COUNTIF('Payment Processing'!$G$135:$G$144,"Tranche 3") | I25: =HYPERLINK("#'Payment Processing'!A133","Open →")
A26: 22 | B26: VAS | C26: Routing | D26: • Jason Harding • Srini Turlapati • Andre Dubreuil • Sunny Thakkar | E26: =COUNTA('VAS'!$B$17:$B$26) | F26: =COUNTIF('VAS'!$G$17:$G$26,"Tranche 1") | G26: =COUNTIF('VAS'!$G$17:$G$26,"Tranche 2") | H26: =COUNTIF('VAS'!$G$17:$G$26,"Tranche 3") | I26: =HYPERLINK("#'VAS'!A15","Open →")
A27: 23 | C27: Networking Payment Tokens | D27: • Jason Harding • Srini Turlapati | E27: =COUNTA('VAS'!$B$33:$B$42) | F27: =COUNTIF('VAS'!$G$33:$G$42,"Tranche 1") | G27: =COUNTIF('VAS'!$G$33:$G$42,"Tranche 2") | H27: =COUNTIF('VAS'!$G$33:$G$42,"Tranche 3") | I27: =HYPERLINK("#'VAS'!A31","Open →")
A28: 24 | C28: DCC eDCC | D28: • Marcus Lang • VikramSuhas Joshi • Jaroslav Farkas | E28: =COUNTA('VAS'!$B$49:$B$58) | F28: =COUNTIF('VAS'!$G$49:$G$58,"Tranche 1") | G28: =COUNTIF('VAS'!$G$49:$G$58,"Tranche 2") | H28: =COUNTIF('VAS'!$G$49:$G$58,"Tranche 3") | I28: =HYPERLINK("#'VAS'!A47","Open →")
A29: 25 | C29: Fraud | D29: • Justin Moore • Srini Turlapati | E29: =COUNTA('VAS'!$B$65:$B$76) | F29: =COUNTIF('VAS'!$G$65:$G$76,"Tranche 1") | G29: =COUNTIF('VAS'!$G$65:$G$76,"Tranche 2") | H29: =COUNTIF('VAS'!$G$65:$G$76,"Tranche 3") | I29: =HYPERLINK("#'VAS'!A63","Open →")
A30: 26 | C30: Credential Management | D30: • Jason Harding • Srini Turlapati • Andre Dubreuil | E30: =COUNTA('VAS'!$B$83:$B$92) | F30: =COUNTIF('VAS'!$G$83:$G$92,"Tranche 1") | G30: =COUNTIF('VAS'!$G$83:$G$92,"Tranche 2") | H30: =COUNTIF('VAS'!$G$83:$G$92,"Tranche 3") | I30: =HYPERLINK("#'VAS'!A81","Open →")
A31: 27 | C31: Gifts | D31: • Genessa Prictor • Srini Turlapati • John Nail | E31: =COUNTA('VAS'!$B$99:$B$110) | F31: =COUNTIF('VAS'!$G$99:$G$110,"Tranche 1") | G31: =COUNTIF('VAS'!$G$99:$G$110,"Tranche 2") | H31: =COUNTIF('VAS'!$G$99:$G$110,"Tranche 3") | I31: =HYPERLINK("#'VAS'!A97","Open →")
A32: 28 | C32: Managed Optimization | D32: • Jason Harding • Srini Turlapati • Andre Dubreuil | E32: =COUNTA('VAS'!$B$117:$B$126) | F32: =COUNTIF('VAS'!$G$117:$G$126,"Tranche 1") | G32: =COUNTIF('VAS'!$G$117:$G$126,"Tranche 2") | H32: =COUNTIF('VAS'!$G$117:$G$126,"Tranche 3") | I32: =HYPERLINK("#'VAS'!A115","Open →")
A33: 29 | C33: 3DS / exemptions | D33: • Sunny Thakkar • Srini Turlapati | E33: =COUNTA('VAS'!$B$133:$B$142) | F33: =COUNTIF('VAS'!$G$133:$G$142,"Tranche 1") | G33: =COUNTIF('VAS'!$G$133:$G$142,"Tranche 2") | H33: =COUNTIF('VAS'!$G$133:$G$142,"Tranche 3") | I33: =HYPERLINK("#'VAS'!A131","Open →")
A34: 30 | C34: FX | D34: • Srini Turlapati • VikramSuhas Joshi | E34: =COUNTA('VAS'!$B$149:$B$158) | F34: =COUNTIF('VAS'!$G$149:$G$158,"Tranche 1") | G34: =COUNTIF('VAS'!$G$149:$G$158,"Tranche 2") | H34: =COUNTIF('VAS'!$G$149:$G$158,"Tranche 3") | I34: =HYPERLINK("#'VAS'!A147","Open →")
A35: 31 | B35: Unified Data and AI | C35: Overall | D35: • Ryan Heaton • Himanshu Shah | E35: =COUNTA('Unified Data and AI'!$B$9:$B$21) | F35: =COUNTIF('Unified Data and AI'!$G$9:$G$21,"Tranche 1") | G35: =COUNTIF('Unified Data and AI'!$G$9:$G$21,"Tranche 2") | H35: =COUNTIF('Unified Data and AI'!$G$9:$G$21,"Tranche 3") | I35: =HYPERLINK("#'Unified Data and AI'!A7","Open →")
A36: 32 | B36: Global Infrastructure | C36: Data Centers | D36: • TBC | E36: =COUNTA('Global Infrastructure'!$B$14:$B$23) | F36: =COUNTIF('Global Infrastructure'!$G$14:$G$23,"Tranche 1") | G36: =COUNTIF('Global Infrastructure'!$G$14:$G$23,"Tranche 2") | H36: =COUNTIF('Global Infrastructure'!$G$14:$G$23,"Tranche 3") | I36: =HYPERLINK("#'Global Infrastructure'!A12","Open →")
A37: 33 | C37: Cloud | D37: • TBC | E37: =COUNTA('Global Infrastructure'!$B$30:$B$39) | F37: =COUNTIF('Global Infrastructure'!$G$30:$G$39,"Tranche 1") | G37: =COUNTIF('Global Infrastructure'!$G$30:$G$39,"Tranche 2") | H37: =COUNTIF('Global Infrastructure'!$G$30:$G$39,"Tranche 3") | I37: =HYPERLINK("#'Global Infrastructure'!A28","Open →")
A38: 34 | C38: Observability | D38: • TBC | E38: =COUNTA('Global Infrastructure'!$B$46:$B$55) | F38: =COUNTIF('Global Infrastructure'!$G$46:$G$55,"Tranche 1") | G38: =COUNTIF('Global Infrastructure'!$G$46:$G$55,"Tranche 2") | H38: =COUNTIF('Global Infrastructure'!$G$46:$G$55,"Tranche 3") | I38: =HYPERLINK("#'Global Infrastructure'!A44","Open →")
A39: 35 | C39: Security | D39: • TBC | E39: =COUNTA('Global Infrastructure'!$B$62:$B$71) | F39: =COUNTIF('Global Infrastructure'!$G$62:$G$71,"Tranche 1") | G39: =COUNTIF('Global Infrastructure'!$G$62:$G$71,"Tranche 2") | H39: =COUNTIF('Global Infrastructure'!$G$62:$G$71,"Tranche 3") | I39: =HYPERLINK("#'Global Infrastructure'!A60","Open →")
A40: 36 | C40: AI Tools | D40: • TBC | E40: =COUNTA('Global Infrastructure'!$B$78:$B$87) | F40: =COUNTIF('Global Infrastructure'!$G$78:$G$87,"Tranche 1") | G40: =COUNTIF('Global Infrastructure'!$G$78:$G$87,"Tranche 2") | H40: =COUNTIF('Global Infrastructure'!$G$78:$G$87,"Tranche 3") | I40: =HYPERLINK("#'Global Infrastructure'!A76","Open →")
A41: 37 | C41: Design Systems | D41: • TBC | E41: =COUNTA('Global Infrastructure'!$B$94:$B$103) | F41: =COUNTIF('Global Infrastructure'!$G$94:$G$103,"Tranche 1") | G41: =COUNTIF('Global Infrastructure'!$G$94:$G$103,"Tranche 2") | H41: =COUNTIF('Global Infrastructure'!$G$94:$G$103,"Tranche 3") | I41: =HYPERLINK("#'Global Infrastructure'!A92","Open →")
...

Sheet Boarding
A1: Boarding — Platform Assessment
A2: =HYPERLINK("#'Summary'!A1","← Back to Summary") | C2: Pick a State, score High / Medium / Low — the tranche, the matrix and the Summary update automatically.
A4: Tracker — jump to a sub-capability:
A5: 1. | B5: =HYPERLINK("#'Boarding'!A12","Boarding Experience")
A6: 2. | B6: =HYPERLINK("#'Boarding'!A44","Ingress")
A7: 3. | B7: =HYPERLINK("#'Boarding'!A60","Boarding Orchestration")
A8: 4. | B8: =HYPERLINK("#'Boarding'!A78","Integration & Messaging")
A9: 5. | B9: =HYPERLINK("#'Boarding'!A94","Credit & Underwriting")
A10: 6. | B10: =HYPERLINK("#'Boarding'!A110","CPQ / Quote-pricing")
A12: Boarding Experience | G12: =HYPERLINK("#'Boarding'!A4","▲ tracker") | K12: Assessment Outcome
A13: # | B13: Platform | C13: State | D13: Imperative to exit | E13: Exit complexity | F13: Supporting facts | G13: Tranche (auto) | K13: Low | L13: Medium | M13: High
A14: ① | B14: Launchpad | C14: Target state | G14: =IF(OR($B14="",$D14="",$E14=""),"",IF(OR($C14="Target state",$C14="Exception"),"Out of scope",IF($D14="Low","No tranche",IF($E14="Low","Tranche 1",IF($E14="Medium","Tranche 2",IF($D14="High","Tranche 3","No tranche")))))) | I14: Benefits | J14: High | K14: ="Tranche 1"&CHAR(10)&_xlfn.TEXTJOIN(CHAR(10),TRUE,O$14:O$39) | L14: ="Tranche 2"&CHAR(10)&_xlfn.TEXTJOIN(CHAR(10),TRUE,P$14:P$39) | M14: ="Tranche 3"&CHAR(10)&_xlfn.TEXTJOIN(CHAR(10),TRUE,Q$14:Q$39) | O14: =IF(AND($B14<>"",$C14<>"Target state",$C14<>"Exception",$D14="High",$E14="Low"),$A14&" "&$B14,"") | P14: =IF(AND($B14<>"",$C14<>"Target state",$C14<>"Exception",$D14="High",$E14="Medium"),$A14&" "&$B14,"") | Q14: =IF(AND($B14<>"",$C14<>"Target state",$C14<>"Exception",$D14="High",$E14="High"),$A14&" "&$B14,"") | R14: =IF(AND($B14<>"",$C14<>"Target state",$C14<>"Exception",$D14="Medium",$E14="Low"),$A14&" "&$B14,"") | S14: =IF(AND($B14<>"",$C14<>"Target state",$C14<>"Exception",$D14="Medium",$E14="Medium"),$A14&" "&$B14,"") | T14: =IF(AND($B14<>"",$C14<>"Target state",$C14<>"Exception",$D14="Medium",$E14="High"),$A14&" "&$B14,"") | U14: =IF(AND($B14<>"",$C14<>"Target state",$C14<>"Exception",$D14="Low",$E14="Low"),$A14&" "&$B14,"") | V14: =IF(AND($B14<>"",$C14<>"Target state",$C14<>"Exception",$D14="Low",$E14="Medium"),$A14&" "&$B14,"") | W14: =IF(AND($B14<>"",$C14<>"Target state",$C14<>"Exception",$D14="Low",$E14="High"),$A14&" "&$B14,"")
A15: ② | B15: ELAPP | C15: Non-target state | F15: Non-strategic TSYS Broomfield boarding application covering about 178K merchants; around $835K in yearly cost; replaced by Base CRM and IDGen under ECHO | G15: =IF(OR($B15="",$D15="",$E15=""),"",IF(OR($C15="Target state",$C15="Exception"),"Out of scope",IF($D15="Low","No tranche",IF($E15="Low","Tranche 1",IF($E15="Medium","Tranche 2",IF($D15="High","Tranche 3","No tranche")))))) | O15: =IF(AND($B15<>"",$C15<>"Target state",$C15<>"Exception",$D15="High",$E15="Low"),$A15&" "&$B15,"") | P15: =IF(AND($B15<>"",$C15<>"Target state",$C15<>"Exception",$D15="High",$E15="Medium"),$A15&" "&$B15,"") | Q15: =IF(AND($B15<>"",$C15<>"Target state",$C15<>"Exception",$D15="High",$E15="High"),$A15&" "&$B15,"") | R15: =IF(AND($B15<>"",$C15<>"Target state",$C15<>"Exception",$D15="Medium",$E15="Low"),$A15&" "&$B15,"") | S15: =IF(AND($B15<>"",$C15<>"Target state",$C15<>"Exception",$D15="Medium",$E15="Medium"),$A15&" "&$B15,"") | T15: =IF(AND($B15<>"",$C15<>"Target state",$C15<>"Exception",$D15="Medium",$E15="High"),$A15&" "&$B15,"") | U15: =IF(AND($B15<>"",$C15<>"Target state",$C15<>"Exception",$D15="Low",$E15="Low"),$A15&" "&$B15,"") | V15: =IF(AND($B15<>"",$C15<>"Target state",$C15<>"Exception",$D15="Low",$E15="Medium"),$A15&" "&$B15,"") | W15: =IF(AND($B15<>"",$C15<>"Target state",$C15<>"Exception",$D15="Low",$E15="High"),$A15&" "&$B15,"")
A16: ③ | B16: Merchant Application Package (MAP) | C16: Non-target state | F16: Non-strategic Omaha boarding solution also used by CPay covering about 87K merchants; around $430K in yearly third-party cost | G16: =IF(OR($B16="",$D16="",$E16=""),"",IF(OR($C16="Target state",$C16="Exception"),"Out of scope",IF($D16="Low","No tranche",IF($E16="Low","Tranche 1",IF($E16="Medium","Tranche 2",IF($D16="High","Tranche 3","No tranche")))))) | O16: =IF(AND($B16<>"",$C16<>"Target state",$C16<>"Exception",$D16="High",$E16="Low"),$A16&" "&$B16,"") | P16: =IF(AND($B16<>"",$C16<>"Target state",$C16<>"Exception",$D16="High",$E16="Medium"),$A16&" "&$B16,"") | Q16: =IF(AND($B16<>"",$C16<>"Target state",$C16<>"Exception",$D16="High",$E16="High"),$A16&" "&$B16,"") | R16: =IF(AND($B16<>"",$C16<>"Target state",$C16<>"Exception",$D16="Medium",$E16="Low"),$A16&" "&$B16,"") | S16: =IF(AND($B16<>"",$C16<>"Target state",$C16<>"Exception",$D16="Medium",$E16="Medium"),$A16&" "&$B16,"") | T16: =IF(AND($B16<>"",$C16<>"Target state",$C16<>"Exception",$D16="Medium",$E16="High"),$A16&" "&$B16,"") | U16: =IF(AND($B16<>"",$C16<>"Target state",$C16<>"Exception",$D16="Low",$E16="Low"),$A16&" "&$B16,"") | V16: =IF(AND($B16<>"",$C16<>"Target state",$C16<>"Exception",$D16="Low",$E16="Medium"),$A16&" "&$B16,"") | W16: =IF(AND($B16<>"",$C16<>"Target state",$C16<>"Exception",$D16="Low",$E16="High"),$A16&" "&$B16,"")
A17: ④ | B17: Central Station (CPay) | C17: Non-target state | F17: Non-strategic all-in-one business management platform for the Central Payments portfolio across 30K MIDs spanning sales, underwriting, boarding and service; about $360K in yearly cost | G17: =IF(OR($B17="",$D17="",$E17=""),"",IF(OR($C17="Target state",$C17="Exception"),"Out of scope",IF($D17="Low","No tranche",IF($E17="Low","Tranche 1",IF($E17="Medium","Tranche 2",IF($D17="High","Tranche 3","No tranche")))))) | O17: =IF(AND($B17<>"",$C17<>"Target state",$C17<>"Exception",$D17="High",$E17="Low"),$A17&" "&$B17,"") | P17: =IF(AND($B17<>"",$C17<>"Target state",$C17<>"Exception",$D17="High",$E17="Medium"),$A17&" "&$B17,"") | Q17: =IF(AND($B17<>"",$C17<>"Target state",$C17<>"Exception",$D17="High",$E17="High"),$A17&" "&$B17,"") | R17: =IF(AND($B17<>"",$C17<>"Target state",$C17<>"Exception",$D17="Medium",$E17="Low"),$A17&" "&$B17,"") | S17: =IF(AND($B17<>"",$C17<>"Target state",$C17<>"Exception",$D17="Medium",$E17="Medium"),$A17&" "&$B17,"") | T17: =IF(AND($B17<>"",$C17<>"Target state",$C17<>"Exception",$D17="Medium",$E17="High"),$A17&" "&$B17,"") | U17: =IF(AND($B17<>"",$C17<>"Target state",$C17<>"Exception",$D17="Low",$E17="Low"),$A17&" "&$B17,"") | V17: =IF(AND($B17<>"",$C17<>"Target state",$C17<>"Exception",$D17="Low",$E17="Medium"),$A17&" "&$B17,"") | W17: =IF(AND($B17<>"",$C17<>"Target state",$C17<>"Exception",$D17="Low",$E17="High"),$A17&" "&$B17,"")
A18: ⑤ | B18: EVONow | C18: Non-target state | F18: Non-strategic partner and merchant online application feeding the underwriting system; about $150K in yearly cost; folds into the EVO simplification program | G18: =IF(OR($B18="",$D18="",$E18=""),"",IF(OR($C18="Target state",$C18="Exception"),"Out of scope",IF($D18="Low","No tranche",IF($E18="Low","Tranche 1",IF($E18="Medium","Tranche 2",IF($D18="High","Tranche 3","No tranche")))))) | O18: =IF(AND($B18<>"",$C18<>"Target state",$C18<>"Exception",$D18="High",$E18="Low"),$A18&" "&$B18,"") | P18: =IF(AND($B18<>"",$C18<>"Target state",$C18<>"Exception",$D18="High",$E18="Medium"),$A18&" "&$B18,"") | Q18: =IF(AND($B18<>"",$C18<>"Target state",$C18<>"Exception",$D18="High",$E18="High"),$A18&" "&$B18,"") | R18: =IF(AND($B18<>"",$C18<>"Target state",$C18<>"Exception",$D18="Medium",$E18="Low"),$A18&" "&$B18,"") | S18: =IF(AND($B18<>"",$C18<>"Target state",$C18<>"Exception",$D18="Medium",$E18="Medium"),$A18&" "&$B18,"") | T18: =IF(AND($B18<>"",$C18<>"Target state",$C18<>"Exception",$D18="Medium",$E18="High"),$A18&" "&$B18,"") | U18: =IF(AND($B18<>"",$C18<>"Target state",$C18<>"Exception",$D18="Low",$E18="Low"),$A18&" "&$B18,"") | V18: =IF(AND($B18<>"",$C18<>"Target state",$C18<>"Exception",$D18="Low",$E18="Medium"),$A18&" "&$B18,"") | W18: =IF(AND($B18<>"",$C18<>"Target state",$C18<>"Exception",$D18="Low",$E18="High"),$A18&" "&$B18,"")
A19: ⑥ | B19: MOSS CA | C19: Non-target state | F19: Non-strategic boarding platform for the legacy GP Canada market with 2.3K active users; about $410K in yearly cost; repository flags initial disposition Keep & Enhance — confirm with SPOC | G19: =IF(OR($B19="",$D19="",$E19=""),"",IF(OR($C19="Target state",$C19="Exception"),"Out of scope",IF($D19="Low","No tranche",IF($E19="Low","Tranche 1",IF($E19="Medium","Tranche 2",IF($D19="High","Tranche 3","No tranche")))))) | O19: =IF(AND($B19<>"",$C19<>"Target state",$C19<>"Exception",$D19="High",$E19="Low"),$A19&" "&$B19,"") | P19: =IF(AND($B19<>"",$C19<>"Target state",$C19<>"Exception",$D19="High",$E19="Medium"),$A19&" "&$B19,"") | Q19: =IF(AND($B19<>"",$C19<>"Target state",$C19<>"Exception",$D19="High",$E19="High"),$A19&" "&$B19,"") | R19: =IF(AND($B19<>"",$C19<>"Target state",$C19<>"Exception",$D19="Medium",$E19="Low"),$A19&" "&$B19,"") | S19: =IF(AND($B19<>"",$C19<>"Target state",$C19<>"Exception",$D19="Medium",$E19="Medium"),$A19&" "&$B19,"") | T19: =IF(AND($B19<>"",$C19<>"Target state",$C19<>"Exception",$D19="Medium",$E19="High"),$A19&" "&$B19,"") | U19: =IF(AND($B19<>"",$C19<>"Target state",$C19<>"Exception",$D19="Low",$E19="Low"),$A19&" "&$B19,"") | V19: =IF(AND($B19<>"",$C19<>"Target state",$C19<>"Exception",$D19="Low",$E19="Medium"),$A19&" "&$B19,"") | W19: =IF(AND($B19<>"",$C19<>"Target state",$C19<>"Exception",$D19="Low",$E19="High"),$A19&" "&$B19,"")
A20: ⑦ | B20: MOSS AP | C20: Non-target state | F20: Non-strategic boarding platform for the legacy GP Asia Pacific market with about 230 active users; about $460K in yearly cost; repository flags initial disposition Keep & Enhance — confirm with SPOC | G20: =IF(OR($B20="",$D20="",$E20=""),"",IF(OR($C20="Target state",$C20="Exception"),"Out of scope",IF($D20="Low","No tranche",IF($E20="Low","Tranche 1",IF($E20="Medium","Tranche 2",IF($D20="High","Tranche 3","No tranche")))))) | O20: =IF(AND($B20<>"",$C20<>"Target state",$C20<>"Exception",$D20="High",$E20="Low"),$A20&" "&$B20,"") | P20: =IF(AND($B20<>"",$C20<>"Target state",$C20<>"Exception",$D20="High",$E20="Medium"),$A20&" "&$B20,"") | Q20: =IF(AND($B20<>"",$C20<>"Target state",$C20<>"Exception",$D20="High",$E20="High"),$A20&" "&$B20,"") | R20: =IF(AND($B20<>"",$C20<>"Target state",$C20<>"Exception",$D20="Medium",$E20="Low"),$A20&" "&$B20,"") | S20: =IF(AND($B20<>"",$C20<>"Target state",$C20<>"Exception",$D20="Medium",$E20="Medium"),$A20&" "&$B20,"") | T20: =IF(AND($B20<>"",$C20<>"Target state",$C20<>"Exception",$D20="Medium",$E20="High"),$A20&" "&$B20,"") | U20: =IF(AND($B20<>"",$C20<>"Target state",$C20<>"Exception",$D20="Low",$E20="Low"),$A20&" "&$B20,"") | V20: =IF(AND($B20<>"",$C20<>"Target state",$C20<>"Exception",$D20="Low",$E20="Medium"),$A20&" "&$B20,"") | W20: =IF(AND($B20<>"",$C20<>"Target state",$C20<>"Exception",$D20="Low",$E20="High"),$A20&" "&$B20,"")
A21: ⑧ | B21: MOSS UK | C21: Non-target state | F21: Non-strategic boarding platform for the legacy GP UK market with about 1.1K active users; about $990K in yearly cost; repository flags initial disposition Keep & Enhance — confirm with SPOC | G21: =IF(OR($B21="",$D21="",$E21=""),"",IF(OR($C21="Target state",$C21="Exception"),"Out of scope",IF($D21="Low","No tranche",IF($E21="Low","Tranche 1",IF($E21="Medium","Tranche 2",IF($D21="High","Tranche 3","No tranche")))))) | O21: =IF(AND($B21<>"",$C21<>"Target state",$C21<>"Exception",$D21="High",$E21="Low"),$A21&" "&$B21,"") | P21: =IF(AND($B21<>"",$C21<>"Target state",$C21<>"Exception",$D21="High",$E21="Medium"),$A21&" "&$B21,"") | Q21: =IF(AND($B21<>"",$C21<>"Target state",$C21<>"Exception",$D21="High",$E21="High"),$A21&" "&$B21,"") | R21: =IF(AND($B21<>"",$C21<>"Target state",$C21<>"Exception",$D21="Medium",$E21="Low"),$A21&" "&$B21,"") | S21: =IF(AND($B21<>"",$C21<>"Target state",$C21<>"Exception",$D21="Medium",$E21="Medium"),$A21&" "&$B21,"") | T21: =IF(AND($B21<>"",$C21<>"Target state",$C21<>"Exception",$D21="Medium",$E21="High"),$A21&" "&$B21,"") | U21: =IF(AND($B21<>"",$C21<>"Target state",$C21<>"Exception",$D21="Low",$E21="Low"),$A21&" "&$B21,"") | V21: =IF(AND($B21<>"",$C21<>"Target state",$C21<>"Exception",$D21="Low",$E21="Medium"),$A21&" "&$B21,"") | W21: =IF(AND($B21<>"",$C21<>"Target state",$C21<>"Exception",$D21="Low",$E21="High"),$A21&" "&$B21,"")
A22: ⑨ | B22: MOSS Mexico | C22: Non-target state | F22: Non-strategic boarding platform for the LATAM market; limited usage detail in the repository | G22: =IF(OR($B22="",$D22="",$E22=""),"",IF(OR($C22="Target state",$C22="Exception"),"Out of scope",IF($D22="Low","No tranche",IF($E22="Low","Tranche 1",IF($E22="Medium","Tranche 2",IF($D22="High","Tranche 3","No tranche")))))) | O22: =IF(AND($B22<>"",$C22<>"Target state",$C22<>"Exception",$D22="High",$E22="Low"),$A22&" "&$B22,"") | P22: =IF(AND($B22<>"",$C22<>"Target state",$C22<>"Exception",$D22="High",$E22="Medium"),$A22&" "&$B22,"") | Q22: =IF(AND($B22<>"",$C22<>"Target state",$C22<>"Exception",$D22="High",$E22="High"),$A22&" "&$B22,"") | R22: =IF(AND($B22<>"",$C22<>"Target state",$C22<>"Exception",$D22="Medium",$E22="Low"),$A22&" "&$B22,"") | S22: =IF(AND($B22<>"",$C22<>"Target state",$C22<>"Exception",$D22="Medium",$E22="Medium"),$A22&" "&$B22,"") | T22: =IF(AND($B22<>"",$C22<>"Target state",$C22<>"Exception",$D22="Medium",$E22="High"),$A22&" "&$B22,"") | U22: =IF(AND($B22<>"",$C22<>"Target state",$C22<>"Exception",$D22="Low",$E22="Low"),$A22&" "&$B22,"") | V22: =IF(AND($B22<>"",$C22<>"Target state",$C22<>"Exception",$D22="Low",$E22="Medium"),$A22&" "&$B22,"") | W22: =IF(AND($B22<>"",$C22<>"Target state",$C22<>"Exception",$D22="Low",$E22="High"),$A22&" "&$B22,"")
A23: ⑩ | B23: i-Apply | C23: Non-target state | F23: Non-strategic application platform for NBG Pay serving all application types; to be replaced by e-service systems | G23: =IF(OR($B23="",$D23="",$E23=""),"",IF(OR($C23="Target state",$C23="Exception"),"Out of scope",IF($D23="Low","No tranche",IF($E23="Low","Tranche 1",IF($E23="Medium","Tranche 2",IF($D23="High","Tranche 3","No tranche")))))) | J23: Medium | K23: ="Tranche 1"&CHAR(10)&_xlfn.TEXTJOIN(CHAR(10),TRUE,R$14:R$39) | L23: ="Tranche 2"&CHAR(10)&_xlfn.TEXTJOIN(CHAR(10),TRUE,S$14:S$39) | M23: =_xlfn.TEXTJOIN(CHAR(10),TRUE,T$14:T$39) | O23: =IF(AND($B23<>"",$C23<>"Target state",$C23<>"Exception",$D23="High",$E23="Low"),$A23&" "&$B23,"") | P23: =IF(AND($B23<>"",$C23<>"Target state",$C23<>"Exception",$D23="High",$E23="Medium"),$A23&" "&$B23,"") | Q23: =IF(AND($B23<>"",$C23<>"Target state",$C23<>"Exception",$D23="High",$E23="High"),$A23&" "&$B23,"") | R23: =IF(AND($B23<>"",$C23<>"Target state",$C23<>"Exception",$D23="Medium",$E23="Low"),$A23&" "&$B23,"") | S23: =IF(AND($B23<>"",$C23<>"Target state",$C23<>"Exception",$D23="Medium",$E23="Medium"),$A23&" "&$B23,"") | T23: =IF(AND($B23<>"",$C23<>"Target state",$C23<>"Exception",$D23="Medium",$E23="High"),$A23&" "&$B23,"") | U23: =IF(AND($B23<>"",$C23<>"Target state",$C23<>"Exception",$D23="Low",$E23="Low"),$A23&" "&$B23,"") | V23: =IF(AND($B23<>"",$C23<>"Target state",$C23<>"Exception",$D23="Low",$E23="Medium"),$A23&" "&$B23,"") | W23: =IF(AND($B23<>"",$C23<>"Target state",$C23<>"Exception",$D23="Low",$E23="High"),$A23&" "&$B23,"")
A24: ⑪ | B24: MVSI Onboard | C24: Non-target state | F24: Non-strategic onboarding platform for a subset of Ezidebit clients; about $50K in yearly licence cost; confirmed for decommission | G24: =IF(OR($B24="",$D24="",$E24=""),"",IF(OR($C24="Target state",$C24="Exception"),"Out of scope",IF($D24="Low","No tranche",IF($E24="Low","Tranche 1",IF($E24="Medium","Tranche 2",IF($D24="High","Tranche 3","No tranche")))))) | O24: =IF(AND($B24<>"",$C24<>"Target state",$C24<>"Exception",$D24="High",$E24="Low"),$A24&" "&$B24,"") | P24: =IF(AND($B24<>"",$C24<>"Target state",$C24<>"Exception",$D24="High",$E24="Medium"),$A24&" "&$B24,"") | Q24: =IF(AND($B24<>"",$C24<>"Target state",$C24<>"Exception",$D24="High",$E24="High"),$A24&" "&$B24,"") | R24: =IF(AND($B24<>"",$C24<>"Target state",$C24<>"Exception",$D24="Medium",$E24="Low"),$A24&" "&$B24,"") | S24: =IF(AND($B24<>"",$C24<>"Target state",$C24<>"Exception",$D24="Medium",$E24="Medium"),$A24&" "&$B24,"") | T24: =IF(AND($B24<>"",$C24<>"Target state",$C24<>"Exception",$D24="Medium",$E24="High"),$A24&" "&$B24,"") | U24: =IF(AND($B24<>"",$C24<>"Target state",$C24<>"Exception",$D24="Low",$E24="Low"),$A24&" "&$B24,"") | V24: =IF(AND($B24<>"",$C24<>"Target state",$C24<>"Exception",$D24="Low",$E24="Medium"),$A24&" "&$B24,"") | W24: =IF(AND($B24<>"",$C24<>"Target state",$C24<>"Exception",$D24="Low",$E24="High"),$A24&" "&$B24,"")
A25: ⑫ | B25: Online Boarding Portal | C25: Non-target state | F25: Non-strategic legacy Heartland and Portico boarding front end for partners feeding Instant Boarding | G25: =IF(OR($B25="",$D25="",$E25=""),"",IF(OR($C25="Target state",$C25="Exception"),"Out of scope",IF($D25="Low","No tranche",IF($E25="Low","Tranche 1",IF($E25="Medium","Tranche 2",IF($D25="High","Tranche 3","No tranche")))))) | O25: =IF(AND($B25<>"",$C25<>"Target state",$C25<>"Exception",$D25="High",$E25="Low"),$A25&" "&$B25,"") | P25: =IF(AND($B25<>"",$C25<>"Target state",$C25<>"Exception",$D25="High",$E25="Medium"),$A25&" "&$B25,"") | Q25: =IF(AND($B25<>"",$C25<>"Target state",$C25<>"Exception",$D25="High",$E25="High"),$A25&" "&$B25,"") | R25: =IF(AND($B25<>"",$C25<>"Target state",$C25<>"Exception",$D25="Medium",$E25="Low"),$A25&" "&$B25,"") | S25: =IF(AND($B25<>"",$C25<>"Target state",$C25<>"Exception",$D25="Medium",$E25="Medium"),$A25&" "&$B25,"") | T25: =IF(AND($B25<>"",$C25<>"Target state",$C25<>"Exception",$D25="Medium",$E25="High"),$A25&" "&$B25,"") | U25: =IF(AND($B25<>"",$C25<>"Target state",$C25<>"Exception",$D25="Low",$E25="Low"),$A25&" "&$B25,"") | V25: =IF(AND($B25<>"",$C25<>"Target state",$C25<>"Exception",$D25="Low",$E25="Medium"),$A25&" "&$B25,"") | W25: =IF(AND($B25<>"",$C25<>"Target state",$C25<>"Exception",$D25="Low",$E25="High"),$A25&" "&$B25,"")
A26: ⑬ | B26: Rapid Activation | C26: Non-target state | F26: Non-strategic legacy GPI boarding for partners and sales users with modest monthly boarding volume | G26: =IF(OR($B26="",$D26="",$E26=""),"",IF(OR($C26="Target state",$C26="Exception"),"Out of scope",IF($D26="Low","No tranche",IF($E26="Low","Tranche 1",IF($E26="Medium","Tranche 2",IF($D26="High","Tranche 3","No tranche")))))) | O26: =IF(AND($B26<>"",$C26<>"Target state",$C26<>"Exception",$D26="High",$E26="Low"),$A26&" "&$B26,"") | P26: =IF(AND($B26<>"",$C26<>"Target state",$C26<>"Exception",$D26="High",$E26="Medium"),$A26&" "&$B26,"") | Q26: =IF(AND($B26<>"",$C26<>"Target state",$C26<>"Exception",$D26="High",$E26="High"),$A26&" "&$B26,"") | R26: =IF(AND($B26<>"",$C26<>"Target state",$C26<>"Exception",$D26="Medium",$E26="Low"),$A26&" "&$B26,"") | S26: =IF(AND($B26<>"",$C26<>"Target state",$C26<>"Exception",$D26="Medium",$E26="Medium"),$A26&" "&$B26,"") | T26: =IF(AND($B26<>"",$C26<>"Target state",$C26<>"Exception",$D26="Medium",$E26="High"),$A26&" "&$B26,"") | U26: =IF(AND($B26<>"",$C26<>"Target state",$C26<>"Exception",$D26="Low",$E26="Low"),$A26&" "&$B26,"") | V26: =IF(AND($B26<>"",$C26<>"Target state",$C26<>"Exception",$D26="Low",$E26="Medium"),$A26&" "&$B26,"") | W26: =IF(AND($B26<>"",$C26<>"Target state",$C26<>"Exception",$D26="Low",$E26="High"),$A26&" "&$B26,"")
A27: ⑭ | B27: Hermes | C27: Non-target state | F27: Non-strategic third-party boarding system for Czech bank advisors and sales reps; about 26K clients processed; modest annual cost | G27: =IF(OR($B27="",$D27="",$E27=""),"",IF(OR($C27="Target state",$C27="Exception"),"Out of scope",IF($D27="Low","No tranche",IF($E27="Low","Tranche 1",IF($E27="Medium","Tranche 2",IF($D27="High","Tranche 3","No tranche")))))) | O27: =IF(AND($B27<>"",$C27<>"Target state",$C27<>"Exception",$D27="High",$E27="Low"),$A27&" "&$B27,"") | P27: =IF(AND($B27<>"",$C27<>"Target state",$C27<>"Exception",$D27="High",$E27="Medium"),$A27&" "&$B27,"") | Q27: =IF(AND($B27<>"",$C27<>"Target state",$C27<>"Exception",$D27="High",$E27="High"),$A27&" "&$B27,"") | R27: =IF(AND($B27<>"",$C27<>"Target state",$C27<>"Exception",$D27="Medium",$E27="Low"),$A27&" "&$B27,"") | S27: =IF(AND($B27<>"",$C27<>"Target state",$C27<>"Exception",$D27="Medium",$E27="Medium"),$A27&" "&$B27,"") | T27: =IF(AND($B27<>"",$C27<>"Target state",$C27<>"Exception",$D27="Medium",$E27="High"),$A27&" "&$B27,"") | U27: =IF(AND($B27<>"",$C27<>"Target state",$C27<>"Exception",$D27="Low",$E27="Low"),$A27&" "&$B27,"") | V27: =IF(AND($B27<>"",$C27<>"Target state",$C27<>"Exception",$D27="Low",$E27="Medium"),$A27&" "&$B27,"") | W27: =IF(AND($B27<>"",$C27<>"Target state",$C27<>"Exception",$D27="Low",$E27="High"),$A27&" "&$B27,"")
A28: ⑮ | B28: Portico Website (POS Gateway) | C28: Non-target state | F28: Non-strategic internal UI for manual Portico boarding, configuration and research across US, Canada and UK portfolios | G28: =IF(OR($B28="",$D28="",$E28=""),"",IF(OR($C28="Target state",$C28="Exception"),"Out of scope",IF($D28="Low","No tranche",IF($E28="Low","Tranche 1",IF($E28="Medium","Tranche 2",IF($D28="High","Tranche 3","No tranche")))))) | O28: =IF(AND($B28<>"",$C28<>"Target state",$C28<>"Exception",$D28="High",$E28="Low"),$A28&" "&$B28,"") | P28: =IF(AND($B28<>"",$C28<>"Target state",$C28<>"Exception",$D28="High",$E28="Medium"),$A28&" "&$B28,"") | Q28: =IF(AND($B28<>"",$C28<>"Target state",$C28<>"Exception",$D28="High",$E28="High"),$A28&" "&$B28,"") | R28: =IF(AND($B28<>"",$C28<>"Target state",$C28<>"Exception",$D28="Medium",$E28="Low"),$A28&" "&$B28,"") | S28: =IF(AND($B28<>"",$C28<>"Target state",$C28<>"Exception",$D28="Medium",$E28="Medium"),$A28&" "&$B28,"") | T28: =IF(AND($B28<>"",$C28<>"Target state",$C28<>"Exception",$D28="Medium",$E28="High"),$A28&" "&$B28,"") | U28: =IF(AND($B28<>"",$C28<>"Target state",$C28<>"Exception",$D28="Low",$E28="Low"),$A28&" "&$B28,"") | V28: =IF(AND($B28<>"",$C28<>"Target state",$C28<>"Exception",$D28="Low",$E28="Medium"),$A28&" "&$B28,"") | W28: =IF(AND($B28<>"",$C28<>"Target state",$C28<>"Exception",$D28="Low",$E28="High"),$A28&" "&$B28,"")
A29: ⑯ | B29: NetSuite (Cayan) | C29: Non-target state | F29: Non-strategic SaaS boarding and servicing customization for the Cayan portfolio with about 670 users; around $670K in yearly cost | G29: =IF(OR($B29="",$D29="",$E29=""),"",IF(OR($C29="Target state",$C29="Exception"),"Out of scope",IF($D29="Low","No tranche",IF($E29="Low","Tranche 1",IF($E29="Medium","Tranche 2",IF($D29="High","Tranche 3","No tranche")))))) | O29: =IF(AND($B29<>"",$C29<>"Target state",$C29<>"Exception",$D29="High",$E29="Low"),$A29&" "&$B29,"") | P29: =IF(AND($B29<>"",$C29<>"Target state",$C29<>"Exception",$D29="High",$E29="Medium"),$A29&" "&$B29,"") | Q29: =IF(AND($B29<>"",$C29<>"Target state",$C29<>"Exception",$D29="High",$E29="High"),$A29&" "&$B29,"") | R29: =IF(AND($B29<>"",$C29<>"Target state",$C29<>"Exception",$D29="Medium",$E29="Low"),$A29&" "&$B29,"") | S29: =IF(AND($B29<>"",$C29<>"Target state",$C29<>"Exception",$D29="Medium",$E29="Medium"),$A29&" "&$B29,"") | T29: =IF(AND($B29<>"",$C29<>"Target state",$C29<>"Exception",$D29="Medium",$E29="High"),$A29&" "&$B29,"") | U29: =IF(AND($B29<>"",$C29<>"Target state",$C29<>"Exception",$D29="Low",$E29="Low"),$A29&" "&$B29,"") | V29: =IF(AND($B29<>"",$C29<>"Target state",$C29<>"Exception",$D29="Low",$E29="Medium"),$A29&" "&$B29,"") | W29: =IF(AND($B29<>"",$C29<>"Target state",$C29<>"Exception",$D29="Low",$E29="High"),$A29&" "&$B29,"")
A30: ⑰ | B30: Payroll CRM | C30: Non-target state | F30: Non-strategic boarding system for payroll clients with about 150 users; modest annual cost | G30: =IF(OR($B30="",$D30="",$E30=""),"",IF(OR($C30="Target state",$C30="Exception"),"Out of scope",IF($D30="Low","No tranche",IF($E30="Low","Tranche 1",IF($E30="Medium","Tranche 2",IF($D30="High","Tranche 3","No tranche")))))) | O30: =IF(AND($B30<>"",$C30<>"Target state",$C30<>"Exception",$D30="High",$E30="Low"),$A30&" "&$B30,"") | P30: =IF(AND($B30<>"",$C30<>"Target state",$C30<>"Exception",$D30="High",$E30="Medium"),$A30&" "&$B30,"") | Q30: =IF(AND($B30<>"",$C30<>"Target state",$C30<>"Exception",$D30="High",$E30="High"),$A30&" "&$B30,"") | R30: =IF(AND($B30<>"",$C30<>"Target state",$C30<>"Exception",$D30="Medium",$E30="Low"),$A30&" "&$B30,"") | S30: =IF(AND($B30<>"",$C30<>"Target state",$C30<>"Exception",$D30="Medium",$E30="Medium"),$A30&" "&$B30,"") | T30: =IF(AND($B30<>"",$C30<>"Target state",$C30<>"Exception",$D30="Medium",$E30="High"),$A30&" "&$B30,"") | U30: =IF(AND($B30<>"",$C30<>"Target state",$C30<>"Exception",$D30="Low",$E30="Low"),$A30&" "&$B30,"") | V30: =IF(AND($B30<>"",$C30<>"Target state",$C30<>"Exception",$D30="Low",$E30="Medium"),$A30&" "&$B30,"") | W30: =IF(AND($B30<>"",$C30<>"Target state",$C30<>"Exception",$D30="Low",$E30="High"),$A30&" "&$B30,"")
A31: ⑱ | B31: eContracts | C31: Non-target state | F31: Non-strategic merchant agreement and eSignature generation used in Poland; about 78K merchants processed; modest annual cost | G31: =IF(OR($B31="",$D31="",$E31=""),"",IF(OR($C31="Target state",$C31="Exception"),"Out of scope",IF($D31="Low","No tranche",IF($E31="Low","Tranche 1",IF($E31="Medium","Tranche 2",IF($D31="High","Tranche 3","No tranche")))))) | O31: =IF(AND($B31<>"",$C31<>"Target state",$C31<>"Exception",$D31="High",$E31="Low"),$A31&" "&$B31,"") | P31: =IF(AND($B31<>"",$C31<>"Target state",$C31<>"Exception",$D31="High",$E31="Medium"),$A31&" "&$B31,"") | Q31: =IF(AND($B31<>"",$C31<>"Target state",$C31<>"Exception",$D31="High",$E31="High"),$A31&" "&$B31,"") | R31: =IF(AND($B31<>"",$C31<>"Target state",$C31<>"Exception",$D31="Medium",$E31="Low"),$A31&" "&$B31,"") | S31: =IF(AND($B31<>"",$C31<>"Target state",$C31<>"Exception",$D31="Medium",$E31="Medium"),$A31&" "&$B31,"") | T31: =IF(AND($B31<>"",$C31<>"Target state",$C31<>"Exception",$D31="Medium",$E31="High"),$A31&" "&$B31,"") | U31: =IF(AND($B31<>"",$C31<>"Target state",$C31<>"Exception",$D31="Low",$E31="Low"),$A31&" "&$B31,"") | V31: =IF(AND($B31<>"",$C31<>"Target state",$C31<>"Exception",$D31="Low",$E31="Medium"),$A31&" "&$B31,"") | W31: =IF(AND($B31<>"",$C31<>"Target state",$C31<>"Exception",$D31="Low",$E31="High"),$A31&" "&$B31,"")
A32: ⑲ | B32: AssureSign | C32: Non-target state | F32: Third-party eSignature vendor for ELAPP priced per document; follows the ELAPP replacement path | G32: =IF(OR($B32="",$D32="",$E32=""),"",IF(OR($C32="Target state",$C32="Exception"),"Out of scope",IF($D32="Low","No tranche",IF($E32="Low","Tranche 1",IF($E32="Medium","Tranche 2",IF($D32="High","Tranche 3","No tranche")))))) | J32: Low | K32: =_xlfn.TEXTJOIN(CHAR(10),TRUE,U$14:U$39) | L32: =_xlfn.TEXTJOIN(CHAR(10),TRUE,V$14:V$39) | M32: =_xlfn.TEXTJOIN(CHAR(10),TRUE,W$14:W$39) | O32: =IF(AND($B32<>"",$C32<>"Target state",$C32<>"Exception",$D32="High",$E32="Low"),$A32&" "&$B32,"") | P32: =IF(AND($B32<>"",$C32<>"Target state",$C32<>"Exception",$D32="High",$E32="Medium"),$A32&" "&$B32,"") | Q32: =IF(AND($B32<>"",$C32<>"Target state",$C32<>"Exception",$D32="High",$E32="High"),$A32&" "&$B32,"") | R32: =IF(AND($B32<>"",$C32<>"Target state",$C32<>"Exception",$D32="Medium",$E32="Low"),$A32&" "&$B32,"") | S32: =IF(AND($B32<>"",$C32<>"Target state",$C32<>"Exception",$D32="Medium",$E32="Medium"),$A32&" "&$B32,"") | T32: =IF(AND($B32<>"",$C32<>"Target state",$C32<>"Exception",$D32="Medium",$E32="High"),$A32&" "&$B32,"") | U32: =IF(AND($B32<>"",$C32<>"Target state",$C32<>"Exception",$D32="Low",$E32="Low"),$A32&" "&$B32,"") | V32: =IF(AND($B32<>"",$C32<>"Target state",$C32<>"Exception",$D32="Low",$E32="Medium"),$A32&" "&$B32,"") | W32: =IF(AND($B32<>"",$C32<>"Target state",$C32<>"Exception",$D32="Low",$E32="High"),$A32&" "&$B32,"")
A33: ⑳ | B33: Agreement Express | C33: Non-target state | F33: Third-party eSignature tool used by the Cayan NetSuite boarding flow; on the decommission path | G33: =IF(OR($B33="",$D33="",$E33=""),"",IF(OR($C33="Target state",$C33="Exception"),"Out of scope",IF($D33="Low","No tranche",IF($E33="Low","Tranche 1",IF($E33="Medium","Tranche 2",IF($D33="High","Tranche 3","No tranche")))))) | O33: =IF(AND($B33<>"",$C33<>"Target state",$C33<>"Exception",$D33="High",$E33="Low"),$A33&" "&$B33,"") | P33: =IF(AND($B33<>"",$C33<>"Target state",$C33<>"Exception",$D33="High",$E33="Medium"),$A33&" "&$B33,"") | Q33: =IF(AND($B33<>"",$C33<>"Target state",$C33<>"Exception",$D33="High",$E33="High"),$A33&" "&$B33,"") | R33: =IF(AND($B33<>"",$C33<>"Target state",$C33<>"Exception",$D33="Medium",$E33="Low"),$A33&" "&$B33,"") | S33: =IF(AND($B33<>"",$C33<>"Target state",$C33<>"Exception",$D33="Medium",$E33="Medium"),$A33&" "&$B33,"") | T33: =IF(AND($B33<>"",$C33<>"Target state",$C33<>"Exception",$D33="Medium",$E33="High"),$A33&" "&$B33,"") | U33: =IF(AND($B33<>"",$C33<>"Target state",$C33<>"Exception",$D33="Low",$E33="Low"),$A33&" "&$B33,"") | V33: =IF(AND($B33<>"",$C33<>"Target state",$C33<>"Exception",$D33="Low",$E33="Medium"),$A33&" "&$B33,"") | W33: =IF(AND($B33<>"",$C33<>"Target state",$C33<>"Exception",$D33="Low",$E33="High"),$A33&" "&$B33,"")
A34: ㉑ | B34: Switch | C34: Non-target state | F34: Non-strategic boarding system for the Mainstream portfolio acquisition processing on the legacy TSYS stack; confirmed for decommission | G34: =IF(OR($B34="",$D34="",$E34=""),"",IF(OR($C34="Target state",$C34="Exception"),"Out of scope",IF($D34="Low","No tranche",IF($E34="Low","Tranche 1",IF($E34="Medium","Tranche 2",IF($D34="High","Tranche 3","No tranche")))))) | O34: =IF(AND($B34<>"",$C34<>"Target state",$C34<>"Exception",$D34="High",$E34="Low"),$A34&" "&$B34,"") | P34: =IF(AND($B34<>"",$C34<>"Target state",$C34<>"Exception",$D34="High",$E34="Medium"),$A34&" "&$B34,"") | Q34: =IF(AND($B34<>"",$C34<>"Target state",$C34<>"Exception",$D34="High",$E34="High"),$A34&" "&$B34,"") | R34: =IF(AND($B34<>"",$C34<>"Target state",$C34<>"Exception",$D34="Medium",$E34="Low"),$A34&" "&$B34,"") | S34: =IF(AND($B34<>"",$C34<>"Target state",$C34<>"Exception",$D34="Medium",$E34="Medium"),$A34&" "&$B34,"") | T34: =IF(AND($B34<>"",$C34<>"Target state",$C34<>"Exception",$D34="Medium",$E34="High"),$A34&" "&$B34,"") | U34: =IF(AND($B34<>"",$C34<>"Target state",$C34<>"Exception",$D34="Low",$E34="Low"),$A34&" "&$B34,"") | V34: =IF(AND($B34<>"",$C34<>"Target state",$C34<>"Exception",$D34="Low",$E34="Medium"),$A34&" "&$B34,"") | W34: =IF(AND($B34<>"",$C34<>"Target state",$C34<>"Exception",$D34="Low",$E34="High"),$A34&" "&$B34,"")
A35: ㉒ | B35: Fi911 | C35: Non-target state | F35: Third-party boarding and deployment platform supporting the NCR portfolio and Jumpman; about $240K in yearly cost; strategy is to move to in-house boarding | G35: =IF(OR($B35="",$D35="",$E35=""),"",IF(OR($C35="Target state",$C35="Exception"),"Out of scope",IF($D35="Low","No tranche",IF($E35="Low","Tranche 1",IF($E35="Medium","Tranche 2",IF($D35="High","Tranche 3","No tranche")))))) | O35: =IF(AND($B35<>"",$C35<>"Target state",$C35<>"Exception",$D35="High",$E35="Low"),$A35&" "&$B35,"") | P35: =IF(AND($B35<>"",$C35<>"Target state",$C35<>"Exception",$D35="High",$E35="Medium"),$A35&" "&$B35,"") | Q35: =IF(AND($B35<>"",$C35<>"Target state",$C35<>"Exception",$D35="High",$E35="High"),$A35&" "&$B35,"") | R35: =IF(AND($B35<>"",$C35<>"Target state",$C35<>"Exception",$D35="Medium",$E35="Low"),$A35&" "&$B35,"") | S35: =IF(AND($B35<>"",$C35<>"Target state",$C35<>"Exception",$D35="Medium",$E35="Medium"),$A35&" "&$B35,"") | T35: =IF(AND($B35<>"",$C35<>"Target state",$C35<>"Exception",$D35="Medium",$E35="High"),$A35&" "&$B35,"") | U35: =IF(AND($B35<>"",$C35<>"Target state",$C35<>"Exception",$D35="Low",$E35="Low"),$A35&" "&$B35,"") | V35: =IF(AND($B35<>"",$C35<>"Target state",$C35<>"Exception",$D35="Low",$E35="Medium"),$A35&" "&$B35,"") | W35: =IF(AND($B35<>"",$C35<>"Target state",$C35<>"Exception",$D35="Low",$E35="High"),$A35&" "&$B35,"")
A36: ㉓ | G36: =IF(OR($B36="",$D36="",$E36=""),"",IF(OR($C36="Target state",$C36="Exception"),"Out of scope",IF($D36="Low","No tranche",IF($E36="Low","Tranche 1",IF($E36="Medium","Tranche 2",IF($D36="High","Tranche 3","No tranche")))))) | O36: =IF(AND($B36<>"",$C36<>"Target state",$C36<>"Exception",$D36="High",$E36="Low"),$A36&" "&$B36,"") | P36: =IF(AND($B36<>"",$C36<>"Target state",$C36<>"Exception",$D36="High",$E36="Medium"),$A36&" "&$B36,"") | Q36: =IF(AND($B36<>"",$C36<>"Target state",$C36<>"Exception",$D36="High",$E36="High"),$A36&" "&$B36,"") | R36: =IF(AND($B36<>"",$C36<>"Target state",$C36<>"Exception",$D36="Medium",$E36="Low"),$A36&" "&$B36,"") | S36: =IF(AND($B36<>"",$C36<>"Target state",$C36<>"Exception",$D36="Medium",$E36="Medium"),$A36&" "&$B36,"") | T36: =IF(AND($B36<>"",$C36<>"Target state",$C36<>"Exception",$D36="Medium",$E36="High"),$A36&" "&$B36,"") | U36: =IF(AND($B36<>"",$C36<>"Target state",$C36<>"Exception",$D36="Low",$E36="Low"),$A36&" "&$B36,"") | V36: =IF(AND($B36<>"",$C36<>"Target state",$C36<>"Exception",$D36="Low",$E36="Medium"),$A36&" "&$B36,"") | W36: =IF(AND($B36<>"",$C36<>"Target state",$C36<>"Exception",$D36="Low",$E36="High"),$A36&" "&$B36,"")
A37: ㉔ | G37: =IF(OR($B37="",$D37="",$E37=""),"",IF(OR($C37="Target state",$C37="Exception"),"Out of scope",IF($D37="Low","No tranche",IF($E37="Low","Tranche 1",IF($E37="Medium","Tranche 2",IF($D37="High","Tranche 3","No tranche")))))) | O37: =IF(AND($B37<>"",$C37<>"Target state",$C37<>"Exception",$D37="High",$E37="Low"),$A37&" "&$B37,"") | P37: =IF(AND($B37<>"",$C37<>"Target state",$C37<>"Exception",$D37="High",$E37="Medium"),$A37&" "&$B37,"") | Q37: =IF(AND($B37<>"",$C37<>"Target state",$C37<>"Exception",$D37="High",$E37="High"),$A37&" "&$B37,"") | R37: =IF(AND($B37<>"",$C37<>"Target state",$C37<>"Exception",$D37="Medium",$E37="Low"),$A37&" "&$B37,"") | S37: =IF(AND($B37<>"",$C37<>"Target state",$C37<>"Exception",$D37="Medium",$E37="Medium"),$A37&" "&$B37,"") | T37: =IF(AND($B37<>"",$C37<>"Target state",$C37<>"Exception",$D37="Medium",$E37="High"),$A37&" "&$B37,"") | U37: =IF(AND($B37<>"",$C37<>"Target state",$C37<>"Exception",$D37="Low",$E37="Low"),$A37&" "&$B37,"") | V37: =IF(AND($B37<>"",$C37<>"Target state",$C37<>"Exception",$D37="Low",$E37="Medium"),$A37&" "&$B37,"") | W37: =IF(AND($B37<>"",$C37<>"Target state",$C37<>"Exception",$D37="Low",$E37="High"),$A37&" "&$B37,"")
A38: ㉕ | G38: =IF(OR($B38="",$D38="",$E38=""),"",IF(OR($C38="Target state",$C38="Exception"),"Out of scope",IF($D38="Low","No tranche",IF($E38="Low","Tranche 1",IF($E38="Medium","Tranche 2",IF($D38="High","Tranche 3","No tranche")))))) | O38: =IF(AND($B38<>"",$C38<>"Target state",$C38<>"Exception",$D38="High",$E38="Low"),$A38&" "&$B38,"") | P38: =IF(AND($B38<>"",$C38<>"Target state",$C38<>"Exception",$D38="High",$E38="Medium"),$A38&" "&$B38,"") | Q38: =IF(AND($B38<>"",$C38<>"Target state",$C38<>"Exception",$D38="High",$E38="High"),$A38&" "&$B38,"") | R38: =IF(AND($B38<>"",$C38<>"Target state",$C38<>"Exception",$D38="Medium",$E38="Low"),$A38&" "&$B38,"") | S38: =IF(AND($B38<>"",$C38<>"Target state",$C38<>"Exception",$D38="Medium",$E38="Medium"),$A38&" "&$B38,"") | T38: =IF(AND($B38<>"",$C38<>"Target state",$C38<>"Exception",$D38="Medium",$E38="High"),$A38&" "&$B38,"") | U38: =IF(AND($B38<>"",$C38<>"Target state",$C38<>"Exception",$D38="Low",$E38="Low"),$A38&" "&$B38,"") | V38: =IF(AND($B38<>"",$C38<>"Target state",$C38<>"Exception",$D38="Low",$E38="Medium"),$A38&" "&$B38,"") | W38: =IF(AND($B38<>"",$C38<>"Target state",$C38<>"Exception",$D38="Low",$E38="High"),$A38&" "&$B38,"")
A39: ㉖ | G39: =IF(OR($B39="",$D39="",$E39=""),"",IF(OR($C39="Target state",$C39="Exception"),"Out of scope",IF($D39="Low","No tranche",IF($E39="Low","Tranche 1",IF($E39="Medium","Tranche 2",IF($D39="High","Tranche 3","No tranche")))))) | O39: =IF(AND($B39<>"",$C39<>"Target state",$C39<>"Exception",$D39="High",$E39="Low"),$A39&" "&$B39,"") | P39: =IF(AND($B39<>"",$C39<>"Target state",$C39<>"Exception",$D39="High",$E39="Medium"),$A39&" "&$B39,"") | Q39: =IF(AND($B39<>"",$C39<>"Target state",$C39<>"Exception",$D39="High",$E39="High"),$A39&" "&$B39,"") | R39: =IF(AND($B39<>"",$C39<>"Target state",$C39<>"Exception",$D39="Medium",$E39="Low"),$A39&" "&$B39,"") | S39: =IF(AND($B39<>"",$C39<>"Target state",$C39<>"Exception",$D39="Medium",$E39="Medium"),$A39&" "&$B39,"") | T39: =IF(AND($B39<>"",$C39<>"Target state",$C39<>"Exception",$D39="Medium",$E39="High"),$A39&" "&$B39,"") | U39: =IF(AND($B39<>"",$C39<>"Target state",$C39<>"Exception",$D39="Low",$E39="Low"),$A39&" "&$B39,"") | V39: =IF(AND($B39<>"",$C39<>"Target state",$C39<>"Exception",$D39="Low",$E39="Medium"),$A39&" "&$B39,"") | W39: =IF(AND($B39<>"",$C39<>"Target state",$C39<>"Exception",$D39="Low",$E39="High"),$A39&" "&$B39,"")
K40: Complexity
A44: Ingress | G44: =HYPERLINK("#'Boarding'!A4","▲ tracker") | K44: Assessment Outcome
A45: # | B45: Platform | C45: State | D45: Imperative to exit | E45: Exit complexity | F45: Supporting facts | G45: Tranche (auto) | K45: Low | L45: Medium | M45: High
...

Sheet Single-in
A1: Single-in — Platform Assessment
A2: =HYPERLINK("#'Summary'!A1","← Back to Summary") | C2: Pick a State, score High / Medium / Low — the tranche, the matrix and the Summary update automatically.
A4: Tracker — jump to a sub-capability:
A5: 1. | B5: =HYPERLINK("#'Single-in'!A11","Global API")
A6: 2. | B6: =HYPERLINK("#'Single-in'!A27","Payment Apps & SDKs")
A7: 3. | B7: =HYPERLINK("#'Single-in'!A56","Developer Experience")
A8: 4. | B8: =HYPERLINK("#'Single-in'!A72","Hosted Solutions")
A9: 5. | B9: =HYPERLINK("#'Single-in'!A88","Unified Proposition")
A11: Global API | G11: =HYPERLINK("#'Single-in'!A4","▲ tracker") | K11: Assessment Outcome
A12: # | B12: Platform | C12: State | D12: Imperative to exit | E12: Exit complexity | F12: Supporting facts | G12: Tranche (auto) | K12: Low | L12: Medium | M12: High
A13: ① | B13: Comercia Addon2.0 API | C13: Non-target state | F13: Non-strategic Addon 2.0 integration API for Comercia merchants offered as JavaScript or host-to-host; on the decommission path | G13: =IF(OR($B13="",$D13="",$E13=""),"",IF(OR($C13="Target state",$C13="Exception"),"Out of scope",IF($D13="Low","No tranche",IF($E13="Low","Tranche 1",IF($E13="Medium","Tranche 2",IF($D13="High","Tranche 3","No tranche")))))) | I13: Benefits | J13: High | K13: ="Tranche 1"&CHAR(10)&_xlfn.TEXTJOIN(CHAR(10),TRUE,O$13:O$22) | L13: ="Tranche 2"&CHAR(10)&_xlfn.TEXTJOIN(CHAR(10),TRUE,P$13:P$22) | M13: ="Tranche 3"&CHAR(10)&_xlfn.TEXTJOIN(CHAR(10),TRUE,Q$13:Q$22) | O13: =IF(AND($B13<>"",$C13<>"Target state",$C13<>"Exception",$D13="High",$E13="Low"),$A13&" "&$B13,"") | P13: =IF(AND($B13<>"",$C13<>"Target state",$C13<>"Exception",$D13="High",$E13="Medium"),$A13&" "&$B13,"") | Q13: =IF(AND($B13<>"",$C13<>"Target state",$C13<>"Exception",$D13="High",$E13="High"),$A13&" "&$B13,"") | R13: =IF(AND($B13<>"",$C13<>"Target state",$C13<>"Exception",$D13="Medium",$E13="Low"),$A13&" "&$B13,"") | S13: =IF(AND($B13<>"",$C13<>"Target state",$C13<>"Exception",$D13="Medium",$E13="Medium"),$A13&" "&$B13,"") | T13: =IF(AND($B13<>"",$C13<>"Target state",$C13<>"Exception",$D13="Medium",$E13="High"),$A13&" "&$B13,"") | U13: =IF(AND($B13<>"",$C13<>"Target state",$C13<>"Exception",$D13="Low",$E13="Low"),$A13&" "&$B13,"") | V13: =IF(AND($B13<>"",$C13<>"Target state",$C13<>"Exception",$D13="Low",$E13="Medium"),$A13&" "&$B13,"") | W13: =IF(AND($B13<>"",$C13<>"Target state",$C13<>"Exception",$D13="Low",$E13="High"),$A13&" "&$B13,"")
A14: ② | G14: =IF(OR($B14="",$D14="",$E14=""),"",IF(OR($C14="Target state",$C14="Exception"),"Out of scope",IF($D14="Low","No tranche",IF($E14="Low","Tranche 1",IF($E14="Medium","Tranche 2",IF($D14="High","Tranche 3","No tranche")))))) | O14: =IF(AND($B14<>"",$C14<>"Target state",$C14<>"Exception",$D14="High",$E14="Low"),$A14&" "&$B14,"") | P14: =IF(AND($B14<>"",$C14<>"Target state",$C14<>"Exception",$D14="High",$E14="Medium"),$A14&" "&$B14,"") | Q14: =IF(AND($B14<>"",$C14<>"Target state",$C14<>"Exception",$D14="High",$E14="High"),$A14&" "&$B14,"") | R14: =IF(AND($B14<>"",$C14<>"Target state",$C14<>"Exception",$D14="Medium",$E14="Low"),$A14&" "&$B14,"") | S14: =IF(AND($B14<>"",$C14<>"Target state",$C14<>"Exception",$D14="Medium",$E14="Medium"),$A14&" "&$B14,"") | T14: =IF(AND($B14<>"",$C14<>"Target state",$C14<>"Exception",$D14="Medium",$E14="High"),$A14&" "&$B14,"") | U14: =IF(AND($B14<>"",$C14<>"Target state",$C14<>"Exception",$D14="Low",$E14="Low"),$A14&" "&$B14,"") | V14: =IF(AND($B14<>"",$C14<>"Target state",$C14<>"Exception",$D14="Low",$E14="Medium"),$A14&" "&$B14,"") | W14: =IF(AND($B14<>"",$C14<>"Target state",$C14<>"Exception",$D14="Low",$E14="High"),$A14&" "&$B14,"")
A15: ③ | G15: =IF(OR($B15="",$D15="",$E15=""),"",IF(OR($C15="Target state",$C15="Exception"),"Out of scope",IF($D15="Low","No tranche",IF($E15="Low","Tranche 1",IF($E15="Medium","Tranche 2",IF($D15="High","Tranche 3","No tranche")))))) | O15: =IF(AND($B15<>"",$C15<>"Target state",$C15<>"Exception",$D15="High",$E15="Low"),$A15&" "&$B15,"") | P15: =IF(AND($B15<>"",$C15<>"Target state",$C15<>"Exception",$D15="High",$E15="Medium"),$A15&" "&$B15,"") | Q15: =IF(AND($B15<>"",$C15<>"Target state",$C15<>"Exception",$D15="High",$E15="High"),$A15&" "&$B15,"") | R15: =IF(AND($B15<>"",$C15<>"Target state",$C15<>"Exception",$D15="Medium",$E15="Low"),$A15&" "&$B15,"") | S15: =IF(AND($B15<>"",$C15<>"Target state",$C15<>"Exception",$D15="Medium",$E15="Medium"),$A15&" "&$B15,"") | T15: =IF(AND($B15<>"",$C15<>"Target state",$C15<>"Exception",$D15="Medium",$E15="High"),$A15&" "&$B15,"") | U15: =IF(AND($B15<>"",$C15<>"Target state",$C15<>"Exception",$D15="Low",$E15="Low"),$A15&" "&$B15,"") | V15: =IF(AND($B15<>"",$C15<>"Target state",$C15<>"Exception",$D15="Low",$E15="Medium"),$A15&" "&$B15,"") | W15: =IF(AND($B15<>"",$C15<>"Target state",$C15<>"Exception",$D15="Low",$E15="High"),$A15&" "&$B15,"")
A16: ④ | G16: =IF(OR($B16="",$D16="",$E16=""),"",IF(OR($C16="Target state",$C16="Exception"),"Out of scope",IF($D16="Low","No tranche",IF($E16="Low","Tranche 1",IF($E16="Medium","Tranche 2",IF($D16="High","Tranche 3","No tranche")))))) | O16: =IF(AND($B16<>"",$C16<>"Target state",$C16<>"Exception",$D16="High",$E16="Low"),$A16&" "&$B16,"") | P16: =IF(AND($B16<>"",$C16<>"Target state",$C16<>"Exception",$D16="High",$E16="Medium"),$A16&" "&$B16,"") | Q16: =IF(AND($B16<>"",$C16<>"Target state",$C16<>"Exception",$D16="High",$E16="High"),$A16&" "&$B16,"") | R16: =IF(AND($B16<>"",$C16<>"Target state",$C16<>"Exception",$D16="Medium",$E16="Low"),$A16&" "&$B16,"") | S16: =IF(AND($B16<>"",$C16<>"Target state",$C16<>"Exception",$D16="Medium",$E16="Medium"),$A16&" "&$B16,"") | T16: =IF(AND($B16<>"",$C16<>"Target state",$C16<>"Exception",$D16="Medium",$E16="High"),$A16&" "&$B16,"") | U16: =IF(AND($B16<>"",$C16<>"Target state",$C16<>"Exception",$D16="Low",$E16="Low"),$A16&" "&$B16,"") | V16: =IF(AND($B16<>"",$C16<>"Target state",$C16<>"Exception",$D16="Low",$E16="Medium"),$A16&" "&$B16,"") | W16: =IF(AND($B16<>"",$C16<>"Target state",$C16<>"Exception",$D16="Low",$E16="High"),$A16&" "&$B16,"")
A17: ⑤ | G17: =IF(OR($B17="",$D17="",$E17=""),"",IF(OR($C17="Target state",$C17="Exception"),"Out of scope",IF($D17="Low","No tranche",IF($E17="Low","Tranche 1",IF($E17="Medium","Tranche 2",IF($D17="High","Tranche 3","No tranche")))))) | J17: Medium | K17: ="Tranche 1"&CHAR(10)&_xlfn.TEXTJOIN(CHAR(10),TRUE,R$13:R$22) | L17: ="Tranche 2"&CHAR(10)&_xlfn.TEXTJOIN(CHAR(10),TRUE,S$13:S$22) | M17: =_xlfn.TEXTJOIN(CHAR(10),TRUE,T$13:T$22) | O17: =IF(AND($B17<>"",$C17<>"Target state",$C17<>"Exception",$D17="High",$E17="Low"),$A17&" "&$B17,"") | P17: =IF(AND($B17<>"",$C17<>"Target state",$C17<>"Exception",$D17="High",$E17="Medium"),$A17&" "&$B17,"") | Q17: =IF(AND($B17<>"",$C17<>"Target state",$C17<>"Exception",$D17="High",$E17="High"),$A17&" "&$B17,"") | R17: =IF(AND($B17<>"",$C17<>"Target state",$C17<>"Exception",$D17="Medium",$E17="Low"),$A17&" "&$B17,"") | S17: =IF(AND($B17<>"",$C17<>"Target state",$C17<>"Exception",$D17="Medium",$E17="Medium"),$A17&" "&$B17,"") | T17: =IF(AND($B17<>"",$C17<>"Target state",$C17<>"Exception",$D17="Medium",$E17="High"),$A17&" "&$B17,"") | U17: =IF(AND($B17<>"",$C17<>"Target state",$C17<>"Exception",$D17="Low",$E17="Low"),$A17&" "&$B17,"") | V17: =IF(AND($B17<>"",$C17<>"Target state",$C17<>"Exception",$D17="Low",$E17="Medium"),$A17&" "&$B17,"") | W17: =IF(AND($B17<>"",$C17<>"Target state",$C17<>"Exception",$D17="Low",$E17="High"),$A17&" "&$B17,"")
A18: ⑥ | G18: =IF(OR($B18="",$D18="",$E18=""),"",IF(OR($C18="Target state",$C18="Exception"),"Out of scope",IF($D18="Low","No tranche",IF($E18="Low","Tranche 1",IF($E18="Medium","Tranche 2",IF($D18="High","Tranche 3","No tranche")))))) | O18: =IF(AND($B18<>"",$C18<>"Target state",$C18<>"Exception",$D18="High",$E18="Low"),$A18&" "&$B18,"") | P18: =IF(AND($B18<>"",$C18<>"Target state",$C18<>"Exception",$D18="High",$E18="Medium"),$A18&" "&$B18,"") | Q18: =IF(AND($B18<>"",$C18<>"Target state",$C18<>"Exception",$D18="High",$E18="High"),$A18&" "&$B18,"") | R18: =IF(AND($B18<>"",$C18<>"Target state",$C18<>"Exception",$D18="Medium",$E18="Low"),$A18&" "&$B18,"") | S18: =IF(AND($B18<>"",$C18<>"Target state",$C18<>"Exception",$D18="Medium",$E18="Medium"),$A18&" "&$B18,"") | T18: =IF(AND($B18<>"",$C18<>"Target state",$C18<>"Exception",$D18="Medium",$E18="High"),$A18&" "&$B18,"") | U18: =IF(AND($B18<>"",$C18<>"Target state",$C18<>"Exception",$D18="Low",$E18="Low"),$A18&" "&$B18,"") | V18: =IF(AND($B18<>"",$C18<>"Target state",$C18<>"Exception",$D18="Low",$E18="Medium"),$A18&" "&$B18,"") | W18: =IF(AND($B18<>"",$C18<>"Target state",$C18<>"Exception",$D18="Low",$E18="High"),$A18&" "&$B18,"")
